Workbook

Sheet Quarter
B1: SHIPPING
A2: FY2027 | B2: Quarter | C2: OCT | D2: NOV | E2: DEC | F2: ∑Q1 | G2: JAN | H2: FEB | I2: MAR | J2: ∑Q2 | K2: APR | L2: MAY | M2: JUN | N2: ∑Q3 | O2: JUL | P2: AUG | Q2: SEP | R2: ∑Q4 | S2: FY2027
B3: Permanent (Regular) Headcount | C3: =OCT!G3 | D3: =NOV!G3 | E3: =DEC!G3 | F3: =IFERROR(AVERAGE(C3:E3),"") | G3: =JAN!G3 | H3: =FEB!G3 | I3: =MAR!G3 | J3: =IFERROR(AVERAGE(G3:I3),"") | K3: =APR!G3 | L3: =MAY!G3 | M3: =JUN!G3 | N3: =IFERROR(AVERAGE(K3:M3),"") | O3: =JUL!G3 | P3: =AUG!G3 | Q3: =SEP!G3 | R3: =IFERROR(AVERAGE(O3:Q3),"") | S3: =IFERROR(AVERAGE(C3:E3,G3:I3,K3:M3,O3:Q3),"")
B4: Temporary (Fix Term) Headcount | C4: =OCT!G4 | D4: =NOV!G4 | E4: =DEC!G4 | F4: =IFERROR(AVERAGE(C4:E4),"") | G4: =JAN!G4 | H4: =FEB!G4 | I4: =MAR!G4 | J4: =IFERROR(AVERAGE(G4:I4),"") | K4: =APR!G4 | L4: =MAY!G4 | M4: =JUN!G4 | N4: =IFERROR(AVERAGE(K4:M4),"") | O4: =JUL!G4 | P4: =AUG!G4 | Q4: =SEP!G4 | R4: =IFERROR(AVERAGE(O4:Q4),"") | S4: =IFERROR(AVERAGE(C4:E4,G4:I4,K4:M4,O4:Q4),"")
B5: Employee Headcount (Productivity) | C5: =OCT!G5 | D5: =NOV!G5 | E5: =DEC!G5 | F5: =IF(COUNT(F3:F4)=0,"",SUM(F3:F4)) | G5: =JAN!G5 | H5: =FEB!G5 | I5: =MAR!G5 | J5: =IF(COUNT(J3:J4)=0,"",SUM(J3:J4)) | K5: =APR!G5 | L5: =MAY!G5 | M5: =JUN!G5 | N5: =IF(COUNT(N3:N4)=0,"",SUM(N3:N4)) | O5: =JUL!G5 | P5: =AUG!G5 | Q5: =SEP!G5 | R5: =IF(COUNT(R3:R4)=0,"",SUM(R3:R4)) | S5: =IF(COUNT(S3:S4)=0,"",SUM(S3:S4))
B6: Headcount = 1.00 | C6: =OCT!G6 | D6: =NOV!G6 | E6: =DEC!G6 | F6: =IFERROR(AVERAGE(C6:E6),"") | G6: =JAN!G6 | H6: =FEB!G6 | I6: =MAR!G6 | J6: =IFERROR(AVERAGE(G6:I6),"") | K6: =APR!G6 | L6: =MAY!G6 | M6: =JUN!G6 | N6: =IFERROR(AVERAGE(K6:M6),"") | O6: =JUL!G6 | P6: =AUG!G6 | Q6: =SEP!G6 | R6: =IFERROR(AVERAGE(O6:Q6),"") | S6: =IFERROR(AVERAGE(C6:E6,G6:I6,K6:M6,O6:Q6),"")
B7: Headcount = 0.75 | C7: =OCT!G7 | D7: =NOV!G7 | E7: =DEC!G7 | F7: =IFERROR(AVERAGE(C7:E7),"") | G7: =JAN!G7 | H7: =FEB!G7 | I7: =MAR!G7 | J7: =IFERROR(AVERAGE(G7:I7),"") | K7: =APR!G7 | L7: =MAY!G7 | M7: =JUN!G7 | N7: =IFERROR(AVERAGE(K7:M7),"") | O7: =JUL!G7 | P7: =AUG!G7 | Q7: =SEP!G7 | R7: =IFERROR(AVERAGE(O7:Q7),"") | S7: =IFERROR(AVERAGE(C7:E7,G7:I7,K7:M7,O7:Q7),"")
B8: Headcount = 0.50 | C8: =OCT!G8 | D8: =NOV!G8 | E8: =DEC!G8 | F8: =IFERROR(AVERAGE(C8:E8),"") | G8: =JAN!G8 | H8: =FEB!G8 | I8: =MAR!G8 | J8: =IFERROR(AVERAGE(G8:I8),"") | K8: =APR!G8 | L8: =MAY!G8 | M8: =JUN!G8 | N8: =IFERROR(AVERAGE(K8:M8),"") | O8: =JUL!G8 | P8: =AUG!G8 | Q8: =SEP!G8 | R8: =IFERROR(AVERAGE(O8:Q8),"") | S8: =IFERROR(AVERAGE(C8:E8,G8:I8,K8:M8,O8:Q8),"")
B9: Headcount = 0.25 | C9: =OCT!G9 | D9: =NOV!G9 | E9: =DEC!G9 | F9: =IFERROR(AVERAGE(C9:E9),"") | G9: =JAN!G9 | H9: =FEB!G9 | I9: =MAR!G9 | J9: =IFERROR(AVERAGE(G9:I9),"") | K9: =APR!G9 | L9: =MAY!G9 | M9: =JUN!G9 | N9: =IFERROR(AVERAGE(K9:M9),"") | O9: =JUL!G9 | P9: =AUG!G9 | Q9: =SEP!G9 | R9: =IFERROR(AVERAGE(O9:Q9),"") | S9: =IFERROR(AVERAGE(C9:E9,G9:I9,K9:M9,O9:Q9),"")
B10: Standard Monthly Hours (FTE basis) | C10: =OCT!G10 | D10: =NOV!G10 | E10: =DEC!G10 | F10: =IFERROR(AVERAGE(C10:E10),"") | G10: =JAN!G10 | H10: =FEB!G10 | I10: =MAR!G10 | J10: =IFERROR(AVERAGE(G10:I10),"") | K10: =APR!G10 | L10: =MAY!G10 | M10: =JUN!G10 | N10: =IFERROR(AVERAGE(K10:M10),"") | O10: =JUL!G10 | P10: =AUG!G10 | Q10: =SEP!G10 | R10: =IFERROR(AVERAGE(O10:Q10),"") | S10: =IFERROR(AVERAGE(C10:E10,G10:I10,K10:M10,O10:Q10),"")
B11: Employee FTE (Finance) | C11: =OCT!G11 | D11: =NOV!G11 | E11: =DEC!G11 | F11: =IF(COUNT(F6:F9)=0,"",N(F6)+N(F7)*0.75+N(F8)*0.5+N(F9)*0.25) | G11: =JAN!G11 | H11: =FEB!G11 | I11: =MAR!G11 | J11: =IF(COUNT(J6:J9)=0,"",N(J6)+N(J7)*0.75+N(J8)*0.5+N(J9)*0.25) | K11: =APR!G11 | L11: =MAY!G11 | M11: =JUN!G11 | N11: =IF(COUNT(N6:N9)=0,"",N(N6)+N(N7)*0.75+N(N8)*0.5+N(N9)*0.25) | O11: =JUL!G11 | P11: =AUG!G11 | Q11: =SEP!G11 | R11: =IF(COUNT(R6:R9)=0,"",N(R6)+N(R7)*0.75+N(R8)*0.5+N(R9)*0.25) | S11: =IF(COUNT(S6:S9)=0,"",N(S6)+N(S7)*0.75+N(S8)*0.5+N(S9)*0.25)
B12: Subcontracted Workforce HC | C12: =OCT!G12 | D12: =NOV!G12 | E12: =DEC!G12 | F12: =IFERROR(AVERAGE(C12:E12),"") | G12: =JAN!G12 | H12: =FEB!G12 | I12: =MAR!G12 | J12: =IFERROR(AVERAGE(G12:I12),"") | K12: =APR!G12 | L12: =MAY!G12 | M12: =JUN!G12 | N12: =IFERROR(AVERAGE(K12:M12),"") | O12: =JUL!G12 | P12: =AUG!G12 | Q12: =SEP!G12 | R12: =IFERROR(AVERAGE(O12:Q12),"") | S12: =IFERROR(AVERAGE(C12:E12,G12:I12,K12:M12,O12:Q12),"")
B13: Subcontracted Productive Hours | C13: =OCT!G13 | D13: =NOV!G13 | E13: =DEC!G13 | F13: =IFERROR(AVERAGE(C13:E13),"") | G13: =JAN!G13 | H13: =FEB!G13 | I13: =MAR!G13 | J13: =IFERROR(AVERAGE(G13:I13),"") | K13: =APR!G13 | L13: =MAY!G13 | M13: =JUN!G13 | N13: =IFERROR(AVERAGE(K13:M13),"") | O13: =JUL!G13 | P13: =AUG!G13 | Q13: =SEP!G13 | R13: =IFERROR(AVERAGE(O13:Q13),"") | S13: =IFERROR(AVERAGE(C13:E13,G13:I13,K13:M13,O13:Q13),"")
B14: Subcontracted FTE | C14: =OCT!G14 | D14: =NOV!G14 | E14: =DEC!G14 | F14: =IFERROR(F13/F10,"") | G14: =JAN!G14 | H14: =FEB!G14 | I14: =MAR!G14 | J14: =IFERROR(J13/J10,"") | K14: =APR!G14 | L14: =MAY!G14 | M14: =JUN!G14 | N14: =IFERROR(N13/N10,"") | O14: =JUL!G14 | P14: =AUG!G14 | Q14: =SEP!G14 | R14: =IFERROR(R13/R10,"") | S14: =IFERROR(S13/S10,"")
B15: Total Operational Workforce | C15: =OCT!G15 | D15: =NOV!G15 | E15: =DEC!G15 | F15: =IF(COUNT(F5,F12)=0,"",SUM(F5,F12)) | G15: =JAN!G15 | H15: =FEB!G15 | I15: =MAR!G15 | J15: =IF(COUNT(J5,J12)=0,"",SUM(J5,J12)) | K15: =APR!G15 | L15: =MAY!G15 | M15: =JUN!G15 | N15: =IF(COUNT(N5,N12)=0,"",SUM(N5,N12)) | O15: =JUL!G15 | P15: =AUG!G15 | Q15: =SEP!G15 | R15: =IF(COUNT(R5,R12)=0,"",SUM(R5,R12)) | S15: =IF(COUNT(S5,S12)=0,"",SUM(S5,S12))
B16: Total Operational FTE | C16: =OCT!G16 | D16: =NOV!G16 | E16: =DEC!G16 | F16: =IF(COUNT(F11,F14)=0,"",SUM(F11,F14)) | G16: =JAN!G16 | H16: =FEB!G16 | I16: =MAR!G16 | J16: =IF(COUNT(J11,J14)=0,"",SUM(J11,J14)) | K16: =APR!G16 | L16: =MAY!G16 | M16: =JUN!G16 | N16: =IF(COUNT(N11,N14)=0,"",SUM(N11,N14)) | O16: =JUL!G16 | P16: =AUG!G16 | Q16: =SEP!G16 | R16: =IF(COUNT(R11,R14)=0,"",SUM(R11,R14)) | S16: =IF(COUNT(S11,S14)=0,"",SUM(S11,S14))
B17: Subcontracted Share of Workforce (%) | C17: =OCT!G17 | D17: =NOV!G17 | E17: =DEC!G17 | F17: =IFERROR(F12/F15,"") | G17: =JAN!G17 | H17: =FEB!G17 | I17: =MAR!G17 | J17: =IFERROR(J12/J15,"") | K17: =APR!G17 | L17: =MAY!G17 | M17: =JUN!G17 | N17: =IFERROR(N12/N15,"") | O17: =JUL!G17 | P17: =AUG!G17 | Q17: =SEP!G17 | R17: =IFERROR(R12/R15,"") | S17: =IFERROR(S12/S15,"")
B18: FTE HR Team | C18: =OCT!G18 | D18: =NOV!G18 | E18: =DEC!G18 | F18: =IFERROR(AVERAGE(C18:E18),"") | G18: =JAN!G18 | H18: =FEB!G18 | I18: =MAR!G18 | J18: =IFERROR(AVERAGE(G18:I18),"") | K18: =APR!G18 | L18: =MAY!G18 | M18: =JUN!G18 | N18: =IFERROR(AVERAGE(K18:M18),"") | O18: =JUL!G18 | P18: =AUG!G18 | Q18: =SEP!G18 | R18: =IFERROR(AVERAGE(O18:Q18),"") | S18: =IFERROR(AVERAGE(C18:E18,G18:I18,K18:M18,O18:Q18),"")
B19: Permanent Hires | C19: =OCT!G19 | D19: =NOV!G19 | E19: =DEC!G19 | F19: =IF(COUNT(C19:E19)=0,"",SUM(C19:E19)) | G19: =JAN!G19 | H19: =FEB!G19 | I19: =MAR!G19 | J19: =IF(COUNT(G19:I19)=0,"",SUM(G19:I19)) | K19: =APR!G19 | L19: =MAY!G19 | M19: =JUN!G19 | N19: =IF(COUNT(K19:M19)=0,"",SUM(K19:M19)) | O19: =JUL!G19 | P19: =AUG!G19 | Q19: =SEP!G19 | R19: =IF(COUNT(O19:Q19)=0,"",SUM(O19:Q19)) | S19: =IF(COUNT(C19:E19,G19:I19,K19:M19,O19:Q19)=0,"",SUM(C19:E19,G19:I19,K19:M19,O19:Q19))
B20: Temporary Hires | C20: =OCT!G20 | D20: =NOV!G20 | E20: =DEC!G20 | F20: =IF(COUNT(C20:E20)=0,"",SUM(C20:E20)) | G20: =JAN!G20 | H20: =FEB!G20 | I20: =MAR!G20 | J20: =IF(COUNT(G20:I20)=0,"",SUM(G20:I20)) | K20: =APR!G20 | L20: =MAY!G20 | M20: =JUN!G20 | N20: =IF(COUNT(K20:M20)=0,"",SUM(K20:M20)) | O20: =JUL!G20 | P20: =AUG!G20 | Q20: =SEP!G20 | R20: =IF(COUNT(O20:Q20)=0,"",SUM(O20:Q20)) | S20: =IF(COUNT(C20:E20,G20:I20,K20:M20,O20:Q20)=0,"",SUM(C20:E20,G20:I20,K20:M20,O20:Q20))
B21: Total Hires | C21: =OCT!G21 | D21: =NOV!G21 | E21: =DEC!G21 | F21: =IF(COUNT(F19:F20)=0,"",SUM(F19:F20)) | G21: =JAN!G21 | H21: =FEB!G21 | I21: =MAR!G21 | J21: =IF(COUNT(J19:J20)=0,"",SUM(J19:J20)) | K21: =APR!G21 | L21: =MAY!G21 | M21: =JUN!G21 | N21: =IF(COUNT(N19:N20)=0,"",SUM(N19:N20)) | O21: =JUL!G21 | P21: =AUG!G21 | Q21: =SEP!G21 | R21: =IF(COUNT(R19:R20)=0,"",SUM(R19:R20)) | S21: =IF(COUNT(S19:S20)=0,"",SUM(S19:S20))
B22: Permanent Exits | C22: =OCT!G22 | D22: =NOV!G22 | E22: =DEC!G22 | F22: =IF(COUNT(C22:E22)=0,"",SUM(C22:E22)) | G22: =JAN!G22 | H22: =FEB!G22 | I22: =MAR!G22 | J22: =IF(COUNT(G22:I22)=0,"",SUM(G22:I22)) | K22: =APR!G22 | L22: =MAY!G22 | M22: =JUN!G22 | N22: =IF(COUNT(K22:M22)=0,"",SUM(K22:M22)) | O22: =JUL!G22 | P22: =AUG!G22 | Q22: =SEP!G22 | R22: =IF(COUNT(O22:Q22)=0,"",SUM(O22:Q22)) | S22: =IF(COUNT(C22:E22,G22:I22,K22:M22,O22:Q22)=0,"",SUM(C22:E22,G22:I22,K22:M22,O22:Q22))
B23: Temporary Exits | C23: =OCT!G23 | D23: =NOV!G23 | E23: =DEC!G23 | F23: =IF(COUNT(C23:E23)=0,"",SUM(C23:E23)) | G23: =JAN!G23 | H23: =FEB!G23 | I23: =MAR!G23 | J23: =IF(COUNT(G23:I23)=0,"",SUM(G23:I23)) | K23: =APR!G23 | L23: =MAY!G23 | M23: =JUN!G23 | N23: =IF(COUNT(K23:M23)=0,"",SUM(K23:M23)) | O23: =JUL!G23 | P23: =AUG!G23 | Q23: =SEP!G23 | R23: =IF(COUNT(O23:Q23)=0,"",SUM(O23:Q23)) | S23: =IF(COUNT(C23:E23,G23:I23,K23:M23,O23:Q23)=0,"",SUM(C23:E23,G23:I23,K23:M23,O23:Q23))
B24: Total Exits | C24: =OCT!G24 | D24: =NOV!G24 | E24: =DEC!G24 | F24: =IF(COUNT(F22:F23)=0,"",SUM(F22:F23)) | G24: =JAN!G24 | H24: =FEB!G24 | I24: =MAR!G24 | J24: =IF(COUNT(J22:J23)=0,"",SUM(J22:J23)) | K24: =APR!G24 | L24: =MAY!G24 | M24: =JUN!G24 | N24: =IF(COUNT(N22:N23)=0,"",SUM(N22:N23)) | O24: =JUL!G24 | P24: =AUG!G24 | Q24: =SEP!G24 | R24: =IF(COUNT(R22:R23)=0,"",SUM(R22:R23)) | S24: =IF(COUNT(S22:S23)=0,"",SUM(S22:S23))
B25: Permanent Turnover (%) | C25: =OCT!G25 | D25: =NOV!G25 | E25: =DEC!G25 | F25: =IF(COUNT(F31,F32)<2,"",IF((F32+F31)=0,"",N(F22)/((F32+F31)/2))) | G25: =JAN!G25 | H25: =FEB!G25 | I25: =MAR!G25 | J25: =IF(COUNT(J31,J32)<2,"",IF((J32+J31)=0,"",N(J22)/((J32+J31)/2))) | K25: =APR!G25 | L25: =MAY!G25 | M25: =JUN!G25 | N25: =IF(COUNT(N31,N32)<2,"",IF((N32+N31)=0,"",N(N22)/((N32+N31)/2))) | O25: =JUL!G25 | P25: =AUG!G25 | Q25: =SEP!G25 | R25: =IF(COUNT(R31,R32)<2,"",IF((R32+R31)=0,"",N(R22)/((R32+R31)/2))) | S25: =IF(COUNT(S31,S32)<2,"",IF((S32+S31)=0,"",N(S22)/((S32+S31)/2)))
B26: Temporary Turnover (%) | C26: =OCT!G26 | D26: =NOV!G26 | E26: =DEC!G26 | F26: =IF(COUNT(F31,F32)<2,"",IF((F32+F31)=0,"",N(F23)/((F32+F31)/2))) | G26: =JAN!G26 | H26: =FEB!G26 | I26: =MAR!G26 | J26: =IF(COUNT(J31,J32)<2,"",IF((J32+J31)=0,"",N(J23)/((J32+J31)/2))) | K26: =APR!G26 | L26: =MAY!G26 | M26: =JUN!G26 | N26: =IF(COUNT(N31,N32)<2,"",IF((N32+N31)=0,"",N(N23)/((N32+N31)/2))) | O26: =JUL!G26 | P26: =AUG!G26 | Q26: =SEP!G26 | R26: =IF(COUNT(R31,R32)<2,"",IF((R32+R31)=0,"",N(R23)/((R32+R31)/2))) | S26: =IF(COUNT(S31,S32)<2,"",IF((S32+S31)=0,"",N(S23)/((S32+S31)/2)))
B27: Voluntary Terminations | C27: =OCT!G27 | D27: =NOV!G27 | E27: =DEC!G27 | F27: =IF(COUNT(C27:E27)=0,"",SUM(C27:E27)) | G27: =JAN!G27 | H27: =FEB!G27 | I27: =MAR!G27 | J27: =IF(COUNT(G27:I27)=0,"",SUM(G27:I27)) | K27: =APR!G27 | L27: =MAY!G27 | M27: =JUN!G27 | N27: =IF(COUNT(K27:M27)=0,"",SUM(K27:M27)) | O27: =JUL!G27 | P27: =AUG!G27 | Q27: =SEP!G27 | R27: =IF(COUNT(O27:Q27)=0,"",SUM(O27:Q27)) | S27: =IF(COUNT(C27:E27,G27:I27,K27:M27,O27:Q27)=0,"",SUM(C27:E27,G27:I27,K27:M27,O27:Q27))
B28: Involuntary Terminations | C28: =OCT!G28 | D28: =NOV!G28 | E28: =DEC!G28 | F28: =IF(COUNT(C28:E28)=0,"",SUM(C28:E28)) | G28: =JAN!G28 | H28: =FEB!G28 | I28: =MAR!G28 | J28: =IF(COUNT(G28:I28)=0,"",SUM(G28:I28)) | K28: =APR!G28 | L28: =MAY!G28 | M28: =JUN!G28 | N28: =IF(COUNT(K28:M28)=0,"",SUM(K28:M28)) | O28: =JUL!G28 | P28: =AUG!G28 | Q28: =SEP!G28 | R28: =IF(COUNT(O28:Q28)=0,"",SUM(O28:Q28)) | S28: =IF(COUNT(C28:E28,G28:I28,K28:M28,O28:Q28)=0,"",SUM(C28:E28,G28:I28,K28:M28,O28:Q28))
B29: Voluntary Turnover (%) | C29: =OCT!G29 | D29: =NOV!G29 | E29: =DEC!G29 | F29: =IF(COUNT(F31,F32)<2,"",IF((F32+F31)=0,"",N(F27)/((F32+F31)/2))) | G29: =JAN!G29 | H29: =FEB!G29 | I29: =MAR!G29 | J29: =IF(COUNT(J31,J32)<2,"",IF((J32+J31)=0,"",N(J27)/((J32+J31)/2))) | K29: =APR!G29 | L29: =MAY!G29 | M29: =JUN!G29 | N29: =IF(COUNT(N31,N32)<2,"",IF((N32+N31)=0,"",N(N27)/((N32+N31)/2))) | O29: =JUL!G29 | P29: =AUG!G29 | Q29: =SEP!G29 | R29: =IF(COUNT(R31,R32)<2,"",IF((R32+R31)=0,"",N(R27)/((R32+R31)/2))) | S29: =IF(COUNT(S31,S32)<2,"",IF((S32+S31)=0,"",N(S27)/((S32+S31)/2)))
B30: Involuntary Turnover (%) | C30: =OCT!G30 | D30: =NOV!G30 | E30: =DEC!G30 | F30: =IF(COUNT(F31,F32)<2,"",IF((F32+F31)=0,"",N(F28)/((F32+F31)/2))) | G30: =JAN!G30 | H30: =FEB!G30 | I30: =MAR!G30 | J30: =IF(COUNT(J31,J32)<2,"",IF((J32+J31)=0,"",N(J28)/((J32+J31)/2))) | K30: =APR!G30 | L30: =MAY!G30 | M30: =JUN!G30 | N30: =IF(COUNT(N31,N32)<2,"",IF((N32+N31)=0,"",N(N28)/((N32+N31)/2))) | O30: =JUL!G30 | P30: =AUG!G30 | Q30: =SEP!G30 | R30: =IF(COUNT(R31,R32)<2,"",IF((R32+R31)=0,"",N(R28)/((R32+R31)/2))) | S30: =IF(COUNT(S31,S32)<2,"",IF((S32+S31)=0,"",N(S28)/((S32+S31)/2)))
B31: Headcount last Month | C31: =OCT!G31 | D31: =NOV!G31 | E31: =DEC!G31 | F31: =IFERROR(AVERAGE(C31:E31),"") | G31: =JAN!G31 | H31: =FEB!G31 | I31: =MAR!G31 | J31: =IFERROR(AVERAGE(G31:I31),"") | K31: =APR!G31 | L31: =MAY!G31 | M31: =JUN!G31 | N31: =IFERROR(AVERAGE(K31:M31),"") | O31: =JUL!G31 | P31: =AUG!G31 | Q31: =SEP!G31 | R31: =IFERROR(AVERAGE(O31:Q31),"") | S31: =IFERROR(AVERAGE(C31:E31,G31:I31,K31:M31,O31:Q31),"")
B32: Headcount this Month | C32: =OCT!G32 | D32: =NOV!G32 | E32: =DEC!G32 | F32: =IFERROR(AVERAGE(C32:E32),"") | G32: =JAN!G32 | H32: =FEB!G32 | I32: =MAR!G32 | J32: =IFERROR(AVERAGE(G32:I32),"") | K32: =APR!G32 | L32: =MAY!G32 | M32: =JUN!G32 | N32: =IFERROR(AVERAGE(K32:M32),"") | O32: =JUL!G32 | P32: =AUG!G32 | Q32: =SEP!G32 | R32: =IFERROR(AVERAGE(O32:Q32),"") | S32: =IFERROR(AVERAGE(C32:E32,G32:I32,K32:M32,O32:Q32),"")
B33: Full Turnover (%) | C33: =OCT!G33 | D33: =NOV!G33 | E33: =DEC!G33 | F33: =IF(COUNT(F31,F32)<2,"",IF((F32+F31)=0,"",N(F24)/((F32+F31)/2))) | G33: =JAN!G33 | H33: =FEB!G33 | I33: =MAR!G33 | J33: =IF(COUNT(J31,J32)<2,"",IF((J32+J31)=0,"",N(J24)/((J32+J31)/2))) | K33: =APR!G33 | L33: =MAY!G33 | M33: =JUN!G33 | N33: =IF(COUNT(N31,N32)<2,"",IF((N32+N31)=0,"",N(N24)/((N32+N31)/2))) | O33: =JUL!G33 | P33: =AUG!G33 | Q33: =SEP!G33 | R33: =IF(COUNT(R31,R32)<2,"",IF((R32+R31)=0,"",N(R24)/((R32+R31)/2))) | S33: =IF(COUNT(S31,S32)<2,"",IF((S32+S31)=0,"",N(S24)/((S32+S31)/2)))
B34: Permanent Vacancies | C34: =OCT!G34 | D34: =NOV!G34 | E34: =DEC!G34 | F34: =IFERROR(AVERAGE(C34:E34),"") | G34: =JAN!G34 | H34: =FEB!G34 | I34: =MAR!G34 | J34: =IFERROR(AVERAGE(G34:I34),"") | K34: =APR!G34 | L34: =MAY!G34 | M34: =JUN!G34 | N34: =IFERROR(AVERAGE(K34:M34),"") | O34: =JUL!G34 | P34: =AUG!G34 | Q34: =SEP!G34 | R34: =IFERROR(AVERAGE(O34:Q34),"") | S34: =IFERROR(AVERAGE(C34:E34,G34:I34,K34:M34,O34:Q34),"")
B35: Temporary Vacancies | C35: =OCT!G35 | D35: =NOV!G35 | E35: =DEC!G35 | F35: =IFERROR(AVERAGE(C35:E35),"") | G35: =JAN!G35 | H35: =FEB!G35 | I35: =MAR!G35 | J35: =IFERROR(AVERAGE(G35:I35),"") | K35: =APR!G35 | L35: =MAY!G35 | M35: =JUN!G35 | N35: =IFERROR(AVERAGE(K35:M35),"") | O35: =JUL!G35 | P35: =AUG!G35 | Q35: =SEP!G35 | R35: =IFERROR(AVERAGE(O35:Q35),"") | S35: =IFERROR(AVERAGE(C35:E35,G35:I35,K35:M35,O35:Q35),"")
B36: Total Vacancies | C36: =OCT!G36 | D36: =NOV!G36 | E36: =DEC!G36 | F36: =IF(COUNT(F34:F35)=0,"",SUM(F34:F35)) | G36: =JAN!G36 | H36: =FEB!G36 | I36: =MAR!G36 | J36: =IF(COUNT(J34:J35)=0,"",SUM(J34:J35)) | K36: =APR!G36 | L36: =MAY!G36 | M36: =JUN!G36 | N36: =IF(COUNT(N34:N35)=0,"",SUM(N34:N35)) | O36: =JUL!G36 | P36: =AUG!G36 | Q36: =SEP!G36 | R36: =IF(COUNT(R34:R35)=0,"",SUM(R34:R35)) | S36: =IF(COUNT(S34:S35)=0,"",SUM(S34:S35))
B37: Authorized Positions | C37: =OCT!G37 | D37: =NOV!G37 | E37: =DEC!G37 | F37: =IF(COUNT(F5,F36)=0,"",N(F5)+N(F36)) | G37: =JAN!G37 | H37: =FEB!G37 | I37: =MAR!G37 | J37: =IF(COUNT(J5,J36)=0,"",N(J5)+N(J36)) | K37: =APR!G37 | L37: =MAY!G37 | M37: =JUN!G37 | N37: =IF(COUNT(N5,N36)=0,"",N(N5)+N(N36)) | O37: =JUL!G37 | P37: =AUG!G37 | Q37: =SEP!G37 | R37: =IF(COUNT(R5,R36)=0,"",N(R5)+N(R36)) | S37: =IF(COUNT(S5,S36)=0,"",N(S5)+N(S36))
B38: Vacancy Rate (%) | C38: =OCT!G38 | D38: =NOV!G38 | E38: =DEC!G38 | F38: =IFERROR(F36/F37,"") | G38: =JAN!G38 | H38: =FEB!G38 | I38: =MAR!G38 | J38: =IFERROR(J36/J37,"") | K38: =APR!G38 | L38: =MAY!G38 | M38: =JUN!G38 | N38: =IFERROR(N36/N37,"") | O38: =JUL!G38 | P38: =AUG!G38 | Q38: =SEP!G38 | R38: =IFERROR(R36/R37,"") | S38: =IFERROR(S36/S37,"")
B39: Permanent TimeToHire (Days) YTD | C39: =OCT!G39 | D39: =NOV!G39 | E39: =DEC!G39 | F39: =IFERROR(LOOKUP(2,1/ISNUMBER(C39:E39),C39:E39),"") | G39: =JAN!G39 | H39: =FEB!G39 | I39: =MAR!G39 | J39: =IFERROR(LOOKUP(2,1/ISNUMBER(G39:I39),G39:I39),"") | K39: =APR!G39 | L39: =MAY!G39 | M39: =JUN!G39 | N39: =IFERROR(LOOKUP(2,1/ISNUMBER(K39:M39),K39:M39),"") | O39: =JUL!G39 | P39: =AUG!G39 | Q39: =SEP!G39 | R39: =IFERROR(LOOKUP(2,1/ISNUMBER(O39:Q39),O39:Q39),"") | S39: =IFERROR(LOOKUP(2,1/ISNUMBER(C39:Q39),C39:Q39),"")
B40: Temporary TimeToHire (Days) YTD | C40: =OCT!G40 | D40: =NOV!G40 | E40: =DEC!G40 | F40: =IFERROR(LOOKUP(2,1/ISNUMBER(C40:E40),C40:E40),"") | G40: =JAN!G40 | H40: =FEB!G40 | I40: =MAR!G40 | J40: =IFERROR(LOOKUP(2,1/ISNUMBER(G40:I40),G40:I40),"") | K40: =APR!G40 | L40: =MAY!G40 | M40: =JUN!G40 | N40: =IFERROR(LOOKUP(2,1/ISNUMBER(K40:M40),K40:M40),"") | O40: =JUL!G40 | P40: =AUG!G40 | Q40: =SEP!G40 | R40: =IFERROR(LOOKUP(2,1/ISNUMBER(O40:Q40),O40:Q40),"") | S40: =IFERROR(LOOKUP(2,1/ISNUMBER(C40:Q40),C40:Q40),"")
...

Sheet OCT
B1: SHIPPING
A2: 202610 | B2: OCT | C2: M&C Shipping | D2: Coreas Hazells (Shipping) | E2: Jonas Browne & Hubbard (Shipping) | F2: Goddards Shipping Barbados | G2: TOTAL | H2: Total by Division | I2: =N(I11)<>0
A3: =+A2 | B3: Permanent (Regular) Headcount | G3: =IF(COUNT(C3:F3)=0,"",SUM(C3:F3)) | H3: ∑
B4: Temporary (Fix Term) Headcount | G4: =IF(COUNT(C4:F4)=0,"",SUM(C4:F4)) | H4: ∑
B5: Employee Headcount (Productivity) | C5: =IF(COUNT(C3:C4)=0,"",SUM(C3:C4)) | D5: =IF(COUNT(D3:D4)=0,"",SUM(D3:D4)) | E5: =IF(COUNT(E3:E4)=0,"",SUM(E3:E4)) | F5: =IF(COUNT(F3:F4)=0,"",SUM(F3:F4)) | G5: =IF(COUNT(G3:G4)=0,"",SUM(G3:G4)) | H5: ϝ
B6: Headcount = 1.00 | G6: =IF(COUNT(C6:F6)=0,"",SUM(C6:F6)) | H6: ∑
B7: Headcount = 0.75 | G7: =IF(COUNT(C7:F7)=0,"",SUM(C7:F7)) | H7: ∑
B8: Headcount = 0.50 | G8: =IF(COUNT(C8:F8)=0,"",SUM(C8:F8)) | H8: ∑
B9: Headcount = 0.25 | G9: =IF(COUNT(C9:F9)=0,"",SUM(C9:F9)) | H9: ∑
B10: Standard Monthly Hours (FTE basis) | G10: =IFERROR(AVERAGE(C10:F10),"") | H10: Avg
B11: Employee FTE (Finance) | C11: =IF(COUNT(C6:C9)=0,"",N(C6)+N(C7)*0.75+N(C8)*0.5+N(C9)*0.25) | D11: =IF(COUNT(D6:D9)=0,"",N(D6)+N(D7)*0.75+N(D8)*0.5+N(D9)*0.25) | E11: =IF(COUNT(E6:E9)=0,"",N(E6)+N(E7)*0.75+N(E8)*0.5+N(E9)*0.25) | F11: =IF(COUNT(F6:F9)=0,"",N(F6)+N(F7)*0.75+N(F8)*0.5+N(F9)*0.25) | G11: =IF(COUNT(G6:G9)=0,"",N(G6)+N(G7)*0.75+N(G8)*0.5+N(G9)*0.25) | H11: FTE | I11: =IF(COUNT(G5:G9)=0,"",N(G6)+N(G7)+N(G8)+N(G9)-N(G5))
B12: Subcontracted Workforce HC | G12: =IF(COUNT(C12:F12)=0,"",SUM(C12:F12)) | H12: ∑
B13: Subcontracted Productive Hours | G13: =IF(COUNT(C13:F13)=0,"",SUM(C13:F13)) | H13: ∑
B14: Subcontracted FTE | C14: =IFERROR(C13/C10,"") | D14: =IFERROR(D13/D10,"") | E14: =IFERROR(E13/E10,"") | F14: =IFERROR(F13/F10,"") | G14: =IF(COUNT(C14:F14)=0,"",SUM(C14:F14)) | H14: FTE
B15: Total Operational Workforce | C15: =IF(COUNT(C5,C12)=0,"",SUM(C5,C12)) | D15: =IF(COUNT(D5,D12)=0,"",SUM(D5,D12)) | E15: =IF(COUNT(E5,E12)=0,"",SUM(E5,E12)) | F15: =IF(COUNT(F5,F12)=0,"",SUM(F5,F12)) | G15: =IF(COUNT(G5,G12)=0,"",SUM(G5,G12)) | H15: ϝ
B16: Total Operational FTE | C16: =IF(COUNT(C11,C14)=0,"",SUM(C11,C14)) | D16: =IF(COUNT(D11,D14)=0,"",SUM(D11,D14)) | E16: =IF(COUNT(E11,E14)=0,"",SUM(E11,E14)) | F16: =IF(COUNT(F11,F14)=0,"",SUM(F11,F14)) | G16: =IF(COUNT(G11,G14)=0,"",SUM(G11,G14)) | H16: FTE
B17: Subcontracted Share of Workforce (%) | C17: =IFERROR(C12/C15,"") | D17: =IFERROR(D12/D15,"") | E17: =IFERROR(E12/E15,"") | F17: =IFERROR(F12/F15,"") | G17: =IFERROR(G12/G15,"") | H17: ϝ
B18: FTE HR Team | G18: =IF(COUNT(C18:F18)=0,"",SUM(C18:F18)) | H18: ∑
B19: Permanent Hires | G19: =IF(COUNT(C19:F19)=0,"",SUM(C19:F19)) | H19: ∑
B20: Temporary Hires | G20: =IF(COUNT(C20:F20)=0,"",SUM(C20:F20)) | H20: ∑
B21: Total Hires | C21: =IF(COUNT(C19:C20)=0,"",SUM(C19:C20)) | D21: =IF(COUNT(D19:D20)=0,"",SUM(D19:D20)) | E21: =IF(COUNT(E19:E20)=0,"",SUM(E19:E20)) | F21: =IF(COUNT(F19:F20)=0,"",SUM(F19:F20)) | G21: =IF(COUNT(G19:G20)=0,"",SUM(G19:G20)) | H21: ϝ
B22: Permanent Exits | G22: =IF(COUNT(C22:F22)=0,"",SUM(C22:F22)) | H22: ∑
B23: Temporary Exits | G23: =IF(COUNT(C23:F23)=0,"",SUM(C23:F23)) | H23: ∑
B24: Total Exits | C24: =IF(COUNT(C22:C23)=0,"",SUM(C22:C23)) | D24: =IF(COUNT(D22:D23)=0,"",SUM(D22:D23)) | E24: =IF(COUNT(E22:E23)=0,"",SUM(E22:E23)) | F24: =IF(COUNT(F22:F23)=0,"",SUM(F22:F23)) | G24: =IF(COUNT(G22:G23)=0,"",SUM(G22:G23)) | H24: ϝ
B25: Permanent Turnover (%) | C25: =IF(COUNT(C31,C32)<2,"",IF((C32+C31)=0,"",N(C22)/((C32+C31)/2))) | D25: =IF(COUNT(D31,D32)<2,"",IF((D32+D31)=0,"",N(D22)/((D32+D31)/2))) | E25: =IF(COUNT(E31,E32)<2,"",IF((E32+E31)=0,"",N(E22)/((E32+E31)/2))) | F25: =IF(COUNT(F31,F32)<2,"",IF((F32+F31)=0,"",N(F22)/((F32+F31)/2))) | G25: =IF(COUNT(G31,G32)<2,"",IF((G32+G31)=0,"",N(G22)/((G32+G31)/2))) | H25: ϝ
B26: Temporary Turnover (%) | C26: =IF(COUNT(C31,C32)<2,"",IF((C32+C31)=0,"",N(C23)/((C32+C31)/2))) | D26: =IF(COUNT(D31,D32)<2,"",IF((D32+D31)=0,"",N(D23)/((D32+D31)/2))) | E26: =IF(COUNT(E31,E32)<2,"",IF((E32+E31)=0,"",N(E23)/((E32+E31)/2))) | F26: =IF(COUNT(F31,F32)<2,"",IF((F32+F31)=0,"",N(F23)/((F32+F31)/2))) | G26: =IF(COUNT(G31,G32)<2,"",IF((G32+G31)=0,"",N(G23)/((G32+G31)/2))) | H26: ϝ
B27: Voluntary Terminations | G27: =IF(COUNT(C27:F27)=0,"",SUM(C27:F27)) | H27: ∑
B28: Involuntary Terminations | G28: =IF(COUNT(C28:F28)=0,"",SUM(C28:F28)) | H28: ∑
B29: Voluntary Turnover (%) | C29: =IF(COUNT(C31,C32)<2,"",IF((C32+C31)=0,"",N(C27)/((C32+C31)/2))) | D29: =IF(COUNT(D31,D32)<2,"",IF((D32+D31)=0,"",N(D27)/((D32+D31)/2))) | E29: =IF(COUNT(E31,E32)<2,"",IF((E32+E31)=0,"",N(E27)/((E32+E31)/2))) | F29: =IF(COUNT(F31,F32)<2,"",IF((F32+F31)=0,"",N(F27)/((F32+F31)/2))) | G29: =IF(COUNT(G31,G32)<2,"",IF((G32+G31)=0,"",N(G27)/((G32+G31)/2))) | H29: ϝ
B30: Involuntary Turnover (%) | C30: =IF(COUNT(C31,C32)<2,"",IF((C32+C31)=0,"",N(C28)/((C32+C31)/2))) | D30: =IF(COUNT(D31,D32)<2,"",IF((D32+D31)=0,"",N(D28)/((D32+D31)/2))) | E30: =IF(COUNT(E31,E32)<2,"",IF((E32+E31)=0,"",N(E28)/((E32+E31)/2))) | F30: =IF(COUNT(F31,F32)<2,"",IF((F32+F31)=0,"",N(F28)/((F32+F31)/2))) | G30: =IF(COUNT(G31,G32)<2,"",IF((G32+G31)=0,"",N(G28)/((G32+G31)/2))) | H30: ϝ
B31: Headcount last Month | G31: =IF(COUNT(C31:F31)=0,"",SUM(C31:F31)) | H31: ∑
B32: Headcount this Month | C32: =IF(C5="","",C5) | D32: =IF(D5="","",D5) | E32: =IF(E5="","",E5) | F32: =IF(F5="","",F5) | G32: =IF(COUNT(C32:F32)=0,"",SUM(C32:F32)) | H32: ∑
B33: Full Turnover (%) | C33: =IF(COUNT(C31,C32)<2,"",IF((C32+C31)=0,"",N(C24)/((C32+C31)/2))) | D33: =IF(COUNT(D31,D32)<2,"",IF((D32+D31)=0,"",N(D24)/((D32+D31)/2))) | E33: =IF(COUNT(E31,E32)<2,"",IF((E32+E31)=0,"",N(E24)/((E32+E31)/2))) | F33: =IF(COUNT(F31,F32)<2,"",IF((F32+F31)=0,"",N(F24)/((F32+F31)/2))) | G33: =IF(COUNT(G31,G32)<2,"",IF((G32+G31)=0,"",N(G24)/((G32+G31)/2))) | H33: ϝ
B34: Permanent Vacancies | G34: =IF(COUNT(C34:F34)=0,"",SUM(C34:F34)) | H34: ∑
B35: Temporary Vacancies | G35: =IF(COUNT(C35:F35)=0,"",SUM(C35:F35)) | H35: ∑
B36: Total Vacancies | C36: =IF(COUNT(C34:C35)=0,"",SUM(C34:C35)) | D36: =IF(COUNT(D34:D35)=0,"",SUM(D34:D35)) | E36: =IF(COUNT(E34:E35)=0,"",SUM(E34:E35)) | F36: =IF(COUNT(F34:F35)=0,"",SUM(F34:F35)) | G36: =IF(COUNT(G34:G35)=0,"",SUM(G34:G35)) | H36: ϝ
B37: Authorized Positions | C37: =IF(COUNT(C5,C36)=0,"",N(C5)+N(C36)) | D37: =IF(COUNT(D5,D36)=0,"",N(D5)+N(D36)) | E37: =IF(COUNT(E5,E36)=0,"",N(E5)+N(E36)) | F37: =IF(COUNT(F5,F36)=0,"",N(F5)+N(F36)) | G37: =IF(COUNT(G5,G36)=0,"",N(G5)+N(G36)) | H37: ϝ
B38: Vacancy Rate (%) | C38: =IFERROR(C36/C37,"") | D38: =IFERROR(D36/D37,"") | E38: =IFERROR(E36/E37,"") | F38: =IFERROR(F36/F37,"") | G38: =IFERROR(G36/G37,"") | H38: ϝ
B39: Permanent TimeToHire (Days) YTD | C39: =IF('(M&C_Shipp)'!$AB$4="","",'(M&C_Shipp)'!$AB$4) | D39: =IF('(Coreas_Shipp)'!$AB$4="","",'(Coreas_Shipp)'!$AB$4) | E39: =IF('(JBH_Shipp)'!$AB$4="","",'(JBH_Shipp)'!$AB$4) | F39: =IF('(Shipping_BRB)'!$AB$4="","",'(Shipping_BRB)'!$AB$4) | G39: =IFERROR(AVERAGE(C39:F39),"") | H39: Avg
B40: Temporary TimeToHire (Days) YTD | C40: =IF('(M&C_Shipp)'!$AD$4="","",'(M&C_Shipp)'!$AD$4) | D40: =IF('(Coreas_Shipp)'!$AD$4="","",'(Coreas_Shipp)'!$AD$4) | E40: =IF('(JBH_Shipp)'!$AD$4="","",'(JBH_Shipp)'!$AD$4) | F40: =IF('(Shipping_BRB)'!$AD$4="","",'(Shipping_BRB)'!$AD$4) | G40: =IFERROR(AVERAGE(C40:F40),"") | H40: Avg
...

Sheet NOV
B1: SHIPPING
A2: =VALUE(TEXT(EDATE(DATE(LEFT(OCT!A2,4),RIGHT(OCT!A2,2),1),1),"yyyymm")) | B2: NOV | C2: M&C Shipping | D2: Coreas Hazells (Shipping) | E2: Jonas Browne & Hubbard (Shipping) | F2: Goddards Shipping Barbados | G2: TOTAL | H2: Total by Division | I2: =N(I11)<>0
A3: =+A2 | B3: Permanent (Regular) Headcount | G3: =IF(COUNT(C3:F3)=0,"",SUM(C3:F3)) | H3: ∑
B4: Temporary (Fix Term) Headcount | G4: =IF(COUNT(C4:F4)=0,"",SUM(C4:F4)) | H4: ∑
B5: Employee Headcount (Productivity) | C5: =IF(COUNT(C3:C4)=0,"",SUM(C3:C4)) | D5: =IF(COUNT(D3:D4)=0,"",SUM(D3:D4)) | E5: =IF(COUNT(E3:E4)=0,"",SUM(E3:E4)) | F5: =IF(COUNT(F3:F4)=0,"",SUM(F3:F4)) | G5: =IF(COUNT(G3:G4)=0,"",SUM(G3:G4)) | H5: ϝ
B6: Headcount = 1.00 | G6: =IF(COUNT(C6:F6)=0,"",SUM(C6:F6)) | H6: ∑
B7: Headcount = 0.75 | G7: =IF(COUNT(C7:F7)=0,"",SUM(C7:F7)) | H7: ∑
B8: Headcount = 0.50 | G8: =IF(COUNT(C8:F8)=0,"",SUM(C8:F8)) | H8: ∑
B9: Headcount = 0.25 | G9: =IF(COUNT(C9:F9)=0,"",SUM(C9:F9)) | H9: ∑
B10: Standard Monthly Hours (FTE basis) | G10: =IFERROR(AVERAGE(C10:F10),"") | H10: Avg
B11: Employee FTE (Finance) | C11: =IF(COUNT(C6:C9)=0,"",N(C6)+N(C7)*0.75+N(C8)*0.5+N(C9)*0.25) | D11: =IF(COUNT(D6:D9)=0,"",N(D6)+N(D7)*0.75+N(D8)*0.5+N(D9)*0.25) | E11: =IF(COUNT(E6:E9)=0,"",N(E6)+N(E7)*0.75+N(E8)*0.5+N(E9)*0.25) | F11: =IF(COUNT(F6:F9)=0,"",N(F6)+N(F7)*0.75+N(F8)*0.5+N(F9)*0.25) | G11: =IF(COUNT(G6:G9)=0,"",N(G6)+N(G7)*0.75+N(G8)*0.5+N(G9)*0.25) | H11: FTE | I11: =IF(COUNT(G5:G9)=0,"",N(G6)+N(G7)+N(G8)+N(G9)-N(G5))
B12: Subcontracted Workforce HC | G12: =IF(COUNT(C12:F12)=0,"",SUM(C12:F12)) | H12: ∑
B13: Subcontracted Productive Hours | G13: =IF(COUNT(C13:F13)=0,"",SUM(C13:F13)) | H13: ∑
B14: Subcontracted FTE | C14: =IFERROR(C13/C10,"") | D14: =IFERROR(D13/D10,"") | E14: =IFERROR(E13/E10,"") | F14: =IFERROR(F13/F10,"") | G14: =IF(COUNT(C14:F14)=0,"",SUM(C14:F14)) | H14: FTE
B15: Total Operational Workforce | C15: =IF(COUNT(C5,C12)=0,"",SUM(C5,C12)) | D15: =IF(COUNT(D5,D12)=0,"",SUM(D5,D12)) | E15: =IF(COUNT(E5,E12)=0,"",SUM(E5,E12)) | F15: =IF(COUNT(F5,F12)=0,"",SUM(F5,F12)) | G15: =IF(COUNT(G5,G12)=0,"",SUM(G5,G12)) | H15: ϝ
B16: Total Operational FTE | C16: =IF(COUNT(C11,C14)=0,"",SUM(C11,C14)) | D16: =IF(COUNT(D11,D14)=0,"",SUM(D11,D14)) | E16: =IF(COUNT(E11,E14)=0,"",SUM(E11,E14)) | F16: =IF(COUNT(F11,F14)=0,"",SUM(F11,F14)) | G16: =IF(COUNT(G11,G14)=0,"",SUM(G11,G14)) | H16: FTE
B17: Subcontracted Share of Workforce (%) | C17: =IFERROR(C12/C15,"") | D17: =IFERROR(D12/D15,"") | E17: =IFERROR(E12/E15,"") | F17: =IFERROR(F12/F15,"") | G17: =IFERROR(G12/G15,"") | H17: ϝ
B18: FTE HR Team | G18: =IF(COUNT(C18:F18)=0,"",SUM(C18:F18)) | H18: ∑
B19: Permanent Hires | G19: =IF(COUNT(C19:F19)=0,"",SUM(C19:F19)) | H19: ∑
B20: Temporary Hires | G20: =IF(COUNT(C20:F20)=0,"",SUM(C20:F20)) | H20: ∑
B21: Total Hires | C21: =IF(COUNT(C19:C20)=0,"",SUM(C19:C20)) | D21: =IF(COUNT(D19:D20)=0,"",SUM(D19:D20)) | E21: =IF(COUNT(E19:E20)=0,"",SUM(E19:E20)) | F21: =IF(COUNT(F19:F20)=0,"",SUM(F19:F20)) | G21: =IF(COUNT(G19:G20)=0,"",SUM(G19:G20)) | H21: ϝ
B22: Permanent Exits | G22: =IF(COUNT(C22:F22)=0,"",SUM(C22:F22)) | H22: ∑
B23: Temporary Exits | G23: =IF(COUNT(C23:F23)=0,"",SUM(C23:F23)) | H23: ∑
B24: Total Exits | C24: =IF(COUNT(C22:C23)=0,"",SUM(C22:C23)) | D24: =IF(COUNT(D22:D23)=0,"",SUM(D22:D23)) | E24: =IF(COUNT(E22:E23)=0,"",SUM(E22:E23)) | F24: =IF(COUNT(F22:F23)=0,"",SUM(F22:F23)) | G24: =IF(COUNT(G22:G23)=0,"",SUM(G22:G23)) | H24: ϝ
B25: Permanent Turnover (%) | C25: =IF(COUNT(C31,C32)<2,"",IF((C32+C31)=0,"",N(C22)/((C32+C31)/2))) | D25: =IF(COUNT(D31,D32)<2,"",IF((D32+D31)=0,"",N(D22)/((D32+D31)/2))) | E25: =IF(COUNT(E31,E32)<2,"",IF((E32+E31)=0,"",N(E22)/((E32+E31)/2))) | F25: =IF(COUNT(F31,F32)<2,"",IF((F32+F31)=0,"",N(F22)/((F32+F31)/2))) | G25: =IF(COUNT(G31,G32)<2,"",IF((G32+G31)=0,"",N(G22)/((G32+G31)/2))) | H25: ϝ
B26: Temporary Turnover (%) | C26: =IF(COUNT(C31,C32)<2,"",IF((C32+C31)=0,"",N(C23)/((C32+C31)/2))) | D26: =IF(COUNT(D31,D32)<2,"",IF((D32+D31)=0,"",N(D23)/((D32+D31)/2))) | E26: =IF(COUNT(E31,E32)<2,"",IF((E32+E31)=0,"",N(E23)/((E32+E31)/2))) | F26: =IF(COUNT(F31,F32)<2,"",IF((F32+F31)=0,"",N(F23)/((F32+F31)/2))) | G26: =IF(COUNT(G31,G32)<2,"",IF((G32+G31)=0,"",N(G23)/((G32+G31)/2))) | H26: ϝ
B27: Voluntary Terminations | G27: =IF(COUNT(C27:F27)=0,"",SUM(C27:F27)) | H27: ∑
B28: Involuntary Terminations | G28: =IF(COUNT(C28:F28)=0,"",SUM(C28:F28)) | H28: ∑
B29: Voluntary Turnover (%) | C29: =IF(COUNT(C31,C32)<2,"",IF((C32+C31)=0,"",N(C27)/((C32+C31)/2))) | D29: =IF(COUNT(D31,D32)<2,"",IF((D32+D31)=0,"",N(D27)/((D32+D31)/2))) | E29: =IF(COUNT(E31,E32)<2,"",IF((E32+E31)=0,"",N(E27)/((E32+E31)/2))) | F29: =IF(COUNT(F31,F32)<2,"",IF((F32+F31)=0,"",N(F27)/((F32+F31)/2))) | G29: =IF(COUNT(G31,G32)<2,"",IF((G32+G31)=0,"",N(G27)/((G32+G31)/2))) | H29: ϝ
B30: Involuntary Turnover (%) | C30: =IF(COUNT(C31,C32)<2,"",IF((C32+C31)=0,"",N(C28)/((C32+C31)/2))) | D30: =IF(COUNT(D31,D32)<2,"",IF((D32+D31)=0,"",N(D28)/((D32+D31)/2))) | E30: =IF(COUNT(E31,E32)<2,"",IF((E32+E31)=0,"",N(E28)/((E32+E31)/2))) | F30: =IF(COUNT(F31,F32)<2,"",IF((F32+F31)=0,"",N(F28)/((F32+F31)/2))) | G30: =IF(COUNT(G31,G32)<2,"",IF((G32+G31)=0,"",N(G28)/((G32+G31)/2))) | H30: ϝ
B31: Headcount last Month | C31: =IF(OCT!C5="","",OCT!C5) | D31: =IF(OCT!D5="","",OCT!D5) | E31: =IF(OCT!E5="","",OCT!E5) | F31: =IF(OCT!F5="","",OCT!F5) | G31: =IF(COUNT(C31:F31)=0,"",SUM(C31:F31)) | H31: ∑
B32: Headcount this Month | C32: =IF(C5="","",C5) | D32: =IF(D5="","",D5) | E32: =IF(E5="","",E5) | F32: =IF(F5="","",F5) | G32: =IF(COUNT(C32:F32)=0,"",SUM(C32:F32)) | H32: ∑
B33: Full Turnover (%) | C33: =IF(COUNT(C31,C32)<2,"",IF((C32+C31)=0,"",N(C24)/((C32+C31)/2))) | D33: =IF(COUNT(D31,D32)<2,"",IF((D32+D31)=0,"",N(D24)/((D32+D31)/2))) | E33: =IF(COUNT(E31,E32)<2,"",IF((E32+E31)=0,"",N(E24)/((E32+E31)/2))) | F33: =IF(COUNT(F31,F32)<2,"",IF((F32+F31)=0,"",N(F24)/((F32+F31)/2))) | G33: =IF(COUNT(G31,G32)<2,"",IF((G32+G31)=0,"",N(G24)/((G32+G31)/2))) | H33: ϝ
B34: Permanent Vacancies | G34: =IF(COUNT(C34:F34)=0,"",SUM(C34:F34)) | H34: ∑
B35: Temporary Vacancies | G35: =IF(COUNT(C35:F35)=0,"",SUM(C35:F35)) | H35: ∑
B36: Total Vacancies | C36: =IF(COUNT(C34:C35)=0,"",SUM(C34:C35)) | D36: =IF(COUNT(D34:D35)=0,"",SUM(D34:D35)) | E36: =IF(COUNT(E34:E35)=0,"",SUM(E34:E35)) | F36: =IF(COUNT(F34:F35)=0,"",SUM(F34:F35)) | G36: =IF(COUNT(G34:G35)=0,"",SUM(G34:G35)) | H36: ϝ
B37: Authorized Positions | C37: =IF(COUNT(C5,C36)=0,"",N(C5)+N(C36)) | D37: =IF(COUNT(D5,D36)=0,"",N(D5)+N(D36)) | E37: =IF(COUNT(E5,E36)=0,"",N(E5)+N(E36)) | F37: =IF(COUNT(F5,F36)=0,"",N(F5)+N(F36)) | G37: =IF(COUNT(G5,G36)=0,"",N(G5)+N(G36)) | H37: ϝ
B38: Vacancy Rate (%) | C38: =IFERROR(C36/C37,"") | D38: =IFERROR(D36/D37,"") | E38: =IFERROR(E36/E37,"") | F38: =IFERROR(F36/F37,"") | G38: =IFERROR(G36/G37,"") | H38: ϝ
B39: Permanent TimeToHire (Days) YTD | C39: =IF('(M&C_Shipp)'!$AB$5="","",'(M&C_Shipp)'!$AB$5) | D39: =IF('(Coreas_Shipp)'!$AB$5="","",'(Coreas_Shipp)'!$AB$5) | E39: =IF('(JBH_Shipp)'!$AB$5="","",'(JBH_Shipp)'!$AB$5) | F39: =IF('(Shipping_BRB)'!$AB$5="","",'(Shipping_BRB)'!$AB$5) | G39: =IFERROR(AVERAGE(C39:F39),"") | H39: Avg
B40: Temporary TimeToHire (Days) YTD | C40: =IF('(M&C_Shipp)'!$AD$5="","",'(M&C_Shipp)'!$AD$5) | D40: =IF('(Coreas_Shipp)'!$AD$5="","",'(Coreas_Shipp)'!$AD$5) | E40: =IF('(JBH_Shipp)'!$AD$5="","",'(JBH_Shipp)'!$AD$5) | F40: =IF('(Shipping_BRB)'!$AD$5="","",'(Shipping_BRB)'!$AD$5) | G40: =IFERROR(AVERAGE(C40:F40),"") | H40: Avg
...

Sheet DEC
B1: SHIPPING
A2: =VALUE(TEXT(EDATE(DATE(LEFT(NOV!A2,4),RIGHT(NOV!A2,2),1),1),"yyyymm")) | B2: DEC | C2: M&C Shipping | D2: Coreas Hazells (Shipping) | E2: Jonas Browne & Hubbard (Shipping) | F2: Goddards Shipping Barbados | G2: TOTAL | H2: Total by Division | I2: =N(I11)<>0
A3: =+A2 | B3: Permanent (Regular) Headcount | G3: =IF(COUNT(C3:F3)=0,"",SUM(C3:F3)) | H3: ∑
B4: Temporary (Fix Term) Headcount | G4: =IF(COUNT(C4:F4)=0,"",SUM(C4:F4)) | H4: ∑
B5: Employee Headcount (Productivity) | C5: =IF(COUNT(C3:C4)=0,"",SUM(C3:C4)) | D5: =IF(COUNT(D3:D4)=0,"",SUM(D3:D4)) | E5: =IF(COUNT(E3:E4)=0,"",SUM(E3:E4)) | F5: =IF(COUNT(F3:F4)=0,"",SUM(F3:F4)) | G5: =IF(COUNT(G3:G4)=0,"",SUM(G3:G4)) | H5: ϝ
B6: Headcount = 1.00 | G6: =IF(COUNT(C6:F6)=0,"",SUM(C6:F6)) | H6: ∑
B7: Headcount = 0.75 | G7: =IF(COUNT(C7:F7)=0,"",SUM(C7:F7)) | H7: ∑
B8: Headcount = 0.50 | G8: =IF(COUNT(C8:F8)=0,"",SUM(C8:F8)) | H8: ∑
B9: Headcount = 0.25 | G9: =IF(COUNT(C9:F9)=0,"",SUM(C9:F9)) | H9: ∑
B10: Standard Monthly Hours (FTE basis) | G10: =IFERROR(AVERAGE(C10:F10),"") | H10: Avg
B11: Employee FTE (Finance) | C11: =IF(COUNT(C6:C9)=0,"",N(C6)+N(C7)*0.75+N(C8)*0.5+N(C9)*0.25) | D11: =IF(COUNT(D6:D9)=0,"",N(D6)+N(D7)*0.75+N(D8)*0.5+N(D9)*0.25) | E11: =IF(COUNT(E6:E9)=0,"",N(E6)+N(E7)*0.75+N(E8)*0.5+N(E9)*0.25) | F11: =IF(COUNT(F6:F9)=0,"",N(F6)+N(F7)*0.75+N(F8)*0.5+N(F9)*0.25) | G11: =IF(COUNT(G6:G9)=0,"",N(G6)+N(G7)*0.75+N(G8)*0.5+N(G9)*0.25) | H11: FTE | I11: =IF(COUNT(G5:G9)=0,"",N(G6)+N(G7)+N(G8)+N(G9)-N(G5))
B12: Subcontracted Workforce HC | G12: =IF(COUNT(C12:F12)=0,"",SUM(C12:F12)) | H12: ∑
B13: Subcontracted Productive Hours | G13: =IF(COUNT(C13:F13)=0,"",SUM(C13:F13)) | H13: ∑
B14: Subcontracted FTE | C14: =IFERROR(C13/C10,"") | D14: =IFERROR(D13/D10,"") | E14: =IFERROR(E13/E10,"") | F14: =IFERROR(F13/F10,"") | G14: =IF(COUNT(C14:F14)=0,"",SUM(C14:F14)) | H14: FTE
B15: Total Operational Workforce | C15: =IF(COUNT(C5,C12)=0,"",SUM(C5,C12)) | D15: =IF(COUNT(D5,D12)=0,"",SUM(D5,D12)) | E15: =IF(COUNT(E5,E12)=0,"",SUM(E5,E12)) | F15: =IF(COUNT(F5,F12)=0,"",SUM(F5,F12)) | G15: =IF(COUNT(G5,G12)=0,"",SUM(G5,G12)) | H15: ϝ
B16: Total Operational FTE | C16: =IF(COUNT(C11,C14)=0,"",SUM(C11,C14)) | D16: =IF(COUNT(D11,D14)=0,"",SUM(D11,D14)) | E16: =IF(COUNT(E11,E14)=0,"",SUM(E11,E14)) | F16: =IF(COUNT(F11,F14)=0,"",SUM(F11,F14)) | G16: =IF(COUNT(G11,G14)=0,"",SUM(G11,G14)) | H16: FTE
B17: Subcontracted Share of Workforce (%) | C17: =IFERROR(C12/C15,"") | D17: =IFERROR(D12/D15,"") | E17: =IFERROR(E12/E15,"") | F17: =IFERROR(F12/F15,"") | G17: =IFERROR(G12/G15,"") | H17: ϝ
B18: FTE HR Team | G18: =IF(COUNT(C18:F18)=0,"",SUM(C18:F18)) | H18: ∑
B19: Permanent Hires | G19: =IF(COUNT(C19:F19)=0,"",SUM(C19:F19)) | H19: ∑
B20: Temporary Hires | G20: =IF(COUNT(C20:F20)=0,"",SUM(C20:F20)) | H20: ∑
B21: Total Hires | C21: =IF(COUNT(C19:C20)=0,"",SUM(C19:C20)) | D21: =IF(COUNT(D19:D20)=0,"",SUM(D19:D20)) | E21: =IF(COUNT(E19:E20)=0,"",SUM(E19:E20)) | F21: =IF(COUNT(F19:F20)=0,"",SUM(F19:F20)) | G21: =IF(COUNT(G19:G20)=0,"",SUM(G19:G20)) | H21: ϝ
B22: Permanent Exits | G22: =IF(COUNT(C22:F22)=0,"",SUM(C22:F22)) | H22: ∑
B23: Temporary Exits | G23: =IF(COUNT(C23:F23)=0,"",SUM(C23:F23)) | H23: ∑
B24: Total Exits | C24: =IF(COUNT(C22:C23)=0,"",SUM(C22:C23)) | D24: =IF(COUNT(D22:D23)=0,"",SUM(D22:D23)) | E24: =IF(COUNT(E22:E23)=0,"",SUM(E22:E23)) | F24: =IF(COUNT(F22:F23)=0,"",SUM(F22:F23)) | G24: =IF(COUNT(G22:G23)=0,"",SUM(G22:G23)) | H24: ϝ
B25: Permanent Turnover (%) | C25: =IF(COUNT(C31,C32)<2,"",IF((C32+C31)=0,"",N(C22)/((C32+C31)/2))) | D25: =IF(COUNT(D31,D32)<2,"",IF((D32+D31)=0,"",N(D22)/((D32+D31)/2))) | E25: =IF(COUNT(E31,E32)<2,"",IF((E32+E31)=0,"",N(E22)/((E32+E31)/2))) | F25: =IF(COUNT(F31,F32)<2,"",IF((F32+F31)=0,"",N(F22)/((F32+F31)/2))) | G25: =IF(COUNT(G31,G32)<2,"",IF((G32+G31)=0,"",N(G22)/((G32+G31)/2))) | H25: ϝ
B26: Temporary Turnover (%) | C26: =IF(COUNT(C31,C32)<2,"",IF((C32+C31)=0,"",N(C23)/((C32+C31)/2))) | D26: =IF(COUNT(D31,D32)<2,"",IF((D32+D31)=0,"",N(D23)/((D32+D31)/2))) | E26: =IF(COUNT(E31,E32)<2,"",IF((E32+E31)=0,"",N(E23)/((E32+E31)/2))) | F26: =IF(COUNT(F31,F32)<2,"",IF((F32+F31)=0,"",N(F23)/((F32+F31)/2))) | G26: =IF(COUNT(G31,G32)<2,"",IF((G32+G31)=0,"",N(G23)/((G32+G31)/2))) | H26: ϝ
B27: Voluntary Terminations | G27: =IF(COUNT(C27:F27)=0,"",SUM(C27:F27)) | H27: ∑
B28: Involuntary Terminations | G28: =IF(COUNT(C28:F28)=0,"",SUM(C28:F28)) | H28: ∑
B29: Voluntary Turnover (%) | C29: =IF(COUNT(C31,C32)<2,"",IF((C32+C31)=0,"",N(C27)/((C32+C31)/2))) | D29: =IF(COUNT(D31,D32)<2,"",IF((D32+D31)=0,"",N(D27)/((D32+D31)/2))) | E29: =IF(COUNT(E31,E32)<2,"",IF((E32+E31)=0,"",N(E27)/((E32+E31)/2))) | F29: =IF(COUNT(F31,F32)<2,"",IF((F32+F31)=0,"",N(F27)/((F32+F31)/2))) | G29: =IF(COUNT(G31,G32)<2,"",IF((G32+G31)=0,"",N(G27)/((G32+G31)/2))) | H29: ϝ
B30: Involuntary Turnover (%) | C30: =IF(COUNT(C31,C32)<2,"",IF((C32+C31)=0,"",N(C28)/((C32+C31)/2))) | D30: =IF(COUNT(D31,D32)<2,"",IF((D32+D31)=0,"",N(D28)/((D32+D31)/2))) | E30: =IF(COUNT(E31,E32)<2,"",IF((E32+E31)=0,"",N(E28)/((E32+E31)/2))) | F30: =IF(COUNT(F31,F32)<2,"",IF((F32+F31)=0,"",N(F28)/((F32+F31)/2))) | G30: =IF(COUNT(G31,G32)<2,"",IF((G32+G31)=0,"",N(G28)/((G32+G31)/2))) | H30: ϝ
B31: Headcount last Month | C31: =IF(NOV!C5="","",NOV!C5) | D31: =IF(NOV!D5="","",NOV!D5) | E31: =IF(NOV!E5="","",NOV!E5) | F31: =IF(NOV!F5="","",NOV!F5) | G31: =IF(COUNT(C31:F31)=0,"",SUM(C31:F31)) | H31: ∑
B32: Headcount this Month | C32: =IF(C5="","",C5) | D32: =IF(D5="","",D5) | E32: =IF(E5="","",E5) | F32: =IF(F5="","",F5) | G32: =IF(COUNT(C32:F32)=0,"",SUM(C32:F32)) | H32: ∑
B33: Full Turnover (%) | C33: =IF(COUNT(C31,C32)<2,"",IF((C32+C31)=0,"",N(C24)/((C32+C31)/2))) | D33: =IF(COUNT(D31,D32)<2,"",IF((D32+D31)=0,"",N(D24)/((D32+D31)/2))) | E33: =IF(COUNT(E31,E32)<2,"",IF((E32+E31)=0,"",N(E24)/((E32+E31)/2))) | F33: =IF(COUNT(F31,F32)<2,"",IF((F32+F31)=0,"",N(F24)/((F32+F31)/2))) | G33: =IF(COUNT(G31,G32)<2,"",IF((G32+G31)=0,"",N(G24)/((G32+G31)/2))) | H33: ϝ
B34: Permanent Vacancies | G34: =IF(COUNT(C34:F34)=0,"",SUM(C34:F34)) | H34: ∑
B35: Temporary Vacancies | G35: =IF(COUNT(C35:F35)=0,"",SUM(C35:F35)) | H35: ∑
B36: Total Vacancies | C36: =IF(COUNT(C34:C35)=0,"",SUM(C34:C35)) | D36: =IF(COUNT(D34:D35)=0,"",SUM(D34:D35)) | E36: =IF(COUNT(E34:E35)=0,"",SUM(E34:E35)) | F36: =IF(COUNT(F34:F35)=0,"",SUM(F34:F35)) | G36: =IF(COUNT(G34:G35)=0,"",SUM(G34:G35)) | H36: ϝ
B37: Authorized Positions | C37: =IF(COUNT(C5,C36)=0,"",N(C5)+N(C36)) | D37: =IF(COUNT(D5,D36)=0,"",N(D5)+N(D36)) | E37: =IF(COUNT(E5,E36)=0,"",N(E5)+N(E36)) | F37: =IF(COUNT(F5,F36)=0,"",N(F5)+N(F36)) | G37: =IF(COUNT(G5,G36)=0,"",N(G5)+N(G36)) | H37: ϝ
B38: Vacancy Rate (%) | C38: =IFERROR(C36/C37,"") | D38: =IFERROR(D36/D37,"") | E38: =IFERROR(E36/E37,"") | F38: =IFERROR(F36/F37,"") | G38: =IFERROR(G36/G37,"") | H38: ϝ
B39: Permanent TimeToHire (Days) YTD | C39: =IF('(M&C_Shipp)'!$AB$6="","",'(M&C_Shipp)'!$AB$6) | D39: =IF('(Coreas_Shipp)'!$AB$6="","",'(Coreas_Shipp)'!$AB$6) | E39: =IF('(JBH_Shipp)'!$AB$6="","",'(JBH_Shipp)'!$AB$6) | F39: =IF('(Shipping_BRB)'!$AB$6="","",'(Shipping_BRB)'!$AB$6) | G39: =IFERROR(AVERAGE(C39:F39),"") | H39: Avg
B40: Temporary TimeToHire (Days) YTD | C40: =IF('(M&C_Shipp)'!$AD$6="","",'(M&C_Shipp)'!$AD$6) | D40: =IF('(Coreas_Shipp)'!$AD$6="","",'(Coreas_Shipp)'!$AD$6) | E40: =IF('(JBH_Shipp)'!$AD$6="","",'(JBH_Shipp)'!$AD$6) | F40: =IF('(Shipping_BRB)'!$AD$6="","",'(Shipping_BRB)'!$AD$6) | G40: =IFERROR(AVERAGE(C40:F40),"") | H40: Avg
...

Sheet JAN
B1: SHIPPING
A2: =VALUE(TEXT(EDATE(DATE(LEFT(DEC!A2,4),RIGHT(DEC!A2,2),1),1),"yyyymm")) | B2: JAN | C2: M&C Shipping | D2: Coreas Hazells (Shipping) | E2: Jonas Browne & Hubbard (Shipping) | F2: Goddards Shipping Barbados | G2: TOTAL | H2: Total by Division | I2: =N(I11)<>0
A3: =+A2 | B3: Permanent (Regular) Headcount | G3: =IF(COUNT(C3:F3)=0,"",SUM(C3:F3)) | H3: ∑
B4: Temporary (Fix Term) Headcount | G4: =IF(COUNT(C4:F4)=0,"",SUM(C4:F4)) | H4: ∑
B5: Employee Headcount (Productivity) | C5: =IF(COUNT(C3:C4)=0,"",SUM(C3:C4)) | D5: =IF(COUNT(D3:D4)=0,"",SUM(D3:D4)) | E5: =IF(COUNT(E3:E4)=0,"",SUM(E3:E4)) | F5: =IF(COUNT(F3:F4)=0,"",SUM(F3:F4)) | G5: =IF(COUNT(G3:G4)=0,"",SUM(G3:G4)) | H5: ϝ
B6: Headcount = 1.00 | G6: =IF(COUNT(C6:F6)=0,"",SUM(C6:F6)) | H6: ∑
B7: Headcount = 0.75 | G7: =IF(COUNT(C7:F7)=0,"",SUM(C7:F7)) | H7: ∑
B8: Headcount = 0.50 | G8: =IF(COUNT(C8:F8)=0,"",SUM(C8:F8)) | H8: ∑
B9: Headcount = 0.25 | G9: =IF(COUNT(C9:F9)=0,"",SUM(C9:F9)) | H9: ∑
B10: Standard Monthly Hours (FTE basis) | G10: =IFERROR(AVERAGE(C10:F10),"") | H10: Avg
B11: Employee FTE (Finance) | C11: =IF(COUNT(C6:C9)=0,"",N(C6)+N(C7)*0.75+N(C8)*0.5+N(C9)*0.25) | D11: =IF(COUNT(D6:D9)=0,"",N(D6)+N(D7)*0.75+N(D8)*0.5+N(D9)*0.25) | E11: =IF(COUNT(E6:E9)=0,"",N(E6)+N(E7)*0.75+N(E8)*0.5+N(E9)*0.25) | F11: =IF(COUNT(F6:F9)=0,"",N(F6)+N(F7)*0.75+N(F8)*0.5+N(F9)*0.25) | G11: =IF(COUNT(G6:G9)=0,"",N(G6)+N(G7)*0.75+N(G8)*0.5+N(G9)*0.25) | H11: FTE | I11: =IF(COUNT(G5:G9)=0,"",N(G6)+N(G7)+N(G8)+N(G9)-N(G5))
B12: Subcontracted Workforce HC | G12: =IF(COUNT(C12:F12)=0,"",SUM(C12:F12)) | H12: ∑
B13: Subcontracted Productive Hours | G13: =IF(COUNT(C13:F13)=0,"",SUM(C13:F13)) | H13: ∑
B14: Subcontracted FTE | C14: =IFERROR(C13/C10,"") | D14: =IFERROR(D13/D10,"") | E14: =IFERROR(E13/E10,"") | F14: =IFERROR(F13/F10,"") | G14: =IF(COUNT(C14:F14)=0,"",SUM(C14:F14)) | H14: FTE
B15: Total Operational Workforce | C15: =IF(COUNT(C5,C12)=0,"",SUM(C5,C12)) | D15: =IF(COUNT(D5,D12)=0,"",SUM(D5,D12)) | E15: =IF(COUNT(E5,E12)=0,"",SUM(E5,E12)) | F15: =IF(COUNT(F5,F12)=0,"",SUM(F5,F12)) | G15: =IF(COUNT(G5,G12)=0,"",SUM(G5,G12)) | H15: ϝ
B16: Total Operational FTE | C16: =IF(COUNT(C11,C14)=0,"",SUM(C11,C14)) | D16: =IF(COUNT(D11,D14)=0,"",SUM(D11,D14)) | E16: =IF(COUNT(E11,E14)=0,"",SUM(E11,E14)) | F16: =IF(COUNT(F11,F14)=0,"",SUM(F11,F14)) | G16: =IF(COUNT(G11,G14)=0,"",SUM(G11,G14)) | H16: FTE
B17: Subcontracted Share of Workforce (%) | C17: =IFERROR(C12/C15,"") | D17: =IFERROR(D12/D15,"") | E17: =IFERROR(E12/E15,"") | F17: =IFERROR(F12/F15,"") | G17: =IFERROR(G12/G15,"") | H17: ϝ
B18: FTE HR Team | G18: =IF(COUNT(C18:F18)=0,"",SUM(C18:F18)) | H18: ∑
B19: Permanent Hires | G19: =IF(COUNT(C19:F19)=0,"",SUM(C19:F19)) | H19: ∑
B20: Temporary Hires | G20: =IF(COUNT(C20:F20)=0,"",SUM(C20:F20)) | H20: ∑
B21: Total Hires | C21: =IF(COUNT(C19:C20)=0,"",SUM(C19:C20)) | D21: =IF(COUNT(D19:D20)=0,"",SUM(D19:D20)) | E21: =IF(COUNT(E19:E20)=0,"",SUM(E19:E20)) | F21: =IF(COUNT(F19:F20)=0,"",SUM(F19:F20)) | G21: =IF(COUNT(G19:G20)=0,"",SUM(G19:G20)) | H21: ϝ
B22: Permanent Exits | G22: =IF(COUNT(C22:F22)=0,"",SUM(C22:F22)) | H22: ∑
B23: Temporary Exits | G23: =IF(COUNT(C23:F23)=0,"",SUM(C23:F23)) | H23: ∑
B24: Total Exits | C24: =IF(COUNT(C22:C23)=0,"",SUM(C22:C23)) | D24: =IF(COUNT(D22:D23)=0,"",SUM(D22:D23)) | E24: =IF(COUNT(E22:E23)=0,"",SUM(E22:E23)) | F24: =IF(COUNT(F22:F23)=0,"",SUM(F22:F23)) | G24: =IF(COUNT(G22:G23)=0,"",SUM(G22:G23)) | H24: ϝ
B25: Permanent Turnover (%) | C25: =IF(COUNT(C31,C32)<2,"",IF((C32+C31)=0,"",N(C22)/((C32+C31)/2))) | D25: =IF(COUNT(D31,D32)<2,"",IF((D32+D31)=0,"",N(D22)/((D32+D31)/2))) | E25: =IF(COUNT(E31,E32)<2,"",IF((E32+E31)=0,"",N(E22)/((E32+E31)/2))) | F25: =IF(COUNT(F31,F32)<2,"",IF((F32+F31)=0,"",N(F22)/((F32+F31)/2))) | G25: =IF(COUNT(G31,G32)<2,"",IF((G32+G31)=0,"",N(G22)/((G32+G31)/2))) | H25: ϝ
B26: Temporary Turnover (%) | C26: =IF(COUNT(C31,C32)<2,"",IF((C32+C31)=0,"",N(C23)/((C32+C31)/2))) | D26: =IF(COUNT(D31,D32)<2,"",IF((D32+D31)=0,"",N(D23)/((D32+D31)/2))) | E26: =IF(COUNT(E31,E32)<2,"",IF((E32+E31)=0,"",N(E23)/((E32+E31)/2))) | F26: =IF(COUNT(F31,F32)<2,"",IF((F32+F31)=0,"",N(F23)/((F32+F31)/2))) | G26: =IF(COUNT(G31,G32)<2,"",IF((G32+G31)=0,"",N(G23)/((G32+G31)/2))) | H26: ϝ
B27: Voluntary Terminations | G27: =IF(COUNT(C27:F27)=0,"",SUM(C27:F27)) | H27: ∑
B28: Involuntary Terminations | G28: =IF(COUNT(C28:F28)=0,"",SUM(C28:F28)) | H28: ∑
B29: Voluntary Turnover (%) | C29: =IF(COUNT(C31,C32)<2,"",IF((C32+C31)=0,"",N(C27)/((C32+C31)/2))) | D29: =IF(COUNT(D31,D32)<2,"",IF((D32+D31)=0,"",N(D27)/((D32+D31)/2))) | E29: =IF(COUNT(E31,E32)<2,"",IF((E32+E31)=0,"",N(E27)/((E32+E31)/2))) | F29: =IF(COUNT(F31,F32)<2,"",IF((F32+F31)=0,"",N(F27)/((F32+F31)/2))) | G29: =IF(COUNT(G31,G32)<2,"",IF((G32+G31)=0,"",N(G27)/((G32+G31)/2))) | H29: ϝ
B30: Involuntary Turnover (%) | C30: =IF(COUNT(C31,C32)<2,"",IF((C32+C31)=0,"",N(C28)/((C32+C31)/2))) | D30: =IF(COUNT(D31,D32)<2,"",IF((D32+D31)=0,"",N(D28)/((D32+D31)/2))) | E30: =IF(COUNT(E31,E32)<2,"",IF((E32+E31)=0,"",N(E28)/((E32+E31)/2))) | F30: =IF(COUNT(F31,F32)<2,"",IF((F32+F31)=0,"",N(F28)/((F32+F31)/2))) | G30: =IF(COUNT(G31,G32)<2,"",IF((G32+G31)=0,"",N(G28)/((G32+G31)/2))) | H30: ϝ
B31: Headcount last Month | C31: =IF(DEC!C5="","",DEC!C5) | D31: =IF(DEC!D5="","",DEC!D5) | E31: =IF(DEC!E5="","",DEC!E5) | F31: =IF(DEC!F5="","",DEC!F5) | G31: =IF(COUNT(C31:F31)=0,"",SUM(C31:F31)) | H31: ∑
B32: Headcount this Month | C32: =IF(C5="","",C5) | D32: =IF(D5="","",D5) | E32: =IF(E5="","",E5) | F32: =IF(F5="","",F5) | G32: =IF(COUNT(C32:F32)=0,"",SUM(C32:F32)) | H32: ∑
B33: Full Turnover (%) | C33: =IF(COUNT(C31,C32)<2,"",IF((C32+C31)=0,"",N(C24)/((C32+C31)/2))) | D33: =IF(COUNT(D31,D32)<2,"",IF((D32+D31)=0,"",N(D24)/((D32+D31)/2))) | E33: =IF(COUNT(E31,E32)<2,"",IF((E32+E31)=0,"",N(E24)/((E32+E31)/2))) | F33: =IF(COUNT(F31,F32)<2,"",IF((F32+F31)=0,"",N(F24)/((F32+F31)/2))) | G33: =IF(COUNT(G31,G32)<2,"",IF((G32+G31)=0,"",N(G24)/((G32+G31)/2))) | H33: ϝ
B34: Permanent Vacancies | G34: =IF(COUNT(C34:F34)=0,"",SUM(C34:F34)) | H34: ∑
B35: Temporary Vacancies | G35: =IF(COUNT(C35:F35)=0,"",SUM(C35:F35)) | H35: ∑
B36: Total Vacancies | C36: =IF(COUNT(C34:C35)=0,"",SUM(C34:C35)) | D36: =IF(COUNT(D34:D35)=0,"",SUM(D34:D35)) | E36: =IF(COUNT(E34:E35)=0,"",SUM(E34:E35)) | F36: =IF(COUNT(F34:F35)=0,"",SUM(F34:F35)) | G36: =IF(COUNT(G34:G35)=0,"",SUM(G34:G35)) | H36: ϝ
B37: Authorized Positions | C37: =IF(COUNT(C5,C36)=0,"",N(C5)+N(C36)) | D37: =IF(COUNT(D5,D36)=0,"",N(D5)+N(D36)) | E37: =IF(COUNT(E5,E36)=0,"",N(E5)+N(E36)) | F37: =IF(COUNT(F5,F36)=0,"",N(F5)+N(F36)) | G37: =IF(COUNT(G5,G36)=0,"",N(G5)+N(G36)) | H37: ϝ
B38: Vacancy Rate (%) | C38: =IFERROR(C36/C37,"") | D38: =IFERROR(D36/D37,"") | E38: =IFERROR(E36/E37,"") | F38: =IFERROR(F36/F37,"") | G38: =IFERROR(G36/G37,"") | H38: ϝ
B39: Permanent TimeToHire (Days) YTD | C39: =IF('(M&C_Shipp)'!$AB$7="","",'(M&C_Shipp)'!$AB$7) | D39: =IF('(Coreas_Shipp)'!$AB$7="","",'(Coreas_Shipp)'!$AB$7) | E39: =IF('(JBH_Shipp)'!$AB$7="","",'(JBH_Shipp)'!$AB$7) | F39: =IF('(Shipping_BRB)'!$AB$7="","",'(Shipping_BRB)'!$AB$7) | G39: =IFERROR(AVERAGE(C39:F39),"") | H39: Avg
B40: Temporary TimeToHire (Days) YTD | C40: =IF('(M&C_Shipp)'!$AD$7="","",'(M&C_Shipp)'!$AD$7) | D40: =IF('(Coreas_Shipp)'!$AD$7="","",'(Coreas_Shipp)'!$AD$7) | E40: =IF('(JBH_Shipp)'!$AD$7="","",'(JBH_Shipp)'!$AD$7) | F40: =IF('(Shipping_BRB)'!$AD$7="","",'(Shipping_BRB)'!$AD$7) | G40: =IFERROR(AVERAGE(C40:F40),"") | H40: Avg
...

Sheet FEB
B1: SHIPPING
A2: =VALUE(TEXT(EDATE(DATE(LEFT(JAN!A2,4),RIGHT(JAN!A2,2),1),1),"yyyymm")) | B2: FEB | C2: M&C Shipping | D2: Coreas Hazells (Shipping) | E2: Jonas Browne & Hubbard (Shipping) | F2: Goddards Shipping Barbados | G2: TOTAL | H2: Total by Division | I2: =N(I11)<>0
A3: =+A2 | B3: Permanent (Regular) Headcount | G3: =IF(COUNT(C3:F3)=0,"",SUM(C3:F3)) | H3: ∑
B4: Temporary (Fix Term) Headcount | G4: =IF(COUNT(C4:F4)=0,"",SUM(C4:F4)) | H4: ∑
B5: Employee Headcount (Productivity) | C5: =IF(COUNT(C3:C4)=0,"",SUM(C3:C4)) | D5: =IF(COUNT(D3:D4)=0,"",SUM(D3:D4)) | E5: =IF(COUNT(E3:E4)=0,"",SUM(E3:E4)) | F5: =IF(COUNT(F3:F4)=0,"",SUM(F3:F4)) | G5: =IF(COUNT(G3:G4)=0,"",SUM(G3:G4)) | H5: ϝ
B6: Headcount = 1.00 | G6: =IF(COUNT(C6:F6)=0,"",SUM(C6:F6)) | H6: ∑
B7: Headcount = 0.75 | G7: =IF(COUNT(C7:F7)=0,"",SUM(C7:F7)) | H7: ∑
B8: Headcount = 0.50 | G8: =IF(COUNT(C8:F8)=0,"",SUM(C8:F8)) | H8: ∑
B9: Headcount = 0.25 | G9: =IF(COUNT(C9:F9)=0,"",SUM(C9:F9)) | H9: ∑
B10: Standard Monthly Hours (FTE basis) | G10: =IFERROR(AVERAGE(C10:F10),"") | H10: Avg
B11: Employee FTE (Finance) | C11: =IF(COUNT(C6:C9)=0,"",N(C6)+N(C7)*0.75+N(C8)*0.5+N(C9)*0.25) | D11: =IF(COUNT(D6:D9)=0,"",N(D6)+N(D7)*0.75+N(D8)*0.5+N(D9)*0.25) | E11: =IF(COUNT(E6:E9)=0,"",N(E6)+N(E7)*0.75+N(E8)*0.5+N(E9)*0.25) | F11: =IF(COUNT(F6:F9)=0,"",N(F6)+N(F7)*0.75+N(F8)*0.5+N(F9)*0.25) | G11: =IF(COUNT(G6:G9)=0,"",N(G6)+N(G7)*0.75+N(G8)*0.5+N(G9)*0.25) | H11: FTE | I11: =IF(COUNT(G5:G9)=0,"",N(G6)+N(G7)+N(G8)+N(G9)-N(G5))
B12: Subcontracted Workforce HC | G12: =IF(COUNT(C12:F12)=0,"",SUM(C12:F12)) | H12: ∑
B13: Subcontracted Productive Hours | G13: =IF(COUNT(C13:F13)=0,"",SUM(C13:F13)) | H13: ∑
B14: Subcontracted FTE | C14: =IFERROR(C13/C10,"") | D14: =IFERROR(D13/D10,"") | E14: =IFERROR(E13/E10,"") | F14: =IFERROR(F13/F10,"") | G14: =IF(COUNT(C14:F14)=0,"",SUM(C14:F14)) | H14: FTE
B15: Total Operational Workforce | C15: =IF(COUNT(C5,C12)=0,"",SUM(C5,C12)) | D15: =IF(COUNT(D5,D12)=0,"",SUM(D5,D12)) | E15: =IF(COUNT(E5,E12)=0,"",SUM(E5,E12)) | F15: =IF(COUNT(F5,F12)=0,"",SUM(F5,F12)) | G15: =IF(COUNT(G5,G12)=0,"",SUM(G5,G12)) | H15: ϝ
B16: Total Operational FTE | C16: =IF(COUNT(C11,C14)=0,"",SUM(C11,C14)) | D16: =IF(COUNT(D11,D14)=0,"",SUM(D11,D14)) | E16: =IF(COUNT(E11,E14)=0,"",SUM(E11,E14)) | F16: =IF(COUNT(F11,F14)=0,"",SUM(F11,F14)) | G16: =IF(COUNT(G11,G14)=0,"",SUM(G11,G14)) | H16: FTE
B17: Subcontracted Share of Workforce (%) | C17: =IFERROR(C12/C15,"") | D17: =IFERROR(D12/D15,"") | E17: =IFERROR(E12/E15,"") | F17: =IFERROR(F12/F15,"") | G17: =IFERROR(G12/G15,"") | H17: ϝ
B18: FTE HR Team | G18: =IF(COUNT(C18:F18)=0,"",SUM(C18:F18)) | H18: ∑
B19: Permanent Hires | G19: =IF(COUNT(C19:F19)=0,"",SUM(C19:F19)) | H19: ∑
B20: Temporary Hires | G20: =IF(COUNT(C20:F20)=0,"",SUM(C20:F20)) | H20: ∑
B21: Total Hires | C21: =IF(COUNT(C19:C20)=0,"",SUM(C19:C20)) | D21: =IF(COUNT(D19:D20)=0,"",SUM(D19:D20)) | E21: =IF(COUNT(E19:E20)=0,"",SUM(E19:E20)) | F21: =IF(COUNT(F19:F20)=0,"",SUM(F19:F20)) | G21: =IF(COUNT(G19:G20)=0,"",SUM(G19:G20)) | H21: ϝ
B22: Permanent Exits | G22: =IF(COUNT(C22:F22)=0,"",SUM(C22:F22)) | H22: ∑
B23: Temporary Exits | G23: =IF(COUNT(C23:F23)=0,"",SUM(C23:F23)) | H23: ∑
B24: Total Exits | C24: =IF(COUNT(C22:C23)=0,"",SUM(C22:C23)) | D24: =IF(COUNT(D22:D23)=0,"",SUM(D22:D23)) | E24: =IF(COUNT(E22:E23)=0,"",SUM(E22:E23)) | F24: =IF(COUNT(F22:F23)=0,"",SUM(F22:F23)) | G24: =IF(COUNT(G22:G23)=0,"",SUM(G22:G23)) | H24: ϝ
B25: Permanent Turnover (%) | C25: =IF(COUNT(C31,C32)<2,"",IF((C32+C31)=0,"",N(C22)/((C32+C31)/2))) | D25: =IF(COUNT(D31,D32)<2,"",IF((D32+D31)=0,"",N(D22)/((D32+D31)/2))) | E25: =IF(COUNT(E31,E32)<2,"",IF((E32+E31)=0,"",N(E22)/((E32+E31)/2))) | F25: =IF(COUNT(F31,F32)<2,"",IF((F32+F31)=0,"",N(F22)/((F32+F31)/2))) | G25: =IF(COUNT(G31,G32)<2,"",IF((G32+G31)=0,"",N(G22)/((G32+G31)/2))) | H25: ϝ
B26: Temporary Turnover (%) | C26: =IF(COUNT(C31,C32)<2,"",IF((C32+C31)=0,"",N(C23)/((C32+C31)/2))) | D26: =IF(COUNT(D31,D32)<2,"",IF((D32+D31)=0,"",N(D23)/((D32+D31)/2))) | E26: =IF(COUNT(E31,E32)<2,"",IF((E32+E31)=0,"",N(E23)/((E32+E31)/2))) | F26: =IF(COUNT(F31,F32)<2,"",IF((F32+F31)=0,"",N(F23)/((F32+F31)/2))) | G26: =IF(COUNT(G31,G32)<2,"",IF((G32+G31)=0,"",N(G23)/((G32+G31)/2))) | H26: ϝ
B27: Voluntary Terminations | G27: =IF(COUNT(C27:F27)=0,"",SUM(C27:F27)) | H27: ∑
B28: Involuntary Terminations | G28: =IF(COUNT(C28:F28)=0,"",SUM(C28:F28)) | H28: ∑
B29: Voluntary Turnover (%) | C29: =IF(COUNT(C31,C32)<2,"",IF((C32+C31)=0,"",N(C27)/((C32+C31)/2))) | D29: =IF(COUNT(D31,D32)<2,"",IF((D32+D31)=0,"",N(D27)/((D32+D31)/2))) | E29: =IF(COUNT(E31,E32)<2,"",IF((E32+E31)=0,"",N(E27)/((E32+E31)/2))) | F29: =IF(COUNT(F31,F32)<2,"",IF((F32+F31)=0,"",N(F27)/((F32+F31)/2))) | G29: =IF(COUNT(G31,G32)<2,"",IF((G32+G31)=0,"",N(G27)/((G32+G31)/2))) | H29: ϝ
B30: Involuntary Turnover (%) | C30: =IF(COUNT(C31,C32)<2,"",IF((C32+C31)=0,"",N(C28)/((C32+C31)/2))) | D30: =IF(COUNT(D31,D32)<2,"",IF((D32+D31)=0,"",N(D28)/((D32+D31)/2))) | E30: =IF(COUNT(E31,E32)<2,"",IF((E32+E31)=0,"",N(E28)/((E32+E31)/2))) | F30: =IF(COUNT(F31,F32)<2,"",IF((F32+F31)=0,"",N(F28)/((F32+F31)/2))) | G30: =IF(COUNT(G31,G32)<2,"",IF((G32+G31)=0,"",N(G28)/((G32+G31)/2))) | H30: ϝ
B31: Headcount last Month | C31: =IF(JAN!C5="","",JAN!C5) | D31: =IF(JAN!D5="","",JAN!D5) | E31: =IF(JAN!E5="","",JAN!E5) | F31: =IF(JAN!F5="","",JAN!F5) | G31: =IF(COUNT(C31:F31)=0,"",SUM(C31:F31)) | H31: ∑
B32: Headcount this Month | C32: =IF(C5="","",C5) | D32: =IF(D5="","",D5) | E32: =IF(E5="","",E5) | F32: =IF(F5="","",F5) | G32: =IF(COUNT(C32:F32)=0,"",SUM(C32:F32)) | H32: ∑
B33: Full Turnover (%) | C33: =IF(COUNT(C31,C32)<2,"",IF((C32+C31)=0,"",N(C24)/((C32+C31)/2))) | D33: =IF(COUNT(D31,D32)<2,"",IF((D32+D31)=0,"",N(D24)/((D32+D31)/2))) | E33: =IF(COUNT(E31,E32)<2,"",IF((E32+E31)=0,"",N(E24)/((E32+E31)/2))) | F33: =IF(COUNT(F31,F32)<2,"",IF((F32+F31)=0,"",N(F24)/((F32+F31)/2))) | G33: =IF(COUNT(G31,G32)<2,"",IF((G32+G31)=0,"",N(G24)/((G32+G31)/2))) | H33: ϝ
B34: Permanent Vacancies | G34: =IF(COUNT(C34:F34)=0,"",SUM(C34:F34)) | H34: ∑
B35: Temporary Vacancies | G35: =IF(COUNT(C35:F35)=0,"",SUM(C35:F35)) | H35: ∑
B36: Total Vacancies | C36: =IF(COUNT(C34:C35)=0,"",SUM(C34:C35)) | D36: =IF(COUNT(D34:D35)=0,"",SUM(D34:D35)) | E36: =IF(COUNT(E34:E35)=0,"",SUM(E34:E35)) | F36: =IF(COUNT(F34:F35)=0,"",SUM(F34:F35)) | G36: =IF(COUNT(G34:G35)=0,"",SUM(G34:G35)) | H36: ϝ
B37: Authorized Positions | C37: =IF(COUNT(C5,C36)=0,"",N(C5)+N(C36)) | D37: =IF(COUNT(D5,D36)=0,"",N(D5)+N(D36)) | E37: =IF(COUNT(E5,E36)=0,"",N(E5)+N(E36)) | F37: =IF(COUNT(F5,F36)=0,"",N(F5)+N(F36)) | G37: =IF(COUNT(G5,G36)=0,"",N(G5)+N(G36)) | H37: ϝ
B38: Vacancy Rate (%) | C38: =IFERROR(C36/C37,"") | D38: =IFERROR(D36/D37,"") | E38: =IFERROR(E36/E37,"") | F38: =IFERROR(F36/F37,"") | G38: =IFERROR(G36/G37,"") | H38: ϝ
B39: Permanent TimeToHire (Days) YTD | C39: =IF('(M&C_Shipp)'!$AB$8="","",'(M&C_Shipp)'!$AB$8) | D39: =IF('(Coreas_Shipp)'!$AB$8="","",'(Coreas_Shipp)'!$AB$8) | E39: =IF('(JBH_Shipp)'!$AB$8="","",'(JBH_Shipp)'!$AB$8) | F39: =IF('(Shipping_BRB)'!$AB$8="","",'(Shipping_BRB)'!$AB$8) | G39: =IFERROR(AVERAGE(C39:F39),"") | H39: Avg
B40: Temporary TimeToHire (Days) YTD | C40: =IF('(M&C_Shipp)'!$AD$8="","",'(M&C_Shipp)'!$AD$8) | D40: =IF('(Coreas_Shipp)'!$AD$8="","",'(Coreas_Shipp)'!$AD$8) | E40: =IF('(JBH_Shipp)'!$AD$8="","",'(JBH_Shipp)'!$AD$8) | F40: =IF('(Shipping_BRB)'!$AD$8="","",'(Shipping_BRB)'!$AD$8) | G40: =IFERROR(AVERAGE(C40:F40),"") | H40: Avg
...

Sheet MAR
B1: SHIPPING
A2: =VALUE(TEXT(EDATE(DATE(LEFT(FEB!A2,4),RIGHT(FEB!A2,2),1),1),"yyyymm")) | B2: MAR | C2: M&C Shipping | D2: Coreas Hazells (Shipping) | E2: Jonas Browne & Hubbard (Shipping) | F2: Goddards Shipping Barbados | G2: TOTAL | H2: Total by Division | I2: =N(I11)<>0
A3: =+A2 | B3: Permanent (Regular) Headcount | G3: =IF(COUNT(C3:F3)=0,"",SUM(C3:F3)) | H3: ∑
B4: Temporary (Fix Term) Headcount | G4: =IF(COUNT(C4:F4)=0,"",SUM(C4:F4)) | H4: ∑
B5: Employee Headcount (Productivity) | C5: =IF(COUNT(C3:C4)=0,"",SUM(C3:C4)) | D5: =IF(COUNT(D3:D4)=0,"",SUM(D3:D4)) | E5: =IF(COUNT(E3:E4)=0,"",SUM(E3:E4)) | F5: =IF(COUNT(F3:F4)=0,"",SUM(F3:F4)) | G5: =IF(COUNT(G3:G4)=0,"",SUM(G3:G4)) | H5: ϝ
B6: Headcount = 1.00 | G6: =IF(COUNT(C6:F6)=0,"",SUM(C6:F6)) | H6: ∑
B7: Headcount = 0.75 | G7: =IF(COUNT(C7:F7)=0,"",SUM(C7:F7)) | H7: ∑
B8: Headcount = 0.50 | G8: =IF(COUNT(C8:F8)=0,"",SUM(C8:F8)) | H8: ∑
B9: Headcount = 0.25 | G9: =IF(COUNT(C9:F9)=0,"",SUM(C9:F9)) | H9: ∑
B10: Standard Monthly Hours (FTE basis) | G10: =IFERROR(AVERAGE(C10:F10),"") | H10: Avg
B11: Employee FTE (Finance) | C11: =IF(COUNT(C6:C9)=0,"",N(C6)+N(C7)*0.75+N(C8)*0.5+N(C9)*0.25) | D11: =IF(COUNT(D6:D9)=0,"",N(D6)+N(D7)*0.75+N(D8)*0.5+N(D9)*0.25) | E11: =IF(COUNT(E6:E9)=0,"",N(E6)+N(E7)*0.75+N(E8)*0.5+N(E9)*0.25) | F11: =IF(COUNT(F6:F9)=0,"",N(F6)+N(F7)*0.75+N(F8)*0.5+N(F9)*0.25) | G11: =IF(COUNT(G6:G9)=0,"",N(G6)+N(G7)*0.75+N(G8)*0.5+N(G9)*0.25) | H11: FTE | I11: =IF(COUNT(G5:G9)=0,"",N(G6)+N(G7)+N(G8)+N(G9)-N(G5))
B12: Subcontracted Workforce HC | G12: =IF(COUNT(C12:F12)=0,"",SUM(C12:F12)) | H12: ∑
B13: Subcontracted Productive Hours | G13: =IF(COUNT(C13:F13)=0,"",SUM(C13:F13)) | H13: ∑
B14: Subcontracted FTE | C14: =IFERROR(C13/C10,"") | D14: =IFERROR(D13/D10,"") | E14: =IFERROR(E13/E10,"") | F14: =IFERROR(F13/F10,"") | G14: =IF(COUNT(C14:F14)=0,"",SUM(C14:F14)) | H14: FTE
B15: Total Operational Workforce | C15: =IF(COUNT(C5,C12)=0,"",SUM(C5,C12)) | D15: =IF(COUNT(D5,D12)=0,"",SUM(D5,D12)) | E15: =IF(COUNT(E5,E12)=0,"",SUM(E5,E12)) | F15: =IF(COUNT(F5,F12)=0,"",SUM(F5,F12)) | G15: =IF(COUNT(G5,G12)=0,"",SUM(G5,G12)) | H15: ϝ
B16: Total Operational FTE | C16: =IF(COUNT(C11,C14)=0,"",SUM(C11,C14)) | D16: =IF(COUNT(D11,D14)=0,"",SUM(D11,D14)) | E16: =IF(COUNT(E11,E14)=0,"",SUM(E11,E14)) | F16: =IF(COUNT(F11,F14)=0,"",SUM(F11,F14)) | G16: =IF(COUNT(G11,G14)=0,"",SUM(G11,G14)) | H16: FTE
B17: Subcontracted Share of Workforce (%) | C17: =IFERROR(C12/C15,"") | D17: =IFERROR(D12/D15,"") | E17: =IFERROR(E12/E15,"") | F17: =IFERROR(F12/F15,"") | G17: =IFERROR(G12/G15,"") | H17: ϝ
B18: FTE HR Team | G18: =IF(COUNT(C18:F18)=0,"",SUM(C18:F18)) | H18: ∑
B19: Permanent Hires | G19: =IF(COUNT(C19:F19)=0,"",SUM(C19:F19)) | H19: ∑
B20: Temporary Hires | G20: =IF(COUNT(C20:F20)=0,"",SUM(C20:F20)) | H20: ∑
B21: Total Hires | C21: =IF(COUNT(C19:C20)=0,"",SUM(C19:C20)) | D21: =IF(COUNT(D19:D20)=0,"",SUM(D19:D20)) | E21: =IF(COUNT(E19:E20)=0,"",SUM(E19:E20)) | F21: =IF(COUNT(F19:F20)=0,"",SUM(F19:F20)) | G21: =IF(COUNT(G19:G20)=0,"",SUM(G19:G20)) | H21: ϝ
B22: Permanent Exits | G22: =IF(COUNT(C22:F22)=0,"",SUM(C22:F22)) | H22: ∑
B23: Temporary Exits | G23: =IF(COUNT(C23:F23)=0,"",SUM(C23:F23)) | H23: ∑
B24: Total Exits | C24: =IF(COUNT(C22:C23)=0,"",SUM(C22:C23)) | D24: =IF(COUNT(D22:D23)=0,"",SUM(D22:D23)) | E24: =IF(COUNT(E22:E23)=0,"",SUM(E22:E23)) | F24: =IF(COUNT(F22:F23)=0,"",SUM(F22:F23)) | G24: =IF(COUNT(G22:G23)=0,"",SUM(G22:G23)) | H24: ϝ
B25: Permanent Turnover (%) | C25: =IF(COUNT(C31,C32)<2,"",IF((C32+C31)=0,"",N(C22)/((C32+C31)/2))) | D25: =IF(COUNT(D31,D32)<2,"",IF((D32+D31)=0,"",N(D22)/((D32+D31)/2))) | E25: =IF(COUNT(E31,E32)<2,"",IF((E32+E31)=0,"",N(E22)/((E32+E31)/2))) | F25: =IF(COUNT(F31,F32)<2,"",IF((F32+F31)=0,"",N(F22)/((F32+F31)/2))) | G25: =IF(COUNT(G31,G32)<2,"",IF((G32+G31)=0,"",N(G22)/((G32+G31)/2))) | H25: ϝ
B26: Temporary Turnover (%) | C26: =IF(COUNT(C31,C32)<2,"",IF((C32+C31)=0,"",N(C23)/((C32+C31)/2))) | D26: =IF(COUNT(D31,D32)<2,"",IF((D32+D31)=0,"",N(D23)/((D32+D31)/2))) | E26: =IF(COUNT(E31,E32)<2,"",IF((E32+E31)=0,"",N(E23)/((E32+E31)/2))) | F26: =IF(COUNT(F31,F32)<2,"",IF((F32+F31)=0,"",N(F23)/((F32+F31)/2))) | G26: =IF(COUNT(G31,G32)<2,"",IF((G32+G31)=0,"",N(G23)/((G32+G31)/2))) | H26: ϝ
B27: Voluntary Terminations | G27: =IF(COUNT(C27:F27)=0,"",SUM(C27:F27)) | H27: ∑
B28: Involuntary Terminations | G28: =IF(COUNT(C28:F28)=0,"",SUM(C28:F28)) | H28: ∑
B29: Voluntary Turnover (%) | C29: =IF(COUNT(C31,C32)<2,"",IF((C32+C31)=0,"",N(C27)/((C32+C31)/2))) | D29: =IF(COUNT(D31,D32)<2,"",IF((D32+D31)=0,"",N(D27)/((D32+D31)/2))) | E29: =IF(COUNT(E31,E32)<2,"",IF((E32+E31)=0,"",N(E27)/((E32+E31)/2))) | F29: =IF(COUNT(F31,F32)<2,"",IF((F32+F31)=0,"",N(F27)/((F32+F31)/2))) | G29: =IF(COUNT(G31,G32)<2,"",IF((G32+G31)=0,"",N(G27)/((G32+G31)/2))) | H29: ϝ
