Workbook

Sheet Quarter
B1: GCG
A2: FY2027 | B2: Quarter | C2: OCT | D2: NOV | E2: DEC | F2: ∑Q1 | G2: JAN | H2: FEB | I2: MAR | J2: ∑Q2 | K2: APR | L2: MAY | M2: JUN | N2: ∑Q3 | O2: JUL | P2: AUG | Q2: SEP | R2: ∑Q4 | S2: FY2027
B3: Permanent (Regular) Headcount | C3: =OCT!AJ3 | D3: =NOV!AJ3 | E3: =DEC!AJ3 | F3: =IFERROR(AVERAGE(C3:E3),"") | G3: =JAN!AJ3 | H3: =FEB!AJ3 | I3: =MAR!AJ3 | J3: =IFERROR(AVERAGE(G3:I3),"") | K3: =APR!AJ3 | L3: =MAY!AJ3 | M3: =JUN!AJ3 | N3: =IFERROR(AVERAGE(K3:M3),"") | O3: =JUL!AJ3 | P3: =AUG!AJ3 | Q3: =SEP!AJ3 | R3: =IFERROR(AVERAGE(O3:Q3),"") | S3: =IFERROR(AVERAGE(C3:E3,G3:I3,K3:M3,O3:Q3),"")
B4: Temporary (Fix Term) Headcount | C4: =OCT!AJ4 | D4: =NOV!AJ4 | E4: =DEC!AJ4 | F4: =IFERROR(AVERAGE(C4:E4),"") | G4: =JAN!AJ4 | H4: =FEB!AJ4 | I4: =MAR!AJ4 | J4: =IFERROR(AVERAGE(G4:I4),"") | K4: =APR!AJ4 | L4: =MAY!AJ4 | M4: =JUN!AJ4 | N4: =IFERROR(AVERAGE(K4:M4),"") | O4: =JUL!AJ4 | P4: =AUG!AJ4 | Q4: =SEP!AJ4 | R4: =IFERROR(AVERAGE(O4:Q4),"") | S4: =IFERROR(AVERAGE(C4:E4,G4:I4,K4:M4,O4:Q4),"")
B5: Employee Headcount (Productivity) | C5: =OCT!AJ5 | D5: =NOV!AJ5 | E5: =DEC!AJ5 | F5: =IF(COUNT(F3:F4)=0,"",SUM(F3:F4)) | G5: =JAN!AJ5 | H5: =FEB!AJ5 | I5: =MAR!AJ5 | J5: =IF(COUNT(J3:J4)=0,"",SUM(J3:J4)) | K5: =APR!AJ5 | L5: =MAY!AJ5 | M5: =JUN!AJ5 | N5: =IF(COUNT(N3:N4)=0,"",SUM(N3:N4)) | O5: =JUL!AJ5 | P5: =AUG!AJ5 | Q5: =SEP!AJ5 | R5: =IF(COUNT(R3:R4)=0,"",SUM(R3:R4)) | S5: =IF(COUNT(S3:S4)=0,"",SUM(S3:S4))
B6: Headcount = 1.00 | C6: =OCT!AJ6 | D6: =NOV!AJ6 | E6: =DEC!AJ6 | F6: =IFERROR(AVERAGE(C6:E6),"") | G6: =JAN!AJ6 | H6: =FEB!AJ6 | I6: =MAR!AJ6 | J6: =IFERROR(AVERAGE(G6:I6),"") | K6: =APR!AJ6 | L6: =MAY!AJ6 | M6: =JUN!AJ6 | N6: =IFERROR(AVERAGE(K6:M6),"") | O6: =JUL!AJ6 | P6: =AUG!AJ6 | Q6: =SEP!AJ6 | R6: =IFERROR(AVERAGE(O6:Q6),"") | S6: =IFERROR(AVERAGE(C6:E6,G6:I6,K6:M6,O6:Q6),"")
B7: Headcount = 0.75 | C7: =OCT!AJ7 | D7: =NOV!AJ7 | E7: =DEC!AJ7 | F7: =IFERROR(AVERAGE(C7:E7),"") | G7: =JAN!AJ7 | H7: =FEB!AJ7 | I7: =MAR!AJ7 | J7: =IFERROR(AVERAGE(G7:I7),"") | K7: =APR!AJ7 | L7: =MAY!AJ7 | M7: =JUN!AJ7 | N7: =IFERROR(AVERAGE(K7:M7),"") | O7: =JUL!AJ7 | P7: =AUG!AJ7 | Q7: =SEP!AJ7 | R7: =IFERROR(AVERAGE(O7:Q7),"") | S7: =IFERROR(AVERAGE(C7:E7,G7:I7,K7:M7,O7:Q7),"")
B8: Headcount = 0.50 | C8: =OCT!AJ8 | D8: =NOV!AJ8 | E8: =DEC!AJ8 | F8: =IFERROR(AVERAGE(C8:E8),"") | G8: =JAN!AJ8 | H8: =FEB!AJ8 | I8: =MAR!AJ8 | J8: =IFERROR(AVERAGE(G8:I8),"") | K8: =APR!AJ8 | L8: =MAY!AJ8 | M8: =JUN!AJ8 | N8: =IFERROR(AVERAGE(K8:M8),"") | O8: =JUL!AJ8 | P8: =AUG!AJ8 | Q8: =SEP!AJ8 | R8: =IFERROR(AVERAGE(O8:Q8),"") | S8: =IFERROR(AVERAGE(C8:E8,G8:I8,K8:M8,O8:Q8),"")
B9: Headcount = 0.25 | C9: =OCT!AJ9 | D9: =NOV!AJ9 | E9: =DEC!AJ9 | F9: =IFERROR(AVERAGE(C9:E9),"") | G9: =JAN!AJ9 | H9: =FEB!AJ9 | I9: =MAR!AJ9 | J9: =IFERROR(AVERAGE(G9:I9),"") | K9: =APR!AJ9 | L9: =MAY!AJ9 | M9: =JUN!AJ9 | N9: =IFERROR(AVERAGE(K9:M9),"") | O9: =JUL!AJ9 | P9: =AUG!AJ9 | Q9: =SEP!AJ9 | R9: =IFERROR(AVERAGE(O9:Q9),"") | S9: =IFERROR(AVERAGE(C9:E9,G9:I9,K9:M9,O9:Q9),"")
B10: Standard Monthly Hours (FTE basis) | C10: =OCT!AJ10 | D10: =NOV!AJ10 | E10: =DEC!AJ10 | F10: =IFERROR(AVERAGE(C10:E10),"") | G10: =JAN!AJ10 | H10: =FEB!AJ10 | I10: =MAR!AJ10 | J10: =IFERROR(AVERAGE(G10:I10),"") | K10: =APR!AJ10 | L10: =MAY!AJ10 | M10: =JUN!AJ10 | N10: =IFERROR(AVERAGE(K10:M10),"") | O10: =JUL!AJ10 | P10: =AUG!AJ10 | Q10: =SEP!AJ10 | R10: =IFERROR(AVERAGE(O10:Q10),"") | S10: =IFERROR(AVERAGE(C10:E10,G10:I10,K10:M10,O10:Q10),"")
B11: Employee FTE (Finance) | C11: =OCT!AJ11 | D11: =NOV!AJ11 | E11: =DEC!AJ11 | F11: =IF(COUNT(F6:F9)=0,"",N(F6)+N(F7)*0.75+N(F8)*0.5+N(F9)*0.25) | G11: =JAN!AJ11 | H11: =FEB!AJ11 | I11: =MAR!AJ11 | J11: =IF(COUNT(J6:J9)=0,"",N(J6)+N(J7)*0.75+N(J8)*0.5+N(J9)*0.25) | K11: =APR!AJ11 | L11: =MAY!AJ11 | M11: =JUN!AJ11 | N11: =IF(COUNT(N6:N9)=0,"",N(N6)+N(N7)*0.75+N(N8)*0.5+N(N9)*0.25) | O11: =JUL!AJ11 | P11: =AUG!AJ11 | Q11: =SEP!AJ11 | R11: =IF(COUNT(R6:R9)=0,"",N(R6)+N(R7)*0.75+N(R8)*0.5+N(R9)*0.25) | S11: =IF(COUNT(S6:S9)=0,"",N(S6)+N(S7)*0.75+N(S8)*0.5+N(S9)*0.25)
B12: Subcontracted Workforce HC | C12: =OCT!AJ12 | D12: =NOV!AJ12 | E12: =DEC!AJ12 | F12: =IFERROR(AVERAGE(C12:E12),"") | G12: =JAN!AJ12 | H12: =FEB!AJ12 | I12: =MAR!AJ12 | J12: =IFERROR(AVERAGE(G12:I12),"") | K12: =APR!AJ12 | L12: =MAY!AJ12 | M12: =JUN!AJ12 | N12: =IFERROR(AVERAGE(K12:M12),"") | O12: =JUL!AJ12 | P12: =AUG!AJ12 | Q12: =SEP!AJ12 | R12: =IFERROR(AVERAGE(O12:Q12),"") | S12: =IFERROR(AVERAGE(C12:E12,G12:I12,K12:M12,O12:Q12),"")
B13: Subcontracted Productive Hours | C13: =OCT!AJ13 | D13: =NOV!AJ13 | E13: =DEC!AJ13 | F13: =IFERROR(AVERAGE(C13:E13),"") | G13: =JAN!AJ13 | H13: =FEB!AJ13 | I13: =MAR!AJ13 | J13: =IFERROR(AVERAGE(G13:I13),"") | K13: =APR!AJ13 | L13: =MAY!AJ13 | M13: =JUN!AJ13 | N13: =IFERROR(AVERAGE(K13:M13),"") | O13: =JUL!AJ13 | P13: =AUG!AJ13 | Q13: =SEP!AJ13 | R13: =IFERROR(AVERAGE(O13:Q13),"") | S13: =IFERROR(AVERAGE(C13:E13,G13:I13,K13:M13,O13:Q13),"")
B14: Subcontracted FTE | C14: =OCT!AJ14 | D14: =NOV!AJ14 | E14: =DEC!AJ14 | F14: =IFERROR(F13/F10,"") | G14: =JAN!AJ14 | H14: =FEB!AJ14 | I14: =MAR!AJ14 | J14: =IFERROR(J13/J10,"") | K14: =APR!AJ14 | L14: =MAY!AJ14 | M14: =JUN!AJ14 | N14: =IFERROR(N13/N10,"") | O14: =JUL!AJ14 | P14: =AUG!AJ14 | Q14: =SEP!AJ14 | R14: =IFERROR(R13/R10,"") | S14: =IFERROR(S13/S10,"")
B15: Total Operational Workforce | C15: =OCT!AJ15 | D15: =NOV!AJ15 | E15: =DEC!AJ15 | F15: =IF(COUNT(F5,F12)=0,"",SUM(F5,F12)) | G15: =JAN!AJ15 | H15: =FEB!AJ15 | I15: =MAR!AJ15 | J15: =IF(COUNT(J5,J12)=0,"",SUM(J5,J12)) | K15: =APR!AJ15 | L15: =MAY!AJ15 | M15: =JUN!AJ15 | N15: =IF(COUNT(N5,N12)=0,"",SUM(N5,N12)) | O15: =JUL!AJ15 | P15: =AUG!AJ15 | Q15: =SEP!AJ15 | R15: =IF(COUNT(R5,R12)=0,"",SUM(R5,R12)) | S15: =IF(COUNT(S5,S12)=0,"",SUM(S5,S12))
B16: Total Operational FTE | C16: =OCT!AJ16 | D16: =NOV!AJ16 | E16: =DEC!AJ16 | F16: =IF(COUNT(F11,F14)=0,"",SUM(F11,F14)) | G16: =JAN!AJ16 | H16: =FEB!AJ16 | I16: =MAR!AJ16 | J16: =IF(COUNT(J11,J14)=0,"",SUM(J11,J14)) | K16: =APR!AJ16 | L16: =MAY!AJ16 | M16: =JUN!AJ16 | N16: =IF(COUNT(N11,N14)=0,"",SUM(N11,N14)) | O16: =JUL!AJ16 | P16: =AUG!AJ16 | Q16: =SEP!AJ16 | R16: =IF(COUNT(R11,R14)=0,"",SUM(R11,R14)) | S16: =IF(COUNT(S11,S14)=0,"",SUM(S11,S14))
B17: Subcontracted Share of Workforce (%) | C17: =OCT!AJ17 | D17: =NOV!AJ17 | E17: =DEC!AJ17 | F17: =IFERROR(F12/F15,"") | G17: =JAN!AJ17 | H17: =FEB!AJ17 | I17: =MAR!AJ17 | J17: =IFERROR(J12/J15,"") | K17: =APR!AJ17 | L17: =MAY!AJ17 | M17: =JUN!AJ17 | N17: =IFERROR(N12/N15,"") | O17: =JUL!AJ17 | P17: =AUG!AJ17 | Q17: =SEP!AJ17 | R17: =IFERROR(R12/R15,"") | S17: =IFERROR(S12/S15,"")
B18: FTE HR Team | C18: =OCT!AJ18 | D18: =NOV!AJ18 | E18: =DEC!AJ18 | F18: =IFERROR(AVERAGE(C18:E18),"") | G18: =JAN!AJ18 | H18: =FEB!AJ18 | I18: =MAR!AJ18 | J18: =IFERROR(AVERAGE(G18:I18),"") | K18: =APR!AJ18 | L18: =MAY!AJ18 | M18: =JUN!AJ18 | N18: =IFERROR(AVERAGE(K18:M18),"") | O18: =JUL!AJ18 | P18: =AUG!AJ18 | Q18: =SEP!AJ18 | R18: =IFERROR(AVERAGE(O18:Q18),"") | S18: =IFERROR(AVERAGE(C18:E18,G18:I18,K18:M18,O18:Q18),"")
B19: Permanent Hires | C19: =OCT!AJ19 | D19: =NOV!AJ19 | E19: =DEC!AJ19 | F19: =IF(COUNT(C19:E19)=0,"",SUM(C19:E19)) | G19: =JAN!AJ19 | H19: =FEB!AJ19 | I19: =MAR!AJ19 | J19: =IF(COUNT(G19:I19)=0,"",SUM(G19:I19)) | K19: =APR!AJ19 | L19: =MAY!AJ19 | M19: =JUN!AJ19 | N19: =IF(COUNT(K19:M19)=0,"",SUM(K19:M19)) | O19: =JUL!AJ19 | P19: =AUG!AJ19 | Q19: =SEP!AJ19 | R19: =IF(COUNT(O19:Q19)=0,"",SUM(O19:Q19)) | S19: =IF(COUNT(C19:E19,G19:I19,K19:M19,O19:Q19)=0,"",SUM(C19:E19,G19:I19,K19:M19,O19:Q19))
B20: Temporary Hires | C20: =OCT!AJ20 | D20: =NOV!AJ20 | E20: =DEC!AJ20 | F20: =IF(COUNT(C20:E20)=0,"",SUM(C20:E20)) | G20: =JAN!AJ20 | H20: =FEB!AJ20 | I20: =MAR!AJ20 | J20: =IF(COUNT(G20:I20)=0,"",SUM(G20:I20)) | K20: =APR!AJ20 | L20: =MAY!AJ20 | M20: =JUN!AJ20 | N20: =IF(COUNT(K20:M20)=0,"",SUM(K20:M20)) | O20: =JUL!AJ20 | P20: =AUG!AJ20 | Q20: =SEP!AJ20 | R20: =IF(COUNT(O20:Q20)=0,"",SUM(O20:Q20)) | S20: =IF(COUNT(C20:E20,G20:I20,K20:M20,O20:Q20)=0,"",SUM(C20:E20,G20:I20,K20:M20,O20:Q20))
B21: Total Hires | C21: =OCT!AJ21 | D21: =NOV!AJ21 | E21: =DEC!AJ21 | F21: =IF(COUNT(F19:F20)=0,"",SUM(F19:F20)) | G21: =JAN!AJ21 | H21: =FEB!AJ21 | I21: =MAR!AJ21 | J21: =IF(COUNT(J19:J20)=0,"",SUM(J19:J20)) | K21: =APR!AJ21 | L21: =MAY!AJ21 | M21: =JUN!AJ21 | N21: =IF(COUNT(N19:N20)=0,"",SUM(N19:N20)) | O21: =JUL!AJ21 | P21: =AUG!AJ21 | Q21: =SEP!AJ21 | R21: =IF(COUNT(R19:R20)=0,"",SUM(R19:R20)) | S21: =IF(COUNT(S19:S20)=0,"",SUM(S19:S20))
B22: Permanent Exits | C22: =OCT!AJ22 | D22: =NOV!AJ22 | E22: =DEC!AJ22 | F22: =IF(COUNT(C22:E22)=0,"",SUM(C22:E22)) | G22: =JAN!AJ22 | H22: =FEB!AJ22 | I22: =MAR!AJ22 | J22: =IF(COUNT(G22:I22)=0,"",SUM(G22:I22)) | K22: =APR!AJ22 | L22: =MAY!AJ22 | M22: =JUN!AJ22 | N22: =IF(COUNT(K22:M22)=0,"",SUM(K22:M22)) | O22: =JUL!AJ22 | P22: =AUG!AJ22 | Q22: =SEP!AJ22 | R22: =IF(COUNT(O22:Q22)=0,"",SUM(O22:Q22)) | S22: =IF(COUNT(C22:E22,G22:I22,K22:M22,O22:Q22)=0,"",SUM(C22:E22,G22:I22,K22:M22,O22:Q22))
B23: Temporary Exits | C23: =OCT!AJ23 | D23: =NOV!AJ23 | E23: =DEC!AJ23 | F23: =IF(COUNT(C23:E23)=0,"",SUM(C23:E23)) | G23: =JAN!AJ23 | H23: =FEB!AJ23 | I23: =MAR!AJ23 | J23: =IF(COUNT(G23:I23)=0,"",SUM(G23:I23)) | K23: =APR!AJ23 | L23: =MAY!AJ23 | M23: =JUN!AJ23 | N23: =IF(COUNT(K23:M23)=0,"",SUM(K23:M23)) | O23: =JUL!AJ23 | P23: =AUG!AJ23 | Q23: =SEP!AJ23 | R23: =IF(COUNT(O23:Q23)=0,"",SUM(O23:Q23)) | S23: =IF(COUNT(C23:E23,G23:I23,K23:M23,O23:Q23)=0,"",SUM(C23:E23,G23:I23,K23:M23,O23:Q23))
B24: Total Exits | C24: =OCT!AJ24 | D24: =NOV!AJ24 | E24: =DEC!AJ24 | F24: =IF(COUNT(F22:F23)=0,"",SUM(F22:F23)) | G24: =JAN!AJ24 | H24: =FEB!AJ24 | I24: =MAR!AJ24 | J24: =IF(COUNT(J22:J23)=0,"",SUM(J22:J23)) | K24: =APR!AJ24 | L24: =MAY!AJ24 | M24: =JUN!AJ24 | N24: =IF(COUNT(N22:N23)=0,"",SUM(N22:N23)) | O24: =JUL!AJ24 | P24: =AUG!AJ24 | Q24: =SEP!AJ24 | R24: =IF(COUNT(R22:R23)=0,"",SUM(R22:R23)) | S24: =IF(COUNT(S22:S23)=0,"",SUM(S22:S23))
B25: Permanent Turnover (%) | C25: =OCT!AJ25 | D25: =NOV!AJ25 | E25: =DEC!AJ25 | F25: =IF(COUNT(F31,F32)<2,"",IF((F32+F31)=0,"",N(F22)/((F32+F31)/2))) | G25: =JAN!AJ25 | H25: =FEB!AJ25 | I25: =MAR!AJ25 | J25: =IF(COUNT(J31,J32)<2,"",IF((J32+J31)=0,"",N(J22)/((J32+J31)/2))) | K25: =APR!AJ25 | L25: =MAY!AJ25 | M25: =JUN!AJ25 | N25: =IF(COUNT(N31,N32)<2,"",IF((N32+N31)=0,"",N(N22)/((N32+N31)/2))) | O25: =JUL!AJ25 | P25: =AUG!AJ25 | Q25: =SEP!AJ25 | R25: =IF(COUNT(R31,R32)<2,"",IF((R32+R31)=0,"",N(R22)/((R32+R31)/2))) | S25: =IF(COUNT(S31,S32)<2,"",IF((S32+S31)=0,"",N(S22)/((S32+S31)/2)))
B26: Temporary Turnover (%) | C26: =OCT!AJ26 | D26: =NOV!AJ26 | E26: =DEC!AJ26 | F26: =IF(COUNT(F31,F32)<2,"",IF((F32+F31)=0,"",N(F23)/((F32+F31)/2))) | G26: =JAN!AJ26 | H26: =FEB!AJ26 | I26: =MAR!AJ26 | J26: =IF(COUNT(J31,J32)<2,"",IF((J32+J31)=0,"",N(J23)/((J32+J31)/2))) | K26: =APR!AJ26 | L26: =MAY!AJ26 | M26: =JUN!AJ26 | N26: =IF(COUNT(N31,N32)<2,"",IF((N32+N31)=0,"",N(N23)/((N32+N31)/2))) | O26: =JUL!AJ26 | P26: =AUG!AJ26 | Q26: =SEP!AJ26 | R26: =IF(COUNT(R31,R32)<2,"",IF((R32+R31)=0,"",N(R23)/((R32+R31)/2))) | S26: =IF(COUNT(S31,S32)<2,"",IF((S32+S31)=0,"",N(S23)/((S32+S31)/2)))
B27: Voluntary Terminations | C27: =OCT!AJ27 | D27: =NOV!AJ27 | E27: =DEC!AJ27 | F27: =IF(COUNT(C27:E27)=0,"",SUM(C27:E27)) | G27: =JAN!AJ27 | H27: =FEB!AJ27 | I27: =MAR!AJ27 | J27: =IF(COUNT(G27:I27)=0,"",SUM(G27:I27)) | K27: =APR!AJ27 | L27: =MAY!AJ27 | M27: =JUN!AJ27 | N27: =IF(COUNT(K27:M27)=0,"",SUM(K27:M27)) | O27: =JUL!AJ27 | P27: =AUG!AJ27 | Q27: =SEP!AJ27 | R27: =IF(COUNT(O27:Q27)=0,"",SUM(O27:Q27)) | S27: =IF(COUNT(C27:E27,G27:I27,K27:M27,O27:Q27)=0,"",SUM(C27:E27,G27:I27,K27:M27,O27:Q27))
B28: Involuntary Terminations | C28: =OCT!AJ28 | D28: =NOV!AJ28 | E28: =DEC!AJ28 | F28: =IF(COUNT(C28:E28)=0,"",SUM(C28:E28)) | G28: =JAN!AJ28 | H28: =FEB!AJ28 | I28: =MAR!AJ28 | J28: =IF(COUNT(G28:I28)=0,"",SUM(G28:I28)) | K28: =APR!AJ28 | L28: =MAY!AJ28 | M28: =JUN!AJ28 | N28: =IF(COUNT(K28:M28)=0,"",SUM(K28:M28)) | O28: =JUL!AJ28 | P28: =AUG!AJ28 | Q28: =SEP!AJ28 | R28: =IF(COUNT(O28:Q28)=0,"",SUM(O28:Q28)) | S28: =IF(COUNT(C28:E28,G28:I28,K28:M28,O28:Q28)=0,"",SUM(C28:E28,G28:I28,K28:M28,O28:Q28))
B29: Voluntary Turnover (%) | C29: =OCT!AJ29 | D29: =NOV!AJ29 | E29: =DEC!AJ29 | F29: =IF(COUNT(F31,F32)<2,"",IF((F32+F31)=0,"",N(F27)/((F32+F31)/2))) | G29: =JAN!AJ29 | H29: =FEB!AJ29 | I29: =MAR!AJ29 | J29: =IF(COUNT(J31,J32)<2,"",IF((J32+J31)=0,"",N(J27)/((J32+J31)/2))) | K29: =APR!AJ29 | L29: =MAY!AJ29 | M29: =JUN!AJ29 | N29: =IF(COUNT(N31,N32)<2,"",IF((N32+N31)=0,"",N(N27)/((N32+N31)/2))) | O29: =JUL!AJ29 | P29: =AUG!AJ29 | Q29: =SEP!AJ29 | R29: =IF(COUNT(R31,R32)<2,"",IF((R32+R31)=0,"",N(R27)/((R32+R31)/2))) | S29: =IF(COUNT(S31,S32)<2,"",IF((S32+S31)=0,"",N(S27)/((S32+S31)/2)))
B30: Involuntary Turnover (%) | C30: =OCT!AJ30 | D30: =NOV!AJ30 | E30: =DEC!AJ30 | F30: =IF(COUNT(F31,F32)<2,"",IF((F32+F31)=0,"",N(F28)/((F32+F31)/2))) | G30: =JAN!AJ30 | H30: =FEB!AJ30 | I30: =MAR!AJ30 | J30: =IF(COUNT(J31,J32)<2,"",IF((J32+J31)=0,"",N(J28)/((J32+J31)/2))) | K30: =APR!AJ30 | L30: =MAY!AJ30 | M30: =JUN!AJ30 | N30: =IF(COUNT(N31,N32)<2,"",IF((N32+N31)=0,"",N(N28)/((N32+N31)/2))) | O30: =JUL!AJ30 | P30: =AUG!AJ30 | Q30: =SEP!AJ30 | R30: =IF(COUNT(R31,R32)<2,"",IF((R32+R31)=0,"",N(R28)/((R32+R31)/2))) | S30: =IF(COUNT(S31,S32)<2,"",IF((S32+S31)=0,"",N(S28)/((S32+S31)/2)))
B31: Headcount last Month | C31: =OCT!AJ31 | D31: =NOV!AJ31 | E31: =DEC!AJ31 | F31: =IFERROR(AVERAGE(C31:E31),"") | G31: =JAN!AJ31 | H31: =FEB!AJ31 | I31: =MAR!AJ31 | J31: =IFERROR(AVERAGE(G31:I31),"") | K31: =APR!AJ31 | L31: =MAY!AJ31 | M31: =JUN!AJ31 | N31: =IFERROR(AVERAGE(K31:M31),"") | O31: =JUL!AJ31 | P31: =AUG!AJ31 | Q31: =SEP!AJ31 | R31: =IFERROR(AVERAGE(O31:Q31),"") | S31: =IFERROR(AVERAGE(C31:E31,G31:I31,K31:M31,O31:Q31),"")
B32: Headcount this Month | C32: =OCT!AJ32 | D32: =NOV!AJ32 | E32: =DEC!AJ32 | F32: =IFERROR(AVERAGE(C32:E32),"") | G32: =JAN!AJ32 | H32: =FEB!AJ32 | I32: =MAR!AJ32 | J32: =IFERROR(AVERAGE(G32:I32),"") | K32: =APR!AJ32 | L32: =MAY!AJ32 | M32: =JUN!AJ32 | N32: =IFERROR(AVERAGE(K32:M32),"") | O32: =JUL!AJ32 | P32: =AUG!AJ32 | Q32: =SEP!AJ32 | R32: =IFERROR(AVERAGE(O32:Q32),"") | S32: =IFERROR(AVERAGE(C32:E32,G32:I32,K32:M32,O32:Q32),"")
B33: Full Turnover (%) | C33: =OCT!AJ33 | D33: =NOV!AJ33 | E33: =DEC!AJ33 | F33: =IF(COUNT(F31,F32)<2,"",IF((F32+F31)=0,"",N(F24)/((F32+F31)/2))) | G33: =JAN!AJ33 | H33: =FEB!AJ33 | I33: =MAR!AJ33 | J33: =IF(COUNT(J31,J32)<2,"",IF((J32+J31)=0,"",N(J24)/((J32+J31)/2))) | K33: =APR!AJ33 | L33: =MAY!AJ33 | M33: =JUN!AJ33 | N33: =IF(COUNT(N31,N32)<2,"",IF((N32+N31)=0,"",N(N24)/((N32+N31)/2))) | O33: =JUL!AJ33 | P33: =AUG!AJ33 | Q33: =SEP!AJ33 | R33: =IF(COUNT(R31,R32)<2,"",IF((R32+R31)=0,"",N(R24)/((R32+R31)/2))) | S33: =IF(COUNT(S31,S32)<2,"",IF((S32+S31)=0,"",N(S24)/((S32+S31)/2)))
B34: Permanent Vacancies | C34: =OCT!AJ34 | D34: =NOV!AJ34 | E34: =DEC!AJ34 | F34: =IFERROR(AVERAGE(C34:E34),"") | G34: =JAN!AJ34 | H34: =FEB!AJ34 | I34: =MAR!AJ34 | J34: =IFERROR(AVERAGE(G34:I34),"") | K34: =APR!AJ34 | L34: =MAY!AJ34 | M34: =JUN!AJ34 | N34: =IFERROR(AVERAGE(K34:M34),"") | O34: =JUL!AJ34 | P34: =AUG!AJ34 | Q34: =SEP!AJ34 | R34: =IFERROR(AVERAGE(O34:Q34),"") | S34: =IFERROR(AVERAGE(C34:E34,G34:I34,K34:M34,O34:Q34),"")
B35: Temporary Vacancies | C35: =OCT!AJ35 | D35: =NOV!AJ35 | E35: =DEC!AJ35 | F35: =IFERROR(AVERAGE(C35:E35),"") | G35: =JAN!AJ35 | H35: =FEB!AJ35 | I35: =MAR!AJ35 | J35: =IFERROR(AVERAGE(G35:I35),"") | K35: =APR!AJ35 | L35: =MAY!AJ35 | M35: =JUN!AJ35 | N35: =IFERROR(AVERAGE(K35:M35),"") | O35: =JUL!AJ35 | P35: =AUG!AJ35 | Q35: =SEP!AJ35 | R35: =IFERROR(AVERAGE(O35:Q35),"") | S35: =IFERROR(AVERAGE(C35:E35,G35:I35,K35:M35,O35:Q35),"")
B36: Total Vacancies | C36: =OCT!AJ36 | D36: =NOV!AJ36 | E36: =DEC!AJ36 | F36: =IF(COUNT(F34:F35)=0,"",SUM(F34:F35)) | G36: =JAN!AJ36 | H36: =FEB!AJ36 | I36: =MAR!AJ36 | J36: =IF(COUNT(J34:J35)=0,"",SUM(J34:J35)) | K36: =APR!AJ36 | L36: =MAY!AJ36 | M36: =JUN!AJ36 | N36: =IF(COUNT(N34:N35)=0,"",SUM(N34:N35)) | O36: =JUL!AJ36 | P36: =AUG!AJ36 | Q36: =SEP!AJ36 | R36: =IF(COUNT(R34:R35)=0,"",SUM(R34:R35)) | S36: =IF(COUNT(S34:S35)=0,"",SUM(S34:S35))
B37: Authorized Positions | C37: =OCT!AJ37 | D37: =NOV!AJ37 | E37: =DEC!AJ37 | F37: =IF(COUNT(F5,F36)=0,"",N(F5)+N(F36)) | G37: =JAN!AJ37 | H37: =FEB!AJ37 | I37: =MAR!AJ37 | J37: =IF(COUNT(J5,J36)=0,"",N(J5)+N(J36)) | K37: =APR!AJ37 | L37: =MAY!AJ37 | M37: =JUN!AJ37 | N37: =IF(COUNT(N5,N36)=0,"",N(N5)+N(N36)) | O37: =JUL!AJ37 | P37: =AUG!AJ37 | Q37: =SEP!AJ37 | R37: =IF(COUNT(R5,R36)=0,"",N(R5)+N(R36)) | S37: =IF(COUNT(S5,S36)=0,"",N(S5)+N(S36))
B38: Vacancy Rate (%) | C38: =OCT!AJ38 | D38: =NOV!AJ38 | E38: =DEC!AJ38 | F38: =IFERROR(F36/F37,"") | G38: =JAN!AJ38 | H38: =FEB!AJ38 | I38: =MAR!AJ38 | J38: =IFERROR(J36/J37,"") | K38: =APR!AJ38 | L38: =MAY!AJ38 | M38: =JUN!AJ38 | N38: =IFERROR(N36/N37,"") | O38: =JUL!AJ38 | P38: =AUG!AJ38 | Q38: =SEP!AJ38 | R38: =IFERROR(R36/R37,"") | S38: =IFERROR(S36/S37,"")
B39: Permanent TimeToHire (Days) YTD | C39: =OCT!AJ39 | D39: =NOV!AJ39 | E39: =DEC!AJ39 | F39: =IFERROR(LOOKUP(2,1/ISNUMBER(C39:E39),C39:E39),"") | G39: =JAN!AJ39 | H39: =FEB!AJ39 | I39: =MAR!AJ39 | J39: =IFERROR(LOOKUP(2,1/ISNUMBER(G39:I39),G39:I39),"") | K39: =APR!AJ39 | L39: =MAY!AJ39 | M39: =JUN!AJ39 | N39: =IFERROR(LOOKUP(2,1/ISNUMBER(K39:M39),K39:M39),"") | O39: =JUL!AJ39 | P39: =AUG!AJ39 | Q39: =SEP!AJ39 | R39: =IFERROR(LOOKUP(2,1/ISNUMBER(O39:Q39),O39:Q39),"") | S39: =IFERROR(LOOKUP(2,1/ISNUMBER(C39:Q39),C39:Q39),"")
B40: Temporary TimeToHire (Days) YTD | C40: =OCT!AJ40 | D40: =NOV!AJ40 | E40: =DEC!AJ40 | F40: =IFERROR(LOOKUP(2,1/ISNUMBER(C40:E40),C40:E40),"") | G40: =JAN!AJ40 | H40: =FEB!AJ40 | I40: =MAR!AJ40 | J40: =IFERROR(LOOKUP(2,1/ISNUMBER(G40:I40),G40:I40),"") | K40: =APR!AJ40 | L40: =MAY!AJ40 | M40: =JUN!AJ40 | N40: =IFERROR(LOOKUP(2,1/ISNUMBER(K40:M40),K40:M40),"") | O40: =JUL!AJ40 | P40: =AUG!AJ40 | Q40: =SEP!AJ40 | R40: =IFERROR(LOOKUP(2,1/ISNUMBER(O40:Q40),O40:Q40),"") | S40: =IFERROR(LOOKUP(2,1/ISNUMBER(C40:Q40),C40:Q40),"")
...

Sheet OCT
B1: GCG | C1: 1079 | D1: 1171 | E1: 1162 | F1: 1076 | G1: 1170 | H1: 1078 | I1: 1172 | J1: 1074 | K1: 1161 | L1: 1062 | M1: 1075 | N1: 1044 | O1: 1066 | P1: 1158 | Q1: 1067 | R1: 1046 | S1: 1069 | T1: 1178 | U1: 1077 | V1: 1081 | W1: 1082 | X1: 1085 | Y1: 1071U | Z1: 1015 | AA1: 1004 | AB1: 1063 | AC1: 1160 | AD1: 1073 | AE1: 1042 | AF1: 1084 | AG1: 1049 | AH1: 1005 | AI1: 1115
A2: 202610 | B2: OCT | C2: GCG HDQ | D2: GCG Culinary Costa Rica | E2: GCG Food Guatemala | F2: GCG Guatemala | G2: GCG Aviation Ground Honduras | H2: GCG Honduras | I2: GCG Concessions Panama | J2: GCG El Salvador | K2: GCG Food El Salvador | L2: GCG Antigua | M2: GCG Grand Cayman | N2: GCG Aviation Ground Jamaica | O2: GCG Jamaica | P2: GCG Aviation Ground Saint Lucia | Q2: GCG Saint Lucia | R2: GCG Ground Saint Thomas | S2: GCG Bogota Colombia | T2: GCG Colombia | U2: GCG Guayaquil | V2: GCG Paraguay | W2: GCG Quito | X2: GCG Uruguay | Y2: GCG Caracas | Z2: Calloway Aruba | AA2: Airport Rest. Barbados | AB2: GCG Barbados | AC2: GCG Aviation Ground Barbados | AD2: GCG Curacao | AE2: GCG Events Curacao | AF2: GCG Sint Maarten Sky Dining | AG2: GCG Sint Maarten Airport Dining | AH2: Allied Caterers Trinidad | AI2: Katerserv Trinidad | AJ2: TOTAL | AK2: Total by Division | AL2: =N(AL11)<>0
A3: =+A2 | B3: Permanent (Regular) Headcount | C3: =IF([1]OCT!C3="","",[1]OCT!C3) | D3: =IF([2]OCT!C3="","",[2]OCT!C3) | E3: =IF([2]OCT!D3="","",[2]OCT!D3) | F3: =IF([2]OCT!E3="","",[2]OCT!E3) | G3: =IF([2]OCT!F3="","",[2]OCT!F3) | H3: =IF([2]OCT!G3="","",[2]OCT!G3) | I3: =IF([2]OCT!H3="","",[2]OCT!H3) | J3: =IF([2]OCT!I3="","",[2]OCT!I3) | K3: =IF([2]OCT!J3="","",[2]OCT!J3) | L3: =IF([3]OCT!C3="","",[3]OCT!C3) | M3: =IF([3]OCT!D3="","",[3]OCT!D3) | N3: =IF([3]OCT!E3="","",[3]OCT!E3) | O3: =IF([3]OCT!F3="","",[3]OCT!F3) | P3: =IF([3]OCT!G3="","",[3]OCT!G3) | Q3: =IF([3]OCT!H3="","",[3]OCT!H3) | R3: =IF([3]OCT!I3="","",[3]OCT!I3) | S3: =IF([4]OCT!C3="","",[4]OCT!C3) | T3: =IF([4]OCT!D3="","",[4]OCT!D3) | U3: =IF([4]OCT!E3="","",[4]OCT!E3) | V3: =IF([4]OCT!F3="","",[4]OCT!F3) | W3: =IF([4]OCT!G3="","",[4]OCT!G3) | X3: =IF([4]OCT!H3="","",[4]OCT!H3) | Y3: =IF([4]OCT!I3="","",[4]OCT!I3) | Z3: =IF([5]OCT!C3="","",[5]OCT!C3) | AA3: =IF([5]OCT!D3="","",[5]OCT!D3) | AB3: =IF([5]OCT!E3="","",[5]OCT!E3) | AC3: =IF([5]OCT!F3="","",[5]OCT!F3) | AD3: =IF([5]OCT!G3="","",[5]OCT!G3) | AE3: =IF([5]OCT!H3="","",[5]OCT!H3) | AF3: =IF([5]OCT!I3="","",[5]OCT!I3) | AG3: =IF([5]OCT!J3="","",[5]OCT!J3) | ... AI3: =IF([5]OCT!L3="","",[5]OCT!L3) | AJ3: =IF(COUNT(C3:AI3)=0,"",SUM(C3:AI3)) | AK3: ∑
B4: Temporary (Fix Term) Headcount | C4: =IF([1]OCT!C4="","",[1]OCT!C4) | D4: =IF([2]OCT!C4="","",[2]OCT!C4) | E4: =IF([2]OCT!D4="","",[2]OCT!D4) | F4: =IF([2]OCT!E4="","",[2]OCT!E4) | G4: =IF([2]OCT!F4="","",[2]OCT!F4) | H4: =IF([2]OCT!G4="","",[2]OCT!G4) | I4: =IF([2]OCT!H4="","",[2]OCT!H4) | J4: =IF([2]OCT!I4="","",[2]OCT!I4) | K4: =IF([2]OCT!J4="","",[2]OCT!J4) | L4: =IF([3]OCT!C4="","",[3]OCT!C4) | M4: =IF([3]OCT!D4="","",[3]OCT!D4) | N4: =IF([3]OCT!E4="","",[3]OCT!E4) | O4: =IF([3]OCT!F4="","",[3]OCT!F4) | P4: =IF([3]OCT!G4="","",[3]OCT!G4) | Q4: =IF([3]OCT!H4="","",[3]OCT!H4) | R4: =IF([3]OCT!I4="","",[3]OCT!I4) | S4: =IF([4]OCT!C4="","",[4]OCT!C4) | T4: =IF([4]OCT!D4="","",[4]OCT!D4) | U4: =IF([4]OCT!E4="","",[4]OCT!E4) | V4: =IF([4]OCT!F4="","",[4]OCT!F4) | W4: =IF([4]OCT!G4="","",[4]OCT!G4) | X4: =IF([4]OCT!H4="","",[4]OCT!H4) | Y4: =IF([4]OCT!I4="","",[4]OCT!I4) | Z4: =IF([5]OCT!C4="","",[5]OCT!C4) | AA4: =IF([5]OCT!D4="","",[5]OCT!D4) | AB4: =IF([5]OCT!E4="","",[5]OCT!E4) | AC4: =IF([5]OCT!F4="","",[5]OCT!F4) | AD4: =IF([5]OCT!G4="","",[5]OCT!G4) | AE4: =IF([5]OCT!H4="","",[5]OCT!H4) | AF4: =IF([5]OCT!I4="","",[5]OCT!I4) | AG4: =IF([5]OCT!J4="","",[5]OCT!J4) | ... AI4: =IF([5]OCT!L4="","",[5]OCT!L4) | AJ4: =IF(COUNT(C4:AI4)=0,"",SUM(C4:AI4)) | AK4: ∑
B5: Employee Headcount (Productivity) | C5: =IF(COUNT(C3:C4)=0,"",SUM(C3:C4)) | D5: =IF(COUNT(D3:D4)=0,"",SUM(D3:D4)) | E5: =IF(COUNT(E3:E4)=0,"",SUM(E3:E4)) | F5: =IF(COUNT(F3:F4)=0,"",SUM(F3:F4)) | G5: =IF(COUNT(G3:G4)=0,"",SUM(G3:G4)) | H5: =IF(COUNT(H3:H4)=0,"",SUM(H3:H4)) | I5: =IF(COUNT(I3:I4)=0,"",SUM(I3:I4)) | J5: =IF(COUNT(J3:J4)=0,"",SUM(J3:J4)) | ... AJ5: =IF(COUNT(AJ3:AJ4)=0,"",SUM(AJ3:AJ4)) | AK5: ϝ
B6: Headcount = 1.00 | C6: =IF([1]OCT!C6="","",[1]OCT!C6) | D6: =IF([2]OCT!C6="","",[2]OCT!C6) | E6: =IF([2]OCT!D6="","",[2]OCT!D6) | F6: =IF([2]OCT!E6="","",[2]OCT!E6) | G6: =IF([2]OCT!F6="","",[2]OCT!F6) | H6: =IF([2]OCT!G6="","",[2]OCT!G6) | I6: =IF([2]OCT!H6="","",[2]OCT!H6) | J6: =IF([2]OCT!I6="","",[2]OCT!I6) | K6: =IF([2]OCT!J6="","",[2]OCT!J6) | L6: =IF([3]OCT!C6="","",[3]OCT!C6) | M6: =IF([3]OCT!D6="","",[3]OCT!D6) | N6: =IF([3]OCT!E6="","",[3]OCT!E6) | O6: =IF([3]OCT!F6="","",[3]OCT!F6) | P6: =IF([3]OCT!G6="","",[3]OCT!G6) | Q6: =IF([3]OCT!H6="","",[3]OCT!H6) | R6: =IF([3]OCT!I6="","",[3]OCT!I6) | S6: =IF([4]OCT!C6="","",[4]OCT!C6) | T6: =IF([4]OCT!D6="","",[4]OCT!D6) | U6: =IF([4]OCT!E6="","",[4]OCT!E6) | V6: =IF([4]OCT!F6="","",[4]OCT!F6) | W6: =IF([4]OCT!G6="","",[4]OCT!G6) | X6: =IF([4]OCT!H6="","",[4]OCT!H6) | Y6: =IF([4]OCT!I6="","",[4]OCT!I6) | Z6: =IF([5]OCT!C6="","",[5]OCT!C6) | AA6: =IF([5]OCT!D6="","",[5]OCT!D6) | AB6: =IF([5]OCT!E6="","",[5]OCT!E6) | AC6: =IF([5]OCT!F6="","",[5]OCT!F6) | AD6: =IF([5]OCT!G6="","",[5]OCT!G6) | AE6: =IF([5]OCT!H6="","",[5]OCT!H6) | AF6: =IF([5]OCT!I6="","",[5]OCT!I6) | AG6: =IF([5]OCT!J6="","",[5]OCT!J6) | ... AI6: =IF([5]OCT!L6="","",[5]OCT!L6) | AJ6: =IF(COUNT(C6:AI6)=0,"",SUM(C6:AI6)) | AK6: ∑
B7: Headcount = 0.75 | C7: =IF([1]OCT!C7="","",[1]OCT!C7) | D7: =IF([2]OCT!C7="","",[2]OCT!C7) | E7: =IF([2]OCT!D7="","",[2]OCT!D7) | F7: =IF([2]OCT!E7="","",[2]OCT!E7) | G7: =IF([2]OCT!F7="","",[2]OCT!F7) | H7: =IF([2]OCT!G7="","",[2]OCT!G7) | I7: =IF([2]OCT!H7="","",[2]OCT!H7) | J7: =IF([2]OCT!I7="","",[2]OCT!I7) | K7: =IF([2]OCT!J7="","",[2]OCT!J7) | L7: =IF([3]OCT!C7="","",[3]OCT!C7) | M7: =IF([3]OCT!D7="","",[3]OCT!D7) | N7: =IF([3]OCT!E7="","",[3]OCT!E7) | O7: =IF([3]OCT!F7="","",[3]OCT!F7) | P7: =IF([3]OCT!G7="","",[3]OCT!G7) | Q7: =IF([3]OCT!H7="","",[3]OCT!H7) | R7: =IF([3]OCT!I7="","",[3]OCT!I7) | S7: =IF([4]OCT!C7="","",[4]OCT!C7) | T7: =IF([4]OCT!D7="","",[4]OCT!D7) | U7: =IF([4]OCT!E7="","",[4]OCT!E7) | V7: =IF([4]OCT!F7="","",[4]OCT!F7) | W7: =IF([4]OCT!G7="","",[4]OCT!G7) | X7: =IF([4]OCT!H7="","",[4]OCT!H7) | Y7: =IF([4]OCT!I7="","",[4]OCT!I7) | Z7: =IF([5]OCT!C7="","",[5]OCT!C7) | AA7: =IF([5]OCT!D7="","",[5]OCT!D7) | AB7: =IF([5]OCT!E7="","",[5]OCT!E7) | AC7: =IF([5]OCT!F7="","",[5]OCT!F7) | AD7: =IF([5]OCT!G7="","",[5]OCT!G7) | AE7: =IF([5]OCT!H7="","",[5]OCT!H7) | AF7: =IF([5]OCT!I7="","",[5]OCT!I7) | AG7: =IF([5]OCT!J7="","",[5]OCT!J7) | ... AI7: =IF([5]OCT!L7="","",[5]OCT!L7) | AJ7: =IF(COUNT(C7:AI7)=0,"",SUM(C7:AI7)) | AK7: ∑
B8: Headcount = 0.50 | C8: =IF([1]OCT!C8="","",[1]OCT!C8) | D8: =IF([2]OCT!C8="","",[2]OCT!C8) | E8: =IF([2]OCT!D8="","",[2]OCT!D8) | F8: =IF([2]OCT!E8="","",[2]OCT!E8) | G8: =IF([2]OCT!F8="","",[2]OCT!F8) | H8: =IF([2]OCT!G8="","",[2]OCT!G8) | I8: =IF([2]OCT!H8="","",[2]OCT!H8) | J8: =IF([2]OCT!I8="","",[2]OCT!I8) | K8: =IF([2]OCT!J8="","",[2]OCT!J8) | L8: =IF([3]OCT!C8="","",[3]OCT!C8) | M8: =IF([3]OCT!D8="","",[3]OCT!D8) | N8: =IF([3]OCT!E8="","",[3]OCT!E8) | O8: =IF([3]OCT!F8="","",[3]OCT!F8) | P8: =IF([3]OCT!G8="","",[3]OCT!G8) | Q8: =IF([3]OCT!H8="","",[3]OCT!H8) | R8: =IF([3]OCT!I8="","",[3]OCT!I8) | S8: =IF([4]OCT!C8="","",[4]OCT!C8) | T8: =IF([4]OCT!D8="","",[4]OCT!D8) | U8: =IF([4]OCT!E8="","",[4]OCT!E8) | V8: =IF([4]OCT!F8="","",[4]OCT!F8) | W8: =IF([4]OCT!G8="","",[4]OCT!G8) | X8: =IF([4]OCT!H8="","",[4]OCT!H8) | Y8: =IF([4]OCT!I8="","",[4]OCT!I8) | Z8: =IF([5]OCT!C8="","",[5]OCT!C8) | AA8: =IF([5]OCT!D8="","",[5]OCT!D8) | AB8: =IF([5]OCT!E8="","",[5]OCT!E8) | AC8: =IF([5]OCT!F8="","",[5]OCT!F8) | AD8: =IF([5]OCT!G8="","",[5]OCT!G8) | AE8: =IF([5]OCT!H8="","",[5]OCT!H8) | AF8: =IF([5]OCT!I8="","",[5]OCT!I8) | AG8: =IF([5]OCT!J8="","",[5]OCT!J8) | ... AI8: =IF([5]OCT!L8="","",[5]OCT!L8) | AJ8: =IF(COUNT(C8:AI8)=0,"",SUM(C8:AI8)) | AK8: ∑
B9: Headcount = 0.25 | C9: =IF([1]OCT!C9="","",[1]OCT!C9) | D9: =IF([2]OCT!C9="","",[2]OCT!C9) | E9: =IF([2]OCT!D9="","",[2]OCT!D9) | F9: =IF([2]OCT!E9="","",[2]OCT!E9) | G9: =IF([2]OCT!F9="","",[2]OCT!F9) | H9: =IF([2]OCT!G9="","",[2]OCT!G9) | I9: =IF([2]OCT!H9="","",[2]OCT!H9) | J9: =IF([2]OCT!I9="","",[2]OCT!I9) | K9: =IF([2]OCT!J9="","",[2]OCT!J9) | L9: =IF([3]OCT!C9="","",[3]OCT!C9) | M9: =IF([3]OCT!D9="","",[3]OCT!D9) | N9: =IF([3]OCT!E9="","",[3]OCT!E9) | O9: =IF([3]OCT!F9="","",[3]OCT!F9) | P9: =IF([3]OCT!G9="","",[3]OCT!G9) | Q9: =IF([3]OCT!H9="","",[3]OCT!H9) | R9: =IF([3]OCT!I9="","",[3]OCT!I9) | S9: =IF([4]OCT!C9="","",[4]OCT!C9) | T9: =IF([4]OCT!D9="","",[4]OCT!D9) | U9: =IF([4]OCT!E9="","",[4]OCT!E9) | V9: =IF([4]OCT!F9="","",[4]OCT!F9) | W9: =IF([4]OCT!G9="","",[4]OCT!G9) | X9: =IF([4]OCT!H9="","",[4]OCT!H9) | Y9: =IF([4]OCT!I9="","",[4]OCT!I9) | Z9: =IF([5]OCT!C9="","",[5]OCT!C9) | AA9: =IF([5]OCT!D9="","",[5]OCT!D9) | AB9: =IF([5]OCT!E9="","",[5]OCT!E9) | AC9: =IF([5]OCT!F9="","",[5]OCT!F9) | AD9: =IF([5]OCT!G9="","",[5]OCT!G9) | AE9: =IF([5]OCT!H9="","",[5]OCT!H9) | AF9: =IF([5]OCT!I9="","",[5]OCT!I9) | AG9: =IF([5]OCT!J9="","",[5]OCT!J9) | ... AI9: =IF([5]OCT!L9="","",[5]OCT!L9) | AJ9: =IF(COUNT(C9:AI9)=0,"",SUM(C9:AI9)) | AK9: ∑
B10: Standard Monthly Hours (FTE basis) | C10: =IF([1]OCT!C10="","",[1]OCT!C10) | D10: =IF([2]OCT!C10="","",[2]OCT!C10) | E10: =IF([2]OCT!D10="","",[2]OCT!D10) | F10: =IF([2]OCT!E10="","",[2]OCT!E10) | G10: =IF([2]OCT!F10="","",[2]OCT!F10) | H10: =IF([2]OCT!G10="","",[2]OCT!G10) | I10: =IF([2]OCT!H10="","",[2]OCT!H10) | J10: =IF([2]OCT!I10="","",[2]OCT!I10) | K10: =IF([2]OCT!J10="","",[2]OCT!J10) | L10: =IF([3]OCT!C10="","",[3]OCT!C10) | M10: =IF([3]OCT!D10="","",[3]OCT!D10) | N10: =IF([3]OCT!E10="","",[3]OCT!E10) | O10: =IF([3]OCT!F10="","",[3]OCT!F10) | P10: =IF([3]OCT!G10="","",[3]OCT!G10) | Q10: =IF([3]OCT!H10="","",[3]OCT!H10) | R10: =IF([3]OCT!I10="","",[3]OCT!I10) | S10: =IF([4]OCT!C10="","",[4]OCT!C10) | T10: =IF([4]OCT!D10="","",[4]OCT!D10) | U10: =IF([4]OCT!E10="","",[4]OCT!E10) | V10: =IF([4]OCT!F10="","",[4]OCT!F10) | W10: =IF([4]OCT!G10="","",[4]OCT!G10) | X10: =IF([4]OCT!H10="","",[4]OCT!H10) | Y10: =IF([4]OCT!I10="","",[4]OCT!I10) | Z10: =IF([5]OCT!C10="","",[5]OCT!C10) | AA10: =IF([5]OCT!D10="","",[5]OCT!D10) | AB10: =IF([5]OCT!E10="","",[5]OCT!E10) | AC10: =IF([5]OCT!F10="","",[5]OCT!F10) | AD10: =IF([5]OCT!G10="","",[5]OCT!G10) | AE10: =IF([5]OCT!H10="","",[5]OCT!H10) | AF10: =IF([5]OCT!I10="","",[5]OCT!I10) | AG10: =IF([5]OCT!J10="","",[5]OCT!J10) | ... AI10: =IF([5]OCT!L10="","",[5]OCT!L10) | AJ10: =IFERROR(AVERAGE(C10:AI10),"") | AK10: Avg
B11: Employee FTE (Finance) | C11: =IF(COUNT(C6:C9)=0,"",N(C6)+N(C7)*0.75+N(C8)*0.5+N(C9)*0.25) | D11: =IF(COUNT(D6:D9)=0,"",N(D6)+N(D7)*0.75+N(D8)*0.5+N(D9)*0.25) | E11: =IF(COUNT(E6:E9)=0,"",N(E6)+N(E7)*0.75+N(E8)*0.5+N(E9)*0.25) | F11: =IF(COUNT(F6:F9)=0,"",N(F6)+N(F7)*0.75+N(F8)*0.5+N(F9)*0.25) | G11: =IF(COUNT(G6:G9)=0,"",N(G6)+N(G7)*0.75+N(G8)*0.5+N(G9)*0.25) | H11: =IF(COUNT(H6:H9)=0,"",N(H6)+N(H7)*0.75+N(H8)*0.5+N(H9)*0.25) | I11: =IF(COUNT(I6:I9)=0,"",N(I6)+N(I7)*0.75+N(I8)*0.5+N(I9)*0.25) | J11: =IF(COUNT(J6:J9)=0,"",N(J6)+N(J7)*0.75+N(J8)*0.5+N(J9)*0.25) | ... AJ11: =IF(COUNT(AJ6:AJ9)=0,"",N(AJ6)+N(AJ7)*0.75+N(AJ8)*0.5+N(AJ9)*0.25) | AK11: FTE | AL11: =IF(COUNT(AJ5:AJ9)=0,"",N(AJ6)+N(AJ7)+N(AJ8)+N(AJ9)-N(AJ5))
B12: Subcontracted Workforce HC | C12: =IF([1]OCT!C12="","",[1]OCT!C12) | D12: =IF([2]OCT!C12="","",[2]OCT!C12) | E12: =IF([2]OCT!D12="","",[2]OCT!D12) | F12: =IF([2]OCT!E12="","",[2]OCT!E12) | G12: =IF([2]OCT!F12="","",[2]OCT!F12) | H12: =IF([2]OCT!G12="","",[2]OCT!G12) | I12: =IF([2]OCT!H12="","",[2]OCT!H12) | J12: =IF([2]OCT!I12="","",[2]OCT!I12) | K12: =IF([2]OCT!J12="","",[2]OCT!J12) | L12: =IF([3]OCT!C12="","",[3]OCT!C12) | M12: =IF([3]OCT!D12="","",[3]OCT!D12) | N12: =IF([3]OCT!E12="","",[3]OCT!E12) | O12: =IF([3]OCT!F12="","",[3]OCT!F12) | P12: =IF([3]OCT!G12="","",[3]OCT!G12) | Q12: =IF([3]OCT!H12="","",[3]OCT!H12) | R12: =IF([3]OCT!I12="","",[3]OCT!I12) | S12: =IF([4]OCT!C12="","",[4]OCT!C12) | T12: =IF([4]OCT!D12="","",[4]OCT!D12) | U12: =IF([4]OCT!E12="","",[4]OCT!E12) | V12: =IF([4]OCT!F12="","",[4]OCT!F12) | W12: =IF([4]OCT!G12="","",[4]OCT!G12) | X12: =IF([4]OCT!H12="","",[4]OCT!H12) | Y12: =IF([4]OCT!I12="","",[4]OCT!I12) | Z12: =IF([5]OCT!C12="","",[5]OCT!C12) | AA12: =IF([5]OCT!D12="","",[5]OCT!D12) | AB12: =IF([5]OCT!E12="","",[5]OCT!E12) | AC12: =IF([5]OCT!F12="","",[5]OCT!F12) | AD12: =IF([5]OCT!G12="","",[5]OCT!G12) | AE12: =IF([5]OCT!H12="","",[5]OCT!H12) | AF12: =IF([5]OCT!I12="","",[5]OCT!I12) | AG12: =IF([5]OCT!J12="","",[5]OCT!J12) | ... AI12: =IF([5]OCT!L12="","",[5]OCT!L12) | AJ12: =IF(COUNT(C12:AI12)=0,"",SUM(C12:AI12)) | AK12: ∑
B13: Subcontracted Productive Hours | C13: =IF([1]OCT!C13="","",[1]OCT!C13) | D13: =IF([2]OCT!C13="","",[2]OCT!C13) | E13: =IF([2]OCT!D13="","",[2]OCT!D13) | F13: =IF([2]OCT!E13="","",[2]OCT!E13) | G13: =IF([2]OCT!F13="","",[2]OCT!F13) | H13: =IF([2]OCT!G13="","",[2]OCT!G13) | I13: =IF([2]OCT!H13="","",[2]OCT!H13) | J13: =IF([2]OCT!I13="","",[2]OCT!I13) | K13: =IF([2]OCT!J13="","",[2]OCT!J13) | L13: =IF([3]OCT!C13="","",[3]OCT!C13) | M13: =IF([3]OCT!D13="","",[3]OCT!D13) | N13: =IF([3]OCT!E13="","",[3]OCT!E13) | O13: =IF([3]OCT!F13="","",[3]OCT!F13) | P13: =IF([3]OCT!G13="","",[3]OCT!G13) | Q13: =IF([3]OCT!H13="","",[3]OCT!H13) | R13: =IF([3]OCT!I13="","",[3]OCT!I13) | S13: =IF([4]OCT!C13="","",[4]OCT!C13) | T13: =IF([4]OCT!D13="","",[4]OCT!D13) | U13: =IF([4]OCT!E13="","",[4]OCT!E13) | V13: =IF([4]OCT!F13="","",[4]OCT!F13) | W13: =IF([4]OCT!G13="","",[4]OCT!G13) | X13: =IF([4]OCT!H13="","",[4]OCT!H13) | Y13: =IF([4]OCT!I13="","",[4]OCT!I13) | Z13: =IF([5]OCT!C13="","",[5]OCT!C13) | AA13: =IF([5]OCT!D13="","",[5]OCT!D13) | AB13: =IF([5]OCT!E13="","",[5]OCT!E13) | AC13: =IF([5]OCT!F13="","",[5]OCT!F13) | AD13: =IF([5]OCT!G13="","",[5]OCT!G13) | AE13: =IF([5]OCT!H13="","",[5]OCT!H13) | AF13: =IF([5]OCT!I13="","",[5]OCT!I13) | AG13: =IF([5]OCT!J13="","",[5]OCT!J13) | ... AI13: =IF([5]OCT!L13="","",[5]OCT!L13) | AJ13: =IF(COUNT(C13:AI13)=0,"",SUM(C13:AI13)) | AK13: ∑
B14: Subcontracted FTE | C14: =IFERROR(C13/C10,"") | D14: =IFERROR(D13/D10,"") | E14: =IFERROR(E13/E10,"") | F14: =IFERROR(F13/F10,"") | G14: =IFERROR(G13/G10,"") | H14: =IFERROR(H13/H10,"") | I14: =IFERROR(I13/I10,"") | J14: =IFERROR(J13/J10,"") | ... AI14: =IFERROR(AI13/AI10,"") | AJ14: =IF(COUNT(C14:AI14)=0,"",SUM(C14:AI14)) | AK14: FTE
B15: Total Operational Workforce | C15: =IF(COUNT(C5,C12)=0,"",SUM(C5,C12)) | D15: =IF(COUNT(D5,D12)=0,"",SUM(D5,D12)) | E15: =IF(COUNT(E5,E12)=0,"",SUM(E5,E12)) | F15: =IF(COUNT(F5,F12)=0,"",SUM(F5,F12)) | G15: =IF(COUNT(G5,G12)=0,"",SUM(G5,G12)) | H15: =IF(COUNT(H5,H12)=0,"",SUM(H5,H12)) | I15: =IF(COUNT(I5,I12)=0,"",SUM(I5,I12)) | J15: =IF(COUNT(J5,J12)=0,"",SUM(J5,J12)) | ... AJ15: =IF(COUNT(AJ5,AJ12)=0,"",SUM(AJ5,AJ12)) | AK15: ϝ
B16: Total Operational FTE | C16: =IF(COUNT(C11,C14)=0,"",SUM(C11,C14)) | D16: =IF(COUNT(D11,D14)=0,"",SUM(D11,D14)) | E16: =IF(COUNT(E11,E14)=0,"",SUM(E11,E14)) | F16: =IF(COUNT(F11,F14)=0,"",SUM(F11,F14)) | G16: =IF(COUNT(G11,G14)=0,"",SUM(G11,G14)) | H16: =IF(COUNT(H11,H14)=0,"",SUM(H11,H14)) | I16: =IF(COUNT(I11,I14)=0,"",SUM(I11,I14)) | J16: =IF(COUNT(J11,J14)=0,"",SUM(J11,J14)) | ... AJ16: =IF(COUNT(AJ11,AJ14)=0,"",SUM(AJ11,AJ14)) | AK16: FTE
B17: Subcontracted Share of Workforce (%) | C17: =IFERROR(C12/C15,"") | D17: =IFERROR(D12/D15,"") | E17: =IFERROR(E12/E15,"") | F17: =IFERROR(F12/F15,"") | G17: =IFERROR(G12/G15,"") | H17: =IFERROR(H12/H15,"") | I17: =IFERROR(I12/I15,"") | J17: =IFERROR(J12/J15,"") | ... AJ17: =IFERROR(AJ12/AJ15,"") | AK17: ϝ
B18: FTE HR Team | C18: =IF([1]OCT!C18="","",[1]OCT!C18) | D18: =IF([2]OCT!C18="","",[2]OCT!C18) | E18: =IF([2]OCT!D18="","",[2]OCT!D18) | F18: =IF([2]OCT!E18="","",[2]OCT!E18) | G18: =IF([2]OCT!F18="","",[2]OCT!F18) | H18: =IF([2]OCT!G18="","",[2]OCT!G18) | I18: =IF([2]OCT!H18="","",[2]OCT!H18) | J18: =IF([2]OCT!I18="","",[2]OCT!I18) | K18: =IF([2]OCT!J18="","",[2]OCT!J18) | L18: =IF([3]OCT!C18="","",[3]OCT!C18) | M18: =IF([3]OCT!D18="","",[3]OCT!D18) | N18: =IF([3]OCT!E18="","",[3]OCT!E18) | O18: =IF([3]OCT!F18="","",[3]OCT!F18) | P18: =IF([3]OCT!G18="","",[3]OCT!G18) | Q18: =IF([3]OCT!H18="","",[3]OCT!H18) | R18: =IF([3]OCT!I18="","",[3]OCT!I18) | S18: =IF([4]OCT!C18="","",[4]OCT!C18) | T18: =IF([4]OCT!D18="","",[4]OCT!D18) | U18: =IF([4]OCT!E18="","",[4]OCT!E18) | V18: =IF([4]OCT!F18="","",[4]OCT!F18) | W18: =IF([4]OCT!G18="","",[4]OCT!G18) | X18: =IF([4]OCT!H18="","",[4]OCT!H18) | Y18: =IF([4]OCT!I18="","",[4]OCT!I18) | Z18: =IF([5]OCT!C18="","",[5]OCT!C18) | AA18: =IF([5]OCT!D18="","",[5]OCT!D18) | AB18: =IF([5]OCT!E18="","",[5]OCT!E18) | AC18: =IF([5]OCT!F18="","",[5]OCT!F18) | AD18: =IF([5]OCT!G18="","",[5]OCT!G18) | AE18: =IF([5]OCT!H18="","",[5]OCT!H18) | AF18: =IF([5]OCT!I18="","",[5]OCT!I18) | AG18: =IF([5]OCT!J18="","",[5]OCT!J18) | ... AI18: =IF([5]OCT!L18="","",[5]OCT!L18) | AJ18: =IF(COUNT(C18:AI18)=0,"",SUM(C18:AI18)) | AK18: ∑
B19: Permanent Hires | C19: =IF([1]OCT!C19="","",[1]OCT!C19) | D19: =IF([2]OCT!C19="","",[2]OCT!C19) | E19: =IF([2]OCT!D19="","",[2]OCT!D19) | F19: =IF([2]OCT!E19="","",[2]OCT!E19) | G19: =IF([2]OCT!F19="","",[2]OCT!F19) | H19: =IF([2]OCT!G19="","",[2]OCT!G19) | I19: =IF([2]OCT!H19="","",[2]OCT!H19) | J19: =IF([2]OCT!I19="","",[2]OCT!I19) | K19: =IF([2]OCT!J19="","",[2]OCT!J19) | L19: =IF([3]OCT!C19="","",[3]OCT!C19) | M19: =IF([3]OCT!D19="","",[3]OCT!D19) | N19: =IF([3]OCT!E19="","",[3]OCT!E19) | O19: =IF([3]OCT!F19="","",[3]OCT!F19) | P19: =IF([3]OCT!G19="","",[3]OCT!G19) | Q19: =IF([3]OCT!H19="","",[3]OCT!H19) | R19: =IF([3]OCT!I19="","",[3]OCT!I19) | S19: =IF([4]OCT!C19="","",[4]OCT!C19) | T19: =IF([4]OCT!D19="","",[4]OCT!D19) | U19: =IF([4]OCT!E19="","",[4]OCT!E19) | V19: =IF([4]OCT!F19="","",[4]OCT!F19) | W19: =IF([4]OCT!G19="","",[4]OCT!G19) | X19: =IF([4]OCT!H19="","",[4]OCT!H19) | Y19: =IF([4]OCT!I19="","",[4]OCT!I19) | Z19: =IF([5]OCT!C19="","",[5]OCT!C19) | AA19: =IF([5]OCT!D19="","",[5]OCT!D19) | AB19: =IF([5]OCT!E19="","",[5]OCT!E19) | AC19: =IF([5]OCT!F19="","",[5]OCT!F19) | AD19: =IF([5]OCT!G19="","",[5]OCT!G19) | AE19: =IF([5]OCT!H19="","",[5]OCT!H19) | AF19: =IF([5]OCT!I19="","",[5]OCT!I19) | AG19: =IF([5]OCT!J19="","",[5]OCT!J19) | ... AI19: =IF([5]OCT!L19="","",[5]OCT!L19) | AJ19: =IF(COUNT(C19:AI19)=0,"",SUM(C19:AI19)) | AK19: ∑
B20: Temporary Hires | C20: =IF([1]OCT!C20="","",[1]OCT!C20) | D20: =IF([2]OCT!C20="","",[2]OCT!C20) | E20: =IF([2]OCT!D20="","",[2]OCT!D20) | F20: =IF([2]OCT!E20="","",[2]OCT!E20) | G20: =IF([2]OCT!F20="","",[2]OCT!F20) | H20: =IF([2]OCT!G20="","",[2]OCT!G20) | I20: =IF([2]OCT!H20="","",[2]OCT!H20) | J20: =IF([2]OCT!I20="","",[2]OCT!I20) | K20: =IF([2]OCT!J20="","",[2]OCT!J20) | L20: =IF([3]OCT!C20="","",[3]OCT!C20) | M20: =IF([3]OCT!D20="","",[3]OCT!D20) | N20: =IF([3]OCT!E20="","",[3]OCT!E20) | O20: =IF([3]OCT!F20="","",[3]OCT!F20) | P20: =IF([3]OCT!G20="","",[3]OCT!G20) | Q20: =IF([3]OCT!H20="","",[3]OCT!H20) | R20: =IF([3]OCT!I20="","",[3]OCT!I20) | S20: =IF([4]OCT!C20="","",[4]OCT!C20) | T20: =IF([4]OCT!D20="","",[4]OCT!D20) | U20: =IF([4]OCT!E20="","",[4]OCT!E20) | V20: =IF([4]OCT!F20="","",[4]OCT!F20) | W20: =IF([4]OCT!G20="","",[4]OCT!G20) | X20: =IF([4]OCT!H20="","",[4]OCT!H20) | Y20: =IF([4]OCT!I20="","",[4]OCT!I20) | Z20: =IF([5]OCT!C20="","",[5]OCT!C20) | AA20: =IF([5]OCT!D20="","",[5]OCT!D20) | AB20: =IF([5]OCT!E20="","",[5]OCT!E20) | AC20: =IF([5]OCT!F20="","",[5]OCT!F20) | AD20: =IF([5]OCT!G20="","",[5]OCT!G20) | AE20: =IF([5]OCT!H20="","",[5]OCT!H20) | AF20: =IF([5]OCT!I20="","",[5]OCT!I20) | AG20: =IF([5]OCT!J20="","",[5]OCT!J20) | ... AI20: =IF([5]OCT!L20="","",[5]OCT!L20) | AJ20: =IF(COUNT(C20:AI20)=0,"",SUM(C20:AI20)) | AK20: ∑
B21: Total Hires | C21: =IF(COUNT(C19:C20)=0,"",SUM(C19:C20)) | D21: =IF(COUNT(D19:D20)=0,"",SUM(D19:D20)) | E21: =IF(COUNT(E19:E20)=0,"",SUM(E19:E20)) | F21: =IF(COUNT(F19:F20)=0,"",SUM(F19:F20)) | G21: =IF(COUNT(G19:G20)=0,"",SUM(G19:G20)) | H21: =IF(COUNT(H19:H20)=0,"",SUM(H19:H20)) | I21: =IF(COUNT(I19:I20)=0,"",SUM(I19:I20)) | J21: =IF(COUNT(J19:J20)=0,"",SUM(J19:J20)) | ... AJ21: =IF(COUNT(AJ19:AJ20)=0,"",SUM(AJ19:AJ20)) | AK21: ϝ
B22: Permanent Exits | C22: =IF([1]OCT!C22="","",[1]OCT!C22) | D22: =IF([2]OCT!C22="","",[2]OCT!C22) | E22: =IF([2]OCT!D22="","",[2]OCT!D22) | F22: =IF([2]OCT!E22="","",[2]OCT!E22) | G22: =IF([2]OCT!F22="","",[2]OCT!F22) | H22: =IF([2]OCT!G22="","",[2]OCT!G22) | I22: =IF([2]OCT!H22="","",[2]OCT!H22) | J22: =IF([2]OCT!I22="","",[2]OCT!I22) | K22: =IF([2]OCT!J22="","",[2]OCT!J22) | L22: =IF([3]OCT!C22="","",[3]OCT!C22) | M22: =IF([3]OCT!D22="","",[3]OCT!D22) | N22: =IF([3]OCT!E22="","",[3]OCT!E22) | O22: =IF([3]OCT!F22="","",[3]OCT!F22) | P22: =IF([3]OCT!G22="","",[3]OCT!G22) | Q22: =IF([3]OCT!H22="","",[3]OCT!H22) | R22: =IF([3]OCT!I22="","",[3]OCT!I22) | S22: =IF([4]OCT!C22="","",[4]OCT!C22) | T22: =IF([4]OCT!D22="","",[4]OCT!D22) | U22: =IF([4]OCT!E22="","",[4]OCT!E22) | V22: =IF([4]OCT!F22="","",[4]OCT!F22) | W22: =IF([4]OCT!G22="","",[4]OCT!G22) | X22: =IF([4]OCT!H22="","",[4]OCT!H22) | Y22: =IF([4]OCT!I22="","",[4]OCT!I22) | Z22: =IF([5]OCT!C22="","",[5]OCT!C22) | AA22: =IF([5]OCT!D22="","",[5]OCT!D22) | AB22: =IF([5]OCT!E22="","",[5]OCT!E22) | AC22: =IF([5]OCT!F22="","",[5]OCT!F22) | AD22: =IF([5]OCT!G22="","",[5]OCT!G22) | AE22: =IF([5]OCT!H22="","",[5]OCT!H22) | AF22: =IF([5]OCT!I22="","",[5]OCT!I22) | AG22: =IF([5]OCT!J22="","",[5]OCT!J22) | ... AI22: =IF([5]OCT!L22="","",[5]OCT!L22) | AJ22: =IF(COUNT(C22:AI22)=0,"",SUM(C22:AI22)) | AK22: ∑
B23: Temporary Exits | C23: =IF([1]OCT!C23="","",[1]OCT!C23) | D23: =IF([2]OCT!C23="","",[2]OCT!C23) | E23: =IF([2]OCT!D23="","",[2]OCT!D23) | F23: =IF([2]OCT!E23="","",[2]OCT!E23) | G23: =IF([2]OCT!F23="","",[2]OCT!F23) | H23: =IF([2]OCT!G23="","",[2]OCT!G23) | I23: =IF([2]OCT!H23="","",[2]OCT!H23) | J23: =IF([2]OCT!I23="","",[2]OCT!I23) | K23: =IF([2]OCT!J23="","",[2]OCT!J23) | L23: =IF([3]OCT!C23="","",[3]OCT!C23) | M23: =IF([3]OCT!D23="","",[3]OCT!D23) | N23: =IF([3]OCT!E23="","",[3]OCT!E23) | O23: =IF([3]OCT!F23="","",[3]OCT!F23) | P23: =IF([3]OCT!G23="","",[3]OCT!G23) | Q23: =IF([3]OCT!H23="","",[3]OCT!H23) | R23: =IF([3]OCT!I23="","",[3]OCT!I23) | S23: =IF([4]OCT!C23="","",[4]OCT!C23) | T23: =IF([4]OCT!D23="","",[4]OCT!D23) | U23: =IF([4]OCT!E23="","",[4]OCT!E23) | V23: =IF([4]OCT!F23="","",[4]OCT!F23) | W23: =IF([4]OCT!G23="","",[4]OCT!G23) | X23: =IF([4]OCT!H23="","",[4]OCT!H23) | Y23: =IF([4]OCT!I23="","",[4]OCT!I23) | Z23: =IF([5]OCT!C23="","",[5]OCT!C23) | AA23: =IF([5]OCT!D23="","",[5]OCT!D23) | AB23: =IF([5]OCT!E23="","",[5]OCT!E23) | AC23: =IF([5]OCT!F23="","",[5]OCT!F23) | AD23: =IF([5]OCT!G23="","",[5]OCT!G23) | AE23: =IF([5]OCT!H23="","",[5]OCT!H23) | AF23: =IF([5]OCT!I23="","",[5]OCT!I23) | AG23: =IF([5]OCT!J23="","",[5]OCT!J23) | ... AI23: =IF([5]OCT!L23="","",[5]OCT!L23) | AJ23: =IF(COUNT(C23:AI23)=0,"",SUM(C23:AI23)) | AK23: ∑
B24: Total Exits | C24: =IF(COUNT(C22:C23)=0,"",SUM(C22:C23)) | D24: =IF(COUNT(D22:D23)=0,"",SUM(D22:D23)) | E24: =IF(COUNT(E22:E23)=0,"",SUM(E22:E23)) | F24: =IF(COUNT(F22:F23)=0,"",SUM(F22:F23)) | G24: =IF(COUNT(G22:G23)=0,"",SUM(G22:G23)) | H24: =IF(COUNT(H22:H23)=0,"",SUM(H22:H23)) | I24: =IF(COUNT(I22:I23)=0,"",SUM(I22:I23)) | J24: =IF(COUNT(J22:J23)=0,"",SUM(J22:J23)) | ... AJ24: =IF(COUNT(AJ22:AJ23)=0,"",SUM(AJ22:AJ23)) | AK24: ϝ
B25: Permanent Turnover (%) | C25: =IF(COUNT(C31,C32)<2,"",IF((C32+C31)=0,"",N(C22)/((C32+C31)/2))) | D25: =IF(COUNT(D31,D32)<2,"",IF((D32+D31)=0,"",N(D22)/((D32+D31)/2))) | E25: =IF(COUNT(E31,E32)<2,"",IF((E32+E31)=0,"",N(E22)/((E32+E31)/2))) | F25: =IF(COUNT(F31,F32)<2,"",IF((F32+F31)=0,"",N(F22)/((F32+F31)/2))) | G25: =IF(COUNT(G31,G32)<2,"",IF((G32+G31)=0,"",N(G22)/((G32+G31)/2))) | H25: =IF(COUNT(H31,H32)<2,"",IF((H32+H31)=0,"",N(H22)/((H32+H31)/2))) | I25: =IF(COUNT(I31,I32)<2,"",IF((I32+I31)=0,"",N(I22)/((I32+I31)/2))) | J25: =IF(COUNT(J31,J32)<2,"",IF((J32+J31)=0,"",N(J22)/((J32+J31)/2))) | ... AJ25: =IF(COUNT(AJ31,AJ32)<2,"",IF((AJ32+AJ31)=0,"",N(AJ22)/((AJ32+AJ31)/2))) | AK25: ϝ
B26: Temporary Turnover (%) | C26: =IF(COUNT(C31,C32)<2,"",IF((C32+C31)=0,"",N(C23)/((C32+C31)/2))) | D26: =IF(COUNT(D31,D32)<2,"",IF((D32+D31)=0,"",N(D23)/((D32+D31)/2))) | E26: =IF(COUNT(E31,E32)<2,"",IF((E32+E31)=0,"",N(E23)/((E32+E31)/2))) | F26: =IF(COUNT(F31,F32)<2,"",IF((F32+F31)=0,"",N(F23)/((F32+F31)/2))) | G26: =IF(COUNT(G31,G32)<2,"",IF((G32+G31)=0,"",N(G23)/((G32+G31)/2))) | H26: =IF(COUNT(H31,H32)<2,"",IF((H32+H31)=0,"",N(H23)/((H32+H31)/2))) | I26: =IF(COUNT(I31,I32)<2,"",IF((I32+I31)=0,"",N(I23)/((I32+I31)/2))) | J26: =IF(COUNT(J31,J32)<2,"",IF((J32+J31)=0,"",N(J23)/((J32+J31)/2))) | ... AJ26: =IF(COUNT(AJ31,AJ32)<2,"",IF((AJ32+AJ31)=0,"",N(AJ23)/((AJ32+AJ31)/2))) | AK26: ϝ
B27: Voluntary Terminations | C27: =IF([1]OCT!C27="","",[1]OCT!C27) | D27: =IF([2]OCT!C27="","",[2]OCT!C27) | E27: =IF([2]OCT!D27="","",[2]OCT!D27) | F27: =IF([2]OCT!E27="","",[2]OCT!E27) | G27: =IF([2]OCT!F27="","",[2]OCT!F27) | H27: =IF([2]OCT!G27="","",[2]OCT!G27) | I27: =IF([2]OCT!H27="","",[2]OCT!H27) | J27: =IF([2]OCT!I27="","",[2]OCT!I27) | K27: =IF([2]OCT!J27="","",[2]OCT!J27) | L27: =IF([3]OCT!C27="","",[3]OCT!C27) | M27: =IF([3]OCT!D27="","",[3]OCT!D27) | N27: =IF([3]OCT!E27="","",[3]OCT!E27) | O27: =IF([3]OCT!F27="","",[3]OCT!F27) | P27: =IF([3]OCT!G27="","",[3]OCT!G27) | Q27: =IF([3]OCT!H27="","",[3]OCT!H27) | R27: =IF([3]OCT!I27="","",[3]OCT!I27) | S27: =IF([4]OCT!C27="","",[4]OCT!C27) | T27: =IF([4]OCT!D27="","",[4]OCT!D27) | U27: =IF([4]OCT!E27="","",[4]OCT!E27) | V27: =IF([4]OCT!F27="","",[4]OCT!F27) | W27: =IF([4]OCT!G27="","",[4]OCT!G27) | X27: =IF([4]OCT!H27="","",[4]OCT!H27) | Y27: =IF([4]OCT!I27="","",[4]OCT!I27) | Z27: =IF([5]OCT!C27="","",[5]OCT!C27) | AA27: =IF([5]OCT!D27="","",[5]OCT!D27) | AB27: =IF([5]OCT!E27="","",[5]OCT!E27) | AC27: =IF([5]OCT!F27="","",[5]OCT!F27) | AD27: =IF([5]OCT!G27="","",[5]OCT!G27) | AE27: =IF([5]OCT!H27="","",[5]OCT!H27) | AF27: =IF([5]OCT!I27="","",[5]OCT!I27) | AG27: =IF([5]OCT!J27="","",[5]OCT!J27) | ... AI27: =IF([5]OCT!L27="","",[5]OCT!L27) | AJ27: =IF(COUNT(C27:AI27)=0,"",SUM(C27:AI27)) | AK27: ∑
B28: Involuntary Terminations | C28: =IF([1]OCT!C28="","",[1]OCT!C28) | D28: =IF([2]OCT!C28="","",[2]OCT!C28) | E28: =IF([2]OCT!D28="","",[2]OCT!D28) | F28: =IF([2]OCT!E28="","",[2]OCT!E28) | G28: =IF([2]OCT!F28="","",[2]OCT!F28) | H28: =IF([2]OCT!G28="","",[2]OCT!G28) | I28: =IF([2]OCT!H28="","",[2]OCT!H28) | J28: =IF([2]OCT!I28="","",[2]OCT!I28) | K28: =IF([2]OCT!J28="","",[2]OCT!J28) | L28: =IF([3]OCT!C28="","",[3]OCT!C28) | M28: =IF([3]OCT!D28="","",[3]OCT!D28) | N28: =IF([3]OCT!E28="","",[3]OCT!E28) | O28: =IF([3]OCT!F28="","",[3]OCT!F28) | P28: =IF([3]OCT!G28="","",[3]OCT!G28) | Q28: =IF([3]OCT!H28="","",[3]OCT!H28) | R28: =IF([3]OCT!I28="","",[3]OCT!I28) | S28: =IF([4]OCT!C28="","",[4]OCT!C28) | T28: =IF([4]OCT!D28="","",[4]OCT!D28) | U28: =IF([4]OCT!E28="","",[4]OCT!E28) | V28: =IF([4]OCT!F28="","",[4]OCT!F28) | W28: =IF([4]OCT!G28="","",[4]OCT!G28) | X28: =IF([4]OCT!H28="","",[4]OCT!H28) | Y28: =IF([4]OCT!I28="","",[4]OCT!I28) | Z28: =IF([5]OCT!C28="","",[5]OCT!C28) | AA28: =IF([5]OCT!D28="","",[5]OCT!D28) | AB28: =IF([5]OCT!E28="","",[5]OCT!E28) | AC28: =IF([5]OCT!F28="","",[5]OCT!F28) | AD28: =IF([5]OCT!G28="","",[5]OCT!G28) | AE28: =IF([5]OCT!H28="","",[5]OCT!H28) | AF28: =IF([5]OCT!I28="","",[5]OCT!I28) | AG28: =IF([5]OCT!J28="","",[5]OCT!J28) | ... AI28: =IF([5]OCT!L28="","",[5]OCT!L28) | AJ28: =IF(COUNT(C28:AI28)=0,"",SUM(C28:AI28)) | AK28: ∑
B29: Voluntary Turnover (%) | C29: =IF(COUNT(C31,C32)<2,"",IF((C32+C31)=0,"",N(C27)/((C32+C31)/2))) | D29: =IF(COUNT(D31,D32)<2,"",IF((D32+D31)=0,"",N(D27)/((D32+D31)/2))) | E29: =IF(COUNT(E31,E32)<2,"",IF((E32+E31)=0,"",N(E27)/((E32+E31)/2))) | F29: =IF(COUNT(F31,F32)<2,"",IF((F32+F31)=0,"",N(F27)/((F32+F31)/2))) | G29: =IF(COUNT(G31,G32)<2,"",IF((G32+G31)=0,"",N(G27)/((G32+G31)/2))) | H29: =IF(COUNT(H31,H32)<2,"",IF((H32+H31)=0,"",N(H27)/((H32+H31)/2))) | I29: =IF(COUNT(I31,I32)<2,"",IF((I32+I31)=0,"",N(I27)/((I32+I31)/2))) | J29: =IF(COUNT(J31,J32)<2,"",IF((J32+J31)=0,"",N(J27)/((J32+J31)/2))) | ... AJ29: =IF(COUNT(AJ31,AJ32)<2,"",IF((AJ32+AJ31)=0,"",N(AJ27)/((AJ32+AJ31)/2))) | AK29: ϝ
B30: Involuntary Turnover (%) | C30: =IF(COUNT(C31,C32)<2,"",IF((C32+C31)=0,"",N(C28)/((C32+C31)/2))) | D30: =IF(COUNT(D31,D32)<2,"",IF((D32+D31)=0,"",N(D28)/((D32+D31)/2))) | E30: =IF(COUNT(E31,E32)<2,"",IF((E32+E31)=0,"",N(E28)/((E32+E31)/2))) | F30: =IF(COUNT(F31,F32)<2,"",IF((F32+F31)=0,"",N(F28)/((F32+F31)/2))) | G30: =IF(COUNT(G31,G32)<2,"",IF((G32+G31)=0,"",N(G28)/((G32+G31)/2))) | H30: =IF(COUNT(H31,H32)<2,"",IF((H32+H31)=0,"",N(H28)/((H32+H31)/2))) | I30: =IF(COUNT(I31,I32)<2,"",IF((I32+I31)=0,"",N(I28)/((I32+I31)/2))) | J30: =IF(COUNT(J31,J32)<2,"",IF((J32+J31)=0,"",N(J28)/((J32+J31)/2))) | ... AJ30: =IF(COUNT(AJ31,AJ32)<2,"",IF((AJ32+AJ31)=0,"",N(AJ28)/((AJ32+AJ31)/2))) | AK30: ϝ
B31: Headcount last Month | C31: =IF([1]OCT!C31="","",[1]OCT!C31) | D31: =IF([2]OCT!C31="","",[2]OCT!C31) | E31: =IF([2]OCT!D31="","",[2]OCT!D31) | F31: =IF([2]OCT!E31="","",[2]OCT!E31) | G31: =IF([2]OCT!F31="","",[2]OCT!F31) | H31: =IF([2]OCT!G31="","",[2]OCT!G31) | I31: =IF([2]OCT!H31="","",[2]OCT!H31) | J31: =IF([2]OCT!I31="","",[2]OCT!I31) | K31: =IF([2]OCT!J31="","",[2]OCT!J31) | L31: =IF([3]OCT!C31="","",[3]OCT!C31) | M31: =IF([3]OCT!D31="","",[3]OCT!D31) | N31: =IF([3]OCT!E31="","",[3]OCT!E31) | O31: =IF([3]OCT!F31="","",[3]OCT!F31) | P31: =IF([3]OCT!G31="","",[3]OCT!G31) | Q31: =IF([3]OCT!H31="","",[3]OCT!H31) | R31: =IF([3]OCT!I31="","",[3]OCT!I31) | S31: =IF([4]OCT!C31="","",[4]OCT!C31) | T31: =IF([4]OCT!D31="","",[4]OCT!D31) | U31: =IF([4]OCT!E31="","",[4]OCT!E31) | V31: =IF([4]OCT!F31="","",[4]OCT!F31) | W31: =IF([4]OCT!G31="","",[4]OCT!G31) | X31: =IF([4]OCT!H31="","",[4]OCT!H31) | Y31: =IF([4]OCT!I31="","",[4]OCT!I31) | Z31: =IF([5]OCT!C31="","",[5]OCT!C31) | AA31: =IF([5]OCT!D31="","",[5]OCT!D31) | AB31: =IF([5]OCT!E31="","",[5]OCT!E31) | AC31: =IF([5]OCT!F31="","",[5]OCT!F31) | AD31: =IF([5]OCT!G31="","",[5]OCT!G31) | AE31: =IF([5]OCT!H31="","",[5]OCT!H31) | AF31: =IF([5]OCT!I31="","",[5]OCT!I31) | AG31: =IF([5]OCT!J31="","",[5]OCT!J31) | ... AI31: =IF([5]OCT!L31="","",[5]OCT!L31) | AJ31: =IF(COUNT(C31:AI31)=0,"",SUM(C31:AI31)) | AK31: ∑
B32: Headcount this Month | C32: =IF(C5="","",C5) | D32: =IF(D5="","",D5) | E32: =IF(E5="","",E5) | F32: =IF(F5="","",F5) | G32: =IF(G5="","",G5) | H32: =IF(H5="","",H5) | I32: =IF(I5="","",I5) | J32: =IF(J5="","",J5) | ... AI32: =IF(AI5="","",AI5) | AJ32: =IF(COUNT(C32:AI32)=0,"",SUM(C32:AI32)) | AK32: ∑
B33: Full Turnover (%) | C33: =IF(COUNT(C31,C32)<2,"",IF((C32+C31)=0,"",N(C24)/((C32+C31)/2))) | D33: =IF(COUNT(D31,D32)<2,"",IF((D32+D31)=0,"",N(D24)/((D32+D31)/2))) | E33: =IF(COUNT(E31,E32)<2,"",IF((E32+E31)=0,"",N(E24)/((E32+E31)/2))) | F33: =IF(COUNT(F31,F32)<2,"",IF((F32+F31)=0,"",N(F24)/((F32+F31)/2))) | G33: =IF(COUNT(G31,G32)<2,"",IF((G32+G31)=0,"",N(G24)/((G32+G31)/2))) | H33: =IF(COUNT(H31,H32)<2,"",IF((H32+H31)=0,"",N(H24)/((H32+H31)/2))) | I33: =IF(COUNT(I31,I32)<2,"",IF((I32+I31)=0,"",N(I24)/((I32+I31)/2))) | J33: =IF(COUNT(J31,J32)<2,"",IF((J32+J31)=0,"",N(J24)/((J32+J31)/2))) | ... AJ33: =IF(COUNT(AJ31,AJ32)<2,"",IF((AJ32+AJ31)=0,"",N(AJ24)/((AJ32+AJ31)/2))) | AK33: ϝ
B34: Permanent Vacancies | C34: =IF([1]OCT!C34="","",[1]OCT!C34) | D34: =IF([2]OCT!C34="","",[2]OCT!C34) | E34: =IF([2]OCT!D34="","",[2]OCT!D34) | F34: =IF([2]OCT!E34="","",[2]OCT!E34) | G34: =IF([2]OCT!F34="","",[2]OCT!F34) | H34: =IF([2]OCT!G34="","",[2]OCT!G34) | I34: =IF([2]OCT!H34="","",[2]OCT!H34) | J34: =IF([2]OCT!I34="","",[2]OCT!I34) | K34: =IF([2]OCT!J34="","",[2]OCT!J34) | L34: =IF([3]OCT!C34="","",[3]OCT!C34) | M34: =IF([3]OCT!D34="","",[3]OCT!D34) | N34: =IF([3]OCT!E34="","",[3]OCT!E34) | O34: =IF([3]OCT!F34="","",[3]OCT!F34) | P34: =IF([3]OCT!G34="","",[3]OCT!G34) | Q34: =IF([3]OCT!H34="","",[3]OCT!H34) | R34: =IF([3]OCT!I34="","",[3]OCT!I34) | S34: =IF([4]OCT!C34="","",[4]OCT!C34) | T34: =IF([4]OCT!D34="","",[4]OCT!D34) | U34: =IF([4]OCT!E34="","",[4]OCT!E34) | V34: =IF([4]OCT!F34="","",[4]OCT!F34) | W34: =IF([4]OCT!G34="","",[4]OCT!G34) | X34: =IF([4]OCT!H34="","",[4]OCT!H34) | Y34: =IF([4]OCT!I34="","",[4]OCT!I34) | Z34: =IF([5]OCT!C34="","",[5]OCT!C34) | AA34: =IF([5]OCT!D34="","",[5]OCT!D34) | AB34: =IF([5]OCT!E34="","",[5]OCT!E34) | AC34: =IF([5]OCT!F34="","",[5]OCT!F34) | AD34: =IF([5]OCT!G34="","",[5]OCT!G34) | AE34: =IF([5]OCT!H34="","",[5]OCT!H34) | AF34: =IF([5]OCT!I34="","",[5]OCT!I34) | AG34: =IF([5]OCT!J34="","",[5]OCT!J34) | ... AI34: =IF([5]OCT!L34="","",[5]OCT!L34) | AJ34: =IF(COUNT(C34:AI34)=0,"",SUM(C34:AI34)) | AK34: ∑
B35: Temporary Vacancies | C35: =IF([1]OCT!C35="","",[1]OCT!C35) | D35: =IF([2]OCT!C35="","",[2]OCT!C35) | E35: =IF([2]OCT!D35="","",[2]OCT!D35) | F35: =IF([2]OCT!E35="","",[2]OCT!E35) | G35: =IF([2]OCT!F35="","",[2]OCT!F35) | H35: =IF([2]OCT!G35="","",[2]OCT!G35) | I35: =IF([2]OCT!H35="","",[2]OCT!H35) | J35: =IF([2]OCT!I35="","",[2]OCT!I35) | K35: =IF([2]OCT!J35="","",[2]OCT!J35) | L35: =IF([3]OCT!C35="","",[3]OCT!C35) | M35: =IF([3]OCT!D35="","",[3]OCT!D35) | N35: =IF([3]OCT!E35="","",[3]OCT!E35) | O35: =IF([3]OCT!F35="","",[3]OCT!F35) | P35: =IF([3]OCT!G35="","",[3]OCT!G35) | Q35: =IF([3]OCT!H35="","",[3]OCT!H35) | R35: =IF([3]OCT!I35="","",[3]OCT!I35) | S35: =IF([4]OCT!C35="","",[4]OCT!C35) | T35: =IF([4]OCT!D35="","",[4]OCT!D35) | U35: =IF([4]OCT!E35="","",[4]OCT!E35) | V35: =IF([4]OCT!F35="","",[4]OCT!F35) | W35: =IF([4]OCT!G35="","",[4]OCT!G35) | X35: =IF([4]OCT!H35="","",[4]OCT!H35) | Y35: =IF([4]OCT!I35="","",[4]OCT!I35) | Z35: =IF([5]OCT!C35="","",[5]OCT!C35) | AA35: =IF([5]OCT!D35="","",[5]OCT!D35) | AB35: =IF([5]OCT!E35="","",[5]OCT!E35) | AC35: =IF([5]OCT!F35="","",[5]OCT!F35) | AD35: =IF([5]OCT!G35="","",[5]OCT!G35) | AE35: =IF([5]OCT!H35="","",[5]OCT!H35) | AF35: =IF([5]OCT!I35="","",[5]OCT!I35) | AG35: =IF([5]OCT!J35="","",[5]OCT!J35) | ... AI35: =IF([5]OCT!L35="","",[5]OCT!L35) | AJ35: =IF(COUNT(C35:AI35)=0,"",SUM(C35:AI35)) | AK35: ∑
B36: Total Vacancies | C36: =IF(COUNT(C34:C35)=0,"",SUM(C34:C35)) | D36: =IF(COUNT(D34:D35)=0,"",SUM(D34:D35)) | E36: =IF(COUNT(E34:E35)=0,"",SUM(E34:E35)) | F36: =IF(COUNT(F34:F35)=0,"",SUM(F34:F35)) | G36: =IF(COUNT(G34:G35)=0,"",SUM(G34:G35)) | H36: =IF(COUNT(H34:H35)=0,"",SUM(H34:H35)) | I36: =IF(COUNT(I34:I35)=0,"",SUM(I34:I35)) | J36: =IF(COUNT(J34:J35)=0,"",SUM(J34:J35)) | ... AJ36: =IF(COUNT(AJ34:AJ35)=0,"",SUM(AJ34:AJ35)) | AK36: ϝ
B37: Authorized Positions | C37: =IF(COUNT(C5,C36)=0,"",N(C5)+N(C36)) | D37: =IF(COUNT(D5,D36)=0,"",N(D5)+N(D36)) | E37: =IF(COUNT(E5,E36)=0,"",N(E5)+N(E36)) | F37: =IF(COUNT(F5,F36)=0,"",N(F5)+N(F36)) | G37: =IF(COUNT(G5,G36)=0,"",N(G5)+N(G36)) | H37: =IF(COUNT(H5,H36)=0,"",N(H5)+N(H36)) | I37: =IF(COUNT(I5,I36)=0,"",N(I5)+N(I36)) | J37: =IF(COUNT(J5,J36)=0,"",N(J5)+N(J36)) | ... AJ37: =IF(COUNT(AJ5,AJ36)=0,"",N(AJ5)+N(AJ36)) | AK37: ϝ
B38: Vacancy Rate (%) | C38: =IFERROR(C36/C37,"") | D38: =IFERROR(D36/D37,"") | E38: =IFERROR(E36/E37,"") | F38: =IFERROR(F36/F37,"") | G38: =IFERROR(G36/G37,"") | H38: =IFERROR(H36/H37,"") | I38: =IFERROR(I36/I37,"") | J38: =IFERROR(J36/J37,"") | ... AJ38: =IFERROR(AJ36/AJ37,"") | AK38: ϝ
B39: Permanent TimeToHire (Days) YTD | C39: =IF([1]OCT!C39="","",[1]OCT!C39) | D39: =IF([2]OCT!C39="","",[2]OCT!C39) | E39: =IF([2]OCT!D39="","",[2]OCT!D39) | F39: =IF([2]OCT!E39="","",[2]OCT!E39) | G39: =IF([2]OCT!F39="","",[2]OCT!F39) | H39: =IF([2]OCT!G39="","",[2]OCT!G39) | I39: =IF([2]OCT!H39="","",[2]OCT!H39) | J39: =IF([2]OCT!I39="","",[2]OCT!I39) | K39: =IF([2]OCT!J39="","",[2]OCT!J39) | L39: =IF([3]OCT!C39="","",[3]OCT!C39) | M39: =IF([3]OCT!D39="","",[3]OCT!D39) | N39: =IF([3]OCT!E39="","",[3]OCT!E39) | O39: =IF([3]OCT!F39="","",[3]OCT!F39) | P39: =IF([3]OCT!G39="","",[3]OCT!G39) | Q39: =IF([3]OCT!H39="","",[3]OCT!H39) | R39: =IF([3]OCT!I39="","",[3]OCT!I39) | S39: =IF([4]OCT!C39="","",[4]OCT!C39) | T39: =IF([4]OCT!D39="","",[4]OCT!D39) | U39: =IF([4]OCT!E39="","",[4]OCT!E39) | V39: =IF([4]OCT!F39="","",[4]OCT!F39) | W39: =IF([4]OCT!G39="","",[4]OCT!G39) | X39: =IF([4]OCT!H39="","",[4]OCT!H39) | Y39: =IF([4]OCT!I39="","",[4]OCT!I39) | Z39: =IF([5]OCT!C39="","",[5]OCT!C39) | AA39: =IF([5]OCT!D39="","",[5]OCT!D39) | AB39: =IF([5]OCT!E39="","",[5]OCT!E39) | AC39: =IF([5]OCT!F39="","",[5]OCT!F39) | AD39: =IF([5]OCT!G39="","",[5]OCT!G39) | AE39: =IF([5]OCT!H39="","",[5]OCT!H39) | AF39: =IF([5]OCT!I39="","",[5]OCT!I39) | AG39: =IF([5]OCT!J39="","",[5]OCT!J39) | ... AI39: =IF([5]OCT!L39="","",[5]OCT!L39) | AJ39: =IFERROR(AVERAGE(C39:AI39),"") | AK39: Avg
B40: Temporary TimeToHire (Days) YTD | C40: =IF([1]OCT!C40="","",[1]OCT!C40) | D40: =IF([2]OCT!C40="","",[2]OCT!C40) | E40: =IF([2]OCT!D40="","",[2]OCT!D40) | F40: =IF([2]OCT!E40="","",[2]OCT!E40) | G40: =IF([2]OCT!F40="","",[2]OCT!F40) | H40: =IF([2]OCT!G40="","",[2]OCT!G40) | I40: =IF([2]OCT!H40="","",[2]OCT!H40) | J40: =IF([2]OCT!I40="","",[2]OCT!I40) | K40: =IF([2]OCT!J40="","",[2]OCT!J40) | L40: =IF([3]OCT!C40="","",[3]OCT!C40) | M40: =IF([3]OCT!D40="","",[3]OCT!D40) | N40: =IF([3]OCT!E40="","",[3]OCT!E40) | O40: =IF([3]OCT!F40="","",[3]OCT!F40) | P40: =IF([3]OCT!G40="","",[3]OCT!G40) | Q40: =IF([3]OCT!H40="","",[3]OCT!H40) | R40: =IF([3]OCT!I40="","",[3]OCT!I40) | S40: =IF([4]OCT!C40="","",[4]OCT!C40) | T40: =IF([4]OCT!D40="","",[4]OCT!D40) | U40: =IF([4]OCT!E40="","",[4]OCT!E40) | V40: =IF([4]OCT!F40="","",[4]OCT!F40) | W40: =IF([4]OCT!G40="","",[4]OCT!G40) | X40: =IF([4]OCT!H40="","",[4]OCT!H40) | Y40: =IF([4]OCT!I40="","",[4]OCT!I40) | Z40: =IF([5]OCT!C40="","",[5]OCT!C40) | AA40: =IF([5]OCT!D40="","",[5]OCT!D40) | AB40: =IF([5]OCT!E40="","",[5]OCT!E40) | AC40: =IF([5]OCT!F40="","",[5]OCT!F40) | AD40: =IF([5]OCT!G40="","",[5]OCT!G40) | AE40: =IF([5]OCT!H40="","",[5]OCT!H40) | AF40: =IF([5]OCT!I40="","",[5]OCT!I40) | AG40: =IF([5]OCT!J40="","",[5]OCT!J40) | ... AI40: =IF([5]OCT!L40="","",[5]OCT!L40) | AJ40: =IFERROR(AVERAGE(C40:AI40),"") | AK40: Avg
...

Sheet NOV
B1: GCG | C1: 1079 | D1: 1171 | E1: 1162 | F1: 1076 | G1: 1170 | H1: 1078 | I1: 1172 | J1: 1074 | K1: 1161 | L1: 1062 | M1: 1075 | N1: 1044 | O1: 1066 | P1: 1158 | Q1: 1067 | R1: 1046 | S1: 1069 | T1: 1178 | U1: 1077 | V1: 1081 | W1: 1082 | X1: 1085 | Y1: 1071U | Z1: 1015 | AA1: 1004 | AB1: 1063 | AC1: 1160 | AD1: 1073 | AE1: 1042 | AF1: 1084 | AG1: 1049 | AH1: 1005 | AI1: 1115
A2: =VALUE(TEXT(EDATE(DATE(LEFT(OCT!A2,4),RIGHT(OCT!A2,2),1),1),"yyyymm")) | B2: NOV | C2: GCG HDQ | D2: GCG Culinary Costa Rica | E2: GCG Food Guatemala | F2: GCG Guatemala | G2: GCG Aviation Ground Honduras | H2: GCG Honduras | I2: GCG Concessions Panama | J2: GCG El Salvador | K2: GCG Food El Salvador | L2: GCG Antigua | M2: GCG Grand Cayman | N2: GCG Aviation Ground Jamaica | O2: GCG Jamaica | P2: GCG Aviation Ground Saint Lucia | Q2: GCG Saint Lucia | R2: GCG Ground Saint Thomas | S2: GCG Bogota Colombia | T2: GCG Colombia | U2: GCG Guayaquil | V2: GCG Paraguay | W2: GCG Quito | X2: GCG Uruguay | Y2: GCG Caracas | Z2: Calloway Aruba | AA2: Airport Rest. Barbados | AB2: GCG Barbados | AC2: GCG Aviation Ground Barbados | AD2: GCG Curacao | AE2: GCG Events Curacao | AF2: GCG Sint Maarten Sky Dining | AG2: GCG Sint Maarten Airport Dining | AH2: Allied Caterers Trinidad | AI2: Katerserv Trinidad | AJ2: TOTAL | AK2: Total by Division | AL2: =N(AL11)<>0
A3: =+A2 | B3: Permanent (Regular) Headcount | C3: =IF([1]NOV!C3="","",[1]NOV!C3) | D3: =IF([2]NOV!C3="","",[2]NOV!C3) | E3: =IF([2]NOV!D3="","",[2]NOV!D3) | F3: =IF([2]NOV!E3="","",[2]NOV!E3) | G3: =IF([2]NOV!F3="","",[2]NOV!F3) | H3: =IF([2]NOV!G3="","",[2]NOV!G3) | I3: =IF([2]NOV!H3="","",[2]NOV!H3) | J3: =IF([2]NOV!I3="","",[2]NOV!I3) | K3: =IF([2]NOV!J3="","",[2]NOV!J3) | L3: =IF([3]NOV!C3="","",[3]NOV!C3) | M3: =IF([3]NOV!D3="","",[3]NOV!D3) | N3: =IF([3]NOV!E3="","",[3]NOV!E3) | O3: =IF([3]NOV!F3="","",[3]NOV!F3) | P3: =IF([3]NOV!G3="","",[3]NOV!G3) | Q3: =IF([3]NOV!H3="","",[3]NOV!H3) | R3: =IF([3]NOV!I3="","",[3]NOV!I3) | S3: =IF([4]NOV!C3="","",[4]NOV!C3) | T3: =IF([4]NOV!D3="","",[4]NOV!D3) | U3: =IF([4]NOV!E3="","",[4]NOV!E3) | V3: =IF([4]NOV!F3="","",[4]NOV!F3) | W3: =IF([4]NOV!G3="","",[4]NOV!G3) | X3: =IF([4]NOV!H3="","",[4]NOV!H3) | Y3: =IF([4]NOV!I3="","",[4]NOV!I3) | Z3: =IF([5]NOV!C3="","",[5]NOV!C3) | AA3: =IF([5]NOV!D3="","",[5]NOV!D3) | AB3: =IF([5]NOV!E3="","",[5]NOV!E3) | AC3: =IF([5]NOV!F3="","",[5]NOV!F3) | AD3: =IF([5]NOV!G3="","",[5]NOV!G3) | AE3: =IF([5]NOV!H3="","",[5]NOV!H3) | AF3: =IF([5]NOV!I3="","",[5]NOV!I3) | AG3: =IF([5]NOV!J3="","",[5]NOV!J3) | ... AI3: =IF([5]NOV!L3="","",[5]NOV!L3) | AJ3: =IF(COUNT(C3:AI3)=0,"",SUM(C3:AI3)) | AK3: ∑
