Workbook

Sheet Quarter
B1: GCG SOUTH CARIBBEAN
A2: FY2027 | B2: Quarter | C2: OCT | D2: NOV | E2: DEC | F2: ∑Q1 | G2: JAN | H2: FEB | I2: MAR | J2: ∑Q2 | K2: APR | L2: MAY | M2: JUN | N2: ∑Q3 | O2: JUL | P2: AUG | Q2: SEP | R2: ∑Q4 | S2: FY2027
B3: Permanent (Regular) Headcount | C3: =OCT!M3 | D3: =NOV!M3 | E3: =DEC!M3 | F3: =IFERROR(AVERAGE(C3:E3),"") | G3: =JAN!M3 | H3: =FEB!M3 | I3: =MAR!M3 | J3: =IFERROR(AVERAGE(G3:I3),"") | K3: =APR!M3 | L3: =MAY!M3 | M3: =JUN!M3 | N3: =IFERROR(AVERAGE(K3:M3),"") | O3: =JUL!M3 | P3: =AUG!M3 | Q3: =SEP!M3 | R3: =IFERROR(AVERAGE(O3:Q3),"") | S3: =IFERROR(AVERAGE(C3:E3,G3:I3,K3:M3,O3:Q3),"")
B4: Temporary (Fix Term) Headcount | C4: =OCT!M4 | D4: =NOV!M4 | E4: =DEC!M4 | F4: =IFERROR(AVERAGE(C4:E4),"") | G4: =JAN!M4 | H4: =FEB!M4 | I4: =MAR!M4 | J4: =IFERROR(AVERAGE(G4:I4),"") | K4: =APR!M4 | L4: =MAY!M4 | M4: =JUN!M4 | N4: =IFERROR(AVERAGE(K4:M4),"") | O4: =JUL!M4 | P4: =AUG!M4 | Q4: =SEP!M4 | R4: =IFERROR(AVERAGE(O4:Q4),"") | S4: =IFERROR(AVERAGE(C4:E4,G4:I4,K4:M4,O4:Q4),"")
B5: Employee Headcount (Productivity) | C5: =OCT!M5 | D5: =NOV!M5 | E5: =DEC!M5 | F5: =IF(COUNT(F3:F4)=0,"",SUM(F3:F4)) | G5: =JAN!M5 | H5: =FEB!M5 | I5: =MAR!M5 | J5: =IF(COUNT(J3:J4)=0,"",SUM(J3:J4)) | K5: =APR!M5 | L5: =MAY!M5 | M5: =JUN!M5 | N5: =IF(COUNT(N3:N4)=0,"",SUM(N3:N4)) | O5: =JUL!M5 | P5: =AUG!M5 | Q5: =SEP!M5 | R5: =IF(COUNT(R3:R4)=0,"",SUM(R3:R4)) | S5: =IF(COUNT(S3:S4)=0,"",SUM(S3:S4))
B6: Headcount = 1.00 | C6: =OCT!M6 | D6: =NOV!M6 | E6: =DEC!M6 | F6: =IFERROR(AVERAGE(C6:E6),"") | G6: =JAN!M6 | H6: =FEB!M6 | I6: =MAR!M6 | J6: =IFERROR(AVERAGE(G6:I6),"") | K6: =APR!M6 | L6: =MAY!M6 | M6: =JUN!M6 | N6: =IFERROR(AVERAGE(K6:M6),"") | O6: =JUL!M6 | P6: =AUG!M6 | Q6: =SEP!M6 | R6: =IFERROR(AVERAGE(O6:Q6),"") | S6: =IFERROR(AVERAGE(C6:E6,G6:I6,K6:M6,O6:Q6),"")
B7: Headcount = 0.75 | C7: =OCT!M7 | D7: =NOV!M7 | E7: =DEC!M7 | F7: =IFERROR(AVERAGE(C7:E7),"") | G7: =JAN!M7 | H7: =FEB!M7 | I7: =MAR!M7 | J7: =IFERROR(AVERAGE(G7:I7),"") | K7: =APR!M7 | L7: =MAY!M7 | M7: =JUN!M7 | N7: =IFERROR(AVERAGE(K7:M7),"") | O7: =JUL!M7 | P7: =AUG!M7 | Q7: =SEP!M7 | R7: =IFERROR(AVERAGE(O7:Q7),"") | S7: =IFERROR(AVERAGE(C7:E7,G7:I7,K7:M7,O7:Q7),"")
B8: Headcount = 0.50 | C8: =OCT!M8 | D8: =NOV!M8 | E8: =DEC!M8 | F8: =IFERROR(AVERAGE(C8:E8),"") | G8: =JAN!M8 | H8: =FEB!M8 | I8: =MAR!M8 | J8: =IFERROR(AVERAGE(G8:I8),"") | K8: =APR!M8 | L8: =MAY!M8 | M8: =JUN!M8 | N8: =IFERROR(AVERAGE(K8:M8),"") | O8: =JUL!M8 | P8: =AUG!M8 | Q8: =SEP!M8 | R8: =IFERROR(AVERAGE(O8:Q8),"") | S8: =IFERROR(AVERAGE(C8:E8,G8:I8,K8:M8,O8:Q8),"")
B9: Headcount = 0.25 | C9: =OCT!M9 | D9: =NOV!M9 | E9: =DEC!M9 | F9: =IFERROR(AVERAGE(C9:E9),"") | G9: =JAN!M9 | H9: =FEB!M9 | I9: =MAR!M9 | J9: =IFERROR(AVERAGE(G9:I9),"") | K9: =APR!M9 | L9: =MAY!M9 | M9: =JUN!M9 | N9: =IFERROR(AVERAGE(K9:M9),"") | O9: =JUL!M9 | P9: =AUG!M9 | Q9: =SEP!M9 | R9: =IFERROR(AVERAGE(O9:Q9),"") | S9: =IFERROR(AVERAGE(C9:E9,G9:I9,K9:M9,O9:Q9),"")
B10: Standard Monthly Hours (FTE basis) | C10: =OCT!M10 | D10: =NOV!M10 | E10: =DEC!M10 | F10: =IFERROR(AVERAGE(C10:E10),"") | G10: =JAN!M10 | H10: =FEB!M10 | I10: =MAR!M10 | J10: =IFERROR(AVERAGE(G10:I10),"") | K10: =APR!M10 | L10: =MAY!M10 | M10: =JUN!M10 | N10: =IFERROR(AVERAGE(K10:M10),"") | O10: =JUL!M10 | P10: =AUG!M10 | Q10: =SEP!M10 | R10: =IFERROR(AVERAGE(O10:Q10),"") | S10: =IFERROR(AVERAGE(C10:E10,G10:I10,K10:M10,O10:Q10),"")
B11: Employee FTE (Finance) | C11: =OCT!M11 | D11: =NOV!M11 | E11: =DEC!M11 | F11: =IF(COUNT(F6:F9)=0,"",N(F6)+N(F7)*0.75+N(F8)*0.5+N(F9)*0.25) | G11: =JAN!M11 | H11: =FEB!M11 | I11: =MAR!M11 | J11: =IF(COUNT(J6:J9)=0,"",N(J6)+N(J7)*0.75+N(J8)*0.5+N(J9)*0.25) | K11: =APR!M11 | L11: =MAY!M11 | M11: =JUN!M11 | N11: =IF(COUNT(N6:N9)=0,"",N(N6)+N(N7)*0.75+N(N8)*0.5+N(N9)*0.25) | O11: =JUL!M11 | P11: =AUG!M11 | Q11: =SEP!M11 | R11: =IF(COUNT(R6:R9)=0,"",N(R6)+N(R7)*0.75+N(R8)*0.5+N(R9)*0.25) | S11: =IF(COUNT(S6:S9)=0,"",N(S6)+N(S7)*0.75+N(S8)*0.5+N(S9)*0.25)
B12: Subcontracted Workforce HC | C12: =OCT!M12 | D12: =NOV!M12 | E12: =DEC!M12 | F12: =IFERROR(AVERAGE(C12:E12),"") | G12: =JAN!M12 | H12: =FEB!M12 | I12: =MAR!M12 | J12: =IFERROR(AVERAGE(G12:I12),"") | K12: =APR!M12 | L12: =MAY!M12 | M12: =JUN!M12 | N12: =IFERROR(AVERAGE(K12:M12),"") | O12: =JUL!M12 | P12: =AUG!M12 | Q12: =SEP!M12 | R12: =IFERROR(AVERAGE(O12:Q12),"") | S12: =IFERROR(AVERAGE(C12:E12,G12:I12,K12:M12,O12:Q12),"")
B13: Subcontracted Productive Hours | C13: =OCT!M13 | D13: =NOV!M13 | E13: =DEC!M13 | F13: =IFERROR(AVERAGE(C13:E13),"") | G13: =JAN!M13 | H13: =FEB!M13 | I13: =MAR!M13 | J13: =IFERROR(AVERAGE(G13:I13),"") | K13: =APR!M13 | L13: =MAY!M13 | M13: =JUN!M13 | N13: =IFERROR(AVERAGE(K13:M13),"") | O13: =JUL!M13 | P13: =AUG!M13 | Q13: =SEP!M13 | R13: =IFERROR(AVERAGE(O13:Q13),"") | S13: =IFERROR(AVERAGE(C13:E13,G13:I13,K13:M13,O13:Q13),"")
B14: Subcontracted FTE | C14: =OCT!M14 | D14: =NOV!M14 | E14: =DEC!M14 | F14: =IFERROR(F13/F10,"") | G14: =JAN!M14 | H14: =FEB!M14 | I14: =MAR!M14 | J14: =IFERROR(J13/J10,"") | K14: =APR!M14 | L14: =MAY!M14 | M14: =JUN!M14 | N14: =IFERROR(N13/N10,"") | O14: =JUL!M14 | P14: =AUG!M14 | Q14: =SEP!M14 | R14: =IFERROR(R13/R10,"") | S14: =IFERROR(S13/S10,"")
B15: Total Operational Workforce | C15: =OCT!M15 | D15: =NOV!M15 | E15: =DEC!M15 | F15: =IF(COUNT(F5,F12)=0,"",SUM(F5,F12)) | G15: =JAN!M15 | H15: =FEB!M15 | I15: =MAR!M15 | J15: =IF(COUNT(J5,J12)=0,"",SUM(J5,J12)) | K15: =APR!M15 | L15: =MAY!M15 | M15: =JUN!M15 | N15: =IF(COUNT(N5,N12)=0,"",SUM(N5,N12)) | O15: =JUL!M15 | P15: =AUG!M15 | Q15: =SEP!M15 | R15: =IF(COUNT(R5,R12)=0,"",SUM(R5,R12)) | S15: =IF(COUNT(S5,S12)=0,"",SUM(S5,S12))
B16: Total Operational FTE | C16: =OCT!M16 | D16: =NOV!M16 | E16: =DEC!M16 | F16: =IF(COUNT(F11,F14)=0,"",SUM(F11,F14)) | G16: =JAN!M16 | H16: =FEB!M16 | I16: =MAR!M16 | J16: =IF(COUNT(J11,J14)=0,"",SUM(J11,J14)) | K16: =APR!M16 | L16: =MAY!M16 | M16: =JUN!M16 | N16: =IF(COUNT(N11,N14)=0,"",SUM(N11,N14)) | O16: =JUL!M16 | P16: =AUG!M16 | Q16: =SEP!M16 | R16: =IF(COUNT(R11,R14)=0,"",SUM(R11,R14)) | S16: =IF(COUNT(S11,S14)=0,"",SUM(S11,S14))
B17: Subcontracted Share of Workforce (%) | C17: =OCT!M17 | D17: =NOV!M17 | E17: =DEC!M17 | F17: =IFERROR(F12/F15,"") | G17: =JAN!M17 | H17: =FEB!M17 | I17: =MAR!M17 | J17: =IFERROR(J12/J15,"") | K17: =APR!M17 | L17: =MAY!M17 | M17: =JUN!M17 | N17: =IFERROR(N12/N15,"") | O17: =JUL!M17 | P17: =AUG!M17 | Q17: =SEP!M17 | R17: =IFERROR(R12/R15,"") | S17: =IFERROR(S12/S15,"")
B18: FTE HR Team | C18: =OCT!M18 | D18: =NOV!M18 | E18: =DEC!M18 | F18: =IFERROR(AVERAGE(C18:E18),"") | G18: =JAN!M18 | H18: =FEB!M18 | I18: =MAR!M18 | J18: =IFERROR(AVERAGE(G18:I18),"") | K18: =APR!M18 | L18: =MAY!M18 | M18: =JUN!M18 | N18: =IFERROR(AVERAGE(K18:M18),"") | O18: =JUL!M18 | P18: =AUG!M18 | Q18: =SEP!M18 | R18: =IFERROR(AVERAGE(O18:Q18),"") | S18: =IFERROR(AVERAGE(C18:E18,G18:I18,K18:M18,O18:Q18),"")
B19: Permanent Hires | C19: =OCT!M19 | D19: =NOV!M19 | E19: =DEC!M19 | F19: =IF(COUNT(C19:E19)=0,"",SUM(C19:E19)) | G19: =JAN!M19 | H19: =FEB!M19 | I19: =MAR!M19 | J19: =IF(COUNT(G19:I19)=0,"",SUM(G19:I19)) | K19: =APR!M19 | L19: =MAY!M19 | M19: =JUN!M19 | N19: =IF(COUNT(K19:M19)=0,"",SUM(K19:M19)) | O19: =JUL!M19 | P19: =AUG!M19 | Q19: =SEP!M19 | R19: =IF(COUNT(O19:Q19)=0,"",SUM(O19:Q19)) | S19: =IF(COUNT(C19:E19,G19:I19,K19:M19,O19:Q19)=0,"",SUM(C19:E19,G19:I19,K19:M19,O19:Q19))
B20: Temporary Hires | C20: =OCT!M20 | D20: =NOV!M20 | E20: =DEC!M20 | F20: =IF(COUNT(C20:E20)=0,"",SUM(C20:E20)) | G20: =JAN!M20 | H20: =FEB!M20 | I20: =MAR!M20 | J20: =IF(COUNT(G20:I20)=0,"",SUM(G20:I20)) | K20: =APR!M20 | L20: =MAY!M20 | M20: =JUN!M20 | N20: =IF(COUNT(K20:M20)=0,"",SUM(K20:M20)) | O20: =JUL!M20 | P20: =AUG!M20 | Q20: =SEP!M20 | R20: =IF(COUNT(O20:Q20)=0,"",SUM(O20:Q20)) | S20: =IF(COUNT(C20:E20,G20:I20,K20:M20,O20:Q20)=0,"",SUM(C20:E20,G20:I20,K20:M20,O20:Q20))
B21: Total Hires | C21: =OCT!M21 | D21: =NOV!M21 | E21: =DEC!M21 | F21: =IF(COUNT(F19:F20)=0,"",SUM(F19:F20)) | G21: =JAN!M21 | H21: =FEB!M21 | I21: =MAR!M21 | J21: =IF(COUNT(J19:J20)=0,"",SUM(J19:J20)) | K21: =APR!M21 | L21: =MAY!M21 | M21: =JUN!M21 | N21: =IF(COUNT(N19:N20)=0,"",SUM(N19:N20)) | O21: =JUL!M21 | P21: =AUG!M21 | Q21: =SEP!M21 | R21: =IF(COUNT(R19:R20)=0,"",SUM(R19:R20)) | S21: =IF(COUNT(S19:S20)=0,"",SUM(S19:S20))
B22: Permanent Exits | C22: =OCT!M22 | D22: =NOV!M22 | E22: =DEC!M22 | F22: =IF(COUNT(C22:E22)=0,"",SUM(C22:E22)) | G22: =JAN!M22 | H22: =FEB!M22 | I22: =MAR!M22 | J22: =IF(COUNT(G22:I22)=0,"",SUM(G22:I22)) | K22: =APR!M22 | L22: =MAY!M22 | M22: =JUN!M22 | N22: =IF(COUNT(K22:M22)=0,"",SUM(K22:M22)) | O22: =JUL!M22 | P22: =AUG!M22 | Q22: =SEP!M22 | R22: =IF(COUNT(O22:Q22)=0,"",SUM(O22:Q22)) | S22: =IF(COUNT(C22:E22,G22:I22,K22:M22,O22:Q22)=0,"",SUM(C22:E22,G22:I22,K22:M22,O22:Q22))
B23: Temporary Exits | C23: =OCT!M23 | D23: =NOV!M23 | E23: =DEC!M23 | F23: =IF(COUNT(C23:E23)=0,"",SUM(C23:E23)) | G23: =JAN!M23 | H23: =FEB!M23 | I23: =MAR!M23 | J23: =IF(COUNT(G23:I23)=0,"",SUM(G23:I23)) | K23: =APR!M23 | L23: =MAY!M23 | M23: =JUN!M23 | N23: =IF(COUNT(K23:M23)=0,"",SUM(K23:M23)) | O23: =JUL!M23 | P23: =AUG!M23 | Q23: =SEP!M23 | R23: =IF(COUNT(O23:Q23)=0,"",SUM(O23:Q23)) | S23: =IF(COUNT(C23:E23,G23:I23,K23:M23,O23:Q23)=0,"",SUM(C23:E23,G23:I23,K23:M23,O23:Q23))
B24: Total Exits | C24: =OCT!M24 | D24: =NOV!M24 | E24: =DEC!M24 | F24: =IF(COUNT(F22:F23)=0,"",SUM(F22:F23)) | G24: =JAN!M24 | H24: =FEB!M24 | I24: =MAR!M24 | J24: =IF(COUNT(J22:J23)=0,"",SUM(J22:J23)) | K24: =APR!M24 | L24: =MAY!M24 | M24: =JUN!M24 | N24: =IF(COUNT(N22:N23)=0,"",SUM(N22:N23)) | O24: =JUL!M24 | P24: =AUG!M24 | Q24: =SEP!M24 | R24: =IF(COUNT(R22:R23)=0,"",SUM(R22:R23)) | S24: =IF(COUNT(S22:S23)=0,"",SUM(S22:S23))
B25: Permanent Turnover (%) | C25: =OCT!M25 | D25: =NOV!M25 | E25: =DEC!M25 | F25: =IF(COUNT(F31,F32)<2,"",IF((F32+F31)=0,"",N(F22)/((F32+F31)/2))) | G25: =JAN!M25 | H25: =FEB!M25 | I25: =MAR!M25 | J25: =IF(COUNT(J31,J32)<2,"",IF((J32+J31)=0,"",N(J22)/((J32+J31)/2))) | K25: =APR!M25 | L25: =MAY!M25 | M25: =JUN!M25 | N25: =IF(COUNT(N31,N32)<2,"",IF((N32+N31)=0,"",N(N22)/((N32+N31)/2))) | O25: =JUL!M25 | P25: =AUG!M25 | Q25: =SEP!M25 | R25: =IF(COUNT(R31,R32)<2,"",IF((R32+R31)=0,"",N(R22)/((R32+R31)/2))) | S25: =IF(COUNT(S31,S32)<2,"",IF((S32+S31)=0,"",N(S22)/((S32+S31)/2)))
B26: Temporary Turnover (%) | C26: =OCT!M26 | D26: =NOV!M26 | E26: =DEC!M26 | F26: =IF(COUNT(F31,F32)<2,"",IF((F32+F31)=0,"",N(F23)/((F32+F31)/2))) | G26: =JAN!M26 | H26: =FEB!M26 | I26: =MAR!M26 | J26: =IF(COUNT(J31,J32)<2,"",IF((J32+J31)=0,"",N(J23)/((J32+J31)/2))) | K26: =APR!M26 | L26: =MAY!M26 | M26: =JUN!M26 | N26: =IF(COUNT(N31,N32)<2,"",IF((N32+N31)=0,"",N(N23)/((N32+N31)/2))) | O26: =JUL!M26 | P26: =AUG!M26 | Q26: =SEP!M26 | R26: =IF(COUNT(R31,R32)<2,"",IF((R32+R31)=0,"",N(R23)/((R32+R31)/2))) | S26: =IF(COUNT(S31,S32)<2,"",IF((S32+S31)=0,"",N(S23)/((S32+S31)/2)))
B27: Voluntary Terminations | C27: =OCT!M27 | D27: =NOV!M27 | E27: =DEC!M27 | F27: =IF(COUNT(C27:E27)=0,"",SUM(C27:E27)) | G27: =JAN!M27 | H27: =FEB!M27 | I27: =MAR!M27 | J27: =IF(COUNT(G27:I27)=0,"",SUM(G27:I27)) | K27: =APR!M27 | L27: =MAY!M27 | M27: =JUN!M27 | N27: =IF(COUNT(K27:M27)=0,"",SUM(K27:M27)) | O27: =JUL!M27 | P27: =AUG!M27 | Q27: =SEP!M27 | R27: =IF(COUNT(O27:Q27)=0,"",SUM(O27:Q27)) | S27: =IF(COUNT(C27:E27,G27:I27,K27:M27,O27:Q27)=0,"",SUM(C27:E27,G27:I27,K27:M27,O27:Q27))
B28: Involuntary Terminations | C28: =OCT!M28 | D28: =NOV!M28 | E28: =DEC!M28 | F28: =IF(COUNT(C28:E28)=0,"",SUM(C28:E28)) | G28: =JAN!M28 | H28: =FEB!M28 | I28: =MAR!M28 | J28: =IF(COUNT(G28:I28)=0,"",SUM(G28:I28)) | K28: =APR!M28 | L28: =MAY!M28 | M28: =JUN!M28 | N28: =IF(COUNT(K28:M28)=0,"",SUM(K28:M28)) | O28: =JUL!M28 | P28: =AUG!M28 | Q28: =SEP!M28 | R28: =IF(COUNT(O28:Q28)=0,"",SUM(O28:Q28)) | S28: =IF(COUNT(C28:E28,G28:I28,K28:M28,O28:Q28)=0,"",SUM(C28:E28,G28:I28,K28:M28,O28:Q28))
B29: Voluntary Turnover (%) | C29: =OCT!M29 | D29: =NOV!M29 | E29: =DEC!M29 | F29: =IF(COUNT(F31,F32)<2,"",IF((F32+F31)=0,"",N(F27)/((F32+F31)/2))) | G29: =JAN!M29 | H29: =FEB!M29 | I29: =MAR!M29 | J29: =IF(COUNT(J31,J32)<2,"",IF((J32+J31)=0,"",N(J27)/((J32+J31)/2))) | K29: =APR!M29 | L29: =MAY!M29 | M29: =JUN!M29 | N29: =IF(COUNT(N31,N32)<2,"",IF((N32+N31)=0,"",N(N27)/((N32+N31)/2))) | O29: =JUL!M29 | P29: =AUG!M29 | Q29: =SEP!M29 | R29: =IF(COUNT(R31,R32)<2,"",IF((R32+R31)=0,"",N(R27)/((R32+R31)/2))) | S29: =IF(COUNT(S31,S32)<2,"",IF((S32+S31)=0,"",N(S27)/((S32+S31)/2)))
B30: Involuntary Turnover (%) | C30: =OCT!M30 | D30: =NOV!M30 | E30: =DEC!M30 | F30: =IF(COUNT(F31,F32)<2,"",IF((F32+F31)=0,"",N(F28)/((F32+F31)/2))) | G30: =JAN!M30 | H30: =FEB!M30 | I30: =MAR!M30 | J30: =IF(COUNT(J31,J32)<2,"",IF((J32+J31)=0,"",N(J28)/((J32+J31)/2))) | K30: =APR!M30 | L30: =MAY!M30 | M30: =JUN!M30 | N30: =IF(COUNT(N31,N32)<2,"",IF((N32+N31)=0,"",N(N28)/((N32+N31)/2))) | O30: =JUL!M30 | P30: =AUG!M30 | Q30: =SEP!M30 | R30: =IF(COUNT(R31,R32)<2,"",IF((R32+R31)=0,"",N(R28)/((R32+R31)/2))) | S30: =IF(COUNT(S31,S32)<2,"",IF((S32+S31)=0,"",N(S28)/((S32+S31)/2)))
B31: Headcount last Month | C31: =OCT!M31 | D31: =NOV!M31 | E31: =DEC!M31 | F31: =IFERROR(AVERAGE(C31:E31),"") | G31: =JAN!M31 | H31: =FEB!M31 | I31: =MAR!M31 | J31: =IFERROR(AVERAGE(G31:I31),"") | K31: =APR!M31 | L31: =MAY!M31 | M31: =JUN!M31 | N31: =IFERROR(AVERAGE(K31:M31),"") | O31: =JUL!M31 | P31: =AUG!M31 | Q31: =SEP!M31 | R31: =IFERROR(AVERAGE(O31:Q31),"") | S31: =IFERROR(AVERAGE(C31:E31,G31:I31,K31:M31,O31:Q31),"")
B32: Headcount this Month | C32: =OCT!M32 | D32: =NOV!M32 | E32: =DEC!M32 | F32: =IFERROR(AVERAGE(C32:E32),"") | G32: =JAN!M32 | H32: =FEB!M32 | I32: =MAR!M32 | J32: =IFERROR(AVERAGE(G32:I32),"") | K32: =APR!M32 | L32: =MAY!M32 | M32: =JUN!M32 | N32: =IFERROR(AVERAGE(K32:M32),"") | O32: =JUL!M32 | P32: =AUG!M32 | Q32: =SEP!M32 | R32: =IFERROR(AVERAGE(O32:Q32),"") | S32: =IFERROR(AVERAGE(C32:E32,G32:I32,K32:M32,O32:Q32),"")
B33: Full Turnover (%) | C33: =OCT!M33 | D33: =NOV!M33 | E33: =DEC!M33 | F33: =IF(COUNT(F31,F32)<2,"",IF((F32+F31)=0,"",N(F24)/((F32+F31)/2))) | G33: =JAN!M33 | H33: =FEB!M33 | I33: =MAR!M33 | J33: =IF(COUNT(J31,J32)<2,"",IF((J32+J31)=0,"",N(J24)/((J32+J31)/2))) | K33: =APR!M33 | L33: =MAY!M33 | M33: =JUN!M33 | N33: =IF(COUNT(N31,N32)<2,"",IF((N32+N31)=0,"",N(N24)/((N32+N31)/2))) | O33: =JUL!M33 | P33: =AUG!M33 | Q33: =SEP!M33 | R33: =IF(COUNT(R31,R32)<2,"",IF((R32+R31)=0,"",N(R24)/((R32+R31)/2))) | S33: =IF(COUNT(S31,S32)<2,"",IF((S32+S31)=0,"",N(S24)/((S32+S31)/2)))
B34: Permanent Vacancies | C34: =OCT!M34 | D34: =NOV!M34 | E34: =DEC!M34 | F34: =IFERROR(AVERAGE(C34:E34),"") | G34: =JAN!M34 | H34: =FEB!M34 | I34: =MAR!M34 | J34: =IFERROR(AVERAGE(G34:I34),"") | K34: =APR!M34 | L34: =MAY!M34 | M34: =JUN!M34 | N34: =IFERROR(AVERAGE(K34:M34),"") | O34: =JUL!M34 | P34: =AUG!M34 | Q34: =SEP!M34 | R34: =IFERROR(AVERAGE(O34:Q34),"") | S34: =IFERROR(AVERAGE(C34:E34,G34:I34,K34:M34,O34:Q34),"")
B35: Temporary Vacancies | C35: =OCT!M35 | D35: =NOV!M35 | E35: =DEC!M35 | F35: =IFERROR(AVERAGE(C35:E35),"") | G35: =JAN!M35 | H35: =FEB!M35 | I35: =MAR!M35 | J35: =IFERROR(AVERAGE(G35:I35),"") | K35: =APR!M35 | L35: =MAY!M35 | M35: =JUN!M35 | N35: =IFERROR(AVERAGE(K35:M35),"") | O35: =JUL!M35 | P35: =AUG!M35 | Q35: =SEP!M35 | R35: =IFERROR(AVERAGE(O35:Q35),"") | S35: =IFERROR(AVERAGE(C35:E35,G35:I35,K35:M35,O35:Q35),"")
B36: Total Vacancies | C36: =OCT!M36 | D36: =NOV!M36 | E36: =DEC!M36 | F36: =IF(COUNT(F34:F35)=0,"",SUM(F34:F35)) | G36: =JAN!M36 | H36: =FEB!M36 | I36: =MAR!M36 | J36: =IF(COUNT(J34:J35)=0,"",SUM(J34:J35)) | K36: =APR!M36 | L36: =MAY!M36 | M36: =JUN!M36 | N36: =IF(COUNT(N34:N35)=0,"",SUM(N34:N35)) | O36: =JUL!M36 | P36: =AUG!M36 | Q36: =SEP!M36 | R36: =IF(COUNT(R34:R35)=0,"",SUM(R34:R35)) | S36: =IF(COUNT(S34:S35)=0,"",SUM(S34:S35))
B37: Authorized Positions | C37: =OCT!M37 | D37: =NOV!M37 | E37: =DEC!M37 | F37: =IF(COUNT(F5,F36)=0,"",N(F5)+N(F36)) | G37: =JAN!M37 | H37: =FEB!M37 | I37: =MAR!M37 | J37: =IF(COUNT(J5,J36)=0,"",N(J5)+N(J36)) | K37: =APR!M37 | L37: =MAY!M37 | M37: =JUN!M37 | N37: =IF(COUNT(N5,N36)=0,"",N(N5)+N(N36)) | O37: =JUL!M37 | P37: =AUG!M37 | Q37: =SEP!M37 | R37: =IF(COUNT(R5,R36)=0,"",N(R5)+N(R36)) | S37: =IF(COUNT(S5,S36)=0,"",N(S5)+N(S36))
B38: Vacancy Rate (%) | C38: =OCT!M38 | D38: =NOV!M38 | E38: =DEC!M38 | F38: =IFERROR(F36/F37,"") | G38: =JAN!M38 | H38: =FEB!M38 | I38: =MAR!M38 | J38: =IFERROR(J36/J37,"") | K38: =APR!M38 | L38: =MAY!M38 | M38: =JUN!M38 | N38: =IFERROR(N36/N37,"") | O38: =JUL!M38 | P38: =AUG!M38 | Q38: =SEP!M38 | R38: =IFERROR(R36/R37,"") | S38: =IFERROR(S36/S37,"")
B39: Permanent TimeToHire (Days) YTD | C39: =OCT!M39 | D39: =NOV!M39 | E39: =DEC!M39 | F39: =IFERROR(LOOKUP(2,1/ISNUMBER(C39:E39),C39:E39),"") | G39: =JAN!M39 | H39: =FEB!M39 | I39: =MAR!M39 | J39: =IFERROR(LOOKUP(2,1/ISNUMBER(G39:I39),G39:I39),"") | K39: =APR!M39 | L39: =MAY!M39 | M39: =JUN!M39 | N39: =IFERROR(LOOKUP(2,1/ISNUMBER(K39:M39),K39:M39),"") | O39: =JUL!M39 | P39: =AUG!M39 | Q39: =SEP!M39 | R39: =IFERROR(LOOKUP(2,1/ISNUMBER(O39:Q39),O39:Q39),"") | S39: =IFERROR(LOOKUP(2,1/ISNUMBER(C39:Q39),C39:Q39),"")
B40: Temporary TimeToHire (Days) YTD | C40: =OCT!M40 | D40: =NOV!M40 | E40: =DEC!M40 | F40: =IFERROR(LOOKUP(2,1/ISNUMBER(C40:E40),C40:E40),"") | G40: =JAN!M40 | H40: =FEB!M40 | I40: =MAR!M40 | J40: =IFERROR(LOOKUP(2,1/ISNUMBER(G40:I40),G40:I40),"") | K40: =APR!M40 | L40: =MAY!M40 | M40: =JUN!M40 | N40: =IFERROR(LOOKUP(2,1/ISNUMBER(K40:M40),K40:M40),"") | O40: =JUL!M40 | P40: =AUG!M40 | Q40: =SEP!M40 | R40: =IFERROR(LOOKUP(2,1/ISNUMBER(O40:Q40),O40:Q40),"") | S40: =IFERROR(LOOKUP(2,1/ISNUMBER(C40:Q40),C40:Q40),"")
...

Sheet OCT
B1: GCG SOUTH CARIBBEAN | C1: 1015 | D1: 1004 | E1: 1063 | F1: 1160 | G1: 1073 | H1: 1042 | I1: 1084 | J1: 1049 | K1: 1005 | L1: 1115
A2: 202610 | B2: OCT | C2: Calloway Aruba | D2: Airport Rest. Barbados | E2: GCG Barbados | F2: GCG Aviation Ground Barbados | G2: GCG Curacao | H2: GCG Events Curacao | I2: GCG Sint Maarten Sky Dining | J2: GCG Sint Maarten Airport Dining | K2: Allied Caterers Trinidad | L2: Katerserv Trinidad | M2: TOTAL | N2: Total by Division | O2: =N(O11)<>0
A3: =+A2 | B3: Permanent (Regular) Headcount | M3: =IF(COUNT(C3:L3)=0,"",SUM(C3:L3)) | N3: ∑
B4: Temporary (Fix Term) Headcount | M4: =IF(COUNT(C4:L4)=0,"",SUM(C4:L4)) | N4: ∑
B5: Employee Headcount (Productivity) | C5: =IF(COUNT(C3:C4)=0,"",SUM(C3:C4)) | D5: =IF(COUNT(D3:D4)=0,"",SUM(D3:D4)) | E5: =IF(COUNT(E3:E4)=0,"",SUM(E3:E4)) | F5: =IF(COUNT(F3:F4)=0,"",SUM(F3:F4)) | G5: =IF(COUNT(G3:G4)=0,"",SUM(G3:G4)) | H5: =IF(COUNT(H3:H4)=0,"",SUM(H3:H4)) | I5: =IF(COUNT(I3:I4)=0,"",SUM(I3:I4)) | J5: =IF(COUNT(J3:J4)=0,"",SUM(J3:J4)) | ... M5: =IF(COUNT(M3:M4)=0,"",SUM(M3:M4)) | N5: ϝ
B6: Headcount = 1.00 | M6: =IF(COUNT(C6:L6)=0,"",SUM(C6:L6)) | N6: ∑
B7: Headcount = 0.75 | M7: =IF(COUNT(C7:L7)=0,"",SUM(C7:L7)) | N7: ∑
B8: Headcount = 0.50 | M8: =IF(COUNT(C8:L8)=0,"",SUM(C8:L8)) | N8: ∑
B9: Headcount = 0.25 | M9: =IF(COUNT(C9:L9)=0,"",SUM(C9:L9)) | N9: ∑
B10: Standard Monthly Hours (FTE basis) | M10: =IFERROR(AVERAGE(C10:L10),"") | N10: Avg
B11: Employee FTE (Finance) | C11: =IF(COUNT(C6:C9)=0,"",N(C6)+N(C7)*0.75+N(C8)*0.5+N(C9)*0.25) | D11: =IF(COUNT(D6:D9)=0,"",N(D6)+N(D7)*0.75+N(D8)*0.5+N(D9)*0.25) | E11: =IF(COUNT(E6:E9)=0,"",N(E6)+N(E7)*0.75+N(E8)*0.5+N(E9)*0.25) | F11: =IF(COUNT(F6:F9)=0,"",N(F6)+N(F7)*0.75+N(F8)*0.5+N(F9)*0.25) | G11: =IF(COUNT(G6:G9)=0,"",N(G6)+N(G7)*0.75+N(G8)*0.5+N(G9)*0.25) | H11: =IF(COUNT(H6:H9)=0,"",N(H6)+N(H7)*0.75+N(H8)*0.5+N(H9)*0.25) | I11: =IF(COUNT(I6:I9)=0,"",N(I6)+N(I7)*0.75+N(I8)*0.5+N(I9)*0.25) | J11: =IF(COUNT(J6:J9)=0,"",N(J6)+N(J7)*0.75+N(J8)*0.5+N(J9)*0.25) | ... M11: =IF(COUNT(M6:M9)=0,"",N(M6)+N(M7)*0.75+N(M8)*0.5+N(M9)*0.25) | N11: FTE | O11: =IF(COUNT(M5:M9)=0,"",N(M6)+N(M7)+N(M8)+N(M9)-N(M5))
B12: Subcontracted Workforce HC | M12: =IF(COUNT(C12:L12)=0,"",SUM(C12:L12)) | N12: ∑
B13: Subcontracted Productive Hours | M13: =IF(COUNT(C13:L13)=0,"",SUM(C13:L13)) | N13: ∑
B14: Subcontracted FTE | C14: =IFERROR(C13/C10,"") | D14: =IFERROR(D13/D10,"") | E14: =IFERROR(E13/E10,"") | F14: =IFERROR(F13/F10,"") | G14: =IFERROR(G13/G10,"") | H14: =IFERROR(H13/H10,"") | I14: =IFERROR(I13/I10,"") | J14: =IFERROR(J13/J10,"") | ... L14: =IFERROR(L13/L10,"") | M14: =IF(COUNT(C14:L14)=0,"",SUM(C14:L14)) | N14: FTE
B15: Total Operational Workforce | C15: =IF(COUNT(C5,C12)=0,"",SUM(C5,C12)) | D15: =IF(COUNT(D5,D12)=0,"",SUM(D5,D12)) | E15: =IF(COUNT(E5,E12)=0,"",SUM(E5,E12)) | F15: =IF(COUNT(F5,F12)=0,"",SUM(F5,F12)) | G15: =IF(COUNT(G5,G12)=0,"",SUM(G5,G12)) | H15: =IF(COUNT(H5,H12)=0,"",SUM(H5,H12)) | I15: =IF(COUNT(I5,I12)=0,"",SUM(I5,I12)) | J15: =IF(COUNT(J5,J12)=0,"",SUM(J5,J12)) | ... M15: =IF(COUNT(M5,M12)=0,"",SUM(M5,M12)) | N15: ϝ
B16: Total Operational FTE | C16: =IF(COUNT(C11,C14)=0,"",SUM(C11,C14)) | D16: =IF(COUNT(D11,D14)=0,"",SUM(D11,D14)) | E16: =IF(COUNT(E11,E14)=0,"",SUM(E11,E14)) | F16: =IF(COUNT(F11,F14)=0,"",SUM(F11,F14)) | G16: =IF(COUNT(G11,G14)=0,"",SUM(G11,G14)) | H16: =IF(COUNT(H11,H14)=0,"",SUM(H11,H14)) | I16: =IF(COUNT(I11,I14)=0,"",SUM(I11,I14)) | J16: =IF(COUNT(J11,J14)=0,"",SUM(J11,J14)) | ... M16: =IF(COUNT(M11,M14)=0,"",SUM(M11,M14)) | N16: FTE
B17: Subcontracted Share of Workforce (%) | C17: =IFERROR(C12/C15,"") | D17: =IFERROR(D12/D15,"") | E17: =IFERROR(E12/E15,"") | F17: =IFERROR(F12/F15,"") | G17: =IFERROR(G12/G15,"") | H17: =IFERROR(H12/H15,"") | I17: =IFERROR(I12/I15,"") | J17: =IFERROR(J12/J15,"") | ... M17: =IFERROR(M12/M15,"") | N17: ϝ
B18: FTE HR Team | M18: =IF(COUNT(C18:L18)=0,"",SUM(C18:L18)) | N18: ∑
B19: Permanent Hires | M19: =IF(COUNT(C19:L19)=0,"",SUM(C19:L19)) | N19: ∑
B20: Temporary Hires | M20: =IF(COUNT(C20:L20)=0,"",SUM(C20:L20)) | N20: ∑
B21: Total Hires | C21: =IF(COUNT(C19:C20)=0,"",SUM(C19:C20)) | D21: =IF(COUNT(D19:D20)=0,"",SUM(D19:D20)) | E21: =IF(COUNT(E19:E20)=0,"",SUM(E19:E20)) | F21: =IF(COUNT(F19:F20)=0,"",SUM(F19:F20)) | G21: =IF(COUNT(G19:G20)=0,"",SUM(G19:G20)) | H21: =IF(COUNT(H19:H20)=0,"",SUM(H19:H20)) | I21: =IF(COUNT(I19:I20)=0,"",SUM(I19:I20)) | J21: =IF(COUNT(J19:J20)=0,"",SUM(J19:J20)) | ... M21: =IF(COUNT(M19:M20)=0,"",SUM(M19:M20)) | N21: ϝ
B22: Permanent Exits | M22: =IF(COUNT(C22:L22)=0,"",SUM(C22:L22)) | N22: ∑
B23: Temporary Exits | M23: =IF(COUNT(C23:L23)=0,"",SUM(C23:L23)) | N23: ∑
B24: Total Exits | C24: =IF(COUNT(C22:C23)=0,"",SUM(C22:C23)) | D24: =IF(COUNT(D22:D23)=0,"",SUM(D22:D23)) | E24: =IF(COUNT(E22:E23)=0,"",SUM(E22:E23)) | F24: =IF(COUNT(F22:F23)=0,"",SUM(F22:F23)) | G24: =IF(COUNT(G22:G23)=0,"",SUM(G22:G23)) | H24: =IF(COUNT(H22:H23)=0,"",SUM(H22:H23)) | I24: =IF(COUNT(I22:I23)=0,"",SUM(I22:I23)) | J24: =IF(COUNT(J22:J23)=0,"",SUM(J22:J23)) | ... M24: =IF(COUNT(M22:M23)=0,"",SUM(M22:M23)) | N24: ϝ
B25: Permanent Turnover (%) | C25: =IF(COUNT(C31,C32)<2,"",IF((C32+C31)=0,"",N(C22)/((C32+C31)/2))) | D25: =IF(COUNT(D31,D32)<2,"",IF((D32+D31)=0,"",N(D22)/((D32+D31)/2))) | E25: =IF(COUNT(E31,E32)<2,"",IF((E32+E31)=0,"",N(E22)/((E32+E31)/2))) | F25: =IF(COUNT(F31,F32)<2,"",IF((F32+F31)=0,"",N(F22)/((F32+F31)/2))) | G25: =IF(COUNT(G31,G32)<2,"",IF((G32+G31)=0,"",N(G22)/((G32+G31)/2))) | H25: =IF(COUNT(H31,H32)<2,"",IF((H32+H31)=0,"",N(H22)/((H32+H31)/2))) | I25: =IF(COUNT(I31,I32)<2,"",IF((I32+I31)=0,"",N(I22)/((I32+I31)/2))) | J25: =IF(COUNT(J31,J32)<2,"",IF((J32+J31)=0,"",N(J22)/((J32+J31)/2))) | ... M25: =IF(COUNT(M31,M32)<2,"",IF((M32+M31)=0,"",N(M22)/((M32+M31)/2))) | N25: ϝ
B26: Temporary Turnover (%) | C26: =IF(COUNT(C31,C32)<2,"",IF((C32+C31)=0,"",N(C23)/((C32+C31)/2))) | D26: =IF(COUNT(D31,D32)<2,"",IF((D32+D31)=0,"",N(D23)/((D32+D31)/2))) | E26: =IF(COUNT(E31,E32)<2,"",IF((E32+E31)=0,"",N(E23)/((E32+E31)/2))) | F26: =IF(COUNT(F31,F32)<2,"",IF((F32+F31)=0,"",N(F23)/((F32+F31)/2))) | G26: =IF(COUNT(G31,G32)<2,"",IF((G32+G31)=0,"",N(G23)/((G32+G31)/2))) | H26: =IF(COUNT(H31,H32)<2,"",IF((H32+H31)=0,"",N(H23)/((H32+H31)/2))) | I26: =IF(COUNT(I31,I32)<2,"",IF((I32+I31)=0,"",N(I23)/((I32+I31)/2))) | J26: =IF(COUNT(J31,J32)<2,"",IF((J32+J31)=0,"",N(J23)/((J32+J31)/2))) | ... M26: =IF(COUNT(M31,M32)<2,"",IF((M32+M31)=0,"",N(M23)/((M32+M31)/2))) | N26: ϝ
B27: Voluntary Terminations | M27: =IF(COUNT(C27:L27)=0,"",SUM(C27:L27)) | N27: ∑
B28: Involuntary Terminations | M28: =IF(COUNT(C28:L28)=0,"",SUM(C28:L28)) | N28: ∑
B29: Voluntary Turnover (%) | C29: =IF(COUNT(C31,C32)<2,"",IF((C32+C31)=0,"",N(C27)/((C32+C31)/2))) | D29: =IF(COUNT(D31,D32)<2,"",IF((D32+D31)=0,"",N(D27)/((D32+D31)/2))) | E29: =IF(COUNT(E31,E32)<2,"",IF((E32+E31)=0,"",N(E27)/((E32+E31)/2))) | F29: =IF(COUNT(F31,F32)<2,"",IF((F32+F31)=0,"",N(F27)/((F32+F31)/2))) | G29: =IF(COUNT(G31,G32)<2,"",IF((G32+G31)=0,"",N(G27)/((G32+G31)/2))) | H29: =IF(COUNT(H31,H32)<2,"",IF((H32+H31)=0,"",N(H27)/((H32+H31)/2))) | I29: =IF(COUNT(I31,I32)<2,"",IF((I32+I31)=0,"",N(I27)/((I32+I31)/2))) | J29: =IF(COUNT(J31,J32)<2,"",IF((J32+J31)=0,"",N(J27)/((J32+J31)/2))) | ... M29: =IF(COUNT(M31,M32)<2,"",IF((M32+M31)=0,"",N(M27)/((M32+M31)/2))) | N29: ϝ
B30: Involuntary Turnover (%) | C30: =IF(COUNT(C31,C32)<2,"",IF((C32+C31)=0,"",N(C28)/((C32+C31)/2))) | D30: =IF(COUNT(D31,D32)<2,"",IF((D32+D31)=0,"",N(D28)/((D32+D31)/2))) | E30: =IF(COUNT(E31,E32)<2,"",IF((E32+E31)=0,"",N(E28)/((E32+E31)/2))) | F30: =IF(COUNT(F31,F32)<2,"",IF((F32+F31)=0,"",N(F28)/((F32+F31)/2))) | G30: =IF(COUNT(G31,G32)<2,"",IF((G32+G31)=0,"",N(G28)/((G32+G31)/2))) | H30: =IF(COUNT(H31,H32)<2,"",IF((H32+H31)=0,"",N(H28)/((H32+H31)/2))) | I30: =IF(COUNT(I31,I32)<2,"",IF((I32+I31)=0,"",N(I28)/((I32+I31)/2))) | J30: =IF(COUNT(J31,J32)<2,"",IF((J32+J31)=0,"",N(J28)/((J32+J31)/2))) | ... M30: =IF(COUNT(M31,M32)<2,"",IF((M32+M31)=0,"",N(M28)/((M32+M31)/2))) | N30: ϝ
B31: Headcount last Month | M31: =IF(COUNT(C31:L31)=0,"",SUM(C31:L31)) | N31: ∑
B32: Headcount this Month | C32: =IF(C5="","",C5) | D32: =IF(D5="","",D5) | E32: =IF(E5="","",E5) | F32: =IF(F5="","",F5) | G32: =IF(G5="","",G5) | H32: =IF(H5="","",H5) | I32: =IF(I5="","",I5) | J32: =IF(J5="","",J5) | ... L32: =IF(L5="","",L5) | M32: =IF(COUNT(C32:L32)=0,"",SUM(C32:L32)) | N32: ∑
B33: Full Turnover (%) | C33: =IF(COUNT(C31,C32)<2,"",IF((C32+C31)=0,"",N(C24)/((C32+C31)/2))) | D33: =IF(COUNT(D31,D32)<2,"",IF((D32+D31)=0,"",N(D24)/((D32+D31)/2))) | E33: =IF(COUNT(E31,E32)<2,"",IF((E32+E31)=0,"",N(E24)/((E32+E31)/2))) | F33: =IF(COUNT(F31,F32)<2,"",IF((F32+F31)=0,"",N(F24)/((F32+F31)/2))) | G33: =IF(COUNT(G31,G32)<2,"",IF((G32+G31)=0,"",N(G24)/((G32+G31)/2))) | H33: =IF(COUNT(H31,H32)<2,"",IF((H32+H31)=0,"",N(H24)/((H32+H31)/2))) | I33: =IF(COUNT(I31,I32)<2,"",IF((I32+I31)=0,"",N(I24)/((I32+I31)/2))) | J33: =IF(COUNT(J31,J32)<2,"",IF((J32+J31)=0,"",N(J24)/((J32+J31)/2))) | ... M33: =IF(COUNT(M31,M32)<2,"",IF((M32+M31)=0,"",N(M24)/((M32+M31)/2))) | N33: ϝ
B34: Permanent Vacancies | M34: =IF(COUNT(C34:L34)=0,"",SUM(C34:L34)) | N34: ∑
B35: Temporary Vacancies | M35: =IF(COUNT(C35:L35)=0,"",SUM(C35:L35)) | N35: ∑
B36: Total Vacancies | C36: =IF(COUNT(C34:C35)=0,"",SUM(C34:C35)) | D36: =IF(COUNT(D34:D35)=0,"",SUM(D34:D35)) | E36: =IF(COUNT(E34:E35)=0,"",SUM(E34:E35)) | F36: =IF(COUNT(F34:F35)=0,"",SUM(F34:F35)) | G36: =IF(COUNT(G34:G35)=0,"",SUM(G34:G35)) | H36: =IF(COUNT(H34:H35)=0,"",SUM(H34:H35)) | I36: =IF(COUNT(I34:I35)=0,"",SUM(I34:I35)) | J36: =IF(COUNT(J34:J35)=0,"",SUM(J34:J35)) | ... M36: =IF(COUNT(M34:M35)=0,"",SUM(M34:M35)) | N36: ϝ
B37: Authorized Positions | C37: =IF(COUNT(C5,C36)=0,"",N(C5)+N(C36)) | D37: =IF(COUNT(D5,D36)=0,"",N(D5)+N(D36)) | E37: =IF(COUNT(E5,E36)=0,"",N(E5)+N(E36)) | F37: =IF(COUNT(F5,F36)=0,"",N(F5)+N(F36)) | G37: =IF(COUNT(G5,G36)=0,"",N(G5)+N(G36)) | H37: =IF(COUNT(H5,H36)=0,"",N(H5)+N(H36)) | I37: =IF(COUNT(I5,I36)=0,"",N(I5)+N(I36)) | J37: =IF(COUNT(J5,J36)=0,"",N(J5)+N(J36)) | ... M37: =IF(COUNT(M5,M36)=0,"",N(M5)+N(M36)) | N37: ϝ
B38: Vacancy Rate (%) | C38: =IFERROR(C36/C37,"") | D38: =IFERROR(D36/D37,"") | E38: =IFERROR(E36/E37,"") | F38: =IFERROR(F36/F37,"") | G38: =IFERROR(G36/G37,"") | H38: =IFERROR(H36/H37,"") | I38: =IFERROR(I36/I37,"") | J38: =IFERROR(J36/J37,"") | ... M38: =IFERROR(M36/M37,"") | N38: ϝ
B39: Permanent TimeToHire (Days) YTD | C39: =IF('(Calloway_AUA)'!$AB$4="","",'(Calloway_AUA)'!$AB$4) | D39: =IF('(Airport_BRB)'!$AB$4="","",'(Airport_BRB)'!$AB$4) | E39: =IF('(GCG_BRB)'!$AB$4="","",'(GCG_BRB)'!$AB$4) | F39: =IF('(Ground_BRB)'!$AB$4="","",'(Ground_BRB)'!$AB$4) | G39: =IF('(GCG_CUR)'!$AB$4="","",'(GCG_CUR)'!$AB$4) | H39: =IF('(Events_CUR)'!$AB$4="","",'(Events_CUR)'!$AB$4) | I39: =IF('(GCG_SXM_Sky)'!$AB$4="","",'(GCG_SXM_Sky)'!$AB$4) | J39: =IF('(GCG_SXM_Airport)'!$AB$4="","",'(GCG_SXM_Airport)'!$AB$4) | K39: =IF('(Allied_TTO)'!$AB$4="","",'(Allied_TTO)'!$AB$4) | L39: =IF('(Katerserv_TTO)'!$AB$4="","",'(Katerserv_TTO)'!$AB$4) | M39: =IFERROR(AVERAGE(C39:L39),"") | N39: Avg
B40: Temporary TimeToHire (Days) YTD | C40: =IF('(Calloway_AUA)'!$AD$4="","",'(Calloway_AUA)'!$AD$4) | D40: =IF('(Airport_BRB)'!$AD$4="","",'(Airport_BRB)'!$AD$4) | E40: =IF('(GCG_BRB)'!$AD$4="","",'(GCG_BRB)'!$AD$4) | F40: =IF('(Ground_BRB)'!$AD$4="","",'(Ground_BRB)'!$AD$4) | G40: =IF('(GCG_CUR)'!$AD$4="","",'(GCG_CUR)'!$AD$4) | H40: =IF('(Events_CUR)'!$AD$4="","",'(Events_CUR)'!$AD$4) | I40: =IF('(GCG_SXM_Sky)'!$AD$4="","",'(GCG_SXM_Sky)'!$AD$4) | J40: =IF('(GCG_SXM_Airport)'!$AD$4="","",'(GCG_SXM_Airport)'!$AD$4) | K40: =IF('(Allied_TTO)'!$AD$4="","",'(Allied_TTO)'!$AD$4) | L40: =IF('(Katerserv_TTO)'!$AD$4="","",'(Katerserv_TTO)'!$AD$4) | M40: =IFERROR(AVERAGE(C40:L40),"") | N40: Avg
...

Sheet NOV
B1: GCG SOUTH CARIBBEAN | C1: 1015 | D1: 1004 | E1: 1063 | F1: 1160 | G1: 1073 | H1: 1042 | I1: 1084 | J1: 1049 | K1: 1005 | L1: 1115
A2: =VALUE(TEXT(EDATE(DATE(LEFT(OCT!A2,4),RIGHT(OCT!A2,2),1),1),"yyyymm")) | B2: NOV | C2: Calloway Aruba | D2: Airport Rest. Barbados | E2: GCG Barbados | F2: GCG Aviation Ground Barbados | G2: GCG Curacao | H2: GCG Events Curacao | I2: GCG Sint Maarten Sky Dining | J2: GCG Sint Maarten Airport Dining | K2: Allied Caterers Trinidad | L2: Katerserv Trinidad | M2: TOTAL | N2: Total by Division | O2: =N(O11)<>0
A3: =+A2 | B3: Permanent (Regular) Headcount | M3: =IF(COUNT(C3:L3)=0,"",SUM(C3:L3)) | N3: ∑
B4: Temporary (Fix Term) Headcount | M4: =IF(COUNT(C4:L4)=0,"",SUM(C4:L4)) | N4: ∑
B5: Employee Headcount (Productivity) | C5: =IF(COUNT(C3:C4)=0,"",SUM(C3:C4)) | D5: =IF(COUNT(D3:D4)=0,"",SUM(D3:D4)) | E5: =IF(COUNT(E3:E4)=0,"",SUM(E3:E4)) | F5: =IF(COUNT(F3:F4)=0,"",SUM(F3:F4)) | G5: =IF(COUNT(G3:G4)=0,"",SUM(G3:G4)) | H5: =IF(COUNT(H3:H4)=0,"",SUM(H3:H4)) | I5: =IF(COUNT(I3:I4)=0,"",SUM(I3:I4)) | J5: =IF(COUNT(J3:J4)=0,"",SUM(J3:J4)) | ... M5: =IF(COUNT(M3:M4)=0,"",SUM(M3:M4)) | N5: ϝ
B6: Headcount = 1.00 | M6: =IF(COUNT(C6:L6)=0,"",SUM(C6:L6)) | N6: ∑
B7: Headcount = 0.75 | M7: =IF(COUNT(C7:L7)=0,"",SUM(C7:L7)) | N7: ∑
B8: Headcount = 0.50 | M8: =IF(COUNT(C8:L8)=0,"",SUM(C8:L8)) | N8: ∑
B9: Headcount = 0.25 | M9: =IF(COUNT(C9:L9)=0,"",SUM(C9:L9)) | N9: ∑
B10: Standard Monthly Hours (FTE basis) | M10: =IFERROR(AVERAGE(C10:L10),"") | N10: Avg
B11: Employee FTE (Finance) | C11: =IF(COUNT(C6:C9)=0,"",N(C6)+N(C7)*0.75+N(C8)*0.5+N(C9)*0.25) | D11: =IF(COUNT(D6:D9)=0,"",N(D6)+N(D7)*0.75+N(D8)*0.5+N(D9)*0.25) | E11: =IF(COUNT(E6:E9)=0,"",N(E6)+N(E7)*0.75+N(E8)*0.5+N(E9)*0.25) | F11: =IF(COUNT(F6:F9)=0,"",N(F6)+N(F7)*0.75+N(F8)*0.5+N(F9)*0.25) | G11: =IF(COUNT(G6:G9)=0,"",N(G6)+N(G7)*0.75+N(G8)*0.5+N(G9)*0.25) | H11: =IF(COUNT(H6:H9)=0,"",N(H6)+N(H7)*0.75+N(H8)*0.5+N(H9)*0.25) | I11: =IF(COUNT(I6:I9)=0,"",N(I6)+N(I7)*0.75+N(I8)*0.5+N(I9)*0.25) | J11: =IF(COUNT(J6:J9)=0,"",N(J6)+N(J7)*0.75+N(J8)*0.5+N(J9)*0.25) | ... M11: =IF(COUNT(M6:M9)=0,"",N(M6)+N(M7)*0.75+N(M8)*0.5+N(M9)*0.25) | N11: FTE | O11: =IF(COUNT(M5:M9)=0,"",N(M6)+N(M7)+N(M8)+N(M9)-N(M5))
B12: Subcontracted Workforce HC | M12: =IF(COUNT(C12:L12)=0,"",SUM(C12:L12)) | N12: ∑
B13: Subcontracted Productive Hours | M13: =IF(COUNT(C13:L13)=0,"",SUM(C13:L13)) | N13: ∑
B14: Subcontracted FTE | C14: =IFERROR(C13/C10,"") | D14: =IFERROR(D13/D10,"") | E14: =IFERROR(E13/E10,"") | F14: =IFERROR(F13/F10,"") | G14: =IFERROR(G13/G10,"") | H14: =IFERROR(H13/H10,"") | I14: =IFERROR(I13/I10,"") | J14: =IFERROR(J13/J10,"") | ... L14: =IFERROR(L13/L10,"") | M14: =IF(COUNT(C14:L14)=0,"",SUM(C14:L14)) | N14: FTE
B15: Total Operational Workforce | C15: =IF(COUNT(C5,C12)=0,"",SUM(C5,C12)) | D15: =IF(COUNT(D5,D12)=0,"",SUM(D5,D12)) | E15: =IF(COUNT(E5,E12)=0,"",SUM(E5,E12)) | F15: =IF(COUNT(F5,F12)=0,"",SUM(F5,F12)) | G15: =IF(COUNT(G5,G12)=0,"",SUM(G5,G12)) | H15: =IF(COUNT(H5,H12)=0,"",SUM(H5,H12)) | I15: =IF(COUNT(I5,I12)=0,"",SUM(I5,I12)) | J15: =IF(COUNT(J5,J12)=0,"",SUM(J5,J12)) | ... M15: =IF(COUNT(M5,M12)=0,"",SUM(M5,M12)) | N15: ϝ
B16: Total Operational FTE | C16: =IF(COUNT(C11,C14)=0,"",SUM(C11,C14)) | D16: =IF(COUNT(D11,D14)=0,"",SUM(D11,D14)) | E16: =IF(COUNT(E11,E14)=0,"",SUM(E11,E14)) | F16: =IF(COUNT(F11,F14)=0,"",SUM(F11,F14)) | G16: =IF(COUNT(G11,G14)=0,"",SUM(G11,G14)) | H16: =IF(COUNT(H11,H14)=0,"",SUM(H11,H14)) | I16: =IF(COUNT(I11,I14)=0,"",SUM(I11,I14)) | J16: =IF(COUNT(J11,J14)=0,"",SUM(J11,J14)) | ... M16: =IF(COUNT(M11,M14)=0,"",SUM(M11,M14)) | N16: FTE
B17: Subcontracted Share of Workforce (%) | C17: =IFERROR(C12/C15,"") | D17: =IFERROR(D12/D15,"") | E17: =IFERROR(E12/E15,"") | F17: =IFERROR(F12/F15,"") | G17: =IFERROR(G12/G15,"") | H17: =IFERROR(H12/H15,"") | I17: =IFERROR(I12/I15,"") | J17: =IFERROR(J12/J15,"") | ... M17: =IFERROR(M12/M15,"") | N17: ϝ
B18: FTE HR Team | M18: =IF(COUNT(C18:L18)=0,"",SUM(C18:L18)) | N18: ∑
B19: Permanent Hires | M19: =IF(COUNT(C19:L19)=0,"",SUM(C19:L19)) | N19: ∑
B20: Temporary Hires | M20: =IF(COUNT(C20:L20)=0,"",SUM(C20:L20)) | N20: ∑
B21: Total Hires | C21: =IF(COUNT(C19:C20)=0,"",SUM(C19:C20)) | D21: =IF(COUNT(D19:D20)=0,"",SUM(D19:D20)) | E21: =IF(COUNT(E19:E20)=0,"",SUM(E19:E20)) | F21: =IF(COUNT(F19:F20)=0,"",SUM(F19:F20)) | G21: =IF(COUNT(G19:G20)=0,"",SUM(G19:G20)) | H21: =IF(COUNT(H19:H20)=0,"",SUM(H19:H20)) | I21: =IF(COUNT(I19:I20)=0,"",SUM(I19:I20)) | J21: =IF(COUNT(J19:J20)=0,"",SUM(J19:J20)) | ... M21: =IF(COUNT(M19:M20)=0,"",SUM(M19:M20)) | N21: ϝ
B22: Permanent Exits | M22: =IF(COUNT(C22:L22)=0,"",SUM(C22:L22)) | N22: ∑
B23: Temporary Exits | M23: =IF(COUNT(C23:L23)=0,"",SUM(C23:L23)) | N23: ∑
B24: Total Exits | C24: =IF(COUNT(C22:C23)=0,"",SUM(C22:C23)) | D24: =IF(COUNT(D22:D23)=0,"",SUM(D22:D23)) | E24: =IF(COUNT(E22:E23)=0,"",SUM(E22:E23)) | F24: =IF(COUNT(F22:F23)=0,"",SUM(F22:F23)) | G24: =IF(COUNT(G22:G23)=0,"",SUM(G22:G23)) | H24: =IF(COUNT(H22:H23)=0,"",SUM(H22:H23)) | I24: =IF(COUNT(I22:I23)=0,"",SUM(I22:I23)) | J24: =IF(COUNT(J22:J23)=0,"",SUM(J22:J23)) | ... M24: =IF(COUNT(M22:M23)=0,"",SUM(M22:M23)) | N24: ϝ
B25: Permanent Turnover (%) | C25: =IF(COUNT(C31,C32)<2,"",IF((C32+C31)=0,"",N(C22)/((C32+C31)/2))) | D25: =IF(COUNT(D31,D32)<2,"",IF((D32+D31)=0,"",N(D22)/((D32+D31)/2))) | E25: =IF(COUNT(E31,E32)<2,"",IF((E32+E31)=0,"",N(E22)/((E32+E31)/2))) | F25: =IF(COUNT(F31,F32)<2,"",IF((F32+F31)=0,"",N(F22)/((F32+F31)/2))) | G25: =IF(COUNT(G31,G32)<2,"",IF((G32+G31)=0,"",N(G22)/((G32+G31)/2))) | H25: =IF(COUNT(H31,H32)<2,"",IF((H32+H31)=0,"",N(H22)/((H32+H31)/2))) | I25: =IF(COUNT(I31,I32)<2,"",IF((I32+I31)=0,"",N(I22)/((I32+I31)/2))) | J25: =IF(COUNT(J31,J32)<2,"",IF((J32+J31)=0,"",N(J22)/((J32+J31)/2))) | ... M25: =IF(COUNT(M31,M32)<2,"",IF((M32+M31)=0,"",N(M22)/((M32+M31)/2))) | N25: ϝ
B26: Temporary Turnover (%) | C26: =IF(COUNT(C31,C32)<2,"",IF((C32+C31)=0,"",N(C23)/((C32+C31)/2))) | D26: =IF(COUNT(D31,D32)<2,"",IF((D32+D31)=0,"",N(D23)/((D32+D31)/2))) | E26: =IF(COUNT(E31,E32)<2,"",IF((E32+E31)=0,"",N(E23)/((E32+E31)/2))) | F26: =IF(COUNT(F31,F32)<2,"",IF((F32+F31)=0,"",N(F23)/((F32+F31)/2))) | G26: =IF(COUNT(G31,G32)<2,"",IF((G32+G31)=0,"",N(G23)/((G32+G31)/2))) | H26: =IF(COUNT(H31,H32)<2,"",IF((H32+H31)=0,"",N(H23)/((H32+H31)/2))) | I26: =IF(COUNT(I31,I32)<2,"",IF((I32+I31)=0,"",N(I23)/((I32+I31)/2))) | J26: =IF(COUNT(J31,J32)<2,"",IF((J32+J31)=0,"",N(J23)/((J32+J31)/2))) | ... M26: =IF(COUNT(M31,M32)<2,"",IF((M32+M31)=0,"",N(M23)/((M32+M31)/2))) | N26: ϝ
B27: Voluntary Terminations | M27: =IF(COUNT(C27:L27)=0,"",SUM(C27:L27)) | N27: ∑
B28: Involuntary Terminations | M28: =IF(COUNT(C28:L28)=0,"",SUM(C28:L28)) | N28: ∑
B29: Voluntary Turnover (%) | C29: =IF(COUNT(C31,C32)<2,"",IF((C32+C31)=0,"",N(C27)/((C32+C31)/2))) | D29: =IF(COUNT(D31,D32)<2,"",IF((D32+D31)=0,"",N(D27)/((D32+D31)/2))) | E29: =IF(COUNT(E31,E32)<2,"",IF((E32+E31)=0,"",N(E27)/((E32+E31)/2))) | F29: =IF(COUNT(F31,F32)<2,"",IF((F32+F31)=0,"",N(F27)/((F32+F31)/2))) | G29: =IF(COUNT(G31,G32)<2,"",IF((G32+G31)=0,"",N(G27)/((G32+G31)/2))) | H29: =IF(COUNT(H31,H32)<2,"",IF((H32+H31)=0,"",N(H27)/((H32+H31)/2))) | I29: =IF(COUNT(I31,I32)<2,"",IF((I32+I31)=0,"",N(I27)/((I32+I31)/2))) | J29: =IF(COUNT(J31,J32)<2,"",IF((J32+J31)=0,"",N(J27)/((J32+J31)/2))) | ... M29: =IF(COUNT(M31,M32)<2,"",IF((M32+M31)=0,"",N(M27)/((M32+M31)/2))) | N29: ϝ
B30: Involuntary Turnover (%) | C30: =IF(COUNT(C31,C32)<2,"",IF((C32+C31)=0,"",N(C28)/((C32+C31)/2))) | D30: =IF(COUNT(D31,D32)<2,"",IF((D32+D31)=0,"",N(D28)/((D32+D31)/2))) | E30: =IF(COUNT(E31,E32)<2,"",IF((E32+E31)=0,"",N(E28)/((E32+E31)/2))) | F30: =IF(COUNT(F31,F32)<2,"",IF((F32+F31)=0,"",N(F28)/((F32+F31)/2))) | G30: =IF(COUNT(G31,G32)<2,"",IF((G32+G31)=0,"",N(G28)/((G32+G31)/2))) | H30: =IF(COUNT(H31,H32)<2,"",IF((H32+H31)=0,"",N(H28)/((H32+H31)/2))) | I30: =IF(COUNT(I31,I32)<2,"",IF((I32+I31)=0,"",N(I28)/((I32+I31)/2))) | J30: =IF(COUNT(J31,J32)<2,"",IF((J32+J31)=0,"",N(J28)/((J32+J31)/2))) | ... M30: =IF(COUNT(M31,M32)<2,"",IF((M32+M31)=0,"",N(M28)/((M32+M31)/2))) | N30: ϝ
B31: Headcount last Month | C31: =IF(OCT!C5="","",OCT!C5) | D31: =IF(OCT!D5="","",OCT!D5) | E31: =IF(OCT!E5="","",OCT!E5) | F31: =IF(OCT!F5="","",OCT!F5) | G31: =IF(OCT!G5="","",OCT!G5) | H31: =IF(OCT!H5="","",OCT!H5) | I31: =IF(OCT!I5="","",OCT!I5) | J31: =IF(OCT!J5="","",OCT!J5) | ... L31: =IF(OCT!L5="","",OCT!L5) | M31: =IF(COUNT(C31:L31)=0,"",SUM(C31:L31)) | N31: ∑
B32: Headcount this Month | C32: =IF(C5="","",C5) | D32: =IF(D5="","",D5) | E32: =IF(E5="","",E5) | F32: =IF(F5="","",F5) | G32: =IF(G5="","",G5) | H32: =IF(H5="","",H5) | I32: =IF(I5="","",I5) | J32: =IF(J5="","",J5) | ... L32: =IF(L5="","",L5) | M32: =IF(COUNT(C32:L32)=0,"",SUM(C32:L32)) | N32: ∑
B33: Full Turnover (%) | C33: =IF(COUNT(C31,C32)<2,"",IF((C32+C31)=0,"",N(C24)/((C32+C31)/2))) | D33: =IF(COUNT(D31,D32)<2,"",IF((D32+D31)=0,"",N(D24)/((D32+D31)/2))) | E33: =IF(COUNT(E31,E32)<2,"",IF((E32+E31)=0,"",N(E24)/((E32+E31)/2))) | F33: =IF(COUNT(F31,F32)<2,"",IF((F32+F31)=0,"",N(F24)/((F32+F31)/2))) | G33: =IF(COUNT(G31,G32)<2,"",IF((G32+G31)=0,"",N(G24)/((G32+G31)/2))) | H33: =IF(COUNT(H31,H32)<2,"",IF((H32+H31)=0,"",N(H24)/((H32+H31)/2))) | I33: =IF(COUNT(I31,I32)<2,"",IF((I32+I31)=0,"",N(I24)/((I32+I31)/2))) | J33: =IF(COUNT(J31,J32)<2,"",IF((J32+J31)=0,"",N(J24)/((J32+J31)/2))) | ... M33: =IF(COUNT(M31,M32)<2,"",IF((M32+M31)=0,"",N(M24)/((M32+M31)/2))) | N33: ϝ
B34: Permanent Vacancies | M34: =IF(COUNT(C34:L34)=0,"",SUM(C34:L34)) | N34: ∑
B35: Temporary Vacancies | M35: =IF(COUNT(C35:L35)=0,"",SUM(C35:L35)) | N35: ∑
B36: Total Vacancies | C36: =IF(COUNT(C34:C35)=0,"",SUM(C34:C35)) | D36: =IF(COUNT(D34:D35)=0,"",SUM(D34:D35)) | E36: =IF(COUNT(E34:E35)=0,"",SUM(E34:E35)) | F36: =IF(COUNT(F34:F35)=0,"",SUM(F34:F35)) | G36: =IF(COUNT(G34:G35)=0,"",SUM(G34:G35)) | H36: =IF(COUNT(H34:H35)=0,"",SUM(H34:H35)) | I36: =IF(COUNT(I34:I35)=0,"",SUM(I34:I35)) | J36: =IF(COUNT(J34:J35)=0,"",SUM(J34:J35)) | ... M36: =IF(COUNT(M34:M35)=0,"",SUM(M34:M35)) | N36: ϝ
B37: Authorized Positions | C37: =IF(COUNT(C5,C36)=0,"",N(C5)+N(C36)) | D37: =IF(COUNT(D5,D36)=0,"",N(D5)+N(D36)) | E37: =IF(COUNT(E5,E36)=0,"",N(E5)+N(E36)) | F37: =IF(COUNT(F5,F36)=0,"",N(F5)+N(F36)) | G37: =IF(COUNT(G5,G36)=0,"",N(G5)+N(G36)) | H37: =IF(COUNT(H5,H36)=0,"",N(H5)+N(H36)) | I37: =IF(COUNT(I5,I36)=0,"",N(I5)+N(I36)) | J37: =IF(COUNT(J5,J36)=0,"",N(J5)+N(J36)) | ... M37: =IF(COUNT(M5,M36)=0,"",N(M5)+N(M36)) | N37: ϝ
B38: Vacancy Rate (%) | C38: =IFERROR(C36/C37,"") | D38: =IFERROR(D36/D37,"") | E38: =IFERROR(E36/E37,"") | F38: =IFERROR(F36/F37,"") | G38: =IFERROR(G36/G37,"") | H38: =IFERROR(H36/H37,"") | I38: =IFERROR(I36/I37,"") | J38: =IFERROR(J36/J37,"") | ... M38: =IFERROR(M36/M37,"") | N38: ϝ
B39: Permanent TimeToHire (Days) YTD | C39: =IF('(Calloway_AUA)'!$AB$5="","",'(Calloway_AUA)'!$AB$5) | D39: =IF('(Airport_BRB)'!$AB$5="","",'(Airport_BRB)'!$AB$5) | E39: =IF('(GCG_BRB)'!$AB$5="","",'(GCG_BRB)'!$AB$5) | F39: =IF('(Ground_BRB)'!$AB$5="","",'(Ground_BRB)'!$AB$5) | G39: =IF('(GCG_CUR)'!$AB$5="","",'(GCG_CUR)'!$AB$5) | H39: =IF('(Events_CUR)'!$AB$5="","",'(Events_CUR)'!$AB$5) | I39: =IF('(GCG_SXM_Sky)'!$AB$5="","",'(GCG_SXM_Sky)'!$AB$5) | J39: =IF('(GCG_SXM_Airport)'!$AB$5="","",'(GCG_SXM_Airport)'!$AB$5) | K39: =IF('(Allied_TTO)'!$AB$5="","",'(Allied_TTO)'!$AB$5) | L39: =IF('(Katerserv_TTO)'!$AB$5="","",'(Katerserv_TTO)'!$AB$5) | M39: =IFERROR(AVERAGE(C39:L39),"") | N39: Avg
B40: Temporary TimeToHire (Days) YTD | C40: =IF('(Calloway_AUA)'!$AD$5="","",'(Calloway_AUA)'!$AD$5) | D40: =IF('(Airport_BRB)'!$AD$5="","",'(Airport_BRB)'!$AD$5) | E40: =IF('(GCG_BRB)'!$AD$5="","",'(GCG_BRB)'!$AD$5) | F40: =IF('(Ground_BRB)'!$AD$5="","",'(Ground_BRB)'!$AD$5) | G40: =IF('(GCG_CUR)'!$AD$5="","",'(GCG_CUR)'!$AD$5) | H40: =IF('(Events_CUR)'!$AD$5="","",'(Events_CUR)'!$AD$5) | I40: =IF('(GCG_SXM_Sky)'!$AD$5="","",'(GCG_SXM_Sky)'!$AD$5) | J40: =IF('(GCG_SXM_Airport)'!$AD$5="","",'(GCG_SXM_Airport)'!$AD$5) | K40: =IF('(Allied_TTO)'!$AD$5="","",'(Allied_TTO)'!$AD$5) | L40: =IF('(Katerserv_TTO)'!$AD$5="","",'(Katerserv_TTO)'!$AD$5) | M40: =IFERROR(AVERAGE(C40:L40),"") | N40: Avg
...

Sheet DEC
B1: GCG SOUTH CARIBBEAN | C1: 1015 | D1: 1004 | E1: 1063 | F1: 1160 | G1: 1073 | H1: 1042 | I1: 1084 | J1: 1049 | K1: 1005 | L1: 1115
A2: =VALUE(TEXT(EDATE(DATE(LEFT(NOV!A2,4),RIGHT(NOV!A2,2),1),1),"yyyymm")) | B2: DEC | C2: Calloway Aruba | D2: Airport Rest. Barbados | E2: GCG Barbados | F2: GCG Aviation Ground Barbados | G2: GCG Curacao | H2: GCG Events Curacao | I2: GCG Sint Maarten Sky Dining | J2: GCG Sint Maarten Airport Dining | K2: Allied Caterers Trinidad | L2: Katerserv Trinidad | M2: TOTAL | N2: Total by Division | O2: =N(O11)<>0
A3: =+A2 | B3: Permanent (Regular) Headcount | M3: =IF(COUNT(C3:L3)=0,"",SUM(C3:L3)) | N3: ∑
B4: Temporary (Fix Term) Headcount | M4: =IF(COUNT(C4:L4)=0,"",SUM(C4:L4)) | N4: ∑
B5: Employee Headcount (Productivity) | C5: =IF(COUNT(C3:C4)=0,"",SUM(C3:C4)) | D5: =IF(COUNT(D3:D4)=0,"",SUM(D3:D4)) | E5: =IF(COUNT(E3:E4)=0,"",SUM(E3:E4)) | F5: =IF(COUNT(F3:F4)=0,"",SUM(F3:F4)) | G5: =IF(COUNT(G3:G4)=0,"",SUM(G3:G4)) | H5: =IF(COUNT(H3:H4)=0,"",SUM(H3:H4)) | I5: =IF(COUNT(I3:I4)=0,"",SUM(I3:I4)) | J5: =IF(COUNT(J3:J4)=0,"",SUM(J3:J4)) | ... M5: =IF(COUNT(M3:M4)=0,"",SUM(M3:M4)) | N5: ϝ
B6: Headcount = 1.00 | M6: =IF(COUNT(C6:L6)=0,"",SUM(C6:L6)) | N6: ∑
B7: Headcount = 0.75 | M7: =IF(COUNT(C7:L7)=0,"",SUM(C7:L7)) | N7: ∑
B8: Headcount = 0.50 | M8: =IF(COUNT(C8:L8)=0,"",SUM(C8:L8)) | N8: ∑
B9: Headcount = 0.25 | M9: =IF(COUNT(C9:L9)=0,"",SUM(C9:L9)) | N9: ∑
B10: Standard Monthly Hours (FTE basis) | M10: =IFERROR(AVERAGE(C10:L10),"") | N10: Avg
B11: Employee FTE (Finance) | C11: =IF(COUNT(C6:C9)=0,"",N(C6)+N(C7)*0.75+N(C8)*0.5+N(C9)*0.25) | D11: =IF(COUNT(D6:D9)=0,"",N(D6)+N(D7)*0.75+N(D8)*0.5+N(D9)*0.25) | E11: =IF(COUNT(E6:E9)=0,"",N(E6)+N(E7)*0.75+N(E8)*0.5+N(E9)*0.25) | F11: =IF(COUNT(F6:F9)=0,"",N(F6)+N(F7)*0.75+N(F8)*0.5+N(F9)*0.25) | G11: =IF(COUNT(G6:G9)=0,"",N(G6)+N(G7)*0.75+N(G8)*0.5+N(G9)*0.25) | H11: =IF(COUNT(H6:H9)=0,"",N(H6)+N(H7)*0.75+N(H8)*0.5+N(H9)*0.25) | I11: =IF(COUNT(I6:I9)=0,"",N(I6)+N(I7)*0.75+N(I8)*0.5+N(I9)*0.25) | J11: =IF(COUNT(J6:J9)=0,"",N(J6)+N(J7)*0.75+N(J8)*0.5+N(J9)*0.25) | ... M11: =IF(COUNT(M6:M9)=0,"",N(M6)+N(M7)*0.75+N(M8)*0.5+N(M9)*0.25) | N11: FTE | O11: =IF(COUNT(M5:M9)=0,"",N(M6)+N(M7)+N(M8)+N(M9)-N(M5))
B12: Subcontracted Workforce HC | M12: =IF(COUNT(C12:L12)=0,"",SUM(C12:L12)) | N12: ∑
B13: Subcontracted Productive Hours | M13: =IF(COUNT(C13:L13)=0,"",SUM(C13:L13)) | N13: ∑
B14: Subcontracted FTE | C14: =IFERROR(C13/C10,"") | D14: =IFERROR(D13/D10,"") | E14: =IFERROR(E13/E10,"") | F14: =IFERROR(F13/F10,"") | G14: =IFERROR(G13/G10,"") | H14: =IFERROR(H13/H10,"") | I14: =IFERROR(I13/I10,"") | J14: =IFERROR(J13/J10,"") | ... L14: =IFERROR(L13/L10,"") | M14: =IF(COUNT(C14:L14)=0,"",SUM(C14:L14)) | N14: FTE
B15: Total Operational Workforce | C15: =IF(COUNT(C5,C12)=0,"",SUM(C5,C12)) | D15: =IF(COUNT(D5,D12)=0,"",SUM(D5,D12)) | E15: =IF(COUNT(E5,E12)=0,"",SUM(E5,E12)) | F15: =IF(COUNT(F5,F12)=0,"",SUM(F5,F12)) | G15: =IF(COUNT(G5,G12)=0,"",SUM(G5,G12)) | H15: =IF(COUNT(H5,H12)=0,"",SUM(H5,H12)) | I15: =IF(COUNT(I5,I12)=0,"",SUM(I5,I12)) | J15: =IF(COUNT(J5,J12)=0,"",SUM(J5,J12)) | ... M15: =IF(COUNT(M5,M12)=0,"",SUM(M5,M12)) | N15: ϝ
B16: Total Operational FTE | C16: =IF(COUNT(C11,C14)=0,"",SUM(C11,C14)) | D16: =IF(COUNT(D11,D14)=0,"",SUM(D11,D14)) | E16: =IF(COUNT(E11,E14)=0,"",SUM(E11,E14)) | F16: =IF(COUNT(F11,F14)=0,"",SUM(F11,F14)) | G16: =IF(COUNT(G11,G14)=0,"",SUM(G11,G14)) | H16: =IF(COUNT(H11,H14)=0,"",SUM(H11,H14)) | I16: =IF(COUNT(I11,I14)=0,"",SUM(I11,I14)) | J16: =IF(COUNT(J11,J14)=0,"",SUM(J11,J14)) | ... M16: =IF(COUNT(M11,M14)=0,"",SUM(M11,M14)) | N16: FTE
B17: Subcontracted Share of Workforce (%) | C17: =IFERROR(C12/C15,"") | D17: =IFERROR(D12/D15,"") | E17: =IFERROR(E12/E15,"") | F17: =IFERROR(F12/F15,"") | G17: =IFERROR(G12/G15,"") | H17: =IFERROR(H12/H15,"") | I17: =IFERROR(I12/I15,"") | J17: =IFERROR(J12/J15,"") | ... M17: =IFERROR(M12/M15,"") | N17: ϝ
B18: FTE HR Team | M18: =IF(COUNT(C18:L18)=0,"",SUM(C18:L18)) | N18: ∑
B19: Permanent Hires | M19: =IF(COUNT(C19:L19)=0,"",SUM(C19:L19)) | N19: ∑
B20: Temporary Hires | M20: =IF(COUNT(C20:L20)=0,"",SUM(C20:L20)) | N20: ∑
B21: Total Hires | C21: =IF(COUNT(C19:C20)=0,"",SUM(C19:C20)) | D21: =IF(COUNT(D19:D20)=0,"",SUM(D19:D20)) | E21: =IF(COUNT(E19:E20)=0,"",SUM(E19:E20)) | F21: =IF(COUNT(F19:F20)=0,"",SUM(F19:F20)) | G21: =IF(COUNT(G19:G20)=0,"",SUM(G19:G20)) | H21: =IF(COUNT(H19:H20)=0,"",SUM(H19:H20)) | I21: =IF(COUNT(I19:I20)=0,"",SUM(I19:I20)) | J21: =IF(COUNT(J19:J20)=0,"",SUM(J19:J20)) | ... M21: =IF(COUNT(M19:M20)=0,"",SUM(M19:M20)) | N21: ϝ
B22: Permanent Exits | M22: =IF(COUNT(C22:L22)=0,"",SUM(C22:L22)) | N22: ∑
B23: Temporary Exits | M23: =IF(COUNT(C23:L23)=0,"",SUM(C23:L23)) | N23: ∑
B24: Total Exits | C24: =IF(COUNT(C22:C23)=0,"",SUM(C22:C23)) | D24: =IF(COUNT(D22:D23)=0,"",SUM(D22:D23)) | E24: =IF(COUNT(E22:E23)=0,"",SUM(E22:E23)) | F24: =IF(COUNT(F22:F23)=0,"",SUM(F22:F23)) | G24: =IF(COUNT(G22:G23)=0,"",SUM(G22:G23)) | H24: =IF(COUNT(H22:H23)=0,"",SUM(H22:H23)) | I24: =IF(COUNT(I22:I23)=0,"",SUM(I22:I23)) | J24: =IF(COUNT(J22:J23)=0,"",SUM(J22:J23)) | ... M24: =IF(COUNT(M22:M23)=0,"",SUM(M22:M23)) | N24: ϝ
B25: Permanent Turnover (%) | C25: =IF(COUNT(C31,C32)<2,"",IF((C32+C31)=0,"",N(C22)/((C32+C31)/2))) | D25: =IF(COUNT(D31,D32)<2,"",IF((D32+D31)=0,"",N(D22)/((D32+D31)/2))) | E25: =IF(COUNT(E31,E32)<2,"",IF((E32+E31)=0,"",N(E22)/((E32+E31)/2))) | F25: =IF(COUNT(F31,F32)<2,"",IF((F32+F31)=0,"",N(F22)/((F32+F31)/2))) | G25: =IF(COUNT(G31,G32)<2,"",IF((G32+G31)=0,"",N(G22)/((G32+G31)/2))) | H25: =IF(COUNT(H31,H32)<2,"",IF((H32+H31)=0,"",N(H22)/((H32+H31)/2))) | I25: =IF(COUNT(I31,I32)<2,"",IF((I32+I31)=0,"",N(I22)/((I32+I31)/2))) | J25: =IF(COUNT(J31,J32)<2,"",IF((J32+J31)=0,"",N(J22)/((J32+J31)/2))) | ... M25: =IF(COUNT(M31,M32)<2,"",IF((M32+M31)=0,"",N(M22)/((M32+M31)/2))) | N25: ϝ
B26: Temporary Turnover (%) | C26: =IF(COUNT(C31,C32)<2,"",IF((C32+C31)=0,"",N(C23)/((C32+C31)/2))) | D26: =IF(COUNT(D31,D32)<2,"",IF((D32+D31)=0,"",N(D23)/((D32+D31)/2))) | E26: =IF(COUNT(E31,E32)<2,"",IF((E32+E31)=0,"",N(E23)/((E32+E31)/2))) | F26: =IF(COUNT(F31,F32)<2,"",IF((F32+F31)=0,"",N(F23)/((F32+F31)/2))) | G26: =IF(COUNT(G31,G32)<2,"",IF((G32+G31)=0,"",N(G23)/((G32+G31)/2))) | H26: =IF(COUNT(H31,H32)<2,"",IF((H32+H31)=0,"",N(H23)/((H32+H31)/2))) | I26: =IF(COUNT(I31,I32)<2,"",IF((I32+I31)=0,"",N(I23)/((I32+I31)/2))) | J26: =IF(COUNT(J31,J32)<2,"",IF((J32+J31)=0,"",N(J23)/((J32+J31)/2))) | ... M26: =IF(COUNT(M31,M32)<2,"",IF((M32+M31)=0,"",N(M23)/((M32+M31)/2))) | N26: ϝ
B27: Voluntary Terminations | M27: =IF(COUNT(C27:L27)=0,"",SUM(C27:L27)) | N27: ∑
B28: Involuntary Terminations | M28: =IF(COUNT(C28:L28)=0,"",SUM(C28:L28)) | N28: ∑
B29: Voluntary Turnover (%) | C29: =IF(COUNT(C31,C32)<2,"",IF((C32+C31)=0,"",N(C27)/((C32+C31)/2))) | D29: =IF(COUNT(D31,D32)<2,"",IF((D32+D31)=0,"",N(D27)/((D32+D31)/2))) | E29: =IF(COUNT(E31,E32)<2,"",IF((E32+E31)=0,"",N(E27)/((E32+E31)/2))) | F29: =IF(COUNT(F31,F32)<2,"",IF((F32+F31)=0,"",N(F27)/((F32+F31)/2))) | G29: =IF(COUNT(G31,G32)<2,"",IF((G32+G31)=0,"",N(G27)/((G32+G31)/2))) | H29: =IF(COUNT(H31,H32)<2,"",IF((H32+H31)=0,"",N(H27)/((H32+H31)/2))) | I29: =IF(COUNT(I31,I32)<2,"",IF((I32+I31)=0,"",N(I27)/((I32+I31)/2))) | J29: =IF(COUNT(J31,J32)<2,"",IF((J32+J31)=0,"",N(J27)/((J32+J31)/2))) | ... M29: =IF(COUNT(M31,M32)<2,"",IF((M32+M31)=0,"",N(M27)/((M32+M31)/2))) | N29: ϝ
B30: Involuntary Turnover (%) | C30: =IF(COUNT(C31,C32)<2,"",IF((C32+C31)=0,"",N(C28)/((C32+C31)/2))) | D30: =IF(COUNT(D31,D32)<2,"",IF((D32+D31)=0,"",N(D28)/((D32+D31)/2))) | E30: =IF(COUNT(E31,E32)<2,"",IF((E32+E31)=0,"",N(E28)/((E32+E31)/2))) | F30: =IF(COUNT(F31,F32)<2,"",IF((F32+F31)=0,"",N(F28)/((F32+F31)/2))) | G30: =IF(COUNT(G31,G32)<2,"",IF((G32+G31)=0,"",N(G28)/((G32+G31)/2))) | H30: =IF(COUNT(H31,H32)<2,"",IF((H32+H31)=0,"",N(H28)/((H32+H31)/2))) | I30: =IF(COUNT(I31,I32)<2,"",IF((I32+I31)=0,"",N(I28)/((I32+I31)/2))) | J30: =IF(COUNT(J31,J32)<2,"",IF((J32+J31)=0,"",N(J28)/((J32+J31)/2))) | ... M30: =IF(COUNT(M31,M32)<2,"",IF((M32+M31)=0,"",N(M28)/((M32+M31)/2))) | N30: ϝ
B31: Headcount last Month | C31: =IF(NOV!C5="","",NOV!C5) | D31: =IF(NOV!D5="","",NOV!D5) | E31: =IF(NOV!E5="","",NOV!E5) | F31: =IF(NOV!F5="","",NOV!F5) | G31: =IF(NOV!G5="","",NOV!G5) | H31: =IF(NOV!H5="","",NOV!H5) | I31: =IF(NOV!I5="","",NOV!I5) | J31: =IF(NOV!J5="","",NOV!J5) | ... L31: =IF(NOV!L5="","",NOV!L5) | M31: =IF(COUNT(C31:L31)=0,"",SUM(C31:L31)) | N31: ∑
B32: Headcount this Month | C32: =IF(C5="","",C5) | D32: =IF(D5="","",D5) | E32: =IF(E5="","",E5) | F32: =IF(F5="","",F5) | G32: =IF(G5="","",G5) | H32: =IF(H5="","",H5) | I32: =IF(I5="","",I5) | J32: =IF(J5="","",J5) | ... L32: =IF(L5="","",L5) | M32: =IF(COUNT(C32:L32)=0,"",SUM(C32:L32)) | N32: ∑
B33: Full Turnover (%) | C33: =IF(COUNT(C31,C32)<2,"",IF((C32+C31)=0,"",N(C24)/((C32+C31)/2))) | D33: =IF(COUNT(D31,D32)<2,"",IF((D32+D31)=0,"",N(D24)/((D32+D31)/2))) | E33: =IF(COUNT(E31,E32)<2,"",IF((E32+E31)=0,"",N(E24)/((E32+E31)/2))) | F33: =IF(COUNT(F31,F32)<2,"",IF((F32+F31)=0,"",N(F24)/((F32+F31)/2))) | G33: =IF(COUNT(G31,G32)<2,"",IF((G32+G31)=0,"",N(G24)/((G32+G31)/2))) | H33: =IF(COUNT(H31,H32)<2,"",IF((H32+H31)=0,"",N(H24)/((H32+H31)/2))) | I33: =IF(COUNT(I31,I32)<2,"",IF((I32+I31)=0,"",N(I24)/((I32+I31)/2))) | J33: =IF(COUNT(J31,J32)<2,"",IF((J32+J31)=0,"",N(J24)/((J32+J31)/2))) | ... M33: =IF(COUNT(M31,M32)<2,"",IF((M32+M31)=0,"",N(M24)/((M32+M31)/2))) | N33: ϝ
B34: Permanent Vacancies | M34: =IF(COUNT(C34:L34)=0,"",SUM(C34:L34)) | N34: ∑
B35: Temporary Vacancies | M35: =IF(COUNT(C35:L35)=0,"",SUM(C35:L35)) | N35: ∑
B36: Total Vacancies | C36: =IF(COUNT(C34:C35)=0,"",SUM(C34:C35)) | D36: =IF(COUNT(D34:D35)=0,"",SUM(D34:D35)) | E36: =IF(COUNT(E34:E35)=0,"",SUM(E34:E35)) | F36: =IF(COUNT(F34:F35)=0,"",SUM(F34:F35)) | G36: =IF(COUNT(G34:G35)=0,"",SUM(G34:G35)) | H36: =IF(COUNT(H34:H35)=0,"",SUM(H34:H35)) | I36: =IF(COUNT(I34:I35)=0,"",SUM(I34:I35)) | J36: =IF(COUNT(J34:J35)=0,"",SUM(J34:J35)) | ... M36: =IF(COUNT(M34:M35)=0,"",SUM(M34:M35)) | N36: ϝ
B37: Authorized Positions | C37: =IF(COUNT(C5,C36)=0,"",N(C5)+N(C36)) | D37: =IF(COUNT(D5,D36)=0,"",N(D5)+N(D36)) | E37: =IF(COUNT(E5,E36)=0,"",N(E5)+N(E36)) | F37: =IF(COUNT(F5,F36)=0,"",N(F5)+N(F36)) | G37: =IF(COUNT(G5,G36)=0,"",N(G5)+N(G36)) | H37: =IF(COUNT(H5,H36)=0,"",N(H5)+N(H36)) | I37: =IF(COUNT(I5,I36)=0,"",N(I5)+N(I36)) | J37: =IF(COUNT(J5,J36)=0,"",N(J5)+N(J36)) | ... M37: =IF(COUNT(M5,M36)=0,"",N(M5)+N(M36)) | N37: ϝ
B38: Vacancy Rate (%) | C38: =IFERROR(C36/C37,"") | D38: =IFERROR(D36/D37,"") | E38: =IFERROR(E36/E37,"") | F38: =IFERROR(F36/F37,"") | G38: =IFERROR(G36/G37,"") | H38: =IFERROR(H36/H37,"") | I38: =IFERROR(I36/I37,"") | J38: =IFERROR(J36/J37,"") | ... M38: =IFERROR(M36/M37,"") | N38: ϝ
B39: Permanent TimeToHire (Days) YTD | C39: =IF('(Calloway_AUA)'!$AB$6="","",'(Calloway_AUA)'!$AB$6) | D39: =IF('(Airport_BRB)'!$AB$6="","",'(Airport_BRB)'!$AB$6) | E39: =IF('(GCG_BRB)'!$AB$6="","",'(GCG_BRB)'!$AB$6) | F39: =IF('(Ground_BRB)'!$AB$6="","",'(Ground_BRB)'!$AB$6) | G39: =IF('(GCG_CUR)'!$AB$6="","",'(GCG_CUR)'!$AB$6) | H39: =IF('(Events_CUR)'!$AB$6="","",'(Events_CUR)'!$AB$6) | I39: =IF('(GCG_SXM_Sky)'!$AB$6="","",'(GCG_SXM_Sky)'!$AB$6) | J39: =IF('(GCG_SXM_Airport)'!$AB$6="","",'(GCG_SXM_Airport)'!$AB$6) | K39: =IF('(Allied_TTO)'!$AB$6="","",'(Allied_TTO)'!$AB$6) | L39: =IF('(Katerserv_TTO)'!$AB$6="","",'(Katerserv_TTO)'!$AB$6) | M39: =IFERROR(AVERAGE(C39:L39),"") | N39: Avg
B40: Temporary TimeToHire (Days) YTD | C40: =IF('(Calloway_AUA)'!$AD$6="","",'(Calloway_AUA)'!$AD$6) | D40: =IF('(Airport_BRB)'!$AD$6="","",'(Airport_BRB)'!$AD$6) | E40: =IF('(GCG_BRB)'!$AD$6="","",'(GCG_BRB)'!$AD$6) | F40: =IF('(Ground_BRB)'!$AD$6="","",'(Ground_BRB)'!$AD$6) | G40: =IF('(GCG_CUR)'!$AD$6="","",'(GCG_CUR)'!$AD$6) | H40: =IF('(Events_CUR)'!$AD$6="","",'(Events_CUR)'!$AD$6) | I40: =IF('(GCG_SXM_Sky)'!$AD$6="","",'(GCG_SXM_Sky)'!$AD$6) | J40: =IF('(GCG_SXM_Airport)'!$AD$6="","",'(GCG_SXM_Airport)'!$AD$6) | K40: =IF('(Allied_TTO)'!$AD$6="","",'(Allied_TTO)'!$AD$6) | L40: =IF('(Katerserv_TTO)'!$AD$6="","",'(Katerserv_TTO)'!$AD$6) | M40: =IFERROR(AVERAGE(C40:L40),"") | N40: Avg
...

Sheet JAN
B1: GCG SOUTH CARIBBEAN | C1: 1015 | D1: 1004 | E1: 1063 | F1: 1160 | G1: 1073 | H1: 1042 | I1: 1084 | J1: 1049 | K1: 1005 | L1: 1115
A2: =VALUE(TEXT(EDATE(DATE(LEFT(DEC!A2,4),RIGHT(DEC!A2,2),1),1),"yyyymm")) | B2: JAN | C2: Calloway Aruba | D2: Airport Rest. Barbados | E2: GCG Barbados | F2: GCG Aviation Ground Barbados | G2: GCG Curacao | H2: GCG Events Curacao | I2: GCG Sint Maarten Sky Dining | J2: GCG Sint Maarten Airport Dining | K2: Allied Caterers Trinidad | L2: Katerserv Trinidad | M2: TOTAL | N2: Total by Division | O2: =N(O11)<>0
A3: =+A2 | B3: Permanent (Regular) Headcount | M3: =IF(COUNT(C3:L3)=0,"",SUM(C3:L3)) | N3: ∑
B4: Temporary (Fix Term) Headcount | M4: =IF(COUNT(C4:L4)=0,"",SUM(C4:L4)) | N4: ∑
B5: Employee Headcount (Productivity) | C5: =IF(COUNT(C3:C4)=0,"",SUM(C3:C4)) | D5: =IF(COUNT(D3:D4)=0,"",SUM(D3:D4)) | E5: =IF(COUNT(E3:E4)=0,"",SUM(E3:E4)) | F5: =IF(COUNT(F3:F4)=0,"",SUM(F3:F4)) | G5: =IF(COUNT(G3:G4)=0,"",SUM(G3:G4)) | H5: =IF(COUNT(H3:H4)=0,"",SUM(H3:H4)) | I5: =IF(COUNT(I3:I4)=0,"",SUM(I3:I4)) | J5: =IF(COUNT(J3:J4)=0,"",SUM(J3:J4)) | ... M5: =IF(COUNT(M3:M4)=0,"",SUM(M3:M4)) | N5: ϝ
B6: Headcount = 1.00 | M6: =IF(COUNT(C6:L6)=0,"",SUM(C6:L6)) | N6: ∑
B7: Headcount = 0.75 | M7: =IF(COUNT(C7:L7)=0,"",SUM(C7:L7)) | N7: ∑
B8: Headcount = 0.50 | M8: =IF(COUNT(C8:L8)=0,"",SUM(C8:L8)) | N8: ∑
B9: Headcount = 0.25 | M9: =IF(COUNT(C9:L9)=0,"",SUM(C9:L9)) | N9: ∑
B10: Standard Monthly Hours (FTE basis) | M10: =IFERROR(AVERAGE(C10:L10),"") | N10: Avg
B11: Employee FTE (Finance) | C11: =IF(COUNT(C6:C9)=0,"",N(C6)+N(C7)*0.75+N(C8)*0.5+N(C9)*0.25) | D11: =IF(COUNT(D6:D9)=0,"",N(D6)+N(D7)*0.75+N(D8)*0.5+N(D9)*0.25) | E11: =IF(COUNT(E6:E9)=0,"",N(E6)+N(E7)*0.75+N(E8)*0.5+N(E9)*0.25) | F11: =IF(COUNT(F6:F9)=0,"",N(F6)+N(F7)*0.75+N(F8)*0.5+N(F9)*0.25) | G11: =IF(COUNT(G6:G9)=0,"",N(G6)+N(G7)*0.75+N(G8)*0.5+N(G9)*0.25) | H11: =IF(COUNT(H6:H9)=0,"",N(H6)+N(H7)*0.75+N(H8)*0.5+N(H9)*0.25) | I11: =IF(COUNT(I6:I9)=0,"",N(I6)+N(I7)*0.75+N(I8)*0.5+N(I9)*0.25) | J11: =IF(COUNT(J6:J9)=0,"",N(J6)+N(J7)*0.75+N(J8)*0.5+N(J9)*0.25) | ... M11: =IF(COUNT(M6:M9)=0,"",N(M6)+N(M7)*0.75+N(M8)*0.5+N(M9)*0.25) | N11: FTE | O11: =IF(COUNT(M5:M9)=0,"",N(M6)+N(M7)+N(M8)+N(M9)-N(M5))
B12: Subcontracted Workforce HC | M12: =IF(COUNT(C12:L12)=0,"",SUM(C12:L12)) | N12: ∑
B13: Subcontracted Productive Hours | M13: =IF(COUNT(C13:L13)=0,"",SUM(C13:L13)) | N13: ∑
B14: Subcontracted FTE | C14: =IFERROR(C13/C10,"") | D14: =IFERROR(D13/D10,"") | E14: =IFERROR(E13/E10,"") | F14: =IFERROR(F13/F10,"") | G14: =IFERROR(G13/G10,"") | H14: =IFERROR(H13/H10,"") | I14: =IFERROR(I13/I10,"") | J14: =IFERROR(J13/J10,"") | ... L14: =IFERROR(L13/L10,"") | M14: =IF(COUNT(C14:L14)=0,"",SUM(C14:L14)) | N14: FTE
B15: Total Operational Workforce | C15: =IF(COUNT(C5,C12)=0,"",SUM(C5,C12)) | D15: =IF(COUNT(D5,D12)=0,"",SUM(D5,D12)) | E15: =IF(COUNT(E5,E12)=0,"",SUM(E5,E12)) | F15: =IF(COUNT(F5,F12)=0,"",SUM(F5,F12)) | G15: =IF(COUNT(G5,G12)=0,"",SUM(G5,G12)) | H15: =IF(COUNT(H5,H12)=0,"",SUM(H5,H12)) | I15: =IF(COUNT(I5,I12)=0,"",SUM(I5,I12)) | J15: =IF(COUNT(J5,J12)=0,"",SUM(J5,J12)) | ... M15: =IF(COUNT(M5,M12)=0,"",SUM(M5,M12)) | N15: ϝ
B16: Total Operational FTE | C16: =IF(COUNT(C11,C14)=0,"",SUM(C11,C14)) | D16: =IF(COUNT(D11,D14)=0,"",SUM(D11,D14)) | E16: =IF(COUNT(E11,E14)=0,"",SUM(E11,E14)) | F16: =IF(COUNT(F11,F14)=0,"",SUM(F11,F14)) | G16: =IF(COUNT(G11,G14)=0,"",SUM(G11,G14)) | H16: =IF(COUNT(H11,H14)=0,"",SUM(H11,H14)) | I16: =IF(COUNT(I11,I14)=0,"",SUM(I11,I14)) | J16: =IF(COUNT(J11,J14)=0,"",SUM(J11,J14)) | ... M16: =IF(COUNT(M11,M14)=0,"",SUM(M11,M14)) | N16: FTE
B17: Subcontracted Share of Workforce (%) | C17: =IFERROR(C12/C15,"") | D17: =IFERROR(D12/D15,"") | E17: =IFERROR(E12/E15,"") | F17: =IFERROR(F12/F15,"") | G17: =IFERROR(G12/G15,"") | H17: =IFERROR(H12/H15,"") | I17: =IFERROR(I12/I15,"") | J17: =IFERROR(J12/J15,"") | ... M17: =IFERROR(M12/M15,"") | N17: ϝ
B18: FTE HR Team | M18: =IF(COUNT(C18:L18)=0,"",SUM(C18:L18)) | N18: ∑
B19: Permanent Hires | M19: =IF(COUNT(C19:L19)=0,"",SUM(C19:L19)) | N19: ∑
B20: Temporary Hires | M20: =IF(COUNT(C20:L20)=0,"",SUM(C20:L20)) | N20: ∑
B21: Total Hires | C21: =IF(COUNT(C19:C20)=0,"",SUM(C19:C20)) | D21: =IF(COUNT(D19:D20)=0,"",SUM(D19:D20)) | E21: =IF(COUNT(E19:E20)=0,"",SUM(E19:E20)) | F21: =IF(COUNT(F19:F20)=0,"",SUM(F19:F20)) | G21: =IF(COUNT(G19:G20)=0,"",SUM(G19:G20)) | H21: =IF(COUNT(H19:H20)=0,"",SUM(H19:H20)) | I21: =IF(COUNT(I19:I20)=0,"",SUM(I19:I20)) | J21: =IF(COUNT(J19:J20)=0,"",SUM(J19:J20)) | ... M21: =IF(COUNT(M19:M20)=0,"",SUM(M19:M20)) | N21: ϝ
B22: Permanent Exits | M22: =IF(COUNT(C22:L22)=0,"",SUM(C22:L22)) | N22: ∑
B23: Temporary Exits | M23: =IF(COUNT(C23:L23)=0,"",SUM(C23:L23)) | N23: ∑
B24: Total Exits | C24: =IF(COUNT(C22:C23)=0,"",SUM(C22:C23)) | D24: =IF(COUNT(D22:D23)=0,"",SUM(D22:D23)) | E24: =IF(COUNT(E22:E23)=0,"",SUM(E22:E23)) | F24: =IF(COUNT(F22:F23)=0,"",SUM(F22:F23)) | G24: =IF(COUNT(G22:G23)=0,"",SUM(G22:G23)) | H24: =IF(COUNT(H22:H23)=0,"",SUM(H22:H23)) | I24: =IF(COUNT(I22:I23)=0,"",SUM(I22:I23)) | J24: =IF(COUNT(J22:J23)=0,"",SUM(J22:J23)) | ... M24: =IF(COUNT(M22:M23)=0,"",SUM(M22:M23)) | N24: ϝ
B25: Permanent Turnover (%) | C25: =IF(COUNT(C31,C32)<2,"",IF((C32+C31)=0,"",N(C22)/((C32+C31)/2))) | D25: =IF(COUNT(D31,D32)<2,"",IF((D32+D31)=0,"",N(D22)/((D32+D31)/2))) | E25: =IF(COUNT(E31,E32)<2,"",IF((E32+E31)=0,"",N(E22)/((E32+E31)/2))) | F25: =IF(COUNT(F31,F32)<2,"",IF((F32+F31)=0,"",N(F22)/((F32+F31)/2))) | G25: =IF(COUNT(G31,G32)<2,"",IF((G32+G31)=0,"",N(G22)/((G32+G31)/2))) | H25: =IF(COUNT(H31,H32)<2,"",IF((H32+H31)=0,"",N(H22)/((H32+H31)/2))) | I25: =IF(COUNT(I31,I32)<2,"",IF((I32+I31)=0,"",N(I22)/((I32+I31)/2))) | J25: =IF(COUNT(J31,J32)<2,"",IF((J32+J31)=0,"",N(J22)/((J32+J31)/2))) | ... M25: =IF(COUNT(M31,M32)<2,"",IF((M32+M31)=0,"",N(M22)/((M32+M31)/2))) | N25: ϝ
