Workbook

Sheet Quarter
B1: GCG HDQ
A2: FY2027 | B2: Quarter | C2: OCT | D2: NOV | E2: DEC | F2: ∑Q1 | G2: JAN | H2: FEB | I2: MAR | J2: ∑Q2 | K2: APR | L2: MAY | M2: JUN | N2: ∑Q3 | O2: JUL | P2: AUG | Q2: SEP | R2: ∑Q4 | S2: FY2027
B3: Permanent (Regular) Headcount | C3: =OCT!D3 | D3: =NOV!D3 | E3: =DEC!D3 | F3: =IFERROR(AVERAGE(C3:E3),"") | G3: =JAN!D3 | H3: =FEB!D3 | I3: =MAR!D3 | J3: =IFERROR(AVERAGE(G3:I3),"") | K3: =APR!D3 | L3: =MAY!D3 | M3: =JUN!D3 | N3: =IFERROR(AVERAGE(K3:M3),"") | O3: =JUL!D3 | P3: =AUG!D3 | Q3: =SEP!D3 | R3: =IFERROR(AVERAGE(O3:Q3),"") | S3: =IFERROR(AVERAGE(C3:E3,G3:I3,K3:M3,O3:Q3),"")
B4: Temporary (Fix Term) Headcount | C4: =OCT!D4 | D4: =NOV!D4 | E4: =DEC!D4 | F4: =IFERROR(AVERAGE(C4:E4),"") | G4: =JAN!D4 | H4: =FEB!D4 | I4: =MAR!D4 | J4: =IFERROR(AVERAGE(G4:I4),"") | K4: =APR!D4 | L4: =MAY!D4 | M4: =JUN!D4 | N4: =IFERROR(AVERAGE(K4:M4),"") | O4: =JUL!D4 | P4: =AUG!D4 | Q4: =SEP!D4 | R4: =IFERROR(AVERAGE(O4:Q4),"") | S4: =IFERROR(AVERAGE(C4:E4,G4:I4,K4:M4,O4:Q4),"")
B5: Employee Headcount (Productivity) | C5: =OCT!D5 | D5: =NOV!D5 | E5: =DEC!D5 | F5: =IF(COUNT(F3:F4)=0,"",SUM(F3:F4)) | G5: =JAN!D5 | H5: =FEB!D5 | I5: =MAR!D5 | J5: =IF(COUNT(J3:J4)=0,"",SUM(J3:J4)) | K5: =APR!D5 | L5: =MAY!D5 | M5: =JUN!D5 | N5: =IF(COUNT(N3:N4)=0,"",SUM(N3:N4)) | O5: =JUL!D5 | P5: =AUG!D5 | Q5: =SEP!D5 | R5: =IF(COUNT(R3:R4)=0,"",SUM(R3:R4)) | S5: =IF(COUNT(S3:S4)=0,"",SUM(S3:S4))
B6: Headcount = 1.00 | C6: =OCT!D6 | D6: =NOV!D6 | E6: =DEC!D6 | F6: =IFERROR(AVERAGE(C6:E6),"") | G6: =JAN!D6 | H6: =FEB!D6 | I6: =MAR!D6 | J6: =IFERROR(AVERAGE(G6:I6),"") | K6: =APR!D6 | L6: =MAY!D6 | M6: =JUN!D6 | N6: =IFERROR(AVERAGE(K6:M6),"") | O6: =JUL!D6 | P6: =AUG!D6 | Q6: =SEP!D6 | R6: =IFERROR(AVERAGE(O6:Q6),"") | S6: =IFERROR(AVERAGE(C6:E6,G6:I6,K6:M6,O6:Q6),"")
B7: Headcount = 0.75 | C7: =OCT!D7 | D7: =NOV!D7 | E7: =DEC!D7 | F7: =IFERROR(AVERAGE(C7:E7),"") | G7: =JAN!D7 | H7: =FEB!D7 | I7: =MAR!D7 | J7: =IFERROR(AVERAGE(G7:I7),"") | K7: =APR!D7 | L7: =MAY!D7 | M7: =JUN!D7 | N7: =IFERROR(AVERAGE(K7:M7),"") | O7: =JUL!D7 | P7: =AUG!D7 | Q7: =SEP!D7 | R7: =IFERROR(AVERAGE(O7:Q7),"") | S7: =IFERROR(AVERAGE(C7:E7,G7:I7,K7:M7,O7:Q7),"")
B8: Headcount = 0.50 | C8: =OCT!D8 | D8: =NOV!D8 | E8: =DEC!D8 | F8: =IFERROR(AVERAGE(C8:E8),"") | G8: =JAN!D8 | H8: =FEB!D8 | I8: =MAR!D8 | J8: =IFERROR(AVERAGE(G8:I8),"") | K8: =APR!D8 | L8: =MAY!D8 | M8: =JUN!D8 | N8: =IFERROR(AVERAGE(K8:M8),"") | O8: =JUL!D8 | P8: =AUG!D8 | Q8: =SEP!D8 | R8: =IFERROR(AVERAGE(O8:Q8),"") | S8: =IFERROR(AVERAGE(C8:E8,G8:I8,K8:M8,O8:Q8),"")
B9: Headcount = 0.25 | C9: =OCT!D9 | D9: =NOV!D9 | E9: =DEC!D9 | F9: =IFERROR(AVERAGE(C9:E9),"") | G9: =JAN!D9 | H9: =FEB!D9 | I9: =MAR!D9 | J9: =IFERROR(AVERAGE(G9:I9),"") | K9: =APR!D9 | L9: =MAY!D9 | M9: =JUN!D9 | N9: =IFERROR(AVERAGE(K9:M9),"") | O9: =JUL!D9 | P9: =AUG!D9 | Q9: =SEP!D9 | R9: =IFERROR(AVERAGE(O9:Q9),"") | S9: =IFERROR(AVERAGE(C9:E9,G9:I9,K9:M9,O9:Q9),"")
B10: Standard Monthly Hours (FTE basis) | C10: =OCT!D10 | D10: =NOV!D10 | E10: =DEC!D10 | F10: =IFERROR(AVERAGE(C10:E10),"") | G10: =JAN!D10 | H10: =FEB!D10 | I10: =MAR!D10 | J10: =IFERROR(AVERAGE(G10:I10),"") | K10: =APR!D10 | L10: =MAY!D10 | M10: =JUN!D10 | N10: =IFERROR(AVERAGE(K10:M10),"") | O10: =JUL!D10 | P10: =AUG!D10 | Q10: =SEP!D10 | R10: =IFERROR(AVERAGE(O10:Q10),"") | S10: =IFERROR(AVERAGE(C10:E10,G10:I10,K10:M10,O10:Q10),"")
B11: Employee FTE (Finance) | C11: =OCT!D11 | D11: =NOV!D11 | E11: =DEC!D11 | F11: =IF(COUNT(F6:F9)=0,"",N(F6)+N(F7)*0.75+N(F8)*0.5+N(F9)*0.25) | G11: =JAN!D11 | H11: =FEB!D11 | I11: =MAR!D11 | J11: =IF(COUNT(J6:J9)=0,"",N(J6)+N(J7)*0.75+N(J8)*0.5+N(J9)*0.25) | K11: =APR!D11 | L11: =MAY!D11 | M11: =JUN!D11 | N11: =IF(COUNT(N6:N9)=0,"",N(N6)+N(N7)*0.75+N(N8)*0.5+N(N9)*0.25) | O11: =JUL!D11 | P11: =AUG!D11 | Q11: =SEP!D11 | R11: =IF(COUNT(R6:R9)=0,"",N(R6)+N(R7)*0.75+N(R8)*0.5+N(R9)*0.25) | S11: =IF(COUNT(S6:S9)=0,"",N(S6)+N(S7)*0.75+N(S8)*0.5+N(S9)*0.25)
B12: Subcontracted Workforce HC | C12: =OCT!D12 | D12: =NOV!D12 | E12: =DEC!D12 | F12: =IFERROR(AVERAGE(C12:E12),"") | G12: =JAN!D12 | H12: =FEB!D12 | I12: =MAR!D12 | J12: =IFERROR(AVERAGE(G12:I12),"") | K12: =APR!D12 | L12: =MAY!D12 | M12: =JUN!D12 | N12: =IFERROR(AVERAGE(K12:M12),"") | O12: =JUL!D12 | P12: =AUG!D12 | Q12: =SEP!D12 | R12: =IFERROR(AVERAGE(O12:Q12),"") | S12: =IFERROR(AVERAGE(C12:E12,G12:I12,K12:M12,O12:Q12),"")
B13: Subcontracted Productive Hours | C13: =OCT!D13 | D13: =NOV!D13 | E13: =DEC!D13 | F13: =IFERROR(AVERAGE(C13:E13),"") | G13: =JAN!D13 | H13: =FEB!D13 | I13: =MAR!D13 | J13: =IFERROR(AVERAGE(G13:I13),"") | K13: =APR!D13 | L13: =MAY!D13 | M13: =JUN!D13 | N13: =IFERROR(AVERAGE(K13:M13),"") | O13: =JUL!D13 | P13: =AUG!D13 | Q13: =SEP!D13 | R13: =IFERROR(AVERAGE(O13:Q13),"") | S13: =IFERROR(AVERAGE(C13:E13,G13:I13,K13:M13,O13:Q13),"")
B14: Subcontracted FTE | C14: =OCT!D14 | D14: =NOV!D14 | E14: =DEC!D14 | F14: =IFERROR(F13/F10,"") | G14: =JAN!D14 | H14: =FEB!D14 | I14: =MAR!D14 | J14: =IFERROR(J13/J10,"") | K14: =APR!D14 | L14: =MAY!D14 | M14: =JUN!D14 | N14: =IFERROR(N13/N10,"") | O14: =JUL!D14 | P14: =AUG!D14 | Q14: =SEP!D14 | R14: =IFERROR(R13/R10,"") | S14: =IFERROR(S13/S10,"")
B15: Total Operational Workforce | C15: =OCT!D15 | D15: =NOV!D15 | E15: =DEC!D15 | F15: =IF(COUNT(F5,F12)=0,"",SUM(F5,F12)) | G15: =JAN!D15 | H15: =FEB!D15 | I15: =MAR!D15 | J15: =IF(COUNT(J5,J12)=0,"",SUM(J5,J12)) | K15: =APR!D15 | L15: =MAY!D15 | M15: =JUN!D15 | N15: =IF(COUNT(N5,N12)=0,"",SUM(N5,N12)) | O15: =JUL!D15 | P15: =AUG!D15 | Q15: =SEP!D15 | R15: =IF(COUNT(R5,R12)=0,"",SUM(R5,R12)) | S15: =IF(COUNT(S5,S12)=0,"",SUM(S5,S12))
B16: Total Operational FTE | C16: =OCT!D16 | D16: =NOV!D16 | E16: =DEC!D16 | F16: =IF(COUNT(F11,F14)=0,"",SUM(F11,F14)) | G16: =JAN!D16 | H16: =FEB!D16 | I16: =MAR!D16 | J16: =IF(COUNT(J11,J14)=0,"",SUM(J11,J14)) | K16: =APR!D16 | L16: =MAY!D16 | M16: =JUN!D16 | N16: =IF(COUNT(N11,N14)=0,"",SUM(N11,N14)) | O16: =JUL!D16 | P16: =AUG!D16 | Q16: =SEP!D16 | R16: =IF(COUNT(R11,R14)=0,"",SUM(R11,R14)) | S16: =IF(COUNT(S11,S14)=0,"",SUM(S11,S14))
B17: Subcontracted Share of Workforce (%) | C17: =OCT!D17 | D17: =NOV!D17 | E17: =DEC!D17 | F17: =IFERROR(F12/F15,"") | G17: =JAN!D17 | H17: =FEB!D17 | I17: =MAR!D17 | J17: =IFERROR(J12/J15,"") | K17: =APR!D17 | L17: =MAY!D17 | M17: =JUN!D17 | N17: =IFERROR(N12/N15,"") | O17: =JUL!D17 | P17: =AUG!D17 | Q17: =SEP!D17 | R17: =IFERROR(R12/R15,"") | S17: =IFERROR(S12/S15,"")
B18: FTE HR Team | C18: =OCT!D18 | D18: =NOV!D18 | E18: =DEC!D18 | F18: =IFERROR(AVERAGE(C18:E18),"") | G18: =JAN!D18 | H18: =FEB!D18 | I18: =MAR!D18 | J18: =IFERROR(AVERAGE(G18:I18),"") | K18: =APR!D18 | L18: =MAY!D18 | M18: =JUN!D18 | N18: =IFERROR(AVERAGE(K18:M18),"") | O18: =JUL!D18 | P18: =AUG!D18 | Q18: =SEP!D18 | R18: =IFERROR(AVERAGE(O18:Q18),"") | S18: =IFERROR(AVERAGE(C18:E18,G18:I18,K18:M18,O18:Q18),"")
B19: Permanent Hires | C19: =OCT!D19 | D19: =NOV!D19 | E19: =DEC!D19 | F19: =IF(COUNT(C19:E19)=0,"",SUM(C19:E19)) | G19: =JAN!D19 | H19: =FEB!D19 | I19: =MAR!D19 | J19: =IF(COUNT(G19:I19)=0,"",SUM(G19:I19)) | K19: =APR!D19 | L19: =MAY!D19 | M19: =JUN!D19 | N19: =IF(COUNT(K19:M19)=0,"",SUM(K19:M19)) | O19: =JUL!D19 | P19: =AUG!D19 | Q19: =SEP!D19 | R19: =IF(COUNT(O19:Q19)=0,"",SUM(O19:Q19)) | S19: =IF(COUNT(C19:E19,G19:I19,K19:M19,O19:Q19)=0,"",SUM(C19:E19,G19:I19,K19:M19,O19:Q19))
B20: Temporary Hires | C20: =OCT!D20 | D20: =NOV!D20 | E20: =DEC!D20 | F20: =IF(COUNT(C20:E20)=0,"",SUM(C20:E20)) | G20: =JAN!D20 | H20: =FEB!D20 | I20: =MAR!D20 | J20: =IF(COUNT(G20:I20)=0,"",SUM(G20:I20)) | K20: =APR!D20 | L20: =MAY!D20 | M20: =JUN!D20 | N20: =IF(COUNT(K20:M20)=0,"",SUM(K20:M20)) | O20: =JUL!D20 | P20: =AUG!D20 | Q20: =SEP!D20 | R20: =IF(COUNT(O20:Q20)=0,"",SUM(O20:Q20)) | S20: =IF(COUNT(C20:E20,G20:I20,K20:M20,O20:Q20)=0,"",SUM(C20:E20,G20:I20,K20:M20,O20:Q20))
B21: Total Hires | C21: =OCT!D21 | D21: =NOV!D21 | E21: =DEC!D21 | F21: =IF(COUNT(F19:F20)=0,"",SUM(F19:F20)) | G21: =JAN!D21 | H21: =FEB!D21 | I21: =MAR!D21 | J21: =IF(COUNT(J19:J20)=0,"",SUM(J19:J20)) | K21: =APR!D21 | L21: =MAY!D21 | M21: =JUN!D21 | N21: =IF(COUNT(N19:N20)=0,"",SUM(N19:N20)) | O21: =JUL!D21 | P21: =AUG!D21 | Q21: =SEP!D21 | R21: =IF(COUNT(R19:R20)=0,"",SUM(R19:R20)) | S21: =IF(COUNT(S19:S20)=0,"",SUM(S19:S20))
B22: Permanent Exits | C22: =OCT!D22 | D22: =NOV!D22 | E22: =DEC!D22 | F22: =IF(COUNT(C22:E22)=0,"",SUM(C22:E22)) | G22: =JAN!D22 | H22: =FEB!D22 | I22: =MAR!D22 | J22: =IF(COUNT(G22:I22)=0,"",SUM(G22:I22)) | K22: =APR!D22 | L22: =MAY!D22 | M22: =JUN!D22 | N22: =IF(COUNT(K22:M22)=0,"",SUM(K22:M22)) | O22: =JUL!D22 | P22: =AUG!D22 | Q22: =SEP!D22 | R22: =IF(COUNT(O22:Q22)=0,"",SUM(O22:Q22)) | S22: =IF(COUNT(C22:E22,G22:I22,K22:M22,O22:Q22)=0,"",SUM(C22:E22,G22:I22,K22:M22,O22:Q22))
B23: Temporary Exits | C23: =OCT!D23 | D23: =NOV!D23 | E23: =DEC!D23 | F23: =IF(COUNT(C23:E23)=0,"",SUM(C23:E23)) | G23: =JAN!D23 | H23: =FEB!D23 | I23: =MAR!D23 | J23: =IF(COUNT(G23:I23)=0,"",SUM(G23:I23)) | K23: =APR!D23 | L23: =MAY!D23 | M23: =JUN!D23 | N23: =IF(COUNT(K23:M23)=0,"",SUM(K23:M23)) | O23: =JUL!D23 | P23: =AUG!D23 | Q23: =SEP!D23 | R23: =IF(COUNT(O23:Q23)=0,"",SUM(O23:Q23)) | S23: =IF(COUNT(C23:E23,G23:I23,K23:M23,O23:Q23)=0,"",SUM(C23:E23,G23:I23,K23:M23,O23:Q23))
B24: Total Exits | C24: =OCT!D24 | D24: =NOV!D24 | E24: =DEC!D24 | F24: =IF(COUNT(F22:F23)=0,"",SUM(F22:F23)) | G24: =JAN!D24 | H24: =FEB!D24 | I24: =MAR!D24 | J24: =IF(COUNT(J22:J23)=0,"",SUM(J22:J23)) | K24: =APR!D24 | L24: =MAY!D24 | M24: =JUN!D24 | N24: =IF(COUNT(N22:N23)=0,"",SUM(N22:N23)) | O24: =JUL!D24 | P24: =AUG!D24 | Q24: =SEP!D24 | R24: =IF(COUNT(R22:R23)=0,"",SUM(R22:R23)) | S24: =IF(COUNT(S22:S23)=0,"",SUM(S22:S23))
B25: Permanent Turnover (%) | C25: =OCT!D25 | D25: =NOV!D25 | E25: =DEC!D25 | F25: =IF(COUNT(F31,F32)<2,"",IF((F32+F31)=0,"",N(F22)/((F32+F31)/2))) | G25: =JAN!D25 | H25: =FEB!D25 | I25: =MAR!D25 | J25: =IF(COUNT(J31,J32)<2,"",IF((J32+J31)=0,"",N(J22)/((J32+J31)/2))) | K25: =APR!D25 | L25: =MAY!D25 | M25: =JUN!D25 | N25: =IF(COUNT(N31,N32)<2,"",IF((N32+N31)=0,"",N(N22)/((N32+N31)/2))) | O25: =JUL!D25 | P25: =AUG!D25 | Q25: =SEP!D25 | R25: =IF(COUNT(R31,R32)<2,"",IF((R32+R31)=0,"",N(R22)/((R32+R31)/2))) | S25: =IF(COUNT(S31,S32)<2,"",IF((S32+S31)=0,"",N(S22)/((S32+S31)/2)))
B26: Temporary Turnover (%) | C26: =OCT!D26 | D26: =NOV!D26 | E26: =DEC!D26 | F26: =IF(COUNT(F31,F32)<2,"",IF((F32+F31)=0,"",N(F23)/((F32+F31)/2))) | G26: =JAN!D26 | H26: =FEB!D26 | I26: =MAR!D26 | J26: =IF(COUNT(J31,J32)<2,"",IF((J32+J31)=0,"",N(J23)/((J32+J31)/2))) | K26: =APR!D26 | L26: =MAY!D26 | M26: =JUN!D26 | N26: =IF(COUNT(N31,N32)<2,"",IF((N32+N31)=0,"",N(N23)/((N32+N31)/2))) | O26: =JUL!D26 | P26: =AUG!D26 | Q26: =SEP!D26 | R26: =IF(COUNT(R31,R32)<2,"",IF((R32+R31)=0,"",N(R23)/((R32+R31)/2))) | S26: =IF(COUNT(S31,S32)<2,"",IF((S32+S31)=0,"",N(S23)/((S32+S31)/2)))
B27: Voluntary Terminations | C27: =OCT!D27 | D27: =NOV!D27 | E27: =DEC!D27 | F27: =IF(COUNT(C27:E27)=0,"",SUM(C27:E27)) | G27: =JAN!D27 | H27: =FEB!D27 | I27: =MAR!D27 | J27: =IF(COUNT(G27:I27)=0,"",SUM(G27:I27)) | K27: =APR!D27 | L27: =MAY!D27 | M27: =JUN!D27 | N27: =IF(COUNT(K27:M27)=0,"",SUM(K27:M27)) | O27: =JUL!D27 | P27: =AUG!D27 | Q27: =SEP!D27 | R27: =IF(COUNT(O27:Q27)=0,"",SUM(O27:Q27)) | S27: =IF(COUNT(C27:E27,G27:I27,K27:M27,O27:Q27)=0,"",SUM(C27:E27,G27:I27,K27:M27,O27:Q27))
B28: Involuntary Terminations | C28: =OCT!D28 | D28: =NOV!D28 | E28: =DEC!D28 | F28: =IF(COUNT(C28:E28)=0,"",SUM(C28:E28)) | G28: =JAN!D28 | H28: =FEB!D28 | I28: =MAR!D28 | J28: =IF(COUNT(G28:I28)=0,"",SUM(G28:I28)) | K28: =APR!D28 | L28: =MAY!D28 | M28: =JUN!D28 | N28: =IF(COUNT(K28:M28)=0,"",SUM(K28:M28)) | O28: =JUL!D28 | P28: =AUG!D28 | Q28: =SEP!D28 | R28: =IF(COUNT(O28:Q28)=0,"",SUM(O28:Q28)) | S28: =IF(COUNT(C28:E28,G28:I28,K28:M28,O28:Q28)=0,"",SUM(C28:E28,G28:I28,K28:M28,O28:Q28))
B29: Voluntary Turnover (%) | C29: =OCT!D29 | D29: =NOV!D29 | E29: =DEC!D29 | F29: =IF(COUNT(F31,F32)<2,"",IF((F32+F31)=0,"",N(F27)/((F32+F31)/2))) | G29: =JAN!D29 | H29: =FEB!D29 | I29: =MAR!D29 | J29: =IF(COUNT(J31,J32)<2,"",IF((J32+J31)=0,"",N(J27)/((J32+J31)/2))) | K29: =APR!D29 | L29: =MAY!D29 | M29: =JUN!D29 | N29: =IF(COUNT(N31,N32)<2,"",IF((N32+N31)=0,"",N(N27)/((N32+N31)/2))) | O29: =JUL!D29 | P29: =AUG!D29 | Q29: =SEP!D29 | R29: =IF(COUNT(R31,R32)<2,"",IF((R32+R31)=0,"",N(R27)/((R32+R31)/2))) | S29: =IF(COUNT(S31,S32)<2,"",IF((S32+S31)=0,"",N(S27)/((S32+S31)/2)))
B30: Involuntary Turnover (%) | C30: =OCT!D30 | D30: =NOV!D30 | E30: =DEC!D30 | F30: =IF(COUNT(F31,F32)<2,"",IF((F32+F31)=0,"",N(F28)/((F32+F31)/2))) | G30: =JAN!D30 | H30: =FEB!D30 | I30: =MAR!D30 | J30: =IF(COUNT(J31,J32)<2,"",IF((J32+J31)=0,"",N(J28)/((J32+J31)/2))) | K30: =APR!D30 | L30: =MAY!D30 | M30: =JUN!D30 | N30: =IF(COUNT(N31,N32)<2,"",IF((N32+N31)=0,"",N(N28)/((N32+N31)/2))) | O30: =JUL!D30 | P30: =AUG!D30 | Q30: =SEP!D30 | R30: =IF(COUNT(R31,R32)<2,"",IF((R32+R31)=0,"",N(R28)/((R32+R31)/2))) | S30: =IF(COUNT(S31,S32)<2,"",IF((S32+S31)=0,"",N(S28)/((S32+S31)/2)))
B31: Headcount last Month | C31: =OCT!D31 | D31: =NOV!D31 | E31: =DEC!D31 | F31: =IFERROR(AVERAGE(C31:E31),"") | G31: =JAN!D31 | H31: =FEB!D31 | I31: =MAR!D31 | J31: =IFERROR(AVERAGE(G31:I31),"") | K31: =APR!D31 | L31: =MAY!D31 | M31: =JUN!D31 | N31: =IFERROR(AVERAGE(K31:M31),"") | O31: =JUL!D31 | P31: =AUG!D31 | Q31: =SEP!D31 | R31: =IFERROR(AVERAGE(O31:Q31),"") | S31: =IFERROR(AVERAGE(C31:E31,G31:I31,K31:M31,O31:Q31),"")
B32: Headcount this Month | C32: =OCT!D32 | D32: =NOV!D32 | E32: =DEC!D32 | F32: =IFERROR(AVERAGE(C32:E32),"") | G32: =JAN!D32 | H32: =FEB!D32 | I32: =MAR!D32 | J32: =IFERROR(AVERAGE(G32:I32),"") | K32: =APR!D32 | L32: =MAY!D32 | M32: =JUN!D32 | N32: =IFERROR(AVERAGE(K32:M32),"") | O32: =JUL!D32 | P32: =AUG!D32 | Q32: =SEP!D32 | R32: =IFERROR(AVERAGE(O32:Q32),"") | S32: =IFERROR(AVERAGE(C32:E32,G32:I32,K32:M32,O32:Q32),"")
B33: Full Turnover (%) | C33: =OCT!D33 | D33: =NOV!D33 | E33: =DEC!D33 | F33: =IF(COUNT(F31,F32)<2,"",IF((F32+F31)=0,"",N(F24)/((F32+F31)/2))) | G33: =JAN!D33 | H33: =FEB!D33 | I33: =MAR!D33 | J33: =IF(COUNT(J31,J32)<2,"",IF((J32+J31)=0,"",N(J24)/((J32+J31)/2))) | K33: =APR!D33 | L33: =MAY!D33 | M33: =JUN!D33 | N33: =IF(COUNT(N31,N32)<2,"",IF((N32+N31)=0,"",N(N24)/((N32+N31)/2))) | O33: =JUL!D33 | P33: =AUG!D33 | Q33: =SEP!D33 | R33: =IF(COUNT(R31,R32)<2,"",IF((R32+R31)=0,"",N(R24)/((R32+R31)/2))) | S33: =IF(COUNT(S31,S32)<2,"",IF((S32+S31)=0,"",N(S24)/((S32+S31)/2)))
B34: Permanent Vacancies | C34: =OCT!D34 | D34: =NOV!D34 | E34: =DEC!D34 | F34: =IFERROR(AVERAGE(C34:E34),"") | G34: =JAN!D34 | H34: =FEB!D34 | I34: =MAR!D34 | J34: =IFERROR(AVERAGE(G34:I34),"") | K34: =APR!D34 | L34: =MAY!D34 | M34: =JUN!D34 | N34: =IFERROR(AVERAGE(K34:M34),"") | O34: =JUL!D34 | P34: =AUG!D34 | Q34: =SEP!D34 | R34: =IFERROR(AVERAGE(O34:Q34),"") | S34: =IFERROR(AVERAGE(C34:E34,G34:I34,K34:M34,O34:Q34),"")
B35: Temporary Vacancies | C35: =OCT!D35 | D35: =NOV!D35 | E35: =DEC!D35 | F35: =IFERROR(AVERAGE(C35:E35),"") | G35: =JAN!D35 | H35: =FEB!D35 | I35: =MAR!D35 | J35: =IFERROR(AVERAGE(G35:I35),"") | K35: =APR!D35 | L35: =MAY!D35 | M35: =JUN!D35 | N35: =IFERROR(AVERAGE(K35:M35),"") | O35: =JUL!D35 | P35: =AUG!D35 | Q35: =SEP!D35 | R35: =IFERROR(AVERAGE(O35:Q35),"") | S35: =IFERROR(AVERAGE(C35:E35,G35:I35,K35:M35,O35:Q35),"")
B36: Total Vacancies | C36: =OCT!D36 | D36: =NOV!D36 | E36: =DEC!D36 | F36: =IF(COUNT(F34:F35)=0,"",SUM(F34:F35)) | G36: =JAN!D36 | H36: =FEB!D36 | I36: =MAR!D36 | J36: =IF(COUNT(J34:J35)=0,"",SUM(J34:J35)) | K36: =APR!D36 | L36: =MAY!D36 | M36: =JUN!D36 | N36: =IF(COUNT(N34:N35)=0,"",SUM(N34:N35)) | O36: =JUL!D36 | P36: =AUG!D36 | Q36: =SEP!D36 | R36: =IF(COUNT(R34:R35)=0,"",SUM(R34:R35)) | S36: =IF(COUNT(S34:S35)=0,"",SUM(S34:S35))
B37: Authorized Positions | C37: =OCT!D37 | D37: =NOV!D37 | E37: =DEC!D37 | F37: =IF(COUNT(F5,F36)=0,"",N(F5)+N(F36)) | G37: =JAN!D37 | H37: =FEB!D37 | I37: =MAR!D37 | J37: =IF(COUNT(J5,J36)=0,"",N(J5)+N(J36)) | K37: =APR!D37 | L37: =MAY!D37 | M37: =JUN!D37 | N37: =IF(COUNT(N5,N36)=0,"",N(N5)+N(N36)) | O37: =JUL!D37 | P37: =AUG!D37 | Q37: =SEP!D37 | R37: =IF(COUNT(R5,R36)=0,"",N(R5)+N(R36)) | S37: =IF(COUNT(S5,S36)=0,"",N(S5)+N(S36))
B38: Vacancy Rate (%) | C38: =OCT!D38 | D38: =NOV!D38 | E38: =DEC!D38 | F38: =IFERROR(F36/F37,"") | G38: =JAN!D38 | H38: =FEB!D38 | I38: =MAR!D38 | J38: =IFERROR(J36/J37,"") | K38: =APR!D38 | L38: =MAY!D38 | M38: =JUN!D38 | N38: =IFERROR(N36/N37,"") | O38: =JUL!D38 | P38: =AUG!D38 | Q38: =SEP!D38 | R38: =IFERROR(R36/R37,"") | S38: =IFERROR(S36/S37,"")
B39: Permanent TimeToHire (Days) YTD | C39: =OCT!D39 | D39: =NOV!D39 | E39: =DEC!D39 | F39: =IFERROR(LOOKUP(2,1/ISNUMBER(C39:E39),C39:E39),"") | G39: =JAN!D39 | H39: =FEB!D39 | I39: =MAR!D39 | J39: =IFERROR(LOOKUP(2,1/ISNUMBER(G39:I39),G39:I39),"") | K39: =APR!D39 | L39: =MAY!D39 | M39: =JUN!D39 | N39: =IFERROR(LOOKUP(2,1/ISNUMBER(K39:M39),K39:M39),"") | O39: =JUL!D39 | P39: =AUG!D39 | Q39: =SEP!D39 | R39: =IFERROR(LOOKUP(2,1/ISNUMBER(O39:Q39),O39:Q39),"") | S39: =IFERROR(LOOKUP(2,1/ISNUMBER(C39:Q39),C39:Q39),"")
B40: Temporary TimeToHire (Days) YTD | C40: =OCT!D40 | D40: =NOV!D40 | E40: =DEC!D40 | F40: =IFERROR(LOOKUP(2,1/ISNUMBER(C40:E40),C40:E40),"") | G40: =JAN!D40 | H40: =FEB!D40 | I40: =MAR!D40 | J40: =IFERROR(LOOKUP(2,1/ISNUMBER(G40:I40),G40:I40),"") | K40: =APR!D40 | L40: =MAY!D40 | M40: =JUN!D40 | N40: =IFERROR(LOOKUP(2,1/ISNUMBER(K40:M40),K40:M40),"") | O40: =JUL!D40 | P40: =AUG!D40 | Q40: =SEP!D40 | R40: =IFERROR(LOOKUP(2,1/ISNUMBER(O40:Q40),O40:Q40),"") | S40: =IFERROR(LOOKUP(2,1/ISNUMBER(C40:Q40),C40:Q40),"")
...

Sheet OCT
B1: GCG HDQ | C1: 1079
A2: 202610 | B2: OCT | C2: GCG HDQ | D2: TOTAL | E2: Total by Division | F2: =N(F11)<>0
A3: =+A2 | B3: Permanent (Regular) Headcount | D3: =IF(COUNT(C3:C3)=0,"",SUM(C3:C3)) | E3: ∑
B4: Temporary (Fix Term) Headcount | D4: =IF(COUNT(C4:C4)=0,"",SUM(C4:C4)) | E4: ∑
B5: Employee Headcount (Productivity) | C5: =IF(COUNT(C3:C4)=0,"",SUM(C3:C4)) | D5: =IF(COUNT(D3:D4)=0,"",SUM(D3:D4)) | E5: ϝ
B6: Headcount = 1.00 | D6: =IF(COUNT(C6:C6)=0,"",SUM(C6:C6)) | E6: ∑
B7: Headcount = 0.75 | D7: =IF(COUNT(C7:C7)=0,"",SUM(C7:C7)) | E7: ∑
B8: Headcount = 0.50 | D8: =IF(COUNT(C8:C8)=0,"",SUM(C8:C8)) | E8: ∑
B9: Headcount = 0.25 | D9: =IF(COUNT(C9:C9)=0,"",SUM(C9:C9)) | E9: ∑
B10: Standard Monthly Hours (FTE basis) | D10: =IFERROR(AVERAGE(C10:C10),"") | E10: Avg
B11: Employee FTE (Finance) | C11: =IF(COUNT(C6:C9)=0,"",N(C6)+N(C7)*0.75+N(C8)*0.5+N(C9)*0.25) | D11: =IF(COUNT(D6:D9)=0,"",N(D6)+N(D7)*0.75+N(D8)*0.5+N(D9)*0.25) | E11: FTE | F11: =IF(COUNT(D5:D9)=0,"",N(D6)+N(D7)+N(D8)+N(D9)-N(D5))
B12: Subcontracted Workforce HC | D12: =IF(COUNT(C12:C12)=0,"",SUM(C12:C12)) | E12: ∑
B13: Subcontracted Productive Hours | D13: =IF(COUNT(C13:C13)=0,"",SUM(C13:C13)) | E13: ∑
B14: Subcontracted FTE | C14: =IFERROR(C13/C10,"") | D14: =IF(COUNT(C14:C14)=0,"",SUM(C14:C14)) | E14: FTE
B15: Total Operational Workforce | C15: =IF(COUNT(C5,C12)=0,"",SUM(C5,C12)) | D15: =IF(COUNT(D5,D12)=0,"",SUM(D5,D12)) | E15: ϝ
B16: Total Operational FTE | C16: =IF(COUNT(C11,C14)=0,"",SUM(C11,C14)) | D16: =IF(COUNT(D11,D14)=0,"",SUM(D11,D14)) | E16: FTE
B17: Subcontracted Share of Workforce (%) | C17: =IFERROR(C12/C15,"") | D17: =IFERROR(D12/D15,"") | E17: ϝ
B18: FTE HR Team | D18: =IF(COUNT(C18:C18)=0,"",SUM(C18:C18)) | E18: ∑
B19: Permanent Hires | D19: =IF(COUNT(C19:C19)=0,"",SUM(C19:C19)) | E19: ∑
B20: Temporary Hires | D20: =IF(COUNT(C20:C20)=0,"",SUM(C20:C20)) | E20: ∑
B21: Total Hires | C21: =IF(COUNT(C19:C20)=0,"",SUM(C19:C20)) | D21: =IF(COUNT(D19:D20)=0,"",SUM(D19:D20)) | E21: ϝ
B22: Permanent Exits | D22: =IF(COUNT(C22:C22)=0,"",SUM(C22:C22)) | E22: ∑
B23: Temporary Exits | D23: =IF(COUNT(C23:C23)=0,"",SUM(C23:C23)) | E23: ∑
B24: Total Exits | C24: =IF(COUNT(C22:C23)=0,"",SUM(C22:C23)) | D24: =IF(COUNT(D22:D23)=0,"",SUM(D22:D23)) | E24: ϝ
B25: Permanent Turnover (%) | C25: =IF(COUNT(C31,C32)<2,"",IF((C32+C31)=0,"",N(C22)/((C32+C31)/2))) | D25: =IF(COUNT(D31,D32)<2,"",IF((D32+D31)=0,"",N(D22)/((D32+D31)/2))) | E25: ϝ
B26: Temporary Turnover (%) | C26: =IF(COUNT(C31,C32)<2,"",IF((C32+C31)=0,"",N(C23)/((C32+C31)/2))) | D26: =IF(COUNT(D31,D32)<2,"",IF((D32+D31)=0,"",N(D23)/((D32+D31)/2))) | E26: ϝ
B27: Voluntary Terminations | D27: =IF(COUNT(C27:C27)=0,"",SUM(C27:C27)) | E27: ∑
B28: Involuntary Terminations | D28: =IF(COUNT(C28:C28)=0,"",SUM(C28:C28)) | E28: ∑
B29: Voluntary Turnover (%) | C29: =IF(COUNT(C31,C32)<2,"",IF((C32+C31)=0,"",N(C27)/((C32+C31)/2))) | D29: =IF(COUNT(D31,D32)<2,"",IF((D32+D31)=0,"",N(D27)/((D32+D31)/2))) | E29: ϝ
B30: Involuntary Turnover (%) | C30: =IF(COUNT(C31,C32)<2,"",IF((C32+C31)=0,"",N(C28)/((C32+C31)/2))) | D30: =IF(COUNT(D31,D32)<2,"",IF((D32+D31)=0,"",N(D28)/((D32+D31)/2))) | E30: ϝ
B31: Headcount last Month | D31: =IF(COUNT(C31:C31)=0,"",SUM(C31:C31)) | E31: ∑
B32: Headcount this Month | C32: =IF(C5="","",C5) | D32: =IF(COUNT(C32:C32)=0,"",SUM(C32:C32)) | E32: ∑
B33: Full Turnover (%) | C33: =IF(COUNT(C31,C32)<2,"",IF((C32+C31)=0,"",N(C24)/((C32+C31)/2))) | D33: =IF(COUNT(D31,D32)<2,"",IF((D32+D31)=0,"",N(D24)/((D32+D31)/2))) | E33: ϝ
B34: Permanent Vacancies | D34: =IF(COUNT(C34:C34)=0,"",SUM(C34:C34)) | E34: ∑
B35: Temporary Vacancies | D35: =IF(COUNT(C35:C35)=0,"",SUM(C35:C35)) | E35: ∑
B36: Total Vacancies | C36: =IF(COUNT(C34:C35)=0,"",SUM(C34:C35)) | D36: =IF(COUNT(D34:D35)=0,"",SUM(D34:D35)) | E36: ϝ
B37: Authorized Positions | C37: =IF(COUNT(C5,C36)=0,"",N(C5)+N(C36)) | D37: =IF(COUNT(D5,D36)=0,"",N(D5)+N(D36)) | E37: ϝ
B38: Vacancy Rate (%) | C38: =IFERROR(C36/C37,"") | D38: =IFERROR(D36/D37,"") | E38: ϝ
B39: Permanent TimeToHire (Days) YTD | C39: =IF('(GCG_HDQ)'!$AB$4="","",'(GCG_HDQ)'!$AB$4) | D39: =IFERROR(AVERAGE(C39:C39),"") | E39: Avg
B40: Temporary TimeToHire (Days) YTD | C40: =IF('(GCG_HDQ)'!$AD$4="","",'(GCG_HDQ)'!$AD$4) | D40: =IFERROR(AVERAGE(C40:C40),"") | E40: Avg
...

Sheet NOV
B1: GCG HDQ | C1: 1079
A2: =VALUE(TEXT(EDATE(DATE(LEFT(OCT!A2,4),RIGHT(OCT!A2,2),1),1),"yyyymm")) | B2: NOV | C2: GCG HDQ | D2: TOTAL | E2: Total by Division | F2: =N(F11)<>0
A3: =+A2 | B3: Permanent (Regular) Headcount | D3: =IF(COUNT(C3:C3)=0,"",SUM(C3:C3)) | E3: ∑
B4: Temporary (Fix Term) Headcount | D4: =IF(COUNT(C4:C4)=0,"",SUM(C4:C4)) | E4: ∑
B5: Employee Headcount (Productivity) | C5: =IF(COUNT(C3:C4)=0,"",SUM(C3:C4)) | D5: =IF(COUNT(D3:D4)=0,"",SUM(D3:D4)) | E5: ϝ
B6: Headcount = 1.00 | D6: =IF(COUNT(C6:C6)=0,"",SUM(C6:C6)) | E6: ∑
B7: Headcount = 0.75 | D7: =IF(COUNT(C7:C7)=0,"",SUM(C7:C7)) | E7: ∑
B8: Headcount = 0.50 | D8: =IF(COUNT(C8:C8)=0,"",SUM(C8:C8)) | E8: ∑
B9: Headcount = 0.25 | D9: =IF(COUNT(C9:C9)=0,"",SUM(C9:C9)) | E9: ∑
B10: Standard Monthly Hours (FTE basis) | D10: =IFERROR(AVERAGE(C10:C10),"") | E10: Avg
B11: Employee FTE (Finance) | C11: =IF(COUNT(C6:C9)=0,"",N(C6)+N(C7)*0.75+N(C8)*0.5+N(C9)*0.25) | D11: =IF(COUNT(D6:D9)=0,"",N(D6)+N(D7)*0.75+N(D8)*0.5+N(D9)*0.25) | E11: FTE | F11: =IF(COUNT(D5:D9)=0,"",N(D6)+N(D7)+N(D8)+N(D9)-N(D5))
B12: Subcontracted Workforce HC | D12: =IF(COUNT(C12:C12)=0,"",SUM(C12:C12)) | E12: ∑
B13: Subcontracted Productive Hours | D13: =IF(COUNT(C13:C13)=0,"",SUM(C13:C13)) | E13: ∑
B14: Subcontracted FTE | C14: =IFERROR(C13/C10,"") | D14: =IF(COUNT(C14:C14)=0,"",SUM(C14:C14)) | E14: FTE
B15: Total Operational Workforce | C15: =IF(COUNT(C5,C12)=0,"",SUM(C5,C12)) | D15: =IF(COUNT(D5,D12)=0,"",SUM(D5,D12)) | E15: ϝ
B16: Total Operational FTE | C16: =IF(COUNT(C11,C14)=0,"",SUM(C11,C14)) | D16: =IF(COUNT(D11,D14)=0,"",SUM(D11,D14)) | E16: FTE
B17: Subcontracted Share of Workforce (%) | C17: =IFERROR(C12/C15,"") | D17: =IFERROR(D12/D15,"") | E17: ϝ
B18: FTE HR Team | D18: =IF(COUNT(C18:C18)=0,"",SUM(C18:C18)) | E18: ∑
B19: Permanent Hires | D19: =IF(COUNT(C19:C19)=0,"",SUM(C19:C19)) | E19: ∑
B20: Temporary Hires | D20: =IF(COUNT(C20:C20)=0,"",SUM(C20:C20)) | E20: ∑
B21: Total Hires | C21: =IF(COUNT(C19:C20)=0,"",SUM(C19:C20)) | D21: =IF(COUNT(D19:D20)=0,"",SUM(D19:D20)) | E21: ϝ
B22: Permanent Exits | D22: =IF(COUNT(C22:C22)=0,"",SUM(C22:C22)) | E22: ∑
B23: Temporary Exits | D23: =IF(COUNT(C23:C23)=0,"",SUM(C23:C23)) | E23: ∑
B24: Total Exits | C24: =IF(COUNT(C22:C23)=0,"",SUM(C22:C23)) | D24: =IF(COUNT(D22:D23)=0,"",SUM(D22:D23)) | E24: ϝ
B25: Permanent Turnover (%) | C25: =IF(COUNT(C31,C32)<2,"",IF((C32+C31)=0,"",N(C22)/((C32+C31)/2))) | D25: =IF(COUNT(D31,D32)<2,"",IF((D32+D31)=0,"",N(D22)/((D32+D31)/2))) | E25: ϝ
B26: Temporary Turnover (%) | C26: =IF(COUNT(C31,C32)<2,"",IF((C32+C31)=0,"",N(C23)/((C32+C31)/2))) | D26: =IF(COUNT(D31,D32)<2,"",IF((D32+D31)=0,"",N(D23)/((D32+D31)/2))) | E26: ϝ
B27: Voluntary Terminations | D27: =IF(COUNT(C27:C27)=0,"",SUM(C27:C27)) | E27: ∑
B28: Involuntary Terminations | D28: =IF(COUNT(C28:C28)=0,"",SUM(C28:C28)) | E28: ∑
B29: Voluntary Turnover (%) | C29: =IF(COUNT(C31,C32)<2,"",IF((C32+C31)=0,"",N(C27)/((C32+C31)/2))) | D29: =IF(COUNT(D31,D32)<2,"",IF((D32+D31)=0,"",N(D27)/((D32+D31)/2))) | E29: ϝ
B30: Involuntary Turnover (%) | C30: =IF(COUNT(C31,C32)<2,"",IF((C32+C31)=0,"",N(C28)/((C32+C31)/2))) | D30: =IF(COUNT(D31,D32)<2,"",IF((D32+D31)=0,"",N(D28)/((D32+D31)/2))) | E30: ϝ
B31: Headcount last Month | C31: =IF(OCT!C5="","",OCT!C5) | D31: =IF(COUNT(C31:C31)=0,"",SUM(C31:C31)) | E31: ∑
B32: Headcount this Month | C32: =IF(C5="","",C5) | D32: =IF(COUNT(C32:C32)=0,"",SUM(C32:C32)) | E32: ∑
B33: Full Turnover (%) | C33: =IF(COUNT(C31,C32)<2,"",IF((C32+C31)=0,"",N(C24)/((C32+C31)/2))) | D33: =IF(COUNT(D31,D32)<2,"",IF((D32+D31)=0,"",N(D24)/((D32+D31)/2))) | E33: ϝ
B34: Permanent Vacancies | D34: =IF(COUNT(C34:C34)=0,"",SUM(C34:C34)) | E34: ∑
B35: Temporary Vacancies | D35: =IF(COUNT(C35:C35)=0,"",SUM(C35:C35)) | E35: ∑
B36: Total Vacancies | C36: =IF(COUNT(C34:C35)=0,"",SUM(C34:C35)) | D36: =IF(COUNT(D34:D35)=0,"",SUM(D34:D35)) | E36: ϝ
B37: Authorized Positions | C37: =IF(COUNT(C5,C36)=0,"",N(C5)+N(C36)) | D37: =IF(COUNT(D5,D36)=0,"",N(D5)+N(D36)) | E37: ϝ
B38: Vacancy Rate (%) | C38: =IFERROR(C36/C37,"") | D38: =IFERROR(D36/D37,"") | E38: ϝ
B39: Permanent TimeToHire (Days) YTD | C39: =IF('(GCG_HDQ)'!$AB$5="","",'(GCG_HDQ)'!$AB$5) | D39: =IFERROR(AVERAGE(C39:C39),"") | E39: Avg
B40: Temporary TimeToHire (Days) YTD | C40: =IF('(GCG_HDQ)'!$AD$5="","",'(GCG_HDQ)'!$AD$5) | D40: =IFERROR(AVERAGE(C40:C40),"") | E40: Avg
...

Sheet DEC
B1: GCG HDQ | C1: 1079
A2: =VALUE(TEXT(EDATE(DATE(LEFT(NOV!A2,4),RIGHT(NOV!A2,2),1),1),"yyyymm")) | B2: DEC | C2: GCG HDQ | D2: TOTAL | E2: Total by Division | F2: =N(F11)<>0
A3: =+A2 | B3: Permanent (Regular) Headcount | D3: =IF(COUNT(C3:C3)=0,"",SUM(C3:C3)) | E3: ∑
B4: Temporary (Fix Term) Headcount | D4: =IF(COUNT(C4:C4)=0,"",SUM(C4:C4)) | E4: ∑
B5: Employee Headcount (Productivity) | C5: =IF(COUNT(C3:C4)=0,"",SUM(C3:C4)) | D5: =IF(COUNT(D3:D4)=0,"",SUM(D3:D4)) | E5: ϝ
B6: Headcount = 1.00 | D6: =IF(COUNT(C6:C6)=0,"",SUM(C6:C6)) | E6: ∑
B7: Headcount = 0.75 | D7: =IF(COUNT(C7:C7)=0,"",SUM(C7:C7)) | E7: ∑
B8: Headcount = 0.50 | D8: =IF(COUNT(C8:C8)=0,"",SUM(C8:C8)) | E8: ∑
B9: Headcount = 0.25 | D9: =IF(COUNT(C9:C9)=0,"",SUM(C9:C9)) | E9: ∑
B10: Standard Monthly Hours (FTE basis) | D10: =IFERROR(AVERAGE(C10:C10),"") | E10: Avg
B11: Employee FTE (Finance) | C11: =IF(COUNT(C6:C9)=0,"",N(C6)+N(C7)*0.75+N(C8)*0.5+N(C9)*0.25) | D11: =IF(COUNT(D6:D9)=0,"",N(D6)+N(D7)*0.75+N(D8)*0.5+N(D9)*0.25) | E11: FTE | F11: =IF(COUNT(D5:D9)=0,"",N(D6)+N(D7)+N(D8)+N(D9)-N(D5))
B12: Subcontracted Workforce HC | D12: =IF(COUNT(C12:C12)=0,"",SUM(C12:C12)) | E12: ∑
B13: Subcontracted Productive Hours | D13: =IF(COUNT(C13:C13)=0,"",SUM(C13:C13)) | E13: ∑
B14: Subcontracted FTE | C14: =IFERROR(C13/C10,"") | D14: =IF(COUNT(C14:C14)=0,"",SUM(C14:C14)) | E14: FTE
B15: Total Operational Workforce | C15: =IF(COUNT(C5,C12)=0,"",SUM(C5,C12)) | D15: =IF(COUNT(D5,D12)=0,"",SUM(D5,D12)) | E15: ϝ
B16: Total Operational FTE | C16: =IF(COUNT(C11,C14)=0,"",SUM(C11,C14)) | D16: =IF(COUNT(D11,D14)=0,"",SUM(D11,D14)) | E16: FTE
B17: Subcontracted Share of Workforce (%) | C17: =IFERROR(C12/C15,"") | D17: =IFERROR(D12/D15,"") | E17: ϝ
B18: FTE HR Team | D18: =IF(COUNT(C18:C18)=0,"",SUM(C18:C18)) | E18: ∑
B19: Permanent Hires | D19: =IF(COUNT(C19:C19)=0,"",SUM(C19:C19)) | E19: ∑
B20: Temporary Hires | D20: =IF(COUNT(C20:C20)=0,"",SUM(C20:C20)) | E20: ∑
B21: Total Hires | C21: =IF(COUNT(C19:C20)=0,"",SUM(C19:C20)) | D21: =IF(COUNT(D19:D20)=0,"",SUM(D19:D20)) | E21: ϝ
B22: Permanent Exits | D22: =IF(COUNT(C22:C22)=0,"",SUM(C22:C22)) | E22: ∑
B23: Temporary Exits | D23: =IF(COUNT(C23:C23)=0,"",SUM(C23:C23)) | E23: ∑
B24: Total Exits | C24: =IF(COUNT(C22:C23)=0,"",SUM(C22:C23)) | D24: =IF(COUNT(D22:D23)=0,"",SUM(D22:D23)) | E24: ϝ
B25: Permanent Turnover (%) | C25: =IF(COUNT(C31,C32)<2,"",IF((C32+C31)=0,"",N(C22)/((C32+C31)/2))) | D25: =IF(COUNT(D31,D32)<2,"",IF((D32+D31)=0,"",N(D22)/((D32+D31)/2))) | E25: ϝ
B26: Temporary Turnover (%) | C26: =IF(COUNT(C31,C32)<2,"",IF((C32+C31)=0,"",N(C23)/((C32+C31)/2))) | D26: =IF(COUNT(D31,D32)<2,"",IF((D32+D31)=0,"",N(D23)/((D32+D31)/2))) | E26: ϝ
B27: Voluntary Terminations | D27: =IF(COUNT(C27:C27)=0,"",SUM(C27:C27)) | E27: ∑
B28: Involuntary Terminations | D28: =IF(COUNT(C28:C28)=0,"",SUM(C28:C28)) | E28: ∑
B29: Voluntary Turnover (%) | C29: =IF(COUNT(C31,C32)<2,"",IF((C32+C31)=0,"",N(C27)/((C32+C31)/2))) | D29: =IF(COUNT(D31,D32)<2,"",IF((D32+D31)=0,"",N(D27)/((D32+D31)/2))) | E29: ϝ
B30: Involuntary Turnover (%) | C30: =IF(COUNT(C31,C32)<2,"",IF((C32+C31)=0,"",N(C28)/((C32+C31)/2))) | D30: =IF(COUNT(D31,D32)<2,"",IF((D32+D31)=0,"",N(D28)/((D32+D31)/2))) | E30: ϝ
B31: Headcount last Month | C31: =IF(NOV!C5="","",NOV!C5) | D31: =IF(COUNT(C31:C31)=0,"",SUM(C31:C31)) | E31: ∑
B32: Headcount this Month | C32: =IF(C5="","",C5) | D32: =IF(COUNT(C32:C32)=0,"",SUM(C32:C32)) | E32: ∑
B33: Full Turnover (%) | C33: =IF(COUNT(C31,C32)<2,"",IF((C32+C31)=0,"",N(C24)/((C32+C31)/2))) | D33: =IF(COUNT(D31,D32)<2,"",IF((D32+D31)=0,"",N(D24)/((D32+D31)/2))) | E33: ϝ
B34: Permanent Vacancies | D34: =IF(COUNT(C34:C34)=0,"",SUM(C34:C34)) | E34: ∑
B35: Temporary Vacancies | D35: =IF(COUNT(C35:C35)=0,"",SUM(C35:C35)) | E35: ∑
B36: Total Vacancies | C36: =IF(COUNT(C34:C35)=0,"",SUM(C34:C35)) | D36: =IF(COUNT(D34:D35)=0,"",SUM(D34:D35)) | E36: ϝ
B37: Authorized Positions | C37: =IF(COUNT(C5,C36)=0,"",N(C5)+N(C36)) | D37: =IF(COUNT(D5,D36)=0,"",N(D5)+N(D36)) | E37: ϝ
B38: Vacancy Rate (%) | C38: =IFERROR(C36/C37,"") | D38: =IFERROR(D36/D37,"") | E38: ϝ
B39: Permanent TimeToHire (Days) YTD | C39: =IF('(GCG_HDQ)'!$AB$6="","",'(GCG_HDQ)'!$AB$6) | D39: =IFERROR(AVERAGE(C39:C39),"") | E39: Avg
B40: Temporary TimeToHire (Days) YTD | C40: =IF('(GCG_HDQ)'!$AD$6="","",'(GCG_HDQ)'!$AD$6) | D40: =IFERROR(AVERAGE(C40:C40),"") | E40: Avg
...

Sheet JAN
B1: GCG HDQ | C1: 1079
A2: =VALUE(TEXT(EDATE(DATE(LEFT(DEC!A2,4),RIGHT(DEC!A2,2),1),1),"yyyymm")) | B2: JAN | C2: GCG HDQ | D2: TOTAL | E2: Total by Division | F2: =N(F11)<>0
A3: =+A2 | B3: Permanent (Regular) Headcount | D3: =IF(COUNT(C3:C3)=0,"",SUM(C3:C3)) | E3: ∑
B4: Temporary (Fix Term) Headcount | D4: =IF(COUNT(C4:C4)=0,"",SUM(C4:C4)) | E4: ∑
B5: Employee Headcount (Productivity) | C5: =IF(COUNT(C3:C4)=0,"",SUM(C3:C4)) | D5: =IF(COUNT(D3:D4)=0,"",SUM(D3:D4)) | E5: ϝ
B6: Headcount = 1.00 | D6: =IF(COUNT(C6:C6)=0,"",SUM(C6:C6)) | E6: ∑
B7: Headcount = 0.75 | D7: =IF(COUNT(C7:C7)=0,"",SUM(C7:C7)) | E7: ∑
B8: Headcount = 0.50 | D8: =IF(COUNT(C8:C8)=0,"",SUM(C8:C8)) | E8: ∑
B9: Headcount = 0.25 | D9: =IF(COUNT(C9:C9)=0,"",SUM(C9:C9)) | E9: ∑
B10: Standard Monthly Hours (FTE basis) | D10: =IFERROR(AVERAGE(C10:C10),"") | E10: Avg
B11: Employee FTE (Finance) | C11: =IF(COUNT(C6:C9)=0,"",N(C6)+N(C7)*0.75+N(C8)*0.5+N(C9)*0.25) | D11: =IF(COUNT(D6:D9)=0,"",N(D6)+N(D7)*0.75+N(D8)*0.5+N(D9)*0.25) | E11: FTE | F11: =IF(COUNT(D5:D9)=0,"",N(D6)+N(D7)+N(D8)+N(D9)-N(D5))
B12: Subcontracted Workforce HC | D12: =IF(COUNT(C12:C12)=0,"",SUM(C12:C12)) | E12: ∑
B13: Subcontracted Productive Hours | D13: =IF(COUNT(C13:C13)=0,"",SUM(C13:C13)) | E13: ∑
B14: Subcontracted FTE | C14: =IFERROR(C13/C10,"") | D14: =IF(COUNT(C14:C14)=0,"",SUM(C14:C14)) | E14: FTE
B15: Total Operational Workforce | C15: =IF(COUNT(C5,C12)=0,"",SUM(C5,C12)) | D15: =IF(COUNT(D5,D12)=0,"",SUM(D5,D12)) | E15: ϝ
B16: Total Operational FTE | C16: =IF(COUNT(C11,C14)=0,"",SUM(C11,C14)) | D16: =IF(COUNT(D11,D14)=0,"",SUM(D11,D14)) | E16: FTE
B17: Subcontracted Share of Workforce (%) | C17: =IFERROR(C12/C15,"") | D17: =IFERROR(D12/D15,"") | E17: ϝ
B18: FTE HR Team | D18: =IF(COUNT(C18:C18)=0,"",SUM(C18:C18)) | E18: ∑
B19: Permanent Hires | D19: =IF(COUNT(C19:C19)=0,"",SUM(C19:C19)) | E19: ∑
B20: Temporary Hires | D20: =IF(COUNT(C20:C20)=0,"",SUM(C20:C20)) | E20: ∑
B21: Total Hires | C21: =IF(COUNT(C19:C20)=0,"",SUM(C19:C20)) | D21: =IF(COUNT(D19:D20)=0,"",SUM(D19:D20)) | E21: ϝ
B22: Permanent Exits | D22: =IF(COUNT(C22:C22)=0,"",SUM(C22:C22)) | E22: ∑
B23: Temporary Exits | D23: =IF(COUNT(C23:C23)=0,"",SUM(C23:C23)) | E23: ∑
B24: Total Exits | C24: =IF(COUNT(C22:C23)=0,"",SUM(C22:C23)) | D24: =IF(COUNT(D22:D23)=0,"",SUM(D22:D23)) | E24: ϝ
B25: Permanent Turnover (%) | C25: =IF(COUNT(C31,C32)<2,"",IF((C32+C31)=0,"",N(C22)/((C32+C31)/2))) | D25: =IF(COUNT(D31,D32)<2,"",IF((D32+D31)=0,"",N(D22)/((D32+D31)/2))) | E25: ϝ
B26: Temporary Turnover (%) | C26: =IF(COUNT(C31,C32)<2,"",IF((C32+C31)=0,"",N(C23)/((C32+C31)/2))) | D26: =IF(COUNT(D31,D32)<2,"",IF((D32+D31)=0,"",N(D23)/((D32+D31)/2))) | E26: ϝ
B27: Voluntary Terminations | D27: =IF(COUNT(C27:C27)=0,"",SUM(C27:C27)) | E27: ∑
B28: Involuntary Terminations | D28: =IF(COUNT(C28:C28)=0,"",SUM(C28:C28)) | E28: ∑
B29: Voluntary Turnover (%) | C29: =IF(COUNT(C31,C32)<2,"",IF((C32+C31)=0,"",N(C27)/((C32+C31)/2))) | D29: =IF(COUNT(D31,D32)<2,"",IF((D32+D31)=0,"",N(D27)/((D32+D31)/2))) | E29: ϝ
B30: Involuntary Turnover (%) | C30: =IF(COUNT(C31,C32)<2,"",IF((C32+C31)=0,"",N(C28)/((C32+C31)/2))) | D30: =IF(COUNT(D31,D32)<2,"",IF((D32+D31)=0,"",N(D28)/((D32+D31)/2))) | E30: ϝ
B31: Headcount last Month | C31: =IF(DEC!C5="","",DEC!C5) | D31: =IF(COUNT(C31:C31)=0,"",SUM(C31:C31)) | E31: ∑
B32: Headcount this Month | C32: =IF(C5="","",C5) | D32: =IF(COUNT(C32:C32)=0,"",SUM(C32:C32)) | E32: ∑
B33: Full Turnover (%) | C33: =IF(COUNT(C31,C32)<2,"",IF((C32+C31)=0,"",N(C24)/((C32+C31)/2))) | D33: =IF(COUNT(D31,D32)<2,"",IF((D32+D31)=0,"",N(D24)/((D32+D31)/2))) | E33: ϝ
B34: Permanent Vacancies | D34: =IF(COUNT(C34:C34)=0,"",SUM(C34:C34)) | E34: ∑
B35: Temporary Vacancies | D35: =IF(COUNT(C35:C35)=0,"",SUM(C35:C35)) | E35: ∑
B36: Total Vacancies | C36: =IF(COUNT(C34:C35)=0,"",SUM(C34:C35)) | D36: =IF(COUNT(D34:D35)=0,"",SUM(D34:D35)) | E36: ϝ
B37: Authorized Positions | C37: =IF(COUNT(C5,C36)=0,"",N(C5)+N(C36)) | D37: =IF(COUNT(D5,D36)=0,"",N(D5)+N(D36)) | E37: ϝ
B38: Vacancy Rate (%) | C38: =IFERROR(C36/C37,"") | D38: =IFERROR(D36/D37,"") | E38: ϝ
B39: Permanent TimeToHire (Days) YTD | C39: =IF('(GCG_HDQ)'!$AB$7="","",'(GCG_HDQ)'!$AB$7) | D39: =IFERROR(AVERAGE(C39:C39),"") | E39: Avg
B40: Temporary TimeToHire (Days) YTD | C40: =IF('(GCG_HDQ)'!$AD$7="","",'(GCG_HDQ)'!$AD$7) | D40: =IFERROR(AVERAGE(C40:C40),"") | E40: Avg
...

Sheet FEB
B1: GCG HDQ | C1: 1079
A2: =VALUE(TEXT(EDATE(DATE(LEFT(JAN!A2,4),RIGHT(JAN!A2,2),1),1),"yyyymm")) | B2: FEB | C2: GCG HDQ | D2: TOTAL | E2: Total by Division | F2: =N(F11)<>0
A3: =+A2 | B3: Permanent (Regular) Headcount | D3: =IF(COUNT(C3:C3)=0,"",SUM(C3:C3)) | E3: ∑
B4: Temporary (Fix Term) Headcount | D4: =IF(COUNT(C4:C4)=0,"",SUM(C4:C4)) | E4: ∑
B5: Employee Headcount (Productivity) | C5: =IF(COUNT(C3:C4)=0,"",SUM(C3:C4)) | D5: =IF(COUNT(D3:D4)=0,"",SUM(D3:D4)) | E5: ϝ
B6: Headcount = 1.00 | D6: =IF(COUNT(C6:C6)=0,"",SUM(C6:C6)) | E6: ∑
B7: Headcount = 0.75 | D7: =IF(COUNT(C7:C7)=0,"",SUM(C7:C7)) | E7: ∑
B8: Headcount = 0.50 | D8: =IF(COUNT(C8:C8)=0,"",SUM(C8:C8)) | E8: ∑
B9: Headcount = 0.25 | D9: =IF(COUNT(C9:C9)=0,"",SUM(C9:C9)) | E9: ∑
B10: Standard Monthly Hours (FTE basis) | D10: =IFERROR(AVERAGE(C10:C10),"") | E10: Avg
B11: Employee FTE (Finance) | C11: =IF(COUNT(C6:C9)=0,"",N(C6)+N(C7)*0.75+N(C8)*0.5+N(C9)*0.25) | D11: =IF(COUNT(D6:D9)=0,"",N(D6)+N(D7)*0.75+N(D8)*0.5+N(D9)*0.25) | E11: FTE | F11: =IF(COUNT(D5:D9)=0,"",N(D6)+N(D7)+N(D8)+N(D9)-N(D5))
B12: Subcontracted Workforce HC | D12: =IF(COUNT(C12:C12)=0,"",SUM(C12:C12)) | E12: ∑
B13: Subcontracted Productive Hours | D13: =IF(COUNT(C13:C13)=0,"",SUM(C13:C13)) | E13: ∑
B14: Subcontracted FTE | C14: =IFERROR(C13/C10,"") | D14: =IF(COUNT(C14:C14)=0,"",SUM(C14:C14)) | E14: FTE
B15: Total Operational Workforce | C15: =IF(COUNT(C5,C12)=0,"",SUM(C5,C12)) | D15: =IF(COUNT(D5,D12)=0,"",SUM(D5,D12)) | E15: ϝ
B16: Total Operational FTE | C16: =IF(COUNT(C11,C14)=0,"",SUM(C11,C14)) | D16: =IF(COUNT(D11,D14)=0,"",SUM(D11,D14)) | E16: FTE
B17: Subcontracted Share of Workforce (%) | C17: =IFERROR(C12/C15,"") | D17: =IFERROR(D12/D15,"") | E17: ϝ
B18: FTE HR Team | D18: =IF(COUNT(C18:C18)=0,"",SUM(C18:C18)) | E18: ∑
B19: Permanent Hires | D19: =IF(COUNT(C19:C19)=0,"",SUM(C19:C19)) | E19: ∑
B20: Temporary Hires | D20: =IF(COUNT(C20:C20)=0,"",SUM(C20:C20)) | E20: ∑
B21: Total Hires | C21: =IF(COUNT(C19:C20)=0,"",SUM(C19:C20)) | D21: =IF(COUNT(D19:D20)=0,"",SUM(D19:D20)) | E21: ϝ
B22: Permanent Exits | D22: =IF(COUNT(C22:C22)=0,"",SUM(C22:C22)) | E22: ∑
B23: Temporary Exits | D23: =IF(COUNT(C23:C23)=0,"",SUM(C23:C23)) | E23: ∑
B24: Total Exits | C24: =IF(COUNT(C22:C23)=0,"",SUM(C22:C23)) | D24: =IF(COUNT(D22:D23)=0,"",SUM(D22:D23)) | E24: ϝ
B25: Permanent Turnover (%) | C25: =IF(COUNT(C31,C32)<2,"",IF((C32+C31)=0,"",N(C22)/((C32+C31)/2))) | D25: =IF(COUNT(D31,D32)<2,"",IF((D32+D31)=0,"",N(D22)/((D32+D31)/2))) | E25: ϝ
B26: Temporary Turnover (%) | C26: =IF(COUNT(C31,C32)<2,"",IF((C32+C31)=0,"",N(C23)/((C32+C31)/2))) | D26: =IF(COUNT(D31,D32)<2,"",IF((D32+D31)=0,"",N(D23)/((D32+D31)/2))) | E26: ϝ
B27: Voluntary Terminations | D27: =IF(COUNT(C27:C27)=0,"",SUM(C27:C27)) | E27: ∑
B28: Involuntary Terminations | D28: =IF(COUNT(C28:C28)=0,"",SUM(C28:C28)) | E28: ∑
B29: Voluntary Turnover (%) | C29: =IF(COUNT(C31,C32)<2,"",IF((C32+C31)=0,"",N(C27)/((C32+C31)/2))) | D29: =IF(COUNT(D31,D32)<2,"",IF((D32+D31)=0,"",N(D27)/((D32+D31)/2))) | E29: ϝ
B30: Involuntary Turnover (%) | C30: =IF(COUNT(C31,C32)<2,"",IF((C32+C31)=0,"",N(C28)/((C32+C31)/2))) | D30: =IF(COUNT(D31,D32)<2,"",IF((D32+D31)=0,"",N(D28)/((D32+D31)/2))) | E30: ϝ
B31: Headcount last Month | C31: =IF(JAN!C5="","",JAN!C5) | D31: =IF(COUNT(C31:C31)=0,"",SUM(C31:C31)) | E31: ∑
B32: Headcount this Month | C32: =IF(C5="","",C5) | D32: =IF(COUNT(C32:C32)=0,"",SUM(C32:C32)) | E32: ∑
B33: Full Turnover (%) | C33: =IF(COUNT(C31,C32)<2,"",IF((C32+C31)=0,"",N(C24)/((C32+C31)/2))) | D33: =IF(COUNT(D31,D32)<2,"",IF((D32+D31)=0,"",N(D24)/((D32+D31)/2))) | E33: ϝ
B34: Permanent Vacancies | D34: =IF(COUNT(C34:C34)=0,"",SUM(C34:C34)) | E34: ∑
B35: Temporary Vacancies | D35: =IF(COUNT(C35:C35)=0,"",SUM(C35:C35)) | E35: ∑
B36: Total Vacancies | C36: =IF(COUNT(C34:C35)=0,"",SUM(C34:C35)) | D36: =IF(COUNT(D34:D35)=0,"",SUM(D34:D35)) | E36: ϝ
B37: Authorized Positions | C37: =IF(COUNT(C5,C36)=0,"",N(C5)+N(C36)) | D37: =IF(COUNT(D5,D36)=0,"",N(D5)+N(D36)) | E37: ϝ
B38: Vacancy Rate (%) | C38: =IFERROR(C36/C37,"") | D38: =IFERROR(D36/D37,"") | E38: ϝ
B39: Permanent TimeToHire (Days) YTD | C39: =IF('(GCG_HDQ)'!$AB$8="","",'(GCG_HDQ)'!$AB$8) | D39: =IFERROR(AVERAGE(C39:C39),"") | E39: Avg
B40: Temporary TimeToHire (Days) YTD | C40: =IF('(GCG_HDQ)'!$AD$8="","",'(GCG_HDQ)'!$AD$8) | D40: =IFERROR(AVERAGE(C40:C40),"") | E40: Avg
...

Sheet MAR
B1: GCG HDQ | C1: 1079
A2: =VALUE(TEXT(EDATE(DATE(LEFT(FEB!A2,4),RIGHT(FEB!A2,2),1),1),"yyyymm")) | B2: MAR | C2: GCG HDQ | D2: TOTAL | E2: Total by Division | F2: =N(F11)<>0
A3: =+A2 | B3: Permanent (Regular) Headcount | D3: =IF(COUNT(C3:C3)=0,"",SUM(C3:C3)) | E3: ∑
B4: Temporary (Fix Term) Headcount | D4: =IF(COUNT(C4:C4)=0,"",SUM(C4:C4)) | E4: ∑
B5: Employee Headcount (Productivity) | C5: =IF(COUNT(C3:C4)=0,"",SUM(C3:C4)) | D5: =IF(COUNT(D3:D4)=0,"",SUM(D3:D4)) | E5: ϝ
B6: Headcount = 1.00 | D6: =IF(COUNT(C6:C6)=0,"",SUM(C6:C6)) | E6: ∑
B7: Headcount = 0.75 | D7: =IF(COUNT(C7:C7)=0,"",SUM(C7:C7)) | E7: ∑
B8: Headcount = 0.50 | D8: =IF(COUNT(C8:C8)=0,"",SUM(C8:C8)) | E8: ∑
B9: Headcount = 0.25 | D9: =IF(COUNT(C9:C9)=0,"",SUM(C9:C9)) | E9: ∑
B10: Standard Monthly Hours (FTE basis) | D10: =IFERROR(AVERAGE(C10:C10),"") | E10: Avg
B11: Employee FTE (Finance) | C11: =IF(COUNT(C6:C9)=0,"",N(C6)+N(C7)*0.75+N(C8)*0.5+N(C9)*0.25) | D11: =IF(COUNT(D6:D9)=0,"",N(D6)+N(D7)*0.75+N(D8)*0.5+N(D9)*0.25) | E11: FTE | F11: =IF(COUNT(D5:D9)=0,"",N(D6)+N(D7)+N(D8)+N(D9)-N(D5))
B12: Subcontracted Workforce HC | D12: =IF(COUNT(C12:C12)=0,"",SUM(C12:C12)) | E12: ∑
B13: Subcontracted Productive Hours | D13: =IF(COUNT(C13:C13)=0,"",SUM(C13:C13)) | E13: ∑
B14: Subcontracted FTE | C14: =IFERROR(C13/C10,"") | D14: =IF(COUNT(C14:C14)=0,"",SUM(C14:C14)) | E14: FTE
B15: Total Operational Workforce | C15: =IF(COUNT(C5,C12)=0,"",SUM(C5,C12)) | D15: =IF(COUNT(D5,D12)=0,"",SUM(D5,D12)) | E15: ϝ
B16: Total Operational FTE | C16: =IF(COUNT(C11,C14)=0,"",SUM(C11,C14)) | D16: =IF(COUNT(D11,D14)=0,"",SUM(D11,D14)) | E16: FTE
B17: Subcontracted Share of Workforce (%) | C17: =IFERROR(C12/C15,"") | D17: =IFERROR(D12/D15,"") | E17: ϝ
B18: FTE HR Team | D18: =IF(COUNT(C18:C18)=0,"",SUM(C18:C18)) | E18: ∑
B19: Permanent Hires | D19: =IF(COUNT(C19:C19)=0,"",SUM(C19:C19)) | E19: ∑
B20: Temporary Hires | D20: =IF(COUNT(C20:C20)=0,"",SUM(C20:C20)) | E20: ∑
B21: Total Hires | C21: =IF(COUNT(C19:C20)=0,"",SUM(C19:C20)) | D21: =IF(COUNT(D19:D20)=0,"",SUM(D19:D20)) | E21: ϝ
B22: Permanent Exits | D22: =IF(COUNT(C22:C22)=0,"",SUM(C22:C22)) | E22: ∑
B23: Temporary Exits | D23: =IF(COUNT(C23:C23)=0,"",SUM(C23:C23)) | E23: ∑
B24: Total Exits | C24: =IF(COUNT(C22:C23)=0,"",SUM(C22:C23)) | D24: =IF(COUNT(D22:D23)=0,"",SUM(D22:D23)) | E24: ϝ
B25: Permanent Turnover (%) | C25: =IF(COUNT(C31,C32)<2,"",IF((C32+C31)=0,"",N(C22)/((C32+C31)/2))) | D25: =IF(COUNT(D31,D32)<2,"",IF((D32+D31)=0,"",N(D22)/((D32+D31)/2))) | E25: ϝ
B26: Temporary Turnover (%) | C26: =IF(COUNT(C31,C32)<2,"",IF((C32+C31)=0,"",N(C23)/((C32+C31)/2))) | D26: =IF(COUNT(D31,D32)<2,"",IF((D32+D31)=0,"",N(D23)/((D32+D31)/2))) | E26: ϝ
B27: Voluntary Terminations | D27: =IF(COUNT(C27:C27)=0,"",SUM(C27:C27)) | E27: ∑
B28: Involuntary Terminations | D28: =IF(COUNT(C28:C28)=0,"",SUM(C28:C28)) | E28: ∑
B29: Voluntary Turnover (%) | C29: =IF(COUNT(C31,C32)<2,"",IF((C32+C31)=0,"",N(C27)/((C32+C31)/2))) | D29: =IF(COUNT(D31,D32)<2,"",IF((D32+D31)=0,"",N(D27)/((D32+D31)/2))) | E29: ϝ
B30: Involuntary Turnover (%) | C30: =IF(COUNT(C31,C32)<2,"",IF((C32+C31)=0,"",N(C28)/((C32+C31)/2))) | D30: =IF(COUNT(D31,D32)<2,"",IF((D32+D31)=0,"",N(D28)/((D32+D31)/2))) | E30: ϝ
B31: Headcount last Month | C31: =IF(FEB!C5="","",FEB!C5) | D31: =IF(COUNT(C31:C31)=0,"",SUM(C31:C31)) | E31: ∑
B32: Headcount this Month | C32: =IF(C5="","",C5) | D32: =IF(COUNT(C32:C32)=0,"",SUM(C32:C32)) | E32: ∑
B33: Full Turnover (%) | C33: =IF(COUNT(C31,C32)<2,"",IF((C32+C31)=0,"",N(C24)/((C32+C31)/2))) | D33: =IF(COUNT(D31,D32)<2,"",IF((D32+D31)=0,"",N(D24)/((D32+D31)/2))) | E33: ϝ
B34: Permanent Vacancies | D34: =IF(COUNT(C34:C34)=0,"",SUM(C34:C34)) | E34: ∑
B35: Temporary Vacancies | D35: =IF(COUNT(C35:C35)=0,"",SUM(C35:C35)) | E35: ∑
B36: Total Vacancies | C36: =IF(COUNT(C34:C35)=0,"",SUM(C34:C35)) | D36: =IF(COUNT(D34:D35)=0,"",SUM(D34:D35)) | E36: ϝ
B37: Authorized Positions | C37: =IF(COUNT(C5,C36)=0,"",N(C5)+N(C36)) | D37: =IF(COUNT(D5,D36)=0,"",N(D5)+N(D36)) | E37: ϝ
B38: Vacancy Rate (%) | C38: =IFERROR(C36/C37,"") | D38: =IFERROR(D36/D37,"") | E38: ϝ
B39: Permanent TimeToHire (Days) YTD | C39: =IF('(GCG_HDQ)'!$AB$9="","",'(GCG_HDQ)'!$AB$9) | D39: =IFERROR(AVERAGE(C39:C39),"") | E39: Avg
B40: Temporary TimeToHire (Days) YTD | C40: =IF('(GCG_HDQ)'!$AD$9="","",'(GCG_HDQ)'!$AD$9) | D40: =IFERROR(AVERAGE(C40:C40),"") | E40: Avg
...

Sheet APR
B1: GCG HDQ | C1: 1079
A2: =VALUE(TEXT(EDATE(DATE(LEFT(MAR!A2,4),RIGHT(MAR!A2,2),1),1),"yyyymm")) | B2: APR | C2: GCG HDQ | D2: TOTAL | E2: Total by Division | F2: =N(F11)<>0
A3: =+A2 | B3: Permanent (Regular) Headcount | D3: =IF(COUNT(C3:C3)=0,"",SUM(C3:C3)) | E3: ∑
B4: Temporary (Fix Term) Headcount | D4: =IF(COUNT(C4:C4)=0,"",SUM(C4:C4)) | E4: ∑
B5: Employee Headcount (Productivity) | C5: =IF(COUNT(C3:C4)=0,"",SUM(C3:C4)) | D5: =IF(COUNT(D3:D4)=0,"",SUM(D3:D4)) | E5: ϝ
B6: Headcount = 1.00 | D6: =IF(COUNT(C6:C6)=0,"",SUM(C6:C6)) | E6: ∑
B7: Headcount = 0.75 | D7: =IF(COUNT(C7:C7)=0,"",SUM(C7:C7)) | E7: ∑
B8: Headcount = 0.50 | D8: =IF(COUNT(C8:C8)=0,"",SUM(C8:C8)) | E8: ∑
B9: Headcount = 0.25 | D9: =IF(COUNT(C9:C9)=0,"",SUM(C9:C9)) | E9: ∑
B10: Standard Monthly Hours (FTE basis) | D10: =IFERROR(AVERAGE(C10:C10),"") | E10: Avg
B11: Employee FTE (Finance) | C11: =IF(COUNT(C6:C9)=0,"",N(C6)+N(C7)*0.75+N(C8)*0.5+N(C9)*0.25) | D11: =IF(COUNT(D6:D9)=0,"",N(D6)+N(D7)*0.75+N(D8)*0.5+N(D9)*0.25) | E11: FTE | F11: =IF(COUNT(D5:D9)=0,"",N(D6)+N(D7)+N(D8)+N(D9)-N(D5))
B12: Subcontracted Workforce HC | D12: =IF(COUNT(C12:C12)=0,"",SUM(C12:C12)) | E12: ∑
B13: Subcontracted Productive Hours | D13: =IF(COUNT(C13:C13)=0,"",SUM(C13:C13)) | E13: ∑
B14: Subcontracted FTE | C14: =IFERROR(C13/C10,"") | D14: =IF(COUNT(C14:C14)=0,"",SUM(C14:C14)) | E14: FTE
B15: Total Operational Workforce | C15: =IF(COUNT(C5,C12)=0,"",SUM(C5,C12)) | D15: =IF(COUNT(D5,D12)=0,"",SUM(D5,D12)) | E15: ϝ
B16: Total Operational FTE | C16: =IF(COUNT(C11,C14)=0,"",SUM(C11,C14)) | D16: =IF(COUNT(D11,D14)=0,"",SUM(D11,D14)) | E16: FTE
B17: Subcontracted Share of Workforce (%) | C17: =IFERROR(C12/C15,"") | D17: =IFERROR(D12/D15,"") | E17: ϝ
B18: FTE HR Team | D18: =IF(COUNT(C18:C18)=0,"",SUM(C18:C18)) | E18: ∑
B19: Permanent Hires | D19: =IF(COUNT(C19:C19)=0,"",SUM(C19:C19)) | E19: ∑
B20: Temporary Hires | D20: =IF(COUNT(C20:C20)=0,"",SUM(C20:C20)) | E20: ∑
B21: Total Hires | C21: =IF(COUNT(C19:C20)=0,"",SUM(C19:C20)) | D21: =IF(COUNT(D19:D20)=0,"",SUM(D19:D20)) | E21: ϝ
B22: Permanent Exits | D22: =IF(COUNT(C22:C22)=0,"",SUM(C22:C22)) | E22: ∑
B23: Temporary Exits | D23: =IF(COUNT(C23:C23)=0,"",SUM(C23:C23)) | E23: ∑
B24: Total Exits | C24: =IF(COUNT(C22:C23)=0,"",SUM(C22:C23)) | D24: =IF(COUNT(D22:D23)=0,"",SUM(D22:D23)) | E24: ϝ
B25: Permanent Turnover (%) | C25: =IF(COUNT(C31,C32)<2,"",IF((C32+C31)=0,"",N(C22)/((C32+C31)/2))) | D25: =IF(COUNT(D31,D32)<2,"",IF((D32+D31)=0,"",N(D22)/((D32+D31)/2))) | E25: ϝ
B26: Temporary Turnover (%) | C26: =IF(COUNT(C31,C32)<2,"",IF((C32+C31)=0,"",N(C23)/((C32+C31)/2))) | D26: =IF(COUNT(D31,D32)<2,"",IF((D32+D31)=0,"",N(D23)/((D32+D31)/2))) | E26: ϝ
B27: Voluntary Terminations | D27: =IF(COUNT(C27:C27)=0,"",SUM(C27:C27)) | E27: ∑
B28: Involuntary Terminations | D28: =IF(COUNT(C28:C28)=0,"",SUM(C28:C28)) | E28: ∑
B29: Voluntary Turnover (%) | C29: =IF(COUNT(C31,C32)<2,"",IF((C32+C31)=0,"",N(C27)/((C32+C31)/2))) | D29: =IF(COUNT(D31,D32)<2,"",IF((D32+D31)=0,"",N(D27)/((D32+D31)/2))) | E29: ϝ
B30: Involuntary Turnover (%) | C30: =IF(COUNT(C31,C32)<2,"",IF((C32+C31)=0,"",N(C28)/((C32+C31)/2))) | D30: =IF(COUNT(D31,D32)<2,"",IF((D32+D31)=0,"",N(D28)/((D32+D31)/2))) | E30: ϝ
B31: Headcount last Month | C31: =IF(MAR!C5="","",MAR!C5) | D31: =IF(COUNT(C31:C31)=0,"",SUM(C31:C31)) | E31: ∑
B32: Headcount this Month | C32: =IF(C5="","",C5) | D32: =IF(COUNT(C32:C32)=0,"",SUM(C32:C32)) | E32: ∑
B33: Full Turnover (%) | C33: =IF(COUNT(C31,C32)<2,"",IF((C32+C31)=0,"",N(C24)/((C32+C31)/2))) | D33: =IF(COUNT(D31,D32)<2,"",IF((D32+D31)=0,"",N(D24)/((D32+D31)/2))) | E33: ϝ
B34: Permanent Vacancies | D34: =IF(COUNT(C34:C34)=0,"",SUM(C34:C34)) | E34: ∑
B35: Temporary Vacancies | D35: =IF(COUNT(C35:C35)=0,"",SUM(C35:C35)) | E35: ∑
B36: Total Vacancies | C36: =IF(COUNT(C34:C35)=0,"",SUM(C34:C35)) | D36: =IF(COUNT(D34:D35)=0,"",SUM(D34:D35)) | E36: ϝ
B37: Authorized Positions | C37: =IF(COUNT(C5,C36)=0,"",N(C5)+N(C36)) | D37: =IF(COUNT(D5,D36)=0,"",N(D5)+N(D36)) | E37: ϝ
B38: Vacancy Rate (%) | C38: =IFERROR(C36/C37,"") | D38: =IFERROR(D36/D37,"") | E38: ϝ
B39: Permanent TimeToHire (Days) YTD | C39: =IF('(GCG_HDQ)'!$AB$10="","",'(GCG_HDQ)'!$AB$10) | D39: =IFERROR(AVERAGE(C39:C39),"") | E39: Avg
B40: Temporary TimeToHire (Days) YTD | C40: =IF('(GCG_HDQ)'!$AD$10="","",'(GCG_HDQ)'!$AD$10) | D40: =IFERROR(AVERAGE(C40:C40),"") | E40: Avg
...

Sheet MAY
B1: GCG HDQ | C1: 1079
A2: =VALUE(TEXT(EDATE(DATE(LEFT(APR!A2,4),RIGHT(APR!A2,2),1),1),"yyyymm")) | B2: MAY | C2: GCG HDQ | D2: TOTAL | E2: Total by Division | F2: =N(F11)<>0
A3: =+A2 | B3: Permanent (Regular) Headcount | D3: =IF(COUNT(C3:C3)=0,"",SUM(C3:C3)) | E3: ∑
B4: Temporary (Fix Term) Headcount | D4: =IF(COUNT(C4:C4)=0,"",SUM(C4:C4)) | E4: ∑
B5: Employee Headcount (Productivity) | C5: =IF(COUNT(C3:C4)=0,"",SUM(C3:C4)) | D5: =IF(COUNT(D3:D4)=0,"",SUM(D3:D4)) | E5: ϝ
B6: Headcount = 1.00 | D6: =IF(COUNT(C6:C6)=0,"",SUM(C6:C6)) | E6: ∑
B7: Headcount = 0.75 | D7: =IF(COUNT(C7:C7)=0,"",SUM(C7:C7)) | E7: ∑
B8: Headcount = 0.50 | D8: =IF(COUNT(C8:C8)=0,"",SUM(C8:C8)) | E8: ∑
B9: Headcount = 0.25 | D9: =IF(COUNT(C9:C9)=0,"",SUM(C9:C9)) | E9: ∑
B10: Standard Monthly Hours (FTE basis) | D10: =IFERROR(AVERAGE(C10:C10),"") | E10: Avg
B11: Employee FTE (Finance) | C11: =IF(COUNT(C6:C9)=0,"",N(C6)+N(C7)*0.75+N(C8)*0.5+N(C9)*0.25) | D11: =IF(COUNT(D6:D9)=0,"",N(D6)+N(D7)*0.75+N(D8)*0.5+N(D9)*0.25) | E11: FTE | F11: =IF(COUNT(D5:D9)=0,"",N(D6)+N(D7)+N(D8)+N(D9)-N(D5))
B12: Subcontracted Workforce HC | D12: =IF(COUNT(C12:C12)=0,"",SUM(C12:C12)) | E12: ∑
B13: Subcontracted Productive Hours | D13: =IF(COUNT(C13:C13)=0,"",SUM(C13:C13)) | E13: ∑
B14: Subcontracted FTE | C14: =IFERROR(C13/C10,"") | D14: =IF(COUNT(C14:C14)=0,"",SUM(C14:C14)) | E14: FTE
B15: Total Operational Workforce | C15: =IF(COUNT(C5,C12)=0,"",SUM(C5,C12)) | D15: =IF(COUNT(D5,D12)=0,"",SUM(D5,D12)) | E15: ϝ
B16: Total Operational FTE | C16: =IF(COUNT(C11,C14)=0,"",SUM(C11,C14)) | D16: =IF(COUNT(D11,D14)=0,"",SUM(D11,D14)) | E16: FTE
B17: Subcontracted Share of Workforce (%) | C17: =IFERROR(C12/C15,"") | D17: =IFERROR(D12/D15,"") | E17: ϝ
B18: FTE HR Team | D18: =IF(COUNT(C18:C18)=0,"",SUM(C18:C18)) | E18: ∑
B19: Permanent Hires | D19: =IF(COUNT(C19:C19)=0,"",SUM(C19:C19)) | E19: ∑
B20: Temporary Hires | D20: =IF(COUNT(C20:C20)=0,"",SUM(C20:C20)) | E20: ∑
B21: Total Hires | C21: =IF(COUNT(C19:C20)=0,"",SUM(C19:C20)) | D21: =IF(COUNT(D19:D20)=0,"",SUM(D19:D20)) | E21: ϝ
B22: Permanent Exits | D22: =IF(COUNT(C22:C22)=0,"",SUM(C22:C22)) | E22: ∑
B23: Temporary Exits | D23: =IF(COUNT(C23:C23)=0,"",SUM(C23:C23)) | E23: ∑
B24: Total Exits | C24: =IF(COUNT(C22:C23)=0,"",SUM(C22:C23)) | D24: =IF(COUNT(D22:D23)=0,"",SUM(D22:D23)) | E24: ϝ
B25: Permanent Turnover (%) | C25: =IF(COUNT(C31,C32)<2,"",IF((C32+C31)=0,"",N(C22)/((C32+C31)/2))) | D25: =IF(COUNT(D31,D32)<2,"",IF((D32+D31)=0,"",N(D22)/((D32+D31)/2))) | E25: ϝ
B26: Temporary Turnover (%) | C26: =IF(COUNT(C31,C32)<2,"",IF((C32+C31)=0,"",N(C23)/((C32+C31)/2))) | D26: =IF(COUNT(D31,D32)<2,"",IF((D32+D31)=0,"",N(D23)/((D32+D31)/2))) | E26: ϝ
B27: Voluntary Terminations | D27: =IF(COUNT(C27:C27)=0,"",SUM(C27:C27)) | E27: ∑
B28: Involuntary Terminations | D28: =IF(COUNT(C28:C28)=0,"",SUM(C28:C28)) | E28: ∑
B29: Voluntary Turnover (%) | C29: =IF(COUNT(C31,C32)<2,"",IF((C32+C31)=0,"",N(C27)/((C32+C31)/2))) | D29: =IF(COUNT(D31,D32)<2,"",IF((D32+D31)=0,"",N(D27)/((D32+D31)/2))) | E29: ϝ
B30: Involuntary Turnover (%) | C30: =IF(COUNT(C31,C32)<2,"",IF((C32+C31)=0,"",N(C28)/((C32+C31)/2))) | D30: =IF(COUNT(D31,D32)<2,"",IF((D32+D31)=0,"",N(D28)/((D32+D31)/2))) | E30: ϝ
B31: Headcount last Month | C31: =IF(APR!C5="","",APR!C5) | D31: =IF(COUNT(C31:C31)=0,"",SUM(C31:C31)) | E31: ∑
B32: Headcount this Month | C32: =IF(C5="","",C5) | D32: =IF(COUNT(C32:C32)=0,"",SUM(C32:C32)) | E32: ∑
B33: Full Turnover (%) | C33: =IF(COUNT(C31,C32)<2,"",IF((C32+C31)=0,"",N(C24)/((C32+C31)/2))) | D33: =IF(COUNT(D31,D32)<2,"",IF((D32+D31)=0,"",N(D24)/((D32+D31)/2))) | E33: ϝ
B34: Permanent Vacancies | D34: =IF(COUNT(C34:C34)=0,"",SUM(C34:C34)) | E34: ∑
B35: Temporary Vacancies | D35: =IF(COUNT(C35:C35)=0,"",SUM(C35:C35)) | E35: ∑
B36: Total Vacancies | C36: =IF(COUNT(C34:C35)=0,"",SUM(C34:C35)) | D36: =IF(COUNT(D34:D35)=0,"",SUM(D34:D35)) | E36: ϝ
B37: Authorized Positions | C37: =IF(COUNT(C5,C36)=0,"",N(C5)+N(C36)) | D37: =IF(COUNT(D5,D36)=0,"",N(D5)+N(D36)) | E37: ϝ
B38: Vacancy Rate (%) | C38: =IFERROR(C36/C37,"") | D38: =IFERROR(D36/D37,"") | E38: ϝ
B39: Permanent TimeToHire (Days) YTD | C39: =IF('(GCG_HDQ)'!$AB$11="","",'(GCG_HDQ)'!$AB$11) | D39: =IFERROR(AVERAGE(C39:C39),"") | E39: Avg
B40: Temporary TimeToHire (Days) YTD | C40: =IF('(GCG_HDQ)'!$AD$11="","",'(GCG_HDQ)'!$AD$11) | D40: =IFERROR(AVERAGE(C40:C40),"") | E40: Avg
...

Sheet JUN
B1: GCG HDQ | C1: 1079
A2: =VALUE(TEXT(EDATE(DATE(LEFT(MAY!A2,4),RIGHT(MAY!A2,2),1),1),"yyyymm")) | B2: JUN | C2: GCG HDQ | D2: TOTAL | E2: Total by Division | F2: =N(F11)<>0
A3: =+A2 | B3: Permanent (Regular) Headcount | D3: =IF(COUNT(C3:C3)=0,"",SUM(C3:C3)) | E3: ∑
B4: Temporary (Fix Term) Headcount | D4: =IF(COUNT(C4:C4)=0,"",SUM(C4:C4)) | E4: ∑
B5: Employee Headcount (Productivity) | C5: =IF(COUNT(C3:C4)=0,"",SUM(C3:C4)) | D5: =IF(COUNT(D3:D4)=0,"",SUM(D3:D4)) | E5: ϝ
B6: Headcount = 1.00 | D6: =IF(COUNT(C6:C6)=0,"",SUM(C6:C6)) | E6: ∑
B7: Headcount = 0.75 | D7: =IF(COUNT(C7:C7)=0,"",SUM(C7:C7)) | E7: ∑
B8: Headcount = 0.50 | D8: =IF(COUNT(C8:C8)=0,"",SUM(C8:C8)) | E8: ∑
B9: Headcount = 0.25 | D9: =IF(COUNT(C9:C9)=0,"",SUM(C9:C9)) | E9: ∑
B10: Standard Monthly Hours (FTE basis) | D10: =IFERROR(AVERAGE(C10:C10),"") | E10: Avg
B11: Employee FTE (Finance) | C11: =IF(COUNT(C6:C9)=0,"",N(C6)+N(C7)*0.75+N(C8)*0.5+N(C9)*0.25) | D11: =IF(COUNT(D6:D9)=0,"",N(D6)+N(D7)*0.75+N(D8)*0.5+N(D9)*0.25) | E11: FTE | F11: =IF(COUNT(D5:D9)=0,"",N(D6)+N(D7)+N(D8)+N(D9)-N(D5))
B12: Subcontracted Workforce HC | D12: =IF(COUNT(C12:C12)=0,"",SUM(C12:C12)) | E12: ∑
B13: Subcontracted Productive Hours | D13: =IF(COUNT(C13:C13)=0,"",SUM(C13:C13)) | E13: ∑
B14: Subcontracted FTE | C14: =IFERROR(C13/C10,"") | D14: =IF(COUNT(C14:C14)=0,"",SUM(C14:C14)) | E14: FTE
B15: Total Operational Workforce | C15: =IF(COUNT(C5,C12)=0,"",SUM(C5,C12)) | D15: =IF(COUNT(D5,D12)=0,"",SUM(D5,D12)) | E15: ϝ
B16: Total Operational FTE | C16: =IF(COUNT(C11,C14)=0,"",SUM(C11,C14)) | D16: =IF(COUNT(D11,D14)=0,"",SUM(D11,D14)) | E16: FTE
B17: Subcontracted Share of Workforce (%) | C17: =IFERROR(C12/C15,"") | D17: =IFERROR(D12/D15,"") | E17: ϝ
B18: FTE HR Team | D18: =IF(COUNT(C18:C18)=0,"",SUM(C18:C18)) | E18: ∑
B19: Permanent Hires | D19: =IF(COUNT(C19:C19)=0,"",SUM(C19:C19)) | E19: ∑
B20: Temporary Hires | D20: =IF(COUNT(C20:C20)=0,"",SUM(C20:C20)) | E20: ∑
B21: Total Hires | C21: =IF(COUNT(C19:C20)=0,"",SUM(C19:C20)) | D21: =IF(COUNT(D19:D20)=0,"",SUM(D19:D20)) | E21: ϝ
B22: Permanent Exits | D22: =IF(COUNT(C22:C22)=0,"",SUM(C22:C22)) | E22: ∑
B23: Temporary Exits | D23: =IF(COUNT(C23:C23)=0,"",SUM(C23:C23)) | E23: ∑
B24: Total Exits | C24: =IF(COUNT(C22:C23)=0,"",SUM(C22:C23)) | D24: =IF(COUNT(D22:D23)=0,"",SUM(D22:D23)) | E24: ϝ
B25: Permanent Turnover (%) | C25: =IF(COUNT(C31,C32)<2,"",IF((C32+C31)=0,"",N(C22)/((C32+C31)/2))) | D25: =IF(COUNT(D31,D32)<2,"",IF((D32+D31)=0,"",N(D22)/((D32+D31)/2))) | E25: ϝ
B26: Temporary Turnover (%) | C26: =IF(COUNT(C31,C32)<2,"",IF((C32+C31)=0,"",N(C23)/((C32+C31)/2))) | D26: =IF(COUNT(D31,D32)<2,"",IF((D32+D31)=0,"",N(D23)/((D32+D31)/2))) | E26: ϝ
B27: Voluntary Terminations | D27: =IF(COUNT(C27:C27)=0,"",SUM(C27:C27)) | E27: ∑
B28: Involuntary Terminations | D28: =IF(COUNT(C28:C28)=0,"",SUM(C28:C28)) | E28: ∑
B29: Voluntary Turnover (%) | C29: =IF(COUNT(C31,C32)<2,"",IF((C32+C31)=0,"",N(C27)/((C32+C31)/2))) | D29: =IF(COUNT(D31,D32)<2,"",IF((D32+D31)=0,"",N(D27)/((D32+D31)/2))) | E29: ϝ
B30: Involuntary Turnover (%) | C30: =IF(COUNT(C31,C32)<2,"",IF((C32+C31)=0,"",N(C28)/((C32+C31)/2))) | D30: =IF(COUNT(D31,D32)<2,"",IF((D32+D31)=0,"",N(D28)/((D32+D31)/2))) | E30: ϝ
B31: Headcount last Month | C31: =IF(MAY!C5="","",MAY!C5) | D31: =IF(COUNT(C31:C31)=0,"",SUM(C31:C31)) | E31: ∑
B32: Headcount this Month | C32: =IF(C5="","",C5) | D32: =IF(COUNT(C32:C32)=0,"",SUM(C32:C32)) | E32: ∑
B33: Full Turnover (%) | C33: =IF(COUNT(C31,C32)<2,"",IF((C32+C31)=0,"",N(C24)/((C32+C31)/2))) | D33: =IF(COUNT(D31,D32)<2,"",IF((D32+D31)=0,"",N(D24)/((D32+D31)/2))) | E33: ϝ
B34: Permanent Vacancies | D34: =IF(COUNT(C34:C34)=0,"",SUM(C34:C34)) | E34: ∑
B35: Temporary Vacancies | D35: =IF(COUNT(C35:C35)=0,"",SUM(C35:C35)) | E35: ∑
B36: Total Vacancies | C36: =IF(COUNT(C34:C35)=0,"",SUM(C34:C35)) | D36: =IF(COUNT(D34:D35)=0,"",SUM(D34:D35)) | E36: ϝ
B37: Authorized Positions | C37: =IF(COUNT(C5,C36)=0,"",N(C5)+N(C36)) | D37: =IF(COUNT(D5,D36)=0,"",N(D5)+N(D36)) | E37: ϝ
B38: Vacancy Rate (%) | C38: =IFERROR(C36/C37,"") | D38: =IFERROR(D36/D37,"") | E38: ϝ
B39: Permanent TimeToHire (Days) YTD | C39: =IF('(GCG_HDQ)'!$AB$12="","",'(GCG_HDQ)'!$AB$12) | D39: =IFERROR(AVERAGE(C39:C39),"") | E39: Avg
B40: Temporary TimeToHire (Days) YTD | C40: =IF('(GCG_HDQ)'!$AD$12="","",'(GCG_HDQ)'!$AD$12) | D40: =IFERROR(AVERAGE(C40:C40),"") | E40: Avg
...

Sheet JUL
B1: GCG HDQ | C1: 1079
A2: =VALUE(TEXT(EDATE(DATE(LEFT(JUN!A2,4),RIGHT(JUN!A2,2),1),1),"yyyymm")) | B2: JUL | C2: GCG HDQ | D2: TOTAL | E2: Total by Division | F2: =N(F11)<>0
A3: =+A2 | B3: Permanent (Regular) Headcount | D3: =IF(COUNT(C3:C3)=0,"",SUM(C3:C3)) | E3: ∑
B4: Temporary (Fix Term) Headcount | D4: =IF(COUNT(C4:C4)=0,"",SUM(C4:C4)) | E4: ∑
B5: Employee Headcount (Productivity) | C5: =IF(COUNT(C3:C4)=0,"",SUM(C3:C4)) | D5: =IF(COUNT(D3:D4)=0,"",SUM(D3:D4)) | E5: ϝ
B6: Headcount = 1.00 | D6: =IF(COUNT(C6:C6)=0,"",SUM(C6:C6)) | E6: ∑
B7: Headcount = 0.75 | D7: =IF(COUNT(C7:C7)=0,"",SUM(C7:C7)) | E7: ∑
B8: Headcount = 0.50 | D8: =IF(COUNT(C8:C8)=0,"",SUM(C8:C8)) | E8: ∑
B9: Headcount = 0.25 | D9: =IF(COUNT(C9:C9)=0,"",SUM(C9:C9)) | E9: ∑
B10: Standard Monthly Hours (FTE basis) | D10: =IFERROR(AVERAGE(C10:C10),"") | E10: Avg
B11: Employee FTE (Finance) | C11: =IF(COUNT(C6:C9)=0,"",N(C6)+N(C7)*0.75+N(C8)*0.5+N(C9)*0.25) | D11: =IF(COUNT(D6:D9)=0,"",N(D6)+N(D7)*0.75+N(D8)*0.5+N(D9)*0.25) | E11: FTE | F11: =IF(COUNT(D5:D9)=0,"",N(D6)+N(D7)+N(D8)+N(D9)-N(D5))
B12: Subcontracted Workforce HC | D12: =IF(COUNT(C12:C12)=0,"",SUM(C12:C12)) | E12: ∑
B13: Subcontracted Productive Hours | D13: =IF(COUNT(C13:C13)=0,"",SUM(C13:C13)) | E13: ∑
B14: Subcontracted FTE | C14: =IFERROR(C13/C10,"") | D14: =IF(COUNT(C14:C14)=0,"",SUM(C14:C14)) | E14: FTE
B15: Total Operational Workforce | C15: =IF(COUNT(C5,C12)=0,"",SUM(C5,C12)) | D15: =IF(COUNT(D5,D12)=0,"",SUM(D5,D12)) | E15: ϝ
B16: Total Operational FTE | C16: =IF(COUNT(C11,C14)=0,"",SUM(C11,C14)) | D16: =IF(COUNT(D11,D14)=0,"",SUM(D11,D14)) | E16: FTE
B17: Subcontracted Share of Workforce (%) | C17: =IFERROR(C12/C15,"") | D17: =IFERROR(D12/D15,"") | E17: ϝ
B18: FTE HR Team | D18: =IF(COUNT(C18:C18)=0,"",SUM(C18:C18)) | E18: ∑
B19: Permanent Hires | D19: =IF(COUNT(C19:C19)=0,"",SUM(C19:C19)) | E19: ∑
B20: Temporary Hires | D20: =IF(COUNT(C20:C20)=0,"",SUM(C20:C20)) | E20: ∑
B21: Total Hires | C21: =IF(COUNT(C19:C20)=0,"",SUM(C19:C20)) | D21: =IF(COUNT(D19:D20)=0,"",SUM(D19:D20)) | E21: ϝ
B22: Permanent Exits | D22: =IF(COUNT(C22:C22)=0,"",SUM(C22:C22)) | E22: ∑
B23: Temporary Exits | D23: =IF(COUNT(C23:C23)=0,"",SUM(C23:C23)) | E23: ∑
B24: Total Exits | C24: =IF(COUNT(C22:C23)=0,"",SUM(C22:C23)) | D24: =IF(COUNT(D22:D23)=0,"",SUM(D22:D23)) | E24: ϝ
B25: Permanent Turnover (%) | C25: =IF(COUNT(C31,C32)<2,"",IF((C32+C31)=0,"",N(C22)/((C32+C31)/2))) | D25: =IF(COUNT(D31,D32)<2,"",IF((D32+D31)=0,"",N(D22)/((D32+D31)/2))) | E25: ϝ
B26: Temporary Turnover (%) | C26: =IF(COUNT(C31,C32)<2,"",IF((C32+C31)=0,"",N(C23)/((C32+C31)/2))) | D26: =IF(COUNT(D31,D32)<2,"",IF((D32+D31)=0,"",N(D23)/((D32+D31)/2))) | E26: ϝ
B27: Voluntary Terminations | D27: =IF(COUNT(C27:C27)=0,"",SUM(C27:C27)) | E27: ∑
B28: Involuntary Terminations | D28: =IF(COUNT(C28:C28)=0,"",SUM(C28:C28)) | E28: ∑
B29: Voluntary Turnover (%) | C29: =IF(COUNT(C31,C32)<2,"",IF((C32+C31)=0,"",N(C27)/((C32+C31)/2))) | D29: =IF(COUNT(D31,D32)<2,"",IF((D32+D31)=0,"",N(D27)/((D32+D31)/2))) | E29: ϝ
