Workbook

Sheet Quarter
B1: GCG NORTH CARIBBEAN
A2: FY2027 | B2: Quarter | C2: OCT | D2: NOV | E2: DEC | F2: ∑Q1 | G2: JAN | H2: FEB | I2: MAR | J2: ∑Q2 | K2: APR | L2: MAY | M2: JUN | N2: ∑Q3 | O2: JUL | P2: AUG | Q2: SEP | R2: ∑Q4 | S2: FY2027
B3: Permanent (Regular) Headcount | C3: =OCT!J3 | D3: =NOV!J3 | E3: =DEC!J3 | F3: =IFERROR(AVERAGE(C3:E3),"") | G3: =JAN!J3 | H3: =FEB!J3 | I3: =MAR!J3 | J3: =IFERROR(AVERAGE(G3:I3),"") | K3: =APR!J3 | L3: =MAY!J3 | M3: =JUN!J3 | N3: =IFERROR(AVERAGE(K3:M3),"") | O3: =JUL!J3 | P3: =AUG!J3 | Q3: =SEP!J3 | R3: =IFERROR(AVERAGE(O3:Q3),"") | S3: =IFERROR(AVERAGE(C3:E3,G3:I3,K3:M3,O3:Q3),"")
B4: Temporary (Fix Term) Headcount | C4: =OCT!J4 | D4: =NOV!J4 | E4: =DEC!J4 | F4: =IFERROR(AVERAGE(C4:E4),"") | G4: =JAN!J4 | H4: =FEB!J4 | I4: =MAR!J4 | J4: =IFERROR(AVERAGE(G4:I4),"") | K4: =APR!J4 | L4: =MAY!J4 | M4: =JUN!J4 | N4: =IFERROR(AVERAGE(K4:M4),"") | O4: =JUL!J4 | P4: =AUG!J4 | Q4: =SEP!J4 | R4: =IFERROR(AVERAGE(O4:Q4),"") | S4: =IFERROR(AVERAGE(C4:E4,G4:I4,K4:M4,O4:Q4),"")
B5: Employee Headcount (Productivity) | C5: =OCT!J5 | D5: =NOV!J5 | E5: =DEC!J5 | F5: =IF(COUNT(F3:F4)=0,"",SUM(F3:F4)) | G5: =JAN!J5 | H5: =FEB!J5 | I5: =MAR!J5 | J5: =IF(COUNT(J3:J4)=0,"",SUM(J3:J4)) | K5: =APR!J5 | L5: =MAY!J5 | M5: =JUN!J5 | N5: =IF(COUNT(N3:N4)=0,"",SUM(N3:N4)) | O5: =JUL!J5 | P5: =AUG!J5 | Q5: =SEP!J5 | R5: =IF(COUNT(R3:R4)=0,"",SUM(R3:R4)) | S5: =IF(COUNT(S3:S4)=0,"",SUM(S3:S4))
B6: Headcount = 1.00 | C6: =OCT!J6 | D6: =NOV!J6 | E6: =DEC!J6 | F6: =IFERROR(AVERAGE(C6:E6),"") | G6: =JAN!J6 | H6: =FEB!J6 | I6: =MAR!J6 | J6: =IFERROR(AVERAGE(G6:I6),"") | K6: =APR!J6 | L6: =MAY!J6 | M6: =JUN!J6 | N6: =IFERROR(AVERAGE(K6:M6),"") | O6: =JUL!J6 | P6: =AUG!J6 | Q6: =SEP!J6 | R6: =IFERROR(AVERAGE(O6:Q6),"") | S6: =IFERROR(AVERAGE(C6:E6,G6:I6,K6:M6,O6:Q6),"")
B7: Headcount = 0.75 | C7: =OCT!J7 | D7: =NOV!J7 | E7: =DEC!J7 | F7: =IFERROR(AVERAGE(C7:E7),"") | G7: =JAN!J7 | H7: =FEB!J7 | I7: =MAR!J7 | J7: =IFERROR(AVERAGE(G7:I7),"") | K7: =APR!J7 | L7: =MAY!J7 | M7: =JUN!J7 | N7: =IFERROR(AVERAGE(K7:M7),"") | O7: =JUL!J7 | P7: =AUG!J7 | Q7: =SEP!J7 | R7: =IFERROR(AVERAGE(O7:Q7),"") | S7: =IFERROR(AVERAGE(C7:E7,G7:I7,K7:M7,O7:Q7),"")
B8: Headcount = 0.50 | C8: =OCT!J8 | D8: =NOV!J8 | E8: =DEC!J8 | F8: =IFERROR(AVERAGE(C8:E8),"") | G8: =JAN!J8 | H8: =FEB!J8 | I8: =MAR!J8 | J8: =IFERROR(AVERAGE(G8:I8),"") | K8: =APR!J8 | L8: =MAY!J8 | M8: =JUN!J8 | N8: =IFERROR(AVERAGE(K8:M8),"") | O8: =JUL!J8 | P8: =AUG!J8 | Q8: =SEP!J8 | R8: =IFERROR(AVERAGE(O8:Q8),"") | S8: =IFERROR(AVERAGE(C8:E8,G8:I8,K8:M8,O8:Q8),"")
B9: Headcount = 0.25 | C9: =OCT!J9 | D9: =NOV!J9 | E9: =DEC!J9 | F9: =IFERROR(AVERAGE(C9:E9),"") | G9: =JAN!J9 | H9: =FEB!J9 | I9: =MAR!J9 | J9: =IFERROR(AVERAGE(G9:I9),"") | K9: =APR!J9 | L9: =MAY!J9 | M9: =JUN!J9 | N9: =IFERROR(AVERAGE(K9:M9),"") | O9: =JUL!J9 | P9: =AUG!J9 | Q9: =SEP!J9 | R9: =IFERROR(AVERAGE(O9:Q9),"") | S9: =IFERROR(AVERAGE(C9:E9,G9:I9,K9:M9,O9:Q9),"")
B10: Standard Monthly Hours (FTE basis) | C10: =OCT!J10 | D10: =NOV!J10 | E10: =DEC!J10 | F10: =IFERROR(AVERAGE(C10:E10),"") | G10: =JAN!J10 | H10: =FEB!J10 | I10: =MAR!J10 | J10: =IFERROR(AVERAGE(G10:I10),"") | K10: =APR!J10 | L10: =MAY!J10 | M10: =JUN!J10 | N10: =IFERROR(AVERAGE(K10:M10),"") | O10: =JUL!J10 | P10: =AUG!J10 | Q10: =SEP!J10 | R10: =IFERROR(AVERAGE(O10:Q10),"") | S10: =IFERROR(AVERAGE(C10:E10,G10:I10,K10:M10,O10:Q10),"")
B11: Employee FTE (Finance) | C11: =OCT!J11 | D11: =NOV!J11 | E11: =DEC!J11 | F11: =IF(COUNT(F6:F9)=0,"",N(F6)+N(F7)*0.75+N(F8)*0.5+N(F9)*0.25) | G11: =JAN!J11 | H11: =FEB!J11 | I11: =MAR!J11 | J11: =IF(COUNT(J6:J9)=0,"",N(J6)+N(J7)*0.75+N(J8)*0.5+N(J9)*0.25) | K11: =APR!J11 | L11: =MAY!J11 | M11: =JUN!J11 | N11: =IF(COUNT(N6:N9)=0,"",N(N6)+N(N7)*0.75+N(N8)*0.5+N(N9)*0.25) | O11: =JUL!J11 | P11: =AUG!J11 | Q11: =SEP!J11 | R11: =IF(COUNT(R6:R9)=0,"",N(R6)+N(R7)*0.75+N(R8)*0.5+N(R9)*0.25) | S11: =IF(COUNT(S6:S9)=0,"",N(S6)+N(S7)*0.75+N(S8)*0.5+N(S9)*0.25)
B12: Subcontracted Workforce HC | C12: =OCT!J12 | D12: =NOV!J12 | E12: =DEC!J12 | F12: =IFERROR(AVERAGE(C12:E12),"") | G12: =JAN!J12 | H12: =FEB!J12 | I12: =MAR!J12 | J12: =IFERROR(AVERAGE(G12:I12),"") | K12: =APR!J12 | L12: =MAY!J12 | M12: =JUN!J12 | N12: =IFERROR(AVERAGE(K12:M12),"") | O12: =JUL!J12 | P12: =AUG!J12 | Q12: =SEP!J12 | R12: =IFERROR(AVERAGE(O12:Q12),"") | S12: =IFERROR(AVERAGE(C12:E12,G12:I12,K12:M12,O12:Q12),"")
B13: Subcontracted Productive Hours | C13: =OCT!J13 | D13: =NOV!J13 | E13: =DEC!J13 | F13: =IFERROR(AVERAGE(C13:E13),"") | G13: =JAN!J13 | H13: =FEB!J13 | I13: =MAR!J13 | J13: =IFERROR(AVERAGE(G13:I13),"") | K13: =APR!J13 | L13: =MAY!J13 | M13: =JUN!J13 | N13: =IFERROR(AVERAGE(K13:M13),"") | O13: =JUL!J13 | P13: =AUG!J13 | Q13: =SEP!J13 | R13: =IFERROR(AVERAGE(O13:Q13),"") | S13: =IFERROR(AVERAGE(C13:E13,G13:I13,K13:M13,O13:Q13),"")
B14: Subcontracted FTE | C14: =OCT!J14 | D14: =NOV!J14 | E14: =DEC!J14 | F14: =IFERROR(F13/F10,"") | G14: =JAN!J14 | H14: =FEB!J14 | I14: =MAR!J14 | J14: =IFERROR(J13/J10,"") | K14: =APR!J14 | L14: =MAY!J14 | M14: =JUN!J14 | N14: =IFERROR(N13/N10,"") | O14: =JUL!J14 | P14: =AUG!J14 | Q14: =SEP!J14 | R14: =IFERROR(R13/R10,"") | S14: =IFERROR(S13/S10,"")
B15: Total Operational Workforce | C15: =OCT!J15 | D15: =NOV!J15 | E15: =DEC!J15 | F15: =IF(COUNT(F5,F12)=0,"",SUM(F5,F12)) | G15: =JAN!J15 | H15: =FEB!J15 | I15: =MAR!J15 | J15: =IF(COUNT(J5,J12)=0,"",SUM(J5,J12)) | K15: =APR!J15 | L15: =MAY!J15 | M15: =JUN!J15 | N15: =IF(COUNT(N5,N12)=0,"",SUM(N5,N12)) | O15: =JUL!J15 | P15: =AUG!J15 | Q15: =SEP!J15 | R15: =IF(COUNT(R5,R12)=0,"",SUM(R5,R12)) | S15: =IF(COUNT(S5,S12)=0,"",SUM(S5,S12))
B16: Total Operational FTE | C16: =OCT!J16 | D16: =NOV!J16 | E16: =DEC!J16 | F16: =IF(COUNT(F11,F14)=0,"",SUM(F11,F14)) | G16: =JAN!J16 | H16: =FEB!J16 | I16: =MAR!J16 | J16: =IF(COUNT(J11,J14)=0,"",SUM(J11,J14)) | K16: =APR!J16 | L16: =MAY!J16 | M16: =JUN!J16 | N16: =IF(COUNT(N11,N14)=0,"",SUM(N11,N14)) | O16: =JUL!J16 | P16: =AUG!J16 | Q16: =SEP!J16 | R16: =IF(COUNT(R11,R14)=0,"",SUM(R11,R14)) | S16: =IF(COUNT(S11,S14)=0,"",SUM(S11,S14))
B17: Subcontracted Share of Workforce (%) | C17: =OCT!J17 | D17: =NOV!J17 | E17: =DEC!J17 | F17: =IFERROR(F12/F15,"") | G17: =JAN!J17 | H17: =FEB!J17 | I17: =MAR!J17 | J17: =IFERROR(J12/J15,"") | K17: =APR!J17 | L17: =MAY!J17 | M17: =JUN!J17 | N17: =IFERROR(N12/N15,"") | O17: =JUL!J17 | P17: =AUG!J17 | Q17: =SEP!J17 | R17: =IFERROR(R12/R15,"") | S17: =IFERROR(S12/S15,"")
B18: FTE HR Team | C18: =OCT!J18 | D18: =NOV!J18 | E18: =DEC!J18 | F18: =IFERROR(AVERAGE(C18:E18),"") | G18: =JAN!J18 | H18: =FEB!J18 | I18: =MAR!J18 | J18: =IFERROR(AVERAGE(G18:I18),"") | K18: =APR!J18 | L18: =MAY!J18 | M18: =JUN!J18 | N18: =IFERROR(AVERAGE(K18:M18),"") | O18: =JUL!J18 | P18: =AUG!J18 | Q18: =SEP!J18 | R18: =IFERROR(AVERAGE(O18:Q18),"") | S18: =IFERROR(AVERAGE(C18:E18,G18:I18,K18:M18,O18:Q18),"")
B19: Permanent Hires | C19: =OCT!J19 | D19: =NOV!J19 | E19: =DEC!J19 | F19: =IF(COUNT(C19:E19)=0,"",SUM(C19:E19)) | G19: =JAN!J19 | H19: =FEB!J19 | I19: =MAR!J19 | J19: =IF(COUNT(G19:I19)=0,"",SUM(G19:I19)) | K19: =APR!J19 | L19: =MAY!J19 | M19: =JUN!J19 | N19: =IF(COUNT(K19:M19)=0,"",SUM(K19:M19)) | O19: =JUL!J19 | P19: =AUG!J19 | Q19: =SEP!J19 | R19: =IF(COUNT(O19:Q19)=0,"",SUM(O19:Q19)) | S19: =IF(COUNT(C19:E19,G19:I19,K19:M19,O19:Q19)=0,"",SUM(C19:E19,G19:I19,K19:M19,O19:Q19))
B20: Temporary Hires | C20: =OCT!J20 | D20: =NOV!J20 | E20: =DEC!J20 | F20: =IF(COUNT(C20:E20)=0,"",SUM(C20:E20)) | G20: =JAN!J20 | H20: =FEB!J20 | I20: =MAR!J20 | J20: =IF(COUNT(G20:I20)=0,"",SUM(G20:I20)) | K20: =APR!J20 | L20: =MAY!J20 | M20: =JUN!J20 | N20: =IF(COUNT(K20:M20)=0,"",SUM(K20:M20)) | O20: =JUL!J20 | P20: =AUG!J20 | Q20: =SEP!J20 | R20: =IF(COUNT(O20:Q20)=0,"",SUM(O20:Q20)) | S20: =IF(COUNT(C20:E20,G20:I20,K20:M20,O20:Q20)=0,"",SUM(C20:E20,G20:I20,K20:M20,O20:Q20))
B21: Total Hires | C21: =OCT!J21 | D21: =NOV!J21 | E21: =DEC!J21 | F21: =IF(COUNT(F19:F20)=0,"",SUM(F19:F20)) | G21: =JAN!J21 | H21: =FEB!J21 | I21: =MAR!J21 | J21: =IF(COUNT(J19:J20)=0,"",SUM(J19:J20)) | K21: =APR!J21 | L21: =MAY!J21 | M21: =JUN!J21 | N21: =IF(COUNT(N19:N20)=0,"",SUM(N19:N20)) | O21: =JUL!J21 | P21: =AUG!J21 | Q21: =SEP!J21 | R21: =IF(COUNT(R19:R20)=0,"",SUM(R19:R20)) | S21: =IF(COUNT(S19:S20)=0,"",SUM(S19:S20))
B22: Permanent Exits | C22: =OCT!J22 | D22: =NOV!J22 | E22: =DEC!J22 | F22: =IF(COUNT(C22:E22)=0,"",SUM(C22:E22)) | G22: =JAN!J22 | H22: =FEB!J22 | I22: =MAR!J22 | J22: =IF(COUNT(G22:I22)=0,"",SUM(G22:I22)) | K22: =APR!J22 | L22: =MAY!J22 | M22: =JUN!J22 | N22: =IF(COUNT(K22:M22)=0,"",SUM(K22:M22)) | O22: =JUL!J22 | P22: =AUG!J22 | Q22: =SEP!J22 | R22: =IF(COUNT(O22:Q22)=0,"",SUM(O22:Q22)) | S22: =IF(COUNT(C22:E22,G22:I22,K22:M22,O22:Q22)=0,"",SUM(C22:E22,G22:I22,K22:M22,O22:Q22))
B23: Temporary Exits | C23: =OCT!J23 | D23: =NOV!J23 | E23: =DEC!J23 | F23: =IF(COUNT(C23:E23)=0,"",SUM(C23:E23)) | G23: =JAN!J23 | H23: =FEB!J23 | I23: =MAR!J23 | J23: =IF(COUNT(G23:I23)=0,"",SUM(G23:I23)) | K23: =APR!J23 | L23: =MAY!J23 | M23: =JUN!J23 | N23: =IF(COUNT(K23:M23)=0,"",SUM(K23:M23)) | O23: =JUL!J23 | P23: =AUG!J23 | Q23: =SEP!J23 | R23: =IF(COUNT(O23:Q23)=0,"",SUM(O23:Q23)) | S23: =IF(COUNT(C23:E23,G23:I23,K23:M23,O23:Q23)=0,"",SUM(C23:E23,G23:I23,K23:M23,O23:Q23))
B24: Total Exits | C24: =OCT!J24 | D24: =NOV!J24 | E24: =DEC!J24 | F24: =IF(COUNT(F22:F23)=0,"",SUM(F22:F23)) | G24: =JAN!J24 | H24: =FEB!J24 | I24: =MAR!J24 | J24: =IF(COUNT(J22:J23)=0,"",SUM(J22:J23)) | K24: =APR!J24 | L24: =MAY!J24 | M24: =JUN!J24 | N24: =IF(COUNT(N22:N23)=0,"",SUM(N22:N23)) | O24: =JUL!J24 | P24: =AUG!J24 | Q24: =SEP!J24 | R24: =IF(COUNT(R22:R23)=0,"",SUM(R22:R23)) | S24: =IF(COUNT(S22:S23)=0,"",SUM(S22:S23))
B25: Permanent Turnover (%) | C25: =OCT!J25 | D25: =NOV!J25 | E25: =DEC!J25 | F25: =IF(COUNT(F31,F32)<2,"",IF((F32+F31)=0,"",N(F22)/((F32+F31)/2))) | G25: =JAN!J25 | H25: =FEB!J25 | I25: =MAR!J25 | J25: =IF(COUNT(J31,J32)<2,"",IF((J32+J31)=0,"",N(J22)/((J32+J31)/2))) | K25: =APR!J25 | L25: =MAY!J25 | M25: =JUN!J25 | N25: =IF(COUNT(N31,N32)<2,"",IF((N32+N31)=0,"",N(N22)/((N32+N31)/2))) | O25: =JUL!J25 | P25: =AUG!J25 | Q25: =SEP!J25 | R25: =IF(COUNT(R31,R32)<2,"",IF((R32+R31)=0,"",N(R22)/((R32+R31)/2))) | S25: =IF(COUNT(S31,S32)<2,"",IF((S32+S31)=0,"",N(S22)/((S32+S31)/2)))
B26: Temporary Turnover (%) | C26: =OCT!J26 | D26: =NOV!J26 | E26: =DEC!J26 | F26: =IF(COUNT(F31,F32)<2,"",IF((F32+F31)=0,"",N(F23)/((F32+F31)/2))) | G26: =JAN!J26 | H26: =FEB!J26 | I26: =MAR!J26 | J26: =IF(COUNT(J31,J32)<2,"",IF((J32+J31)=0,"",N(J23)/((J32+J31)/2))) | K26: =APR!J26 | L26: =MAY!J26 | M26: =JUN!J26 | N26: =IF(COUNT(N31,N32)<2,"",IF((N32+N31)=0,"",N(N23)/((N32+N31)/2))) | O26: =JUL!J26 | P26: =AUG!J26 | Q26: =SEP!J26 | R26: =IF(COUNT(R31,R32)<2,"",IF((R32+R31)=0,"",N(R23)/((R32+R31)/2))) | S26: =IF(COUNT(S31,S32)<2,"",IF((S32+S31)=0,"",N(S23)/((S32+S31)/2)))
B27: Voluntary Terminations | C27: =OCT!J27 | D27: =NOV!J27 | E27: =DEC!J27 | F27: =IF(COUNT(C27:E27)=0,"",SUM(C27:E27)) | G27: =JAN!J27 | H27: =FEB!J27 | I27: =MAR!J27 | J27: =IF(COUNT(G27:I27)=0,"",SUM(G27:I27)) | K27: =APR!J27 | L27: =MAY!J27 | M27: =JUN!J27 | N27: =IF(COUNT(K27:M27)=0,"",SUM(K27:M27)) | O27: =JUL!J27 | P27: =AUG!J27 | Q27: =SEP!J27 | R27: =IF(COUNT(O27:Q27)=0,"",SUM(O27:Q27)) | S27: =IF(COUNT(C27:E27,G27:I27,K27:M27,O27:Q27)=0,"",SUM(C27:E27,G27:I27,K27:M27,O27:Q27))
B28: Involuntary Terminations | C28: =OCT!J28 | D28: =NOV!J28 | E28: =DEC!J28 | F28: =IF(COUNT(C28:E28)=0,"",SUM(C28:E28)) | G28: =JAN!J28 | H28: =FEB!J28 | I28: =MAR!J28 | J28: =IF(COUNT(G28:I28)=0,"",SUM(G28:I28)) | K28: =APR!J28 | L28: =MAY!J28 | M28: =JUN!J28 | N28: =IF(COUNT(K28:M28)=0,"",SUM(K28:M28)) | O28: =JUL!J28 | P28: =AUG!J28 | Q28: =SEP!J28 | R28: =IF(COUNT(O28:Q28)=0,"",SUM(O28:Q28)) | S28: =IF(COUNT(C28:E28,G28:I28,K28:M28,O28:Q28)=0,"",SUM(C28:E28,G28:I28,K28:M28,O28:Q28))
B29: Voluntary Turnover (%) | C29: =OCT!J29 | D29: =NOV!J29 | E29: =DEC!J29 | F29: =IF(COUNT(F31,F32)<2,"",IF((F32+F31)=0,"",N(F27)/((F32+F31)/2))) | G29: =JAN!J29 | H29: =FEB!J29 | I29: =MAR!J29 | J29: =IF(COUNT(J31,J32)<2,"",IF((J32+J31)=0,"",N(J27)/((J32+J31)/2))) | K29: =APR!J29 | L29: =MAY!J29 | M29: =JUN!J29 | N29: =IF(COUNT(N31,N32)<2,"",IF((N32+N31)=0,"",N(N27)/((N32+N31)/2))) | O29: =JUL!J29 | P29: =AUG!J29 | Q29: =SEP!J29 | R29: =IF(COUNT(R31,R32)<2,"",IF((R32+R31)=0,"",N(R27)/((R32+R31)/2))) | S29: =IF(COUNT(S31,S32)<2,"",IF((S32+S31)=0,"",N(S27)/((S32+S31)/2)))
B30: Involuntary Turnover (%) | C30: =OCT!J30 | D30: =NOV!J30 | E30: =DEC!J30 | F30: =IF(COUNT(F31,F32)<2,"",IF((F32+F31)=0,"",N(F28)/((F32+F31)/2))) | G30: =JAN!J30 | H30: =FEB!J30 | I30: =MAR!J30 | J30: =IF(COUNT(J31,J32)<2,"",IF((J32+J31)=0,"",N(J28)/((J32+J31)/2))) | K30: =APR!J30 | L30: =MAY!J30 | M30: =JUN!J30 | N30: =IF(COUNT(N31,N32)<2,"",IF((N32+N31)=0,"",N(N28)/((N32+N31)/2))) | O30: =JUL!J30 | P30: =AUG!J30 | Q30: =SEP!J30 | R30: =IF(COUNT(R31,R32)<2,"",IF((R32+R31)=0,"",N(R28)/((R32+R31)/2))) | S30: =IF(COUNT(S31,S32)<2,"",IF((S32+S31)=0,"",N(S28)/((S32+S31)/2)))
B31: Headcount last Month | C31: =OCT!J31 | D31: =NOV!J31 | E31: =DEC!J31 | F31: =IFERROR(AVERAGE(C31:E31),"") | G31: =JAN!J31 | H31: =FEB!J31 | I31: =MAR!J31 | J31: =IFERROR(AVERAGE(G31:I31),"") | K31: =APR!J31 | L31: =MAY!J31 | M31: =JUN!J31 | N31: =IFERROR(AVERAGE(K31:M31),"") | O31: =JUL!J31 | P31: =AUG!J31 | Q31: =SEP!J31 | R31: =IFERROR(AVERAGE(O31:Q31),"") | S31: =IFERROR(AVERAGE(C31:E31,G31:I31,K31:M31,O31:Q31),"")
B32: Headcount this Month | C32: =OCT!J32 | D32: =NOV!J32 | E32: =DEC!J32 | F32: =IFERROR(AVERAGE(C32:E32),"") | G32: =JAN!J32 | H32: =FEB!J32 | I32: =MAR!J32 | J32: =IFERROR(AVERAGE(G32:I32),"") | K32: =APR!J32 | L32: =MAY!J32 | M32: =JUN!J32 | N32: =IFERROR(AVERAGE(K32:M32),"") | O32: =JUL!J32 | P32: =AUG!J32 | Q32: =SEP!J32 | R32: =IFERROR(AVERAGE(O32:Q32),"") | S32: =IFERROR(AVERAGE(C32:E32,G32:I32,K32:M32,O32:Q32),"")
B33: Full Turnover (%) | C33: =OCT!J33 | D33: =NOV!J33 | E33: =DEC!J33 | F33: =IF(COUNT(F31,F32)<2,"",IF((F32+F31)=0,"",N(F24)/((F32+F31)/2))) | G33: =JAN!J33 | H33: =FEB!J33 | I33: =MAR!J33 | J33: =IF(COUNT(J31,J32)<2,"",IF((J32+J31)=0,"",N(J24)/((J32+J31)/2))) | K33: =APR!J33 | L33: =MAY!J33 | M33: =JUN!J33 | N33: =IF(COUNT(N31,N32)<2,"",IF((N32+N31)=0,"",N(N24)/((N32+N31)/2))) | O33: =JUL!J33 | P33: =AUG!J33 | Q33: =SEP!J33 | R33: =IF(COUNT(R31,R32)<2,"",IF((R32+R31)=0,"",N(R24)/((R32+R31)/2))) | S33: =IF(COUNT(S31,S32)<2,"",IF((S32+S31)=0,"",N(S24)/((S32+S31)/2)))
B34: Permanent Vacancies | C34: =OCT!J34 | D34: =NOV!J34 | E34: =DEC!J34 | F34: =IFERROR(AVERAGE(C34:E34),"") | G34: =JAN!J34 | H34: =FEB!J34 | I34: =MAR!J34 | J34: =IFERROR(AVERAGE(G34:I34),"") | K34: =APR!J34 | L34: =MAY!J34 | M34: =JUN!J34 | N34: =IFERROR(AVERAGE(K34:M34),"") | O34: =JUL!J34 | P34: =AUG!J34 | Q34: =SEP!J34 | R34: =IFERROR(AVERAGE(O34:Q34),"") | S34: =IFERROR(AVERAGE(C34:E34,G34:I34,K34:M34,O34:Q34),"")
B35: Temporary Vacancies | C35: =OCT!J35 | D35: =NOV!J35 | E35: =DEC!J35 | F35: =IFERROR(AVERAGE(C35:E35),"") | G35: =JAN!J35 | H35: =FEB!J35 | I35: =MAR!J35 | J35: =IFERROR(AVERAGE(G35:I35),"") | K35: =APR!J35 | L35: =MAY!J35 | M35: =JUN!J35 | N35: =IFERROR(AVERAGE(K35:M35),"") | O35: =JUL!J35 | P35: =AUG!J35 | Q35: =SEP!J35 | R35: =IFERROR(AVERAGE(O35:Q35),"") | S35: =IFERROR(AVERAGE(C35:E35,G35:I35,K35:M35,O35:Q35),"")
B36: Total Vacancies | C36: =OCT!J36 | D36: =NOV!J36 | E36: =DEC!J36 | F36: =IF(COUNT(F34:F35)=0,"",SUM(F34:F35)) | G36: =JAN!J36 | H36: =FEB!J36 | I36: =MAR!J36 | J36: =IF(COUNT(J34:J35)=0,"",SUM(J34:J35)) | K36: =APR!J36 | L36: =MAY!J36 | M36: =JUN!J36 | N36: =IF(COUNT(N34:N35)=0,"",SUM(N34:N35)) | O36: =JUL!J36 | P36: =AUG!J36 | Q36: =SEP!J36 | R36: =IF(COUNT(R34:R35)=0,"",SUM(R34:R35)) | S36: =IF(COUNT(S34:S35)=0,"",SUM(S34:S35))
B37: Authorized Positions | C37: =OCT!J37 | D37: =NOV!J37 | E37: =DEC!J37 | F37: =IF(COUNT(F5,F36)=0,"",N(F5)+N(F36)) | G37: =JAN!J37 | H37: =FEB!J37 | I37: =MAR!J37 | J37: =IF(COUNT(J5,J36)=0,"",N(J5)+N(J36)) | K37: =APR!J37 | L37: =MAY!J37 | M37: =JUN!J37 | N37: =IF(COUNT(N5,N36)=0,"",N(N5)+N(N36)) | O37: =JUL!J37 | P37: =AUG!J37 | Q37: =SEP!J37 | R37: =IF(COUNT(R5,R36)=0,"",N(R5)+N(R36)) | S37: =IF(COUNT(S5,S36)=0,"",N(S5)+N(S36))
B38: Vacancy Rate (%) | C38: =OCT!J38 | D38: =NOV!J38 | E38: =DEC!J38 | F38: =IFERROR(F36/F37,"") | G38: =JAN!J38 | H38: =FEB!J38 | I38: =MAR!J38 | J38: =IFERROR(J36/J37,"") | K38: =APR!J38 | L38: =MAY!J38 | M38: =JUN!J38 | N38: =IFERROR(N36/N37,"") | O38: =JUL!J38 | P38: =AUG!J38 | Q38: =SEP!J38 | R38: =IFERROR(R36/R37,"") | S38: =IFERROR(S36/S37,"")
B39: Permanent TimeToHire (Days) YTD | C39: =OCT!J39 | D39: =NOV!J39 | E39: =DEC!J39 | F39: =IFERROR(LOOKUP(2,1/ISNUMBER(C39:E39),C39:E39),"") | G39: =JAN!J39 | H39: =FEB!J39 | I39: =MAR!J39 | J39: =IFERROR(LOOKUP(2,1/ISNUMBER(G39:I39),G39:I39),"") | K39: =APR!J39 | L39: =MAY!J39 | M39: =JUN!J39 | N39: =IFERROR(LOOKUP(2,1/ISNUMBER(K39:M39),K39:M39),"") | O39: =JUL!J39 | P39: =AUG!J39 | Q39: =SEP!J39 | R39: =IFERROR(LOOKUP(2,1/ISNUMBER(O39:Q39),O39:Q39),"") | S39: =IFERROR(LOOKUP(2,1/ISNUMBER(C39:Q39),C39:Q39),"")
B40: Temporary TimeToHire (Days) YTD | C40: =OCT!J40 | D40: =NOV!J40 | E40: =DEC!J40 | F40: =IFERROR(LOOKUP(2,1/ISNUMBER(C40:E40),C40:E40),"") | G40: =JAN!J40 | H40: =FEB!J40 | I40: =MAR!J40 | J40: =IFERROR(LOOKUP(2,1/ISNUMBER(G40:I40),G40:I40),"") | K40: =APR!J40 | L40: =MAY!J40 | M40: =JUN!J40 | N40: =IFERROR(LOOKUP(2,1/ISNUMBER(K40:M40),K40:M40),"") | O40: =JUL!J40 | P40: =AUG!J40 | Q40: =SEP!J40 | R40: =IFERROR(LOOKUP(2,1/ISNUMBER(O40:Q40),O40:Q40),"") | S40: =IFERROR(LOOKUP(2,1/ISNUMBER(C40:Q40),C40:Q40),"")
...

Sheet OCT
B1: GCG NORTH CARIBBEAN | C1: 1062 | D1: 1075 | E1: 1044 | F1: 1066 | G1: 1158 | H1: 1067 | I1: 1046
A2: 202610 | B2: OCT | C2: GCG Antigua | D2: GCG Grand Cayman | E2: GCG Aviation Ground Jamaica | F2: GCG Jamaica | G2: GCG Aviation Ground Saint Lucia | H2: GCG Saint Lucia | I2: GCG Ground Saint Thomas | J2: TOTAL | K2: Total by Division | L2: =N(L11)<>0
A3: =+A2 | B3: Permanent (Regular) Headcount | J3: =IF(COUNT(C3:I3)=0,"",SUM(C3:I3)) | K3: ∑
B4: Temporary (Fix Term) Headcount | J4: =IF(COUNT(C4:I4)=0,"",SUM(C4:I4)) | K4: ∑
B5: Employee Headcount (Productivity) | C5: =IF(COUNT(C3:C4)=0,"",SUM(C3:C4)) | D5: =IF(COUNT(D3:D4)=0,"",SUM(D3:D4)) | E5: =IF(COUNT(E3:E4)=0,"",SUM(E3:E4)) | F5: =IF(COUNT(F3:F4)=0,"",SUM(F3:F4)) | G5: =IF(COUNT(G3:G4)=0,"",SUM(G3:G4)) | H5: =IF(COUNT(H3:H4)=0,"",SUM(H3:H4)) | I5: =IF(COUNT(I3:I4)=0,"",SUM(I3:I4)) | J5: =IF(COUNT(J3:J4)=0,"",SUM(J3:J4)) | K5: ϝ
B6: Headcount = 1.00 | J6: =IF(COUNT(C6:I6)=0,"",SUM(C6:I6)) | K6: ∑
B7: Headcount = 0.75 | J7: =IF(COUNT(C7:I7)=0,"",SUM(C7:I7)) | K7: ∑
B8: Headcount = 0.50 | J8: =IF(COUNT(C8:I8)=0,"",SUM(C8:I8)) | K8: ∑
B9: Headcount = 0.25 | J9: =IF(COUNT(C9:I9)=0,"",SUM(C9:I9)) | K9: ∑
B10: Standard Monthly Hours (FTE basis) | J10: =IFERROR(AVERAGE(C10:I10),"") | K10: Avg
B11: Employee FTE (Finance) | C11: =IF(COUNT(C6:C9)=0,"",N(C6)+N(C7)*0.75+N(C8)*0.5+N(C9)*0.25) | D11: =IF(COUNT(D6:D9)=0,"",N(D6)+N(D7)*0.75+N(D8)*0.5+N(D9)*0.25) | E11: =IF(COUNT(E6:E9)=0,"",N(E6)+N(E7)*0.75+N(E8)*0.5+N(E9)*0.25) | F11: =IF(COUNT(F6:F9)=0,"",N(F6)+N(F7)*0.75+N(F8)*0.5+N(F9)*0.25) | G11: =IF(COUNT(G6:G9)=0,"",N(G6)+N(G7)*0.75+N(G8)*0.5+N(G9)*0.25) | H11: =IF(COUNT(H6:H9)=0,"",N(H6)+N(H7)*0.75+N(H8)*0.5+N(H9)*0.25) | I11: =IF(COUNT(I6:I9)=0,"",N(I6)+N(I7)*0.75+N(I8)*0.5+N(I9)*0.25) | J11: =IF(COUNT(J6:J9)=0,"",N(J6)+N(J7)*0.75+N(J8)*0.5+N(J9)*0.25) | K11: FTE | L11: =IF(COUNT(J5:J9)=0,"",N(J6)+N(J7)+N(J8)+N(J9)-N(J5))
B12: Subcontracted Workforce HC | J12: =IF(COUNT(C12:I12)=0,"",SUM(C12:I12)) | K12: ∑
B13: Subcontracted Productive Hours | J13: =IF(COUNT(C13:I13)=0,"",SUM(C13:I13)) | K13: ∑
B14: Subcontracted FTE | C14: =IFERROR(C13/C10,"") | D14: =IFERROR(D13/D10,"") | E14: =IFERROR(E13/E10,"") | F14: =IFERROR(F13/F10,"") | G14: =IFERROR(G13/G10,"") | H14: =IFERROR(H13/H10,"") | I14: =IFERROR(I13/I10,"") | J14: =IF(COUNT(C14:I14)=0,"",SUM(C14:I14)) | K14: FTE
B15: Total Operational Workforce | C15: =IF(COUNT(C5,C12)=0,"",SUM(C5,C12)) | D15: =IF(COUNT(D5,D12)=0,"",SUM(D5,D12)) | E15: =IF(COUNT(E5,E12)=0,"",SUM(E5,E12)) | F15: =IF(COUNT(F5,F12)=0,"",SUM(F5,F12)) | G15: =IF(COUNT(G5,G12)=0,"",SUM(G5,G12)) | H15: =IF(COUNT(H5,H12)=0,"",SUM(H5,H12)) | I15: =IF(COUNT(I5,I12)=0,"",SUM(I5,I12)) | J15: =IF(COUNT(J5,J12)=0,"",SUM(J5,J12)) | K15: ϝ
B16: Total Operational FTE | C16: =IF(COUNT(C11,C14)=0,"",SUM(C11,C14)) | D16: =IF(COUNT(D11,D14)=0,"",SUM(D11,D14)) | E16: =IF(COUNT(E11,E14)=0,"",SUM(E11,E14)) | F16: =IF(COUNT(F11,F14)=0,"",SUM(F11,F14)) | G16: =IF(COUNT(G11,G14)=0,"",SUM(G11,G14)) | H16: =IF(COUNT(H11,H14)=0,"",SUM(H11,H14)) | I16: =IF(COUNT(I11,I14)=0,"",SUM(I11,I14)) | J16: =IF(COUNT(J11,J14)=0,"",SUM(J11,J14)) | K16: FTE
B17: Subcontracted Share of Workforce (%) | C17: =IFERROR(C12/C15,"") | D17: =IFERROR(D12/D15,"") | E17: =IFERROR(E12/E15,"") | F17: =IFERROR(F12/F15,"") | G17: =IFERROR(G12/G15,"") | H17: =IFERROR(H12/H15,"") | I17: =IFERROR(I12/I15,"") | J17: =IFERROR(J12/J15,"") | K17: ϝ
B18: FTE HR Team | J18: =IF(COUNT(C18:I18)=0,"",SUM(C18:I18)) | K18: ∑
B19: Permanent Hires | J19: =IF(COUNT(C19:I19)=0,"",SUM(C19:I19)) | K19: ∑
B20: Temporary Hires | J20: =IF(COUNT(C20:I20)=0,"",SUM(C20:I20)) | K20: ∑
B21: Total Hires | C21: =IF(COUNT(C19:C20)=0,"",SUM(C19:C20)) | D21: =IF(COUNT(D19:D20)=0,"",SUM(D19:D20)) | E21: =IF(COUNT(E19:E20)=0,"",SUM(E19:E20)) | F21: =IF(COUNT(F19:F20)=0,"",SUM(F19:F20)) | G21: =IF(COUNT(G19:G20)=0,"",SUM(G19:G20)) | H21: =IF(COUNT(H19:H20)=0,"",SUM(H19:H20)) | I21: =IF(COUNT(I19:I20)=0,"",SUM(I19:I20)) | J21: =IF(COUNT(J19:J20)=0,"",SUM(J19:J20)) | K21: ϝ
B22: Permanent Exits | J22: =IF(COUNT(C22:I22)=0,"",SUM(C22:I22)) | K22: ∑
B23: Temporary Exits | J23: =IF(COUNT(C23:I23)=0,"",SUM(C23:I23)) | K23: ∑
B24: Total Exits | C24: =IF(COUNT(C22:C23)=0,"",SUM(C22:C23)) | D24: =IF(COUNT(D22:D23)=0,"",SUM(D22:D23)) | E24: =IF(COUNT(E22:E23)=0,"",SUM(E22:E23)) | F24: =IF(COUNT(F22:F23)=0,"",SUM(F22:F23)) | G24: =IF(COUNT(G22:G23)=0,"",SUM(G22:G23)) | H24: =IF(COUNT(H22:H23)=0,"",SUM(H22:H23)) | I24: =IF(COUNT(I22:I23)=0,"",SUM(I22:I23)) | J24: =IF(COUNT(J22:J23)=0,"",SUM(J22:J23)) | K24: ϝ
B25: Permanent Turnover (%) | C25: =IF(COUNT(C31,C32)<2,"",IF((C32+C31)=0,"",N(C22)/((C32+C31)/2))) | D25: =IF(COUNT(D31,D32)<2,"",IF((D32+D31)=0,"",N(D22)/((D32+D31)/2))) | E25: =IF(COUNT(E31,E32)<2,"",IF((E32+E31)=0,"",N(E22)/((E32+E31)/2))) | F25: =IF(COUNT(F31,F32)<2,"",IF((F32+F31)=0,"",N(F22)/((F32+F31)/2))) | G25: =IF(COUNT(G31,G32)<2,"",IF((G32+G31)=0,"",N(G22)/((G32+G31)/2))) | H25: =IF(COUNT(H31,H32)<2,"",IF((H32+H31)=0,"",N(H22)/((H32+H31)/2))) | I25: =IF(COUNT(I31,I32)<2,"",IF((I32+I31)=0,"",N(I22)/((I32+I31)/2))) | J25: =IF(COUNT(J31,J32)<2,"",IF((J32+J31)=0,"",N(J22)/((J32+J31)/2))) | K25: ϝ
B26: Temporary Turnover (%) | C26: =IF(COUNT(C31,C32)<2,"",IF((C32+C31)=0,"",N(C23)/((C32+C31)/2))) | D26: =IF(COUNT(D31,D32)<2,"",IF((D32+D31)=0,"",N(D23)/((D32+D31)/2))) | E26: =IF(COUNT(E31,E32)<2,"",IF((E32+E31)=0,"",N(E23)/((E32+E31)/2))) | F26: =IF(COUNT(F31,F32)<2,"",IF((F32+F31)=0,"",N(F23)/((F32+F31)/2))) | G26: =IF(COUNT(G31,G32)<2,"",IF((G32+G31)=0,"",N(G23)/((G32+G31)/2))) | H26: =IF(COUNT(H31,H32)<2,"",IF((H32+H31)=0,"",N(H23)/((H32+H31)/2))) | I26: =IF(COUNT(I31,I32)<2,"",IF((I32+I31)=0,"",N(I23)/((I32+I31)/2))) | J26: =IF(COUNT(J31,J32)<2,"",IF((J32+J31)=0,"",N(J23)/((J32+J31)/2))) | K26: ϝ
B27: Voluntary Terminations | J27: =IF(COUNT(C27:I27)=0,"",SUM(C27:I27)) | K27: ∑
B28: Involuntary Terminations | J28: =IF(COUNT(C28:I28)=0,"",SUM(C28:I28)) | K28: ∑
B29: Voluntary Turnover (%) | C29: =IF(COUNT(C31,C32)<2,"",IF((C32+C31)=0,"",N(C27)/((C32+C31)/2))) | D29: =IF(COUNT(D31,D32)<2,"",IF((D32+D31)=0,"",N(D27)/((D32+D31)/2))) | E29: =IF(COUNT(E31,E32)<2,"",IF((E32+E31)=0,"",N(E27)/((E32+E31)/2))) | F29: =IF(COUNT(F31,F32)<2,"",IF((F32+F31)=0,"",N(F27)/((F32+F31)/2))) | G29: =IF(COUNT(G31,G32)<2,"",IF((G32+G31)=0,"",N(G27)/((G32+G31)/2))) | H29: =IF(COUNT(H31,H32)<2,"",IF((H32+H31)=0,"",N(H27)/((H32+H31)/2))) | I29: =IF(COUNT(I31,I32)<2,"",IF((I32+I31)=0,"",N(I27)/((I32+I31)/2))) | J29: =IF(COUNT(J31,J32)<2,"",IF((J32+J31)=0,"",N(J27)/((J32+J31)/2))) | K29: ϝ
B30: Involuntary Turnover (%) | C30: =IF(COUNT(C31,C32)<2,"",IF((C32+C31)=0,"",N(C28)/((C32+C31)/2))) | D30: =IF(COUNT(D31,D32)<2,"",IF((D32+D31)=0,"",N(D28)/((D32+D31)/2))) | E30: =IF(COUNT(E31,E32)<2,"",IF((E32+E31)=0,"",N(E28)/((E32+E31)/2))) | F30: =IF(COUNT(F31,F32)<2,"",IF((F32+F31)=0,"",N(F28)/((F32+F31)/2))) | G30: =IF(COUNT(G31,G32)<2,"",IF((G32+G31)=0,"",N(G28)/((G32+G31)/2))) | H30: =IF(COUNT(H31,H32)<2,"",IF((H32+H31)=0,"",N(H28)/((H32+H31)/2))) | I30: =IF(COUNT(I31,I32)<2,"",IF((I32+I31)=0,"",N(I28)/((I32+I31)/2))) | J30: =IF(COUNT(J31,J32)<2,"",IF((J32+J31)=0,"",N(J28)/((J32+J31)/2))) | K30: ϝ
B31: Headcount last Month | J31: =IF(COUNT(C31:I31)=0,"",SUM(C31:I31)) | K31: ∑
B32: Headcount this Month | C32: =IF(C5="","",C5) | D32: =IF(D5="","",D5) | E32: =IF(E5="","",E5) | F32: =IF(F5="","",F5) | G32: =IF(G5="","",G5) | H32: =IF(H5="","",H5) | I32: =IF(I5="","",I5) | J32: =IF(COUNT(C32:I32)=0,"",SUM(C32:I32)) | K32: ∑
B33: Full Turnover (%) | C33: =IF(COUNT(C31,C32)<2,"",IF((C32+C31)=0,"",N(C24)/((C32+C31)/2))) | D33: =IF(COUNT(D31,D32)<2,"",IF((D32+D31)=0,"",N(D24)/((D32+D31)/2))) | E33: =IF(COUNT(E31,E32)<2,"",IF((E32+E31)=0,"",N(E24)/((E32+E31)/2))) | F33: =IF(COUNT(F31,F32)<2,"",IF((F32+F31)=0,"",N(F24)/((F32+F31)/2))) | G33: =IF(COUNT(G31,G32)<2,"",IF((G32+G31)=0,"",N(G24)/((G32+G31)/2))) | H33: =IF(COUNT(H31,H32)<2,"",IF((H32+H31)=0,"",N(H24)/((H32+H31)/2))) | I33: =IF(COUNT(I31,I32)<2,"",IF((I32+I31)=0,"",N(I24)/((I32+I31)/2))) | J33: =IF(COUNT(J31,J32)<2,"",IF((J32+J31)=0,"",N(J24)/((J32+J31)/2))) | K33: ϝ
B34: Permanent Vacancies | J34: =IF(COUNT(C34:I34)=0,"",SUM(C34:I34)) | K34: ∑
B35: Temporary Vacancies | J35: =IF(COUNT(C35:I35)=0,"",SUM(C35:I35)) | K35: ∑
B36: Total Vacancies | C36: =IF(COUNT(C34:C35)=0,"",SUM(C34:C35)) | D36: =IF(COUNT(D34:D35)=0,"",SUM(D34:D35)) | E36: =IF(COUNT(E34:E35)=0,"",SUM(E34:E35)) | F36: =IF(COUNT(F34:F35)=0,"",SUM(F34:F35)) | G36: =IF(COUNT(G34:G35)=0,"",SUM(G34:G35)) | H36: =IF(COUNT(H34:H35)=0,"",SUM(H34:H35)) | I36: =IF(COUNT(I34:I35)=0,"",SUM(I34:I35)) | J36: =IF(COUNT(J34:J35)=0,"",SUM(J34:J35)) | K36: ϝ
B37: Authorized Positions | C37: =IF(COUNT(C5,C36)=0,"",N(C5)+N(C36)) | D37: =IF(COUNT(D5,D36)=0,"",N(D5)+N(D36)) | E37: =IF(COUNT(E5,E36)=0,"",N(E5)+N(E36)) | F37: =IF(COUNT(F5,F36)=0,"",N(F5)+N(F36)) | G37: =IF(COUNT(G5,G36)=0,"",N(G5)+N(G36)) | H37: =IF(COUNT(H5,H36)=0,"",N(H5)+N(H36)) | I37: =IF(COUNT(I5,I36)=0,"",N(I5)+N(I36)) | J37: =IF(COUNT(J5,J36)=0,"",N(J5)+N(J36)) | K37: ϝ
B38: Vacancy Rate (%) | C38: =IFERROR(C36/C37,"") | D38: =IFERROR(D36/D37,"") | E38: =IFERROR(E36/E37,"") | F38: =IFERROR(F36/F37,"") | G38: =IFERROR(G36/G37,"") | H38: =IFERROR(H36/H37,"") | I38: =IFERROR(I36/I37,"") | J38: =IFERROR(J36/J37,"") | K38: ϝ
B39: Permanent TimeToHire (Days) YTD | C39: =IF('(GCG_ATG)'!$AB$4="","",'(GCG_ATG)'!$AB$4) | D39: =IF('(GCG_GCM)'!$AB$4="","",'(GCG_GCM)'!$AB$4) | E39: =IF('(Ground_JAM)'!$AB$4="","",'(Ground_JAM)'!$AB$4) | F39: =IF('(GCG_JAM)'!$AB$4="","",'(GCG_JAM)'!$AB$4) | G39: =IF('(Ground_LCA)'!$AB$4="","",'(Ground_LCA)'!$AB$4) | H39: =IF('(GCG_LCA)'!$AB$4="","",'(GCG_LCA)'!$AB$4) | I39: =IF('(Ground_STT)'!$AB$4="","",'(Ground_STT)'!$AB$4) | J39: =IFERROR(AVERAGE(C39:I39),"") | K39: Avg
B40: Temporary TimeToHire (Days) YTD | C40: =IF('(GCG_ATG)'!$AD$4="","",'(GCG_ATG)'!$AD$4) | D40: =IF('(GCG_GCM)'!$AD$4="","",'(GCG_GCM)'!$AD$4) | E40: =IF('(Ground_JAM)'!$AD$4="","",'(Ground_JAM)'!$AD$4) | F40: =IF('(GCG_JAM)'!$AD$4="","",'(GCG_JAM)'!$AD$4) | G40: =IF('(Ground_LCA)'!$AD$4="","",'(Ground_LCA)'!$AD$4) | H40: =IF('(GCG_LCA)'!$AD$4="","",'(GCG_LCA)'!$AD$4) | I40: =IF('(Ground_STT)'!$AD$4="","",'(Ground_STT)'!$AD$4) | J40: =IFERROR(AVERAGE(C40:I40),"") | K40: Avg
...

Sheet NOV
B1: GCG NORTH CARIBBEAN | C1: 1062 | D1: 1075 | E1: 1044 | F1: 1066 | G1: 1158 | H1: 1067 | I1: 1046
A2: =VALUE(TEXT(EDATE(DATE(LEFT(OCT!A2,4),RIGHT(OCT!A2,2),1),1),"yyyymm")) | B2: NOV | C2: GCG Antigua | D2: GCG Grand Cayman | E2: GCG Aviation Ground Jamaica | F2: GCG Jamaica | G2: GCG Aviation Ground Saint Lucia | H2: GCG Saint Lucia | I2: GCG Ground Saint Thomas | J2: TOTAL | K2: Total by Division | L2: =N(L11)<>0
A3: =+A2 | B3: Permanent (Regular) Headcount | J3: =IF(COUNT(C3:I3)=0,"",SUM(C3:I3)) | K3: ∑
B4: Temporary (Fix Term) Headcount | J4: =IF(COUNT(C4:I4)=0,"",SUM(C4:I4)) | K4: ∑
B5: Employee Headcount (Productivity) | C5: =IF(COUNT(C3:C4)=0,"",SUM(C3:C4)) | D5: =IF(COUNT(D3:D4)=0,"",SUM(D3:D4)) | E5: =IF(COUNT(E3:E4)=0,"",SUM(E3:E4)) | F5: =IF(COUNT(F3:F4)=0,"",SUM(F3:F4)) | G5: =IF(COUNT(G3:G4)=0,"",SUM(G3:G4)) | H5: =IF(COUNT(H3:H4)=0,"",SUM(H3:H4)) | I5: =IF(COUNT(I3:I4)=0,"",SUM(I3:I4)) | J5: =IF(COUNT(J3:J4)=0,"",SUM(J3:J4)) | K5: ϝ
B6: Headcount = 1.00 | J6: =IF(COUNT(C6:I6)=0,"",SUM(C6:I6)) | K6: ∑
B7: Headcount = 0.75 | J7: =IF(COUNT(C7:I7)=0,"",SUM(C7:I7)) | K7: ∑
B8: Headcount = 0.50 | J8: =IF(COUNT(C8:I8)=0,"",SUM(C8:I8)) | K8: ∑
B9: Headcount = 0.25 | J9: =IF(COUNT(C9:I9)=0,"",SUM(C9:I9)) | K9: ∑
B10: Standard Monthly Hours (FTE basis) | J10: =IFERROR(AVERAGE(C10:I10),"") | K10: Avg
B11: Employee FTE (Finance) | C11: =IF(COUNT(C6:C9)=0,"",N(C6)+N(C7)*0.75+N(C8)*0.5+N(C9)*0.25) | D11: =IF(COUNT(D6:D9)=0,"",N(D6)+N(D7)*0.75+N(D8)*0.5+N(D9)*0.25) | E11: =IF(COUNT(E6:E9)=0,"",N(E6)+N(E7)*0.75+N(E8)*0.5+N(E9)*0.25) | F11: =IF(COUNT(F6:F9)=0,"",N(F6)+N(F7)*0.75+N(F8)*0.5+N(F9)*0.25) | G11: =IF(COUNT(G6:G9)=0,"",N(G6)+N(G7)*0.75+N(G8)*0.5+N(G9)*0.25) | H11: =IF(COUNT(H6:H9)=0,"",N(H6)+N(H7)*0.75+N(H8)*0.5+N(H9)*0.25) | I11: =IF(COUNT(I6:I9)=0,"",N(I6)+N(I7)*0.75+N(I8)*0.5+N(I9)*0.25) | J11: =IF(COUNT(J6:J9)=0,"",N(J6)+N(J7)*0.75+N(J8)*0.5+N(J9)*0.25) | K11: FTE | L11: =IF(COUNT(J5:J9)=0,"",N(J6)+N(J7)+N(J8)+N(J9)-N(J5))
B12: Subcontracted Workforce HC | J12: =IF(COUNT(C12:I12)=0,"",SUM(C12:I12)) | K12: ∑
B13: Subcontracted Productive Hours | J13: =IF(COUNT(C13:I13)=0,"",SUM(C13:I13)) | K13: ∑
B14: Subcontracted FTE | C14: =IFERROR(C13/C10,"") | D14: =IFERROR(D13/D10,"") | E14: =IFERROR(E13/E10,"") | F14: =IFERROR(F13/F10,"") | G14: =IFERROR(G13/G10,"") | H14: =IFERROR(H13/H10,"") | I14: =IFERROR(I13/I10,"") | J14: =IF(COUNT(C14:I14)=0,"",SUM(C14:I14)) | K14: FTE
B15: Total Operational Workforce | C15: =IF(COUNT(C5,C12)=0,"",SUM(C5,C12)) | D15: =IF(COUNT(D5,D12)=0,"",SUM(D5,D12)) | E15: =IF(COUNT(E5,E12)=0,"",SUM(E5,E12)) | F15: =IF(COUNT(F5,F12)=0,"",SUM(F5,F12)) | G15: =IF(COUNT(G5,G12)=0,"",SUM(G5,G12)) | H15: =IF(COUNT(H5,H12)=0,"",SUM(H5,H12)) | I15: =IF(COUNT(I5,I12)=0,"",SUM(I5,I12)) | J15: =IF(COUNT(J5,J12)=0,"",SUM(J5,J12)) | K15: ϝ
B16: Total Operational FTE | C16: =IF(COUNT(C11,C14)=0,"",SUM(C11,C14)) | D16: =IF(COUNT(D11,D14)=0,"",SUM(D11,D14)) | E16: =IF(COUNT(E11,E14)=0,"",SUM(E11,E14)) | F16: =IF(COUNT(F11,F14)=0,"",SUM(F11,F14)) | G16: =IF(COUNT(G11,G14)=0,"",SUM(G11,G14)) | H16: =IF(COUNT(H11,H14)=0,"",SUM(H11,H14)) | I16: =IF(COUNT(I11,I14)=0,"",SUM(I11,I14)) | J16: =IF(COUNT(J11,J14)=0,"",SUM(J11,J14)) | K16: FTE
B17: Subcontracted Share of Workforce (%) | C17: =IFERROR(C12/C15,"") | D17: =IFERROR(D12/D15,"") | E17: =IFERROR(E12/E15,"") | F17: =IFERROR(F12/F15,"") | G17: =IFERROR(G12/G15,"") | H17: =IFERROR(H12/H15,"") | I17: =IFERROR(I12/I15,"") | J17: =IFERROR(J12/J15,"") | K17: ϝ
B18: FTE HR Team | J18: =IF(COUNT(C18:I18)=0,"",SUM(C18:I18)) | K18: ∑
B19: Permanent Hires | J19: =IF(COUNT(C19:I19)=0,"",SUM(C19:I19)) | K19: ∑
B20: Temporary Hires | J20: =IF(COUNT(C20:I20)=0,"",SUM(C20:I20)) | K20: ∑
B21: Total Hires | C21: =IF(COUNT(C19:C20)=0,"",SUM(C19:C20)) | D21: =IF(COUNT(D19:D20)=0,"",SUM(D19:D20)) | E21: =IF(COUNT(E19:E20)=0,"",SUM(E19:E20)) | F21: =IF(COUNT(F19:F20)=0,"",SUM(F19:F20)) | G21: =IF(COUNT(G19:G20)=0,"",SUM(G19:G20)) | H21: =IF(COUNT(H19:H20)=0,"",SUM(H19:H20)) | I21: =IF(COUNT(I19:I20)=0,"",SUM(I19:I20)) | J21: =IF(COUNT(J19:J20)=0,"",SUM(J19:J20)) | K21: ϝ
B22: Permanent Exits | J22: =IF(COUNT(C22:I22)=0,"",SUM(C22:I22)) | K22: ∑
B23: Temporary Exits | J23: =IF(COUNT(C23:I23)=0,"",SUM(C23:I23)) | K23: ∑
B24: Total Exits | C24: =IF(COUNT(C22:C23)=0,"",SUM(C22:C23)) | D24: =IF(COUNT(D22:D23)=0,"",SUM(D22:D23)) | E24: =IF(COUNT(E22:E23)=0,"",SUM(E22:E23)) | F24: =IF(COUNT(F22:F23)=0,"",SUM(F22:F23)) | G24: =IF(COUNT(G22:G23)=0,"",SUM(G22:G23)) | H24: =IF(COUNT(H22:H23)=0,"",SUM(H22:H23)) | I24: =IF(COUNT(I22:I23)=0,"",SUM(I22:I23)) | J24: =IF(COUNT(J22:J23)=0,"",SUM(J22:J23)) | K24: ϝ
B25: Permanent Turnover (%) | C25: =IF(COUNT(C31,C32)<2,"",IF((C32+C31)=0,"",N(C22)/((C32+C31)/2))) | D25: =IF(COUNT(D31,D32)<2,"",IF((D32+D31)=0,"",N(D22)/((D32+D31)/2))) | E25: =IF(COUNT(E31,E32)<2,"",IF((E32+E31)=0,"",N(E22)/((E32+E31)/2))) | F25: =IF(COUNT(F31,F32)<2,"",IF((F32+F31)=0,"",N(F22)/((F32+F31)/2))) | G25: =IF(COUNT(G31,G32)<2,"",IF((G32+G31)=0,"",N(G22)/((G32+G31)/2))) | H25: =IF(COUNT(H31,H32)<2,"",IF((H32+H31)=0,"",N(H22)/((H32+H31)/2))) | I25: =IF(COUNT(I31,I32)<2,"",IF((I32+I31)=0,"",N(I22)/((I32+I31)/2))) | J25: =IF(COUNT(J31,J32)<2,"",IF((J32+J31)=0,"",N(J22)/((J32+J31)/2))) | K25: ϝ
B26: Temporary Turnover (%) | C26: =IF(COUNT(C31,C32)<2,"",IF((C32+C31)=0,"",N(C23)/((C32+C31)/2))) | D26: =IF(COUNT(D31,D32)<2,"",IF((D32+D31)=0,"",N(D23)/((D32+D31)/2))) | E26: =IF(COUNT(E31,E32)<2,"",IF((E32+E31)=0,"",N(E23)/((E32+E31)/2))) | F26: =IF(COUNT(F31,F32)<2,"",IF((F32+F31)=0,"",N(F23)/((F32+F31)/2))) | G26: =IF(COUNT(G31,G32)<2,"",IF((G32+G31)=0,"",N(G23)/((G32+G31)/2))) | H26: =IF(COUNT(H31,H32)<2,"",IF((H32+H31)=0,"",N(H23)/((H32+H31)/2))) | I26: =IF(COUNT(I31,I32)<2,"",IF((I32+I31)=0,"",N(I23)/((I32+I31)/2))) | J26: =IF(COUNT(J31,J32)<2,"",IF((J32+J31)=0,"",N(J23)/((J32+J31)/2))) | K26: ϝ
B27: Voluntary Terminations | J27: =IF(COUNT(C27:I27)=0,"",SUM(C27:I27)) | K27: ∑
B28: Involuntary Terminations | J28: =IF(COUNT(C28:I28)=0,"",SUM(C28:I28)) | K28: ∑
B29: Voluntary Turnover (%) | C29: =IF(COUNT(C31,C32)<2,"",IF((C32+C31)=0,"",N(C27)/((C32+C31)/2))) | D29: =IF(COUNT(D31,D32)<2,"",IF((D32+D31)=0,"",N(D27)/((D32+D31)/2))) | E29: =IF(COUNT(E31,E32)<2,"",IF((E32+E31)=0,"",N(E27)/((E32+E31)/2))) | F29: =IF(COUNT(F31,F32)<2,"",IF((F32+F31)=0,"",N(F27)/((F32+F31)/2))) | G29: =IF(COUNT(G31,G32)<2,"",IF((G32+G31)=0,"",N(G27)/((G32+G31)/2))) | H29: =IF(COUNT(H31,H32)<2,"",IF((H32+H31)=0,"",N(H27)/((H32+H31)/2))) | I29: =IF(COUNT(I31,I32)<2,"",IF((I32+I31)=0,"",N(I27)/((I32+I31)/2))) | J29: =IF(COUNT(J31,J32)<2,"",IF((J32+J31)=0,"",N(J27)/((J32+J31)/2))) | K29: ϝ
B30: Involuntary Turnover (%) | C30: =IF(COUNT(C31,C32)<2,"",IF((C32+C31)=0,"",N(C28)/((C32+C31)/2))) | D30: =IF(COUNT(D31,D32)<2,"",IF((D32+D31)=0,"",N(D28)/((D32+D31)/2))) | E30: =IF(COUNT(E31,E32)<2,"",IF((E32+E31)=0,"",N(E28)/((E32+E31)/2))) | F30: =IF(COUNT(F31,F32)<2,"",IF((F32+F31)=0,"",N(F28)/((F32+F31)/2))) | G30: =IF(COUNT(G31,G32)<2,"",IF((G32+G31)=0,"",N(G28)/((G32+G31)/2))) | H30: =IF(COUNT(H31,H32)<2,"",IF((H32+H31)=0,"",N(H28)/((H32+H31)/2))) | I30: =IF(COUNT(I31,I32)<2,"",IF((I32+I31)=0,"",N(I28)/((I32+I31)/2))) | J30: =IF(COUNT(J31,J32)<2,"",IF((J32+J31)=0,"",N(J28)/((J32+J31)/2))) | K30: ϝ
B31: Headcount last Month | C31: =IF(OCT!C5="","",OCT!C5) | D31: =IF(OCT!D5="","",OCT!D5) | E31: =IF(OCT!E5="","",OCT!E5) | F31: =IF(OCT!F5="","",OCT!F5) | G31: =IF(OCT!G5="","",OCT!G5) | H31: =IF(OCT!H5="","",OCT!H5) | I31: =IF(OCT!I5="","",OCT!I5) | J31: =IF(COUNT(C31:I31)=0,"",SUM(C31:I31)) | K31: ∑
B32: Headcount this Month | C32: =IF(C5="","",C5) | D32: =IF(D5="","",D5) | E32: =IF(E5="","",E5) | F32: =IF(F5="","",F5) | G32: =IF(G5="","",G5) | H32: =IF(H5="","",H5) | I32: =IF(I5="","",I5) | J32: =IF(COUNT(C32:I32)=0,"",SUM(C32:I32)) | K32: ∑
B33: Full Turnover (%) | C33: =IF(COUNT(C31,C32)<2,"",IF((C32+C31)=0,"",N(C24)/((C32+C31)/2))) | D33: =IF(COUNT(D31,D32)<2,"",IF((D32+D31)=0,"",N(D24)/((D32+D31)/2))) | E33: =IF(COUNT(E31,E32)<2,"",IF((E32+E31)=0,"",N(E24)/((E32+E31)/2))) | F33: =IF(COUNT(F31,F32)<2,"",IF((F32+F31)=0,"",N(F24)/((F32+F31)/2))) | G33: =IF(COUNT(G31,G32)<2,"",IF((G32+G31)=0,"",N(G24)/((G32+G31)/2))) | H33: =IF(COUNT(H31,H32)<2,"",IF((H32+H31)=0,"",N(H24)/((H32+H31)/2))) | I33: =IF(COUNT(I31,I32)<2,"",IF((I32+I31)=0,"",N(I24)/((I32+I31)/2))) | J33: =IF(COUNT(J31,J32)<2,"",IF((J32+J31)=0,"",N(J24)/((J32+J31)/2))) | K33: ϝ
B34: Permanent Vacancies | J34: =IF(COUNT(C34:I34)=0,"",SUM(C34:I34)) | K34: ∑
B35: Temporary Vacancies | J35: =IF(COUNT(C35:I35)=0,"",SUM(C35:I35)) | K35: ∑
B36: Total Vacancies | C36: =IF(COUNT(C34:C35)=0,"",SUM(C34:C35)) | D36: =IF(COUNT(D34:D35)=0,"",SUM(D34:D35)) | E36: =IF(COUNT(E34:E35)=0,"",SUM(E34:E35)) | F36: =IF(COUNT(F34:F35)=0,"",SUM(F34:F35)) | G36: =IF(COUNT(G34:G35)=0,"",SUM(G34:G35)) | H36: =IF(COUNT(H34:H35)=0,"",SUM(H34:H35)) | I36: =IF(COUNT(I34:I35)=0,"",SUM(I34:I35)) | J36: =IF(COUNT(J34:J35)=0,"",SUM(J34:J35)) | K36: ϝ
B37: Authorized Positions | C37: =IF(COUNT(C5,C36)=0,"",N(C5)+N(C36)) | D37: =IF(COUNT(D5,D36)=0,"",N(D5)+N(D36)) | E37: =IF(COUNT(E5,E36)=0,"",N(E5)+N(E36)) | F37: =IF(COUNT(F5,F36)=0,"",N(F5)+N(F36)) | G37: =IF(COUNT(G5,G36)=0,"",N(G5)+N(G36)) | H37: =IF(COUNT(H5,H36)=0,"",N(H5)+N(H36)) | I37: =IF(COUNT(I5,I36)=0,"",N(I5)+N(I36)) | J37: =IF(COUNT(J5,J36)=0,"",N(J5)+N(J36)) | K37: ϝ
B38: Vacancy Rate (%) | C38: =IFERROR(C36/C37,"") | D38: =IFERROR(D36/D37,"") | E38: =IFERROR(E36/E37,"") | F38: =IFERROR(F36/F37,"") | G38: =IFERROR(G36/G37,"") | H38: =IFERROR(H36/H37,"") | I38: =IFERROR(I36/I37,"") | J38: =IFERROR(J36/J37,"") | K38: ϝ
B39: Permanent TimeToHire (Days) YTD | C39: =IF('(GCG_ATG)'!$AB$5="","",'(GCG_ATG)'!$AB$5) | D39: =IF('(GCG_GCM)'!$AB$5="","",'(GCG_GCM)'!$AB$5) | E39: =IF('(Ground_JAM)'!$AB$5="","",'(Ground_JAM)'!$AB$5) | F39: =IF('(GCG_JAM)'!$AB$5="","",'(GCG_JAM)'!$AB$5) | G39: =IF('(Ground_LCA)'!$AB$5="","",'(Ground_LCA)'!$AB$5) | H39: =IF('(GCG_LCA)'!$AB$5="","",'(GCG_LCA)'!$AB$5) | I39: =IF('(Ground_STT)'!$AB$5="","",'(Ground_STT)'!$AB$5) | J39: =IFERROR(AVERAGE(C39:I39),"") | K39: Avg
B40: Temporary TimeToHire (Days) YTD | C40: =IF('(GCG_ATG)'!$AD$5="","",'(GCG_ATG)'!$AD$5) | D40: =IF('(GCG_GCM)'!$AD$5="","",'(GCG_GCM)'!$AD$5) | E40: =IF('(Ground_JAM)'!$AD$5="","",'(Ground_JAM)'!$AD$5) | F40: =IF('(GCG_JAM)'!$AD$5="","",'(GCG_JAM)'!$AD$5) | G40: =IF('(Ground_LCA)'!$AD$5="","",'(Ground_LCA)'!$AD$5) | H40: =IF('(GCG_LCA)'!$AD$5="","",'(GCG_LCA)'!$AD$5) | I40: =IF('(Ground_STT)'!$AD$5="","",'(Ground_STT)'!$AD$5) | J40: =IFERROR(AVERAGE(C40:I40),"") | K40: Avg
...

Sheet DEC
B1: GCG NORTH CARIBBEAN | C1: 1062 | D1: 1075 | E1: 1044 | F1: 1066 | G1: 1158 | H1: 1067 | I1: 1046
A2: =VALUE(TEXT(EDATE(DATE(LEFT(NOV!A2,4),RIGHT(NOV!A2,2),1),1),"yyyymm")) | B2: DEC | C2: GCG Antigua | D2: GCG Grand Cayman | E2: GCG Aviation Ground Jamaica | F2: GCG Jamaica | G2: GCG Aviation Ground Saint Lucia | H2: GCG Saint Lucia | I2: GCG Ground Saint Thomas | J2: TOTAL | K2: Total by Division | L2: =N(L11)<>0
A3: =+A2 | B3: Permanent (Regular) Headcount | J3: =IF(COUNT(C3:I3)=0,"",SUM(C3:I3)) | K3: ∑
B4: Temporary (Fix Term) Headcount | J4: =IF(COUNT(C4:I4)=0,"",SUM(C4:I4)) | K4: ∑
B5: Employee Headcount (Productivity) | C5: =IF(COUNT(C3:C4)=0,"",SUM(C3:C4)) | D5: =IF(COUNT(D3:D4)=0,"",SUM(D3:D4)) | E5: =IF(COUNT(E3:E4)=0,"",SUM(E3:E4)) | F5: =IF(COUNT(F3:F4)=0,"",SUM(F3:F4)) | G5: =IF(COUNT(G3:G4)=0,"",SUM(G3:G4)) | H5: =IF(COUNT(H3:H4)=0,"",SUM(H3:H4)) | I5: =IF(COUNT(I3:I4)=0,"",SUM(I3:I4)) | J5: =IF(COUNT(J3:J4)=0,"",SUM(J3:J4)) | K5: ϝ
B6: Headcount = 1.00 | J6: =IF(COUNT(C6:I6)=0,"",SUM(C6:I6)) | K6: ∑
B7: Headcount = 0.75 | J7: =IF(COUNT(C7:I7)=0,"",SUM(C7:I7)) | K7: ∑
B8: Headcount = 0.50 | J8: =IF(COUNT(C8:I8)=0,"",SUM(C8:I8)) | K8: ∑
B9: Headcount = 0.25 | J9: =IF(COUNT(C9:I9)=0,"",SUM(C9:I9)) | K9: ∑
B10: Standard Monthly Hours (FTE basis) | J10: =IFERROR(AVERAGE(C10:I10),"") | K10: Avg
B11: Employee FTE (Finance) | C11: =IF(COUNT(C6:C9)=0,"",N(C6)+N(C7)*0.75+N(C8)*0.5+N(C9)*0.25) | D11: =IF(COUNT(D6:D9)=0,"",N(D6)+N(D7)*0.75+N(D8)*0.5+N(D9)*0.25) | E11: =IF(COUNT(E6:E9)=0,"",N(E6)+N(E7)*0.75+N(E8)*0.5+N(E9)*0.25) | F11: =IF(COUNT(F6:F9)=0,"",N(F6)+N(F7)*0.75+N(F8)*0.5+N(F9)*0.25) | G11: =IF(COUNT(G6:G9)=0,"",N(G6)+N(G7)*0.75+N(G8)*0.5+N(G9)*0.25) | H11: =IF(COUNT(H6:H9)=0,"",N(H6)+N(H7)*0.75+N(H8)*0.5+N(H9)*0.25) | I11: =IF(COUNT(I6:I9)=0,"",N(I6)+N(I7)*0.75+N(I8)*0.5+N(I9)*0.25) | J11: =IF(COUNT(J6:J9)=0,"",N(J6)+N(J7)*0.75+N(J8)*0.5+N(J9)*0.25) | K11: FTE | L11: =IF(COUNT(J5:J9)=0,"",N(J6)+N(J7)+N(J8)+N(J9)-N(J5))
B12: Subcontracted Workforce HC | J12: =IF(COUNT(C12:I12)=0,"",SUM(C12:I12)) | K12: ∑
B13: Subcontracted Productive Hours | J13: =IF(COUNT(C13:I13)=0,"",SUM(C13:I13)) | K13: ∑
B14: Subcontracted FTE | C14: =IFERROR(C13/C10,"") | D14: =IFERROR(D13/D10,"") | E14: =IFERROR(E13/E10,"") | F14: =IFERROR(F13/F10,"") | G14: =IFERROR(G13/G10,"") | H14: =IFERROR(H13/H10,"") | I14: =IFERROR(I13/I10,"") | J14: =IF(COUNT(C14:I14)=0,"",SUM(C14:I14)) | K14: FTE
B15: Total Operational Workforce | C15: =IF(COUNT(C5,C12)=0,"",SUM(C5,C12)) | D15: =IF(COUNT(D5,D12)=0,"",SUM(D5,D12)) | E15: =IF(COUNT(E5,E12)=0,"",SUM(E5,E12)) | F15: =IF(COUNT(F5,F12)=0,"",SUM(F5,F12)) | G15: =IF(COUNT(G5,G12)=0,"",SUM(G5,G12)) | H15: =IF(COUNT(H5,H12)=0,"",SUM(H5,H12)) | I15: =IF(COUNT(I5,I12)=0,"",SUM(I5,I12)) | J15: =IF(COUNT(J5,J12)=0,"",SUM(J5,J12)) | K15: ϝ
B16: Total Operational FTE | C16: =IF(COUNT(C11,C14)=0,"",SUM(C11,C14)) | D16: =IF(COUNT(D11,D14)=0,"",SUM(D11,D14)) | E16: =IF(COUNT(E11,E14)=0,"",SUM(E11,E14)) | F16: =IF(COUNT(F11,F14)=0,"",SUM(F11,F14)) | G16: =IF(COUNT(G11,G14)=0,"",SUM(G11,G14)) | H16: =IF(COUNT(H11,H14)=0,"",SUM(H11,H14)) | I16: =IF(COUNT(I11,I14)=0,"",SUM(I11,I14)) | J16: =IF(COUNT(J11,J14)=0,"",SUM(J11,J14)) | K16: FTE
B17: Subcontracted Share of Workforce (%) | C17: =IFERROR(C12/C15,"") | D17: =IFERROR(D12/D15,"") | E17: =IFERROR(E12/E15,"") | F17: =IFERROR(F12/F15,"") | G17: =IFERROR(G12/G15,"") | H17: =IFERROR(H12/H15,"") | I17: =IFERROR(I12/I15,"") | J17: =IFERROR(J12/J15,"") | K17: ϝ
B18: FTE HR Team | J18: =IF(COUNT(C18:I18)=0,"",SUM(C18:I18)) | K18: ∑
B19: Permanent Hires | J19: =IF(COUNT(C19:I19)=0,"",SUM(C19:I19)) | K19: ∑
B20: Temporary Hires | J20: =IF(COUNT(C20:I20)=0,"",SUM(C20:I20)) | K20: ∑
B21: Total Hires | C21: =IF(COUNT(C19:C20)=0,"",SUM(C19:C20)) | D21: =IF(COUNT(D19:D20)=0,"",SUM(D19:D20)) | E21: =IF(COUNT(E19:E20)=0,"",SUM(E19:E20)) | F21: =IF(COUNT(F19:F20)=0,"",SUM(F19:F20)) | G21: =IF(COUNT(G19:G20)=0,"",SUM(G19:G20)) | H21: =IF(COUNT(H19:H20)=0,"",SUM(H19:H20)) | I21: =IF(COUNT(I19:I20)=0,"",SUM(I19:I20)) | J21: =IF(COUNT(J19:J20)=0,"",SUM(J19:J20)) | K21: ϝ
B22: Permanent Exits | J22: =IF(COUNT(C22:I22)=0,"",SUM(C22:I22)) | K22: ∑
B23: Temporary Exits | J23: =IF(COUNT(C23:I23)=0,"",SUM(C23:I23)) | K23: ∑
B24: Total Exits | C24: =IF(COUNT(C22:C23)=0,"",SUM(C22:C23)) | D24: =IF(COUNT(D22:D23)=0,"",SUM(D22:D23)) | E24: =IF(COUNT(E22:E23)=0,"",SUM(E22:E23)) | F24: =IF(COUNT(F22:F23)=0,"",SUM(F22:F23)) | G24: =IF(COUNT(G22:G23)=0,"",SUM(G22:G23)) | H24: =IF(COUNT(H22:H23)=0,"",SUM(H22:H23)) | I24: =IF(COUNT(I22:I23)=0,"",SUM(I22:I23)) | J24: =IF(COUNT(J22:J23)=0,"",SUM(J22:J23)) | K24: ϝ
B25: Permanent Turnover (%) | C25: =IF(COUNT(C31,C32)<2,"",IF((C32+C31)=0,"",N(C22)/((C32+C31)/2))) | D25: =IF(COUNT(D31,D32)<2,"",IF((D32+D31)=0,"",N(D22)/((D32+D31)/2))) | E25: =IF(COUNT(E31,E32)<2,"",IF((E32+E31)=0,"",N(E22)/((E32+E31)/2))) | F25: =IF(COUNT(F31,F32)<2,"",IF((F32+F31)=0,"",N(F22)/((F32+F31)/2))) | G25: =IF(COUNT(G31,G32)<2,"",IF((G32+G31)=0,"",N(G22)/((G32+G31)/2))) | H25: =IF(COUNT(H31,H32)<2,"",IF((H32+H31)=0,"",N(H22)/((H32+H31)/2))) | I25: =IF(COUNT(I31,I32)<2,"",IF((I32+I31)=0,"",N(I22)/((I32+I31)/2))) | J25: =IF(COUNT(J31,J32)<2,"",IF((J32+J31)=0,"",N(J22)/((J32+J31)/2))) | K25: ϝ
B26: Temporary Turnover (%) | C26: =IF(COUNT(C31,C32)<2,"",IF((C32+C31)=0,"",N(C23)/((C32+C31)/2))) | D26: =IF(COUNT(D31,D32)<2,"",IF((D32+D31)=0,"",N(D23)/((D32+D31)/2))) | E26: =IF(COUNT(E31,E32)<2,"",IF((E32+E31)=0,"",N(E23)/((E32+E31)/2))) | F26: =IF(COUNT(F31,F32)<2,"",IF((F32+F31)=0,"",N(F23)/((F32+F31)/2))) | G26: =IF(COUNT(G31,G32)<2,"",IF((G32+G31)=0,"",N(G23)/((G32+G31)/2))) | H26: =IF(COUNT(H31,H32)<2,"",IF((H32+H31)=0,"",N(H23)/((H32+H31)/2))) | I26: =IF(COUNT(I31,I32)<2,"",IF((I32+I31)=0,"",N(I23)/((I32+I31)/2))) | J26: =IF(COUNT(J31,J32)<2,"",IF((J32+J31)=0,"",N(J23)/((J32+J31)/2))) | K26: ϝ
B27: Voluntary Terminations | J27: =IF(COUNT(C27:I27)=0,"",SUM(C27:I27)) | K27: ∑
B28: Involuntary Terminations | J28: =IF(COUNT(C28:I28)=0,"",SUM(C28:I28)) | K28: ∑
B29: Voluntary Turnover (%) | C29: =IF(COUNT(C31,C32)<2,"",IF((C32+C31)=0,"",N(C27)/((C32+C31)/2))) | D29: =IF(COUNT(D31,D32)<2,"",IF((D32+D31)=0,"",N(D27)/((D32+D31)/2))) | E29: =IF(COUNT(E31,E32)<2,"",IF((E32+E31)=0,"",N(E27)/((E32+E31)/2))) | F29: =IF(COUNT(F31,F32)<2,"",IF((F32+F31)=0,"",N(F27)/((F32+F31)/2))) | G29: =IF(COUNT(G31,G32)<2,"",IF((G32+G31)=0,"",N(G27)/((G32+G31)/2))) | H29: =IF(COUNT(H31,H32)<2,"",IF((H32+H31)=0,"",N(H27)/((H32+H31)/2))) | I29: =IF(COUNT(I31,I32)<2,"",IF((I32+I31)=0,"",N(I27)/((I32+I31)/2))) | J29: =IF(COUNT(J31,J32)<2,"",IF((J32+J31)=0,"",N(J27)/((J32+J31)/2))) | K29: ϝ
B30: Involuntary Turnover (%) | C30: =IF(COUNT(C31,C32)<2,"",IF((C32+C31)=0,"",N(C28)/((C32+C31)/2))) | D30: =IF(COUNT(D31,D32)<2,"",IF((D32+D31)=0,"",N(D28)/((D32+D31)/2))) | E30: =IF(COUNT(E31,E32)<2,"",IF((E32+E31)=0,"",N(E28)/((E32+E31)/2))) | F30: =IF(COUNT(F31,F32)<2,"",IF((F32+F31)=0,"",N(F28)/((F32+F31)/2))) | G30: =IF(COUNT(G31,G32)<2,"",IF((G32+G31)=0,"",N(G28)/((G32+G31)/2))) | H30: =IF(COUNT(H31,H32)<2,"",IF((H32+H31)=0,"",N(H28)/((H32+H31)/2))) | I30: =IF(COUNT(I31,I32)<2,"",IF((I32+I31)=0,"",N(I28)/((I32+I31)/2))) | J30: =IF(COUNT(J31,J32)<2,"",IF((J32+J31)=0,"",N(J28)/((J32+J31)/2))) | K30: ϝ
B31: Headcount last Month | C31: =IF(NOV!C5="","",NOV!C5) | D31: =IF(NOV!D5="","",NOV!D5) | E31: =IF(NOV!E5="","",NOV!E5) | F31: =IF(NOV!F5="","",NOV!F5) | G31: =IF(NOV!G5="","",NOV!G5) | H31: =IF(NOV!H5="","",NOV!H5) | I31: =IF(NOV!I5="","",NOV!I5) | J31: =IF(COUNT(C31:I31)=0,"",SUM(C31:I31)) | K31: ∑
B32: Headcount this Month | C32: =IF(C5="","",C5) | D32: =IF(D5="","",D5) | E32: =IF(E5="","",E5) | F32: =IF(F5="","",F5) | G32: =IF(G5="","",G5) | H32: =IF(H5="","",H5) | I32: =IF(I5="","",I5) | J32: =IF(COUNT(C32:I32)=0,"",SUM(C32:I32)) | K32: ∑
B33: Full Turnover (%) | C33: =IF(COUNT(C31,C32)<2,"",IF((C32+C31)=0,"",N(C24)/((C32+C31)/2))) | D33: =IF(COUNT(D31,D32)<2,"",IF((D32+D31)=0,"",N(D24)/((D32+D31)/2))) | E33: =IF(COUNT(E31,E32)<2,"",IF((E32+E31)=0,"",N(E24)/((E32+E31)/2))) | F33: =IF(COUNT(F31,F32)<2,"",IF((F32+F31)=0,"",N(F24)/((F32+F31)/2))) | G33: =IF(COUNT(G31,G32)<2,"",IF((G32+G31)=0,"",N(G24)/((G32+G31)/2))) | H33: =IF(COUNT(H31,H32)<2,"",IF((H32+H31)=0,"",N(H24)/((H32+H31)/2))) | I33: =IF(COUNT(I31,I32)<2,"",IF((I32+I31)=0,"",N(I24)/((I32+I31)/2))) | J33: =IF(COUNT(J31,J32)<2,"",IF((J32+J31)=0,"",N(J24)/((J32+J31)/2))) | K33: ϝ
B34: Permanent Vacancies | J34: =IF(COUNT(C34:I34)=0,"",SUM(C34:I34)) | K34: ∑
B35: Temporary Vacancies | J35: =IF(COUNT(C35:I35)=0,"",SUM(C35:I35)) | K35: ∑
B36: Total Vacancies | C36: =IF(COUNT(C34:C35)=0,"",SUM(C34:C35)) | D36: =IF(COUNT(D34:D35)=0,"",SUM(D34:D35)) | E36: =IF(COUNT(E34:E35)=0,"",SUM(E34:E35)) | F36: =IF(COUNT(F34:F35)=0,"",SUM(F34:F35)) | G36: =IF(COUNT(G34:G35)=0,"",SUM(G34:G35)) | H36: =IF(COUNT(H34:H35)=0,"",SUM(H34:H35)) | I36: =IF(COUNT(I34:I35)=0,"",SUM(I34:I35)) | J36: =IF(COUNT(J34:J35)=0,"",SUM(J34:J35)) | K36: ϝ
B37: Authorized Positions | C37: =IF(COUNT(C5,C36)=0,"",N(C5)+N(C36)) | D37: =IF(COUNT(D5,D36)=0,"",N(D5)+N(D36)) | E37: =IF(COUNT(E5,E36)=0,"",N(E5)+N(E36)) | F37: =IF(COUNT(F5,F36)=0,"",N(F5)+N(F36)) | G37: =IF(COUNT(G5,G36)=0,"",N(G5)+N(G36)) | H37: =IF(COUNT(H5,H36)=0,"",N(H5)+N(H36)) | I37: =IF(COUNT(I5,I36)=0,"",N(I5)+N(I36)) | J37: =IF(COUNT(J5,J36)=0,"",N(J5)+N(J36)) | K37: ϝ
B38: Vacancy Rate (%) | C38: =IFERROR(C36/C37,"") | D38: =IFERROR(D36/D37,"") | E38: =IFERROR(E36/E37,"") | F38: =IFERROR(F36/F37,"") | G38: =IFERROR(G36/G37,"") | H38: =IFERROR(H36/H37,"") | I38: =IFERROR(I36/I37,"") | J38: =IFERROR(J36/J37,"") | K38: ϝ
B39: Permanent TimeToHire (Days) YTD | C39: =IF('(GCG_ATG)'!$AB$6="","",'(GCG_ATG)'!$AB$6) | D39: =IF('(GCG_GCM)'!$AB$6="","",'(GCG_GCM)'!$AB$6) | E39: =IF('(Ground_JAM)'!$AB$6="","",'(Ground_JAM)'!$AB$6) | F39: =IF('(GCG_JAM)'!$AB$6="","",'(GCG_JAM)'!$AB$6) | G39: =IF('(Ground_LCA)'!$AB$6="","",'(Ground_LCA)'!$AB$6) | H39: =IF('(GCG_LCA)'!$AB$6="","",'(GCG_LCA)'!$AB$6) | I39: =IF('(Ground_STT)'!$AB$6="","",'(Ground_STT)'!$AB$6) | J39: =IFERROR(AVERAGE(C39:I39),"") | K39: Avg
B40: Temporary TimeToHire (Days) YTD | C40: =IF('(GCG_ATG)'!$AD$6="","",'(GCG_ATG)'!$AD$6) | D40: =IF('(GCG_GCM)'!$AD$6="","",'(GCG_GCM)'!$AD$6) | E40: =IF('(Ground_JAM)'!$AD$6="","",'(Ground_JAM)'!$AD$6) | F40: =IF('(GCG_JAM)'!$AD$6="","",'(GCG_JAM)'!$AD$6) | G40: =IF('(Ground_LCA)'!$AD$6="","",'(Ground_LCA)'!$AD$6) | H40: =IF('(GCG_LCA)'!$AD$6="","",'(GCG_LCA)'!$AD$6) | I40: =IF('(Ground_STT)'!$AD$6="","",'(Ground_STT)'!$AD$6) | J40: =IFERROR(AVERAGE(C40:I40),"") | K40: Avg
...

Sheet JAN
B1: GCG NORTH CARIBBEAN | C1: 1062 | D1: 1075 | E1: 1044 | F1: 1066 | G1: 1158 | H1: 1067 | I1: 1046
A2: =VALUE(TEXT(EDATE(DATE(LEFT(DEC!A2,4),RIGHT(DEC!A2,2),1),1),"yyyymm")) | B2: JAN | C2: GCG Antigua | D2: GCG Grand Cayman | E2: GCG Aviation Ground Jamaica | F2: GCG Jamaica | G2: GCG Aviation Ground Saint Lucia | H2: GCG Saint Lucia | I2: GCG Ground Saint Thomas | J2: TOTAL | K2: Total by Division | L2: =N(L11)<>0
A3: =+A2 | B3: Permanent (Regular) Headcount | J3: =IF(COUNT(C3:I3)=0,"",SUM(C3:I3)) | K3: ∑
B4: Temporary (Fix Term) Headcount | J4: =IF(COUNT(C4:I4)=0,"",SUM(C4:I4)) | K4: ∑
B5: Employee Headcount (Productivity) | C5: =IF(COUNT(C3:C4)=0,"",SUM(C3:C4)) | D5: =IF(COUNT(D3:D4)=0,"",SUM(D3:D4)) | E5: =IF(COUNT(E3:E4)=0,"",SUM(E3:E4)) | F5: =IF(COUNT(F3:F4)=0,"",SUM(F3:F4)) | G5: =IF(COUNT(G3:G4)=0,"",SUM(G3:G4)) | H5: =IF(COUNT(H3:H4)=0,"",SUM(H3:H4)) | I5: =IF(COUNT(I3:I4)=0,"",SUM(I3:I4)) | J5: =IF(COUNT(J3:J4)=0,"",SUM(J3:J4)) | K5: ϝ
B6: Headcount = 1.00 | J6: =IF(COUNT(C6:I6)=0,"",SUM(C6:I6)) | K6: ∑
B7: Headcount = 0.75 | J7: =IF(COUNT(C7:I7)=0,"",SUM(C7:I7)) | K7: ∑
B8: Headcount = 0.50 | J8: =IF(COUNT(C8:I8)=0,"",SUM(C8:I8)) | K8: ∑
B9: Headcount = 0.25 | J9: =IF(COUNT(C9:I9)=0,"",SUM(C9:I9)) | K9: ∑
B10: Standard Monthly Hours (FTE basis) | J10: =IFERROR(AVERAGE(C10:I10),"") | K10: Avg
B11: Employee FTE (Finance) | C11: =IF(COUNT(C6:C9)=0,"",N(C6)+N(C7)*0.75+N(C8)*0.5+N(C9)*0.25) | D11: =IF(COUNT(D6:D9)=0,"",N(D6)+N(D7)*0.75+N(D8)*0.5+N(D9)*0.25) | E11: =IF(COUNT(E6:E9)=0,"",N(E6)+N(E7)*0.75+N(E8)*0.5+N(E9)*0.25) | F11: =IF(COUNT(F6:F9)=0,"",N(F6)+N(F7)*0.75+N(F8)*0.5+N(F9)*0.25) | G11: =IF(COUNT(G6:G9)=0,"",N(G6)+N(G7)*0.75+N(G8)*0.5+N(G9)*0.25) | H11: =IF(COUNT(H6:H9)=0,"",N(H6)+N(H7)*0.75+N(H8)*0.5+N(H9)*0.25) | I11: =IF(COUNT(I6:I9)=0,"",N(I6)+N(I7)*0.75+N(I8)*0.5+N(I9)*0.25) | J11: =IF(COUNT(J6:J9)=0,"",N(J6)+N(J7)*0.75+N(J8)*0.5+N(J9)*0.25) | K11: FTE | L11: =IF(COUNT(J5:J9)=0,"",N(J6)+N(J7)+N(J8)+N(J9)-N(J5))
B12: Subcontracted Workforce HC | J12: =IF(COUNT(C12:I12)=0,"",SUM(C12:I12)) | K12: ∑
B13: Subcontracted Productive Hours | J13: =IF(COUNT(C13:I13)=0,"",SUM(C13:I13)) | K13: ∑
B14: Subcontracted FTE | C14: =IFERROR(C13/C10,"") | D14: =IFERROR(D13/D10,"") | E14: =IFERROR(E13/E10,"") | F14: =IFERROR(F13/F10,"") | G14: =IFERROR(G13/G10,"") | H14: =IFERROR(H13/H10,"") | I14: =IFERROR(I13/I10,"") | J14: =IF(COUNT(C14:I14)=0,"",SUM(C14:I14)) | K14: FTE
B15: Total Operational Workforce | C15: =IF(COUNT(C5,C12)=0,"",SUM(C5,C12)) | D15: =IF(COUNT(D5,D12)=0,"",SUM(D5,D12)) | E15: =IF(COUNT(E5,E12)=0,"",SUM(E5,E12)) | F15: =IF(COUNT(F5,F12)=0,"",SUM(F5,F12)) | G15: =IF(COUNT(G5,G12)=0,"",SUM(G5,G12)) | H15: =IF(COUNT(H5,H12)=0,"",SUM(H5,H12)) | I15: =IF(COUNT(I5,I12)=0,"",SUM(I5,I12)) | J15: =IF(COUNT(J5,J12)=0,"",SUM(J5,J12)) | K15: ϝ
B16: Total Operational FTE | C16: =IF(COUNT(C11,C14)=0,"",SUM(C11,C14)) | D16: =IF(COUNT(D11,D14)=0,"",SUM(D11,D14)) | E16: =IF(COUNT(E11,E14)=0,"",SUM(E11,E14)) | F16: =IF(COUNT(F11,F14)=0,"",SUM(F11,F14)) | G16: =IF(COUNT(G11,G14)=0,"",SUM(G11,G14)) | H16: =IF(COUNT(H11,H14)=0,"",SUM(H11,H14)) | I16: =IF(COUNT(I11,I14)=0,"",SUM(I11,I14)) | J16: =IF(COUNT(J11,J14)=0,"",SUM(J11,J14)) | K16: FTE
B17: Subcontracted Share of Workforce (%) | C17: =IFERROR(C12/C15,"") | D17: =IFERROR(D12/D15,"") | E17: =IFERROR(E12/E15,"") | F17: =IFERROR(F12/F15,"") | G17: =IFERROR(G12/G15,"") | H17: =IFERROR(H12/H15,"") | I17: =IFERROR(I12/I15,"") | J17: =IFERROR(J12/J15,"") | K17: ϝ
B18: FTE HR Team | J18: =IF(COUNT(C18:I18)=0,"",SUM(C18:I18)) | K18: ∑
B19: Permanent Hires | J19: =IF(COUNT(C19:I19)=0,"",SUM(C19:I19)) | K19: ∑
B20: Temporary Hires | J20: =IF(COUNT(C20:I20)=0,"",SUM(C20:I20)) | K20: ∑
B21: Total Hires | C21: =IF(COUNT(C19:C20)=0,"",SUM(C19:C20)) | D21: =IF(COUNT(D19:D20)=0,"",SUM(D19:D20)) | E21: =IF(COUNT(E19:E20)=0,"",SUM(E19:E20)) | F21: =IF(COUNT(F19:F20)=0,"",SUM(F19:F20)) | G21: =IF(COUNT(G19:G20)=0,"",SUM(G19:G20)) | H21: =IF(COUNT(H19:H20)=0,"",SUM(H19:H20)) | I21: =IF(COUNT(I19:I20)=0,"",SUM(I19:I20)) | J21: =IF(COUNT(J19:J20)=0,"",SUM(J19:J20)) | K21: ϝ
B22: Permanent Exits | J22: =IF(COUNT(C22:I22)=0,"",SUM(C22:I22)) | K22: ∑
B23: Temporary Exits | J23: =IF(COUNT(C23:I23)=0,"",SUM(C23:I23)) | K23: ∑
B24: Total Exits | C24: =IF(COUNT(C22:C23)=0,"",SUM(C22:C23)) | D24: =IF(COUNT(D22:D23)=0,"",SUM(D22:D23)) | E24: =IF(COUNT(E22:E23)=0,"",SUM(E22:E23)) | F24: =IF(COUNT(F22:F23)=0,"",SUM(F22:F23)) | G24: =IF(COUNT(G22:G23)=0,"",SUM(G22:G23)) | H24: =IF(COUNT(H22:H23)=0,"",SUM(H22:H23)) | I24: =IF(COUNT(I22:I23)=0,"",SUM(I22:I23)) | J24: =IF(COUNT(J22:J23)=0,"",SUM(J22:J23)) | K24: ϝ
B25: Permanent Turnover (%) | C25: =IF(COUNT(C31,C32)<2,"",IF((C32+C31)=0,"",N(C22)/((C32+C31)/2))) | D25: =IF(COUNT(D31,D32)<2,"",IF((D32+D31)=0,"",N(D22)/((D32+D31)/2))) | E25: =IF(COUNT(E31,E32)<2,"",IF((E32+E31)=0,"",N(E22)/((E32+E31)/2))) | F25: =IF(COUNT(F31,F32)<2,"",IF((F32+F31)=0,"",N(F22)/((F32+F31)/2))) | G25: =IF(COUNT(G31,G32)<2,"",IF((G32+G31)=0,"",N(G22)/((G32+G31)/2))) | H25: =IF(COUNT(H31,H32)<2,"",IF((H32+H31)=0,"",N(H22)/((H32+H31)/2))) | I25: =IF(COUNT(I31,I32)<2,"",IF((I32+I31)=0,"",N(I22)/((I32+I31)/2))) | J25: =IF(COUNT(J31,J32)<2,"",IF((J32+J31)=0,"",N(J22)/((J32+J31)/2))) | K25: ϝ
B26: Temporary Turnover (%) | C26: =IF(COUNT(C31,C32)<2,"",IF((C32+C31)=0,"",N(C23)/((C32+C31)/2))) | D26: =IF(COUNT(D31,D32)<2,"",IF((D32+D31)=0,"",N(D23)/((D32+D31)/2))) | E26: =IF(COUNT(E31,E32)<2,"",IF((E32+E31)=0,"",N(E23)/((E32+E31)/2))) | F26: =IF(COUNT(F31,F32)<2,"",IF((F32+F31)=0,"",N(F23)/((F32+F31)/2))) | G26: =IF(COUNT(G31,G32)<2,"",IF((G32+G31)=0,"",N(G23)/((G32+G31)/2))) | H26: =IF(COUNT(H31,H32)<2,"",IF((H32+H31)=0,"",N(H23)/((H32+H31)/2))) | I26: =IF(COUNT(I31,I32)<2,"",IF((I32+I31)=0,"",N(I23)/((I32+I31)/2))) | J26: =IF(COUNT(J31,J32)<2,"",IF((J32+J31)=0,"",N(J23)/((J32+J31)/2))) | K26: ϝ
B27: Voluntary Terminations | J27: =IF(COUNT(C27:I27)=0,"",SUM(C27:I27)) | K27: ∑
B28: Involuntary Terminations | J28: =IF(COUNT(C28:I28)=0,"",SUM(C28:I28)) | K28: ∑
B29: Voluntary Turnover (%) | C29: =IF(COUNT(C31,C32)<2,"",IF((C32+C31)=0,"",N(C27)/((C32+C31)/2))) | D29: =IF(COUNT(D31,D32)<2,"",IF((D32+D31)=0,"",N(D27)/((D32+D31)/2))) | E29: =IF(COUNT(E31,E32)<2,"",IF((E32+E31)=0,"",N(E27)/((E32+E31)/2))) | F29: =IF(COUNT(F31,F32)<2,"",IF((F32+F31)=0,"",N(F27)/((F32+F31)/2))) | G29: =IF(COUNT(G31,G32)<2,"",IF((G32+G31)=0,"",N(G27)/((G32+G31)/2))) | H29: =IF(COUNT(H31,H32)<2,"",IF((H32+H31)=0,"",N(H27)/((H32+H31)/2))) | I29: =IF(COUNT(I31,I32)<2,"",IF((I32+I31)=0,"",N(I27)/((I32+I31)/2))) | J29: =IF(COUNT(J31,J32)<2,"",IF((J32+J31)=0,"",N(J27)/((J32+J31)/2))) | K29: ϝ
B30: Involuntary Turnover (%) | C30: =IF(COUNT(C31,C32)<2,"",IF((C32+C31)=0,"",N(C28)/((C32+C31)/2))) | D30: =IF(COUNT(D31,D32)<2,"",IF((D32+D31)=0,"",N(D28)/((D32+D31)/2))) | E30: =IF(COUNT(E31,E32)<2,"",IF((E32+E31)=0,"",N(E28)/((E32+E31)/2))) | F30: =IF(COUNT(F31,F32)<2,"",IF((F32+F31)=0,"",N(F28)/((F32+F31)/2))) | G30: =IF(COUNT(G31,G32)<2,"",IF((G32+G31)=0,"",N(G28)/((G32+G31)/2))) | H30: =IF(COUNT(H31,H32)<2,"",IF((H32+H31)=0,"",N(H28)/((H32+H31)/2))) | I30: =IF(COUNT(I31,I32)<2,"",IF((I32+I31)=0,"",N(I28)/((I32+I31)/2))) | J30: =IF(COUNT(J31,J32)<2,"",IF((J32+J31)=0,"",N(J28)/((J32+J31)/2))) | K30: ϝ
B31: Headcount last Month | C31: =IF(DEC!C5="","",DEC!C5) | D31: =IF(DEC!D5="","",DEC!D5) | E31: =IF(DEC!E5="","",DEC!E5) | F31: =IF(DEC!F5="","",DEC!F5) | G31: =IF(DEC!G5="","",DEC!G5) | H31: =IF(DEC!H5="","",DEC!H5) | I31: =IF(DEC!I5="","",DEC!I5) | J31: =IF(COUNT(C31:I31)=0,"",SUM(C31:I31)) | K31: ∑
B32: Headcount this Month | C32: =IF(C5="","",C5) | D32: =IF(D5="","",D5) | E32: =IF(E5="","",E5) | F32: =IF(F5="","",F5) | G32: =IF(G5="","",G5) | H32: =IF(H5="","",H5) | I32: =IF(I5="","",I5) | J32: =IF(COUNT(C32:I32)=0,"",SUM(C32:I32)) | K32: ∑
B33: Full Turnover (%) | C33: =IF(COUNT(C31,C32)<2,"",IF((C32+C31)=0,"",N(C24)/((C32+C31)/2))) | D33: =IF(COUNT(D31,D32)<2,"",IF((D32+D31)=0,"",N(D24)/((D32+D31)/2))) | E33: =IF(COUNT(E31,E32)<2,"",IF((E32+E31)=0,"",N(E24)/((E32+E31)/2))) | F33: =IF(COUNT(F31,F32)<2,"",IF((F32+F31)=0,"",N(F24)/((F32+F31)/2))) | G33: =IF(COUNT(G31,G32)<2,"",IF((G32+G31)=0,"",N(G24)/((G32+G31)/2))) | H33: =IF(COUNT(H31,H32)<2,"",IF((H32+H31)=0,"",N(H24)/((H32+H31)/2))) | I33: =IF(COUNT(I31,I32)<2,"",IF((I32+I31)=0,"",N(I24)/((I32+I31)/2))) | J33: =IF(COUNT(J31,J32)<2,"",IF((J32+J31)=0,"",N(J24)/((J32+J31)/2))) | K33: ϝ
B34: Permanent Vacancies | J34: =IF(COUNT(C34:I34)=0,"",SUM(C34:I34)) | K34: ∑
B35: Temporary Vacancies | J35: =IF(COUNT(C35:I35)=0,"",SUM(C35:I35)) | K35: ∑
B36: Total Vacancies | C36: =IF(COUNT(C34:C35)=0,"",SUM(C34:C35)) | D36: =IF(COUNT(D34:D35)=0,"",SUM(D34:D35)) | E36: =IF(COUNT(E34:E35)=0,"",SUM(E34:E35)) | F36: =IF(COUNT(F34:F35)=0,"",SUM(F34:F35)) | G36: =IF(COUNT(G34:G35)=0,"",SUM(G34:G35)) | H36: =IF(COUNT(H34:H35)=0,"",SUM(H34:H35)) | I36: =IF(COUNT(I34:I35)=0,"",SUM(I34:I35)) | J36: =IF(COUNT(J34:J35)=0,"",SUM(J34:J35)) | K36: ϝ
B37: Authorized Positions | C37: =IF(COUNT(C5,C36)=0,"",N(C5)+N(C36)) | D37: =IF(COUNT(D5,D36)=0,"",N(D5)+N(D36)) | E37: =IF(COUNT(E5,E36)=0,"",N(E5)+N(E36)) | F37: =IF(COUNT(F5,F36)=0,"",N(F5)+N(F36)) | G37: =IF(COUNT(G5,G36)=0,"",N(G5)+N(G36)) | H37: =IF(COUNT(H5,H36)=0,"",N(H5)+N(H36)) | I37: =IF(COUNT(I5,I36)=0,"",N(I5)+N(I36)) | J37: =IF(COUNT(J5,J36)=0,"",N(J5)+N(J36)) | K37: ϝ
B38: Vacancy Rate (%) | C38: =IFERROR(C36/C37,"") | D38: =IFERROR(D36/D37,"") | E38: =IFERROR(E36/E37,"") | F38: =IFERROR(F36/F37,"") | G38: =IFERROR(G36/G37,"") | H38: =IFERROR(H36/H37,"") | I38: =IFERROR(I36/I37,"") | J38: =IFERROR(J36/J37,"") | K38: ϝ
B39: Permanent TimeToHire (Days) YTD | C39: =IF('(GCG_ATG)'!$AB$7="","",'(GCG_ATG)'!$AB$7) | D39: =IF('(GCG_GCM)'!$AB$7="","",'(GCG_GCM)'!$AB$7) | E39: =IF('(Ground_JAM)'!$AB$7="","",'(Ground_JAM)'!$AB$7) | F39: =IF('(GCG_JAM)'!$AB$7="","",'(GCG_JAM)'!$AB$7) | G39: =IF('(Ground_LCA)'!$AB$7="","",'(Ground_LCA)'!$AB$7) | H39: =IF('(GCG_LCA)'!$AB$7="","",'(GCG_LCA)'!$AB$7) | I39: =IF('(Ground_STT)'!$AB$7="","",'(Ground_STT)'!$AB$7) | J39: =IFERROR(AVERAGE(C39:I39),"") | K39: Avg
B40: Temporary TimeToHire (Days) YTD | C40: =IF('(GCG_ATG)'!$AD$7="","",'(GCG_ATG)'!$AD$7) | D40: =IF('(GCG_GCM)'!$AD$7="","",'(GCG_GCM)'!$AD$7) | E40: =IF('(Ground_JAM)'!$AD$7="","",'(Ground_JAM)'!$AD$7) | F40: =IF('(GCG_JAM)'!$AD$7="","",'(GCG_JAM)'!$AD$7) | G40: =IF('(Ground_LCA)'!$AD$7="","",'(Ground_LCA)'!$AD$7) | H40: =IF('(GCG_LCA)'!$AD$7="","",'(GCG_LCA)'!$AD$7) | I40: =IF('(Ground_STT)'!$AD$7="","",'(Ground_STT)'!$AD$7) | J40: =IFERROR(AVERAGE(C40:I40),"") | K40: Avg
...

Sheet FEB
B1: GCG NORTH CARIBBEAN | C1: 1062 | D1: 1075 | E1: 1044 | F1: 1066 | G1: 1158 | H1: 1067 | I1: 1046
A2: =VALUE(TEXT(EDATE(DATE(LEFT(JAN!A2,4),RIGHT(JAN!A2,2),1),1),"yyyymm")) | B2: FEB | C2: GCG Antigua | D2: GCG Grand Cayman | E2: GCG Aviation Ground Jamaica | F2: GCG Jamaica | G2: GCG Aviation Ground Saint Lucia | H2: GCG Saint Lucia | I2: GCG Ground Saint Thomas | J2: TOTAL | K2: Total by Division | L2: =N(L11)<>0
