Workbook

Sheet Quarter
B1: GCG CENTRAL AMERICA
A2: FY2027 | B2: Quarter | C2: OCT | D2: NOV | E2: DEC | F2: ∑Q1 | G2: JAN | H2: FEB | I2: MAR | J2: ∑Q2 | K2: APR | L2: MAY | M2: JUN | N2: ∑Q3 | O2: JUL | P2: AUG | Q2: SEP | R2: ∑Q4 | S2: FY2027
B3: Permanent (Regular) Headcount | C3: =OCT!K3 | D3: =NOV!K3 | E3: =DEC!K3 | F3: =IFERROR(AVERAGE(C3:E3),"") | G3: =JAN!K3 | H3: =FEB!K3 | I3: =MAR!K3 | J3: =IFERROR(AVERAGE(G3:I3),"") | K3: =APR!K3 | L3: =MAY!K3 | M3: =JUN!K3 | N3: =IFERROR(AVERAGE(K3:M3),"") | O3: =JUL!K3 | P3: =AUG!K3 | Q3: =SEP!K3 | R3: =IFERROR(AVERAGE(O3:Q3),"") | S3: =IFERROR(AVERAGE(C3:E3,G3:I3,K3:M3,O3:Q3),"")
B4: Temporary (Fix Term) Headcount | C4: =OCT!K4 | D4: =NOV!K4 | E4: =DEC!K4 | F4: =IFERROR(AVERAGE(C4:E4),"") | G4: =JAN!K4 | H4: =FEB!K4 | I4: =MAR!K4 | J4: =IFERROR(AVERAGE(G4:I4),"") | K4: =APR!K4 | L4: =MAY!K4 | M4: =JUN!K4 | N4: =IFERROR(AVERAGE(K4:M4),"") | O4: =JUL!K4 | P4: =AUG!K4 | Q4: =SEP!K4 | R4: =IFERROR(AVERAGE(O4:Q4),"") | S4: =IFERROR(AVERAGE(C4:E4,G4:I4,K4:M4,O4:Q4),"")
B5: Employee Headcount (Productivity) | C5: =OCT!K5 | D5: =NOV!K5 | E5: =DEC!K5 | F5: =IF(COUNT(F3:F4)=0,"",SUM(F3:F4)) | G5: =JAN!K5 | H5: =FEB!K5 | I5: =MAR!K5 | J5: =IF(COUNT(J3:J4)=0,"",SUM(J3:J4)) | K5: =APR!K5 | L5: =MAY!K5 | M5: =JUN!K5 | N5: =IF(COUNT(N3:N4)=0,"",SUM(N3:N4)) | O5: =JUL!K5 | P5: =AUG!K5 | Q5: =SEP!K5 | R5: =IF(COUNT(R3:R4)=0,"",SUM(R3:R4)) | S5: =IF(COUNT(S3:S4)=0,"",SUM(S3:S4))
B6: Headcount = 1.00 | C6: =OCT!K6 | D6: =NOV!K6 | E6: =DEC!K6 | F6: =IFERROR(AVERAGE(C6:E6),"") | G6: =JAN!K6 | H6: =FEB!K6 | I6: =MAR!K6 | J6: =IFERROR(AVERAGE(G6:I6),"") | K6: =APR!K6 | L6: =MAY!K6 | M6: =JUN!K6 | N6: =IFERROR(AVERAGE(K6:M6),"") | O6: =JUL!K6 | P6: =AUG!K6 | Q6: =SEP!K6 | R6: =IFERROR(AVERAGE(O6:Q6),"") | S6: =IFERROR(AVERAGE(C6:E6,G6:I6,K6:M6,O6:Q6),"")
B7: Headcount = 0.75 | C7: =OCT!K7 | D7: =NOV!K7 | E7: =DEC!K7 | F7: =IFERROR(AVERAGE(C7:E7),"") | G7: =JAN!K7 | H7: =FEB!K7 | I7: =MAR!K7 | J7: =IFERROR(AVERAGE(G7:I7),"") | K7: =APR!K7 | L7: =MAY!K7 | M7: =JUN!K7 | N7: =IFERROR(AVERAGE(K7:M7),"") | O7: =JUL!K7 | P7: =AUG!K7 | Q7: =SEP!K7 | R7: =IFERROR(AVERAGE(O7:Q7),"") | S7: =IFERROR(AVERAGE(C7:E7,G7:I7,K7:M7,O7:Q7),"")
B8: Headcount = 0.50 | C8: =OCT!K8 | D8: =NOV!K8 | E8: =DEC!K8 | F8: =IFERROR(AVERAGE(C8:E8),"") | G8: =JAN!K8 | H8: =FEB!K8 | I8: =MAR!K8 | J8: =IFERROR(AVERAGE(G8:I8),"") | K8: =APR!K8 | L8: =MAY!K8 | M8: =JUN!K8 | N8: =IFERROR(AVERAGE(K8:M8),"") | O8: =JUL!K8 | P8: =AUG!K8 | Q8: =SEP!K8 | R8: =IFERROR(AVERAGE(O8:Q8),"") | S8: =IFERROR(AVERAGE(C8:E8,G8:I8,K8:M8,O8:Q8),"")
B9: Headcount = 0.25 | C9: =OCT!K9 | D9: =NOV!K9 | E9: =DEC!K9 | F9: =IFERROR(AVERAGE(C9:E9),"") | G9: =JAN!K9 | H9: =FEB!K9 | I9: =MAR!K9 | J9: =IFERROR(AVERAGE(G9:I9),"") | K9: =APR!K9 | L9: =MAY!K9 | M9: =JUN!K9 | N9: =IFERROR(AVERAGE(K9:M9),"") | O9: =JUL!K9 | P9: =AUG!K9 | Q9: =SEP!K9 | R9: =IFERROR(AVERAGE(O9:Q9),"") | S9: =IFERROR(AVERAGE(C9:E9,G9:I9,K9:M9,O9:Q9),"")
B10: Standard Monthly Hours (FTE basis) | C10: =OCT!K10 | D10: =NOV!K10 | E10: =DEC!K10 | F10: =IFERROR(AVERAGE(C10:E10),"") | G10: =JAN!K10 | H10: =FEB!K10 | I10: =MAR!K10 | J10: =IFERROR(AVERAGE(G10:I10),"") | K10: =APR!K10 | L10: =MAY!K10 | M10: =JUN!K10 | N10: =IFERROR(AVERAGE(K10:M10),"") | O10: =JUL!K10 | P10: =AUG!K10 | Q10: =SEP!K10 | R10: =IFERROR(AVERAGE(O10:Q10),"") | S10: =IFERROR(AVERAGE(C10:E10,G10:I10,K10:M10,O10:Q10),"")
B11: Employee FTE (Finance) | C11: =OCT!K11 | D11: =NOV!K11 | E11: =DEC!K11 | F11: =IF(COUNT(F6:F9)=0,"",N(F6)+N(F7)*0.75+N(F8)*0.5+N(F9)*0.25) | G11: =JAN!K11 | H11: =FEB!K11 | I11: =MAR!K11 | J11: =IF(COUNT(J6:J9)=0,"",N(J6)+N(J7)*0.75+N(J8)*0.5+N(J9)*0.25) | K11: =APR!K11 | L11: =MAY!K11 | M11: =JUN!K11 | N11: =IF(COUNT(N6:N9)=0,"",N(N6)+N(N7)*0.75+N(N8)*0.5+N(N9)*0.25) | O11: =JUL!K11 | P11: =AUG!K11 | Q11: =SEP!K11 | R11: =IF(COUNT(R6:R9)=0,"",N(R6)+N(R7)*0.75+N(R8)*0.5+N(R9)*0.25) | S11: =IF(COUNT(S6:S9)=0,"",N(S6)+N(S7)*0.75+N(S8)*0.5+N(S9)*0.25)
B12: Subcontracted Workforce HC | C12: =OCT!K12 | D12: =NOV!K12 | E12: =DEC!K12 | F12: =IFERROR(AVERAGE(C12:E12),"") | G12: =JAN!K12 | H12: =FEB!K12 | I12: =MAR!K12 | J12: =IFERROR(AVERAGE(G12:I12),"") | K12: =APR!K12 | L12: =MAY!K12 | M12: =JUN!K12 | N12: =IFERROR(AVERAGE(K12:M12),"") | O12: =JUL!K12 | P12: =AUG!K12 | Q12: =SEP!K12 | R12: =IFERROR(AVERAGE(O12:Q12),"") | S12: =IFERROR(AVERAGE(C12:E12,G12:I12,K12:M12,O12:Q12),"")
B13: Subcontracted Productive Hours | C13: =OCT!K13 | D13: =NOV!K13 | E13: =DEC!K13 | F13: =IFERROR(AVERAGE(C13:E13),"") | G13: =JAN!K13 | H13: =FEB!K13 | I13: =MAR!K13 | J13: =IFERROR(AVERAGE(G13:I13),"") | K13: =APR!K13 | L13: =MAY!K13 | M13: =JUN!K13 | N13: =IFERROR(AVERAGE(K13:M13),"") | O13: =JUL!K13 | P13: =AUG!K13 | Q13: =SEP!K13 | R13: =IFERROR(AVERAGE(O13:Q13),"") | S13: =IFERROR(AVERAGE(C13:E13,G13:I13,K13:M13,O13:Q13),"")
B14: Subcontracted FTE | C14: =OCT!K14 | D14: =NOV!K14 | E14: =DEC!K14 | F14: =IFERROR(F13/F10,"") | G14: =JAN!K14 | H14: =FEB!K14 | I14: =MAR!K14 | J14: =IFERROR(J13/J10,"") | K14: =APR!K14 | L14: =MAY!K14 | M14: =JUN!K14 | N14: =IFERROR(N13/N10,"") | O14: =JUL!K14 | P14: =AUG!K14 | Q14: =SEP!K14 | R14: =IFERROR(R13/R10,"") | S14: =IFERROR(S13/S10,"")
B15: Total Operational Workforce | C15: =OCT!K15 | D15: =NOV!K15 | E15: =DEC!K15 | F15: =IF(COUNT(F5,F12)=0,"",SUM(F5,F12)) | G15: =JAN!K15 | H15: =FEB!K15 | I15: =MAR!K15 | J15: =IF(COUNT(J5,J12)=0,"",SUM(J5,J12)) | K15: =APR!K15 | L15: =MAY!K15 | M15: =JUN!K15 | N15: =IF(COUNT(N5,N12)=0,"",SUM(N5,N12)) | O15: =JUL!K15 | P15: =AUG!K15 | Q15: =SEP!K15 | R15: =IF(COUNT(R5,R12)=0,"",SUM(R5,R12)) | S15: =IF(COUNT(S5,S12)=0,"",SUM(S5,S12))
B16: Total Operational FTE | C16: =OCT!K16 | D16: =NOV!K16 | E16: =DEC!K16 | F16: =IF(COUNT(F11,F14)=0,"",SUM(F11,F14)) | G16: =JAN!K16 | H16: =FEB!K16 | I16: =MAR!K16 | J16: =IF(COUNT(J11,J14)=0,"",SUM(J11,J14)) | K16: =APR!K16 | L16: =MAY!K16 | M16: =JUN!K16 | N16: =IF(COUNT(N11,N14)=0,"",SUM(N11,N14)) | O16: =JUL!K16 | P16: =AUG!K16 | Q16: =SEP!K16 | R16: =IF(COUNT(R11,R14)=0,"",SUM(R11,R14)) | S16: =IF(COUNT(S11,S14)=0,"",SUM(S11,S14))
B17: Subcontracted Share of Workforce (%) | C17: =OCT!K17 | D17: =NOV!K17 | E17: =DEC!K17 | F17: =IFERROR(F12/F15,"") | G17: =JAN!K17 | H17: =FEB!K17 | I17: =MAR!K17 | J17: =IFERROR(J12/J15,"") | K17: =APR!K17 | L17: =MAY!K17 | M17: =JUN!K17 | N17: =IFERROR(N12/N15,"") | O17: =JUL!K17 | P17: =AUG!K17 | Q17: =SEP!K17 | R17: =IFERROR(R12/R15,"") | S17: =IFERROR(S12/S15,"")
B18: FTE HR Team | C18: =OCT!K18 | D18: =NOV!K18 | E18: =DEC!K18 | F18: =IFERROR(AVERAGE(C18:E18),"") | G18: =JAN!K18 | H18: =FEB!K18 | I18: =MAR!K18 | J18: =IFERROR(AVERAGE(G18:I18),"") | K18: =APR!K18 | L18: =MAY!K18 | M18: =JUN!K18 | N18: =IFERROR(AVERAGE(K18:M18),"") | O18: =JUL!K18 | P18: =AUG!K18 | Q18: =SEP!K18 | R18: =IFERROR(AVERAGE(O18:Q18),"") | S18: =IFERROR(AVERAGE(C18:E18,G18:I18,K18:M18,O18:Q18),"")
B19: Permanent Hires | C19: =OCT!K19 | D19: =NOV!K19 | E19: =DEC!K19 | F19: =IF(COUNT(C19:E19)=0,"",SUM(C19:E19)) | G19: =JAN!K19 | H19: =FEB!K19 | I19: =MAR!K19 | J19: =IF(COUNT(G19:I19)=0,"",SUM(G19:I19)) | K19: =APR!K19 | L19: =MAY!K19 | M19: =JUN!K19 | N19: =IF(COUNT(K19:M19)=0,"",SUM(K19:M19)) | O19: =JUL!K19 | P19: =AUG!K19 | Q19: =SEP!K19 | R19: =IF(COUNT(O19:Q19)=0,"",SUM(O19:Q19)) | S19: =IF(COUNT(C19:E19,G19:I19,K19:M19,O19:Q19)=0,"",SUM(C19:E19,G19:I19,K19:M19,O19:Q19))
B20: Temporary Hires | C20: =OCT!K20 | D20: =NOV!K20 | E20: =DEC!K20 | F20: =IF(COUNT(C20:E20)=0,"",SUM(C20:E20)) | G20: =JAN!K20 | H20: =FEB!K20 | I20: =MAR!K20 | J20: =IF(COUNT(G20:I20)=0,"",SUM(G20:I20)) | K20: =APR!K20 | L20: =MAY!K20 | M20: =JUN!K20 | N20: =IF(COUNT(K20:M20)=0,"",SUM(K20:M20)) | O20: =JUL!K20 | P20: =AUG!K20 | Q20: =SEP!K20 | R20: =IF(COUNT(O20:Q20)=0,"",SUM(O20:Q20)) | S20: =IF(COUNT(C20:E20,G20:I20,K20:M20,O20:Q20)=0,"",SUM(C20:E20,G20:I20,K20:M20,O20:Q20))
B21: Total Hires | C21: =OCT!K21 | D21: =NOV!K21 | E21: =DEC!K21 | F21: =IF(COUNT(F19:F20)=0,"",SUM(F19:F20)) | G21: =JAN!K21 | H21: =FEB!K21 | I21: =MAR!K21 | J21: =IF(COUNT(J19:J20)=0,"",SUM(J19:J20)) | K21: =APR!K21 | L21: =MAY!K21 | M21: =JUN!K21 | N21: =IF(COUNT(N19:N20)=0,"",SUM(N19:N20)) | O21: =JUL!K21 | P21: =AUG!K21 | Q21: =SEP!K21 | R21: =IF(COUNT(R19:R20)=0,"",SUM(R19:R20)) | S21: =IF(COUNT(S19:S20)=0,"",SUM(S19:S20))
B22: Permanent Exits | C22: =OCT!K22 | D22: =NOV!K22 | E22: =DEC!K22 | F22: =IF(COUNT(C22:E22)=0,"",SUM(C22:E22)) | G22: =JAN!K22 | H22: =FEB!K22 | I22: =MAR!K22 | J22: =IF(COUNT(G22:I22)=0,"",SUM(G22:I22)) | K22: =APR!K22 | L22: =MAY!K22 | M22: =JUN!K22 | N22: =IF(COUNT(K22:M22)=0,"",SUM(K22:M22)) | O22: =JUL!K22 | P22: =AUG!K22 | Q22: =SEP!K22 | R22: =IF(COUNT(O22:Q22)=0,"",SUM(O22:Q22)) | S22: =IF(COUNT(C22:E22,G22:I22,K22:M22,O22:Q22)=0,"",SUM(C22:E22,G22:I22,K22:M22,O22:Q22))
B23: Temporary Exits | C23: =OCT!K23 | D23: =NOV!K23 | E23: =DEC!K23 | F23: =IF(COUNT(C23:E23)=0,"",SUM(C23:E23)) | G23: =JAN!K23 | H23: =FEB!K23 | I23: =MAR!K23 | J23: =IF(COUNT(G23:I23)=0,"",SUM(G23:I23)) | K23: =APR!K23 | L23: =MAY!K23 | M23: =JUN!K23 | N23: =IF(COUNT(K23:M23)=0,"",SUM(K23:M23)) | O23: =JUL!K23 | P23: =AUG!K23 | Q23: =SEP!K23 | R23: =IF(COUNT(O23:Q23)=0,"",SUM(O23:Q23)) | S23: =IF(COUNT(C23:E23,G23:I23,K23:M23,O23:Q23)=0,"",SUM(C23:E23,G23:I23,K23:M23,O23:Q23))
B24: Total Exits | C24: =OCT!K24 | D24: =NOV!K24 | E24: =DEC!K24 | F24: =IF(COUNT(F22:F23)=0,"",SUM(F22:F23)) | G24: =JAN!K24 | H24: =FEB!K24 | I24: =MAR!K24 | J24: =IF(COUNT(J22:J23)=0,"",SUM(J22:J23)) | K24: =APR!K24 | L24: =MAY!K24 | M24: =JUN!K24 | N24: =IF(COUNT(N22:N23)=0,"",SUM(N22:N23)) | O24: =JUL!K24 | P24: =AUG!K24 | Q24: =SEP!K24 | R24: =IF(COUNT(R22:R23)=0,"",SUM(R22:R23)) | S24: =IF(COUNT(S22:S23)=0,"",SUM(S22:S23))
B25: Permanent Turnover (%) | C25: =OCT!K25 | D25: =NOV!K25 | E25: =DEC!K25 | F25: =IF(COUNT(F31,F32)<2,"",IF((F32+F31)=0,"",N(F22)/((F32+F31)/2))) | G25: =JAN!K25 | H25: =FEB!K25 | I25: =MAR!K25 | J25: =IF(COUNT(J31,J32)<2,"",IF((J32+J31)=0,"",N(J22)/((J32+J31)/2))) | K25: =APR!K25 | L25: =MAY!K25 | M25: =JUN!K25 | N25: =IF(COUNT(N31,N32)<2,"",IF((N32+N31)=0,"",N(N22)/((N32+N31)/2))) | O25: =JUL!K25 | P25: =AUG!K25 | Q25: =SEP!K25 | R25: =IF(COUNT(R31,R32)<2,"",IF((R32+R31)=0,"",N(R22)/((R32+R31)/2))) | S25: =IF(COUNT(S31,S32)<2,"",IF((S32+S31)=0,"",N(S22)/((S32+S31)/2)))
B26: Temporary Turnover (%) | C26: =OCT!K26 | D26: =NOV!K26 | E26: =DEC!K26 | F26: =IF(COUNT(F31,F32)<2,"",IF((F32+F31)=0,"",N(F23)/((F32+F31)/2))) | G26: =JAN!K26 | H26: =FEB!K26 | I26: =MAR!K26 | J26: =IF(COUNT(J31,J32)<2,"",IF((J32+J31)=0,"",N(J23)/((J32+J31)/2))) | K26: =APR!K26 | L26: =MAY!K26 | M26: =JUN!K26 | N26: =IF(COUNT(N31,N32)<2,"",IF((N32+N31)=0,"",N(N23)/((N32+N31)/2))) | O26: =JUL!K26 | P26: =AUG!K26 | Q26: =SEP!K26 | R26: =IF(COUNT(R31,R32)<2,"",IF((R32+R31)=0,"",N(R23)/((R32+R31)/2))) | S26: =IF(COUNT(S31,S32)<2,"",IF((S32+S31)=0,"",N(S23)/((S32+S31)/2)))
B27: Voluntary Terminations | C27: =OCT!K27 | D27: =NOV!K27 | E27: =DEC!K27 | F27: =IF(COUNT(C27:E27)=0,"",SUM(C27:E27)) | G27: =JAN!K27 | H27: =FEB!K27 | I27: =MAR!K27 | J27: =IF(COUNT(G27:I27)=0,"",SUM(G27:I27)) | K27: =APR!K27 | L27: =MAY!K27 | M27: =JUN!K27 | N27: =IF(COUNT(K27:M27)=0,"",SUM(K27:M27)) | O27: =JUL!K27 | P27: =AUG!K27 | Q27: =SEP!K27 | R27: =IF(COUNT(O27:Q27)=0,"",SUM(O27:Q27)) | S27: =IF(COUNT(C27:E27,G27:I27,K27:M27,O27:Q27)=0,"",SUM(C27:E27,G27:I27,K27:M27,O27:Q27))
B28: Involuntary Terminations | C28: =OCT!K28 | D28: =NOV!K28 | E28: =DEC!K28 | F28: =IF(COUNT(C28:E28)=0,"",SUM(C28:E28)) | G28: =JAN!K28 | H28: =FEB!K28 | I28: =MAR!K28 | J28: =IF(COUNT(G28:I28)=0,"",SUM(G28:I28)) | K28: =APR!K28 | L28: =MAY!K28 | M28: =JUN!K28 | N28: =IF(COUNT(K28:M28)=0,"",SUM(K28:M28)) | O28: =JUL!K28 | P28: =AUG!K28 | Q28: =SEP!K28 | R28: =IF(COUNT(O28:Q28)=0,"",SUM(O28:Q28)) | S28: =IF(COUNT(C28:E28,G28:I28,K28:M28,O28:Q28)=0,"",SUM(C28:E28,G28:I28,K28:M28,O28:Q28))
B29: Voluntary Turnover (%) | C29: =OCT!K29 | D29: =NOV!K29 | E29: =DEC!K29 | F29: =IF(COUNT(F31,F32)<2,"",IF((F32+F31)=0,"",N(F27)/((F32+F31)/2))) | G29: =JAN!K29 | H29: =FEB!K29 | I29: =MAR!K29 | J29: =IF(COUNT(J31,J32)<2,"",IF((J32+J31)=0,"",N(J27)/((J32+J31)/2))) | K29: =APR!K29 | L29: =MAY!K29 | M29: =JUN!K29 | N29: =IF(COUNT(N31,N32)<2,"",IF((N32+N31)=0,"",N(N27)/((N32+N31)/2))) | O29: =JUL!K29 | P29: =AUG!K29 | Q29: =SEP!K29 | R29: =IF(COUNT(R31,R32)<2,"",IF((R32+R31)=0,"",N(R27)/((R32+R31)/2))) | S29: =IF(COUNT(S31,S32)<2,"",IF((S32+S31)=0,"",N(S27)/((S32+S31)/2)))
B30: Involuntary Turnover (%) | C30: =OCT!K30 | D30: =NOV!K30 | E30: =DEC!K30 | F30: =IF(COUNT(F31,F32)<2,"",IF((F32+F31)=0,"",N(F28)/((F32+F31)/2))) | G30: =JAN!K30 | H30: =FEB!K30 | I30: =MAR!K30 | J30: =IF(COUNT(J31,J32)<2,"",IF((J32+J31)=0,"",N(J28)/((J32+J31)/2))) | K30: =APR!K30 | L30: =MAY!K30 | M30: =JUN!K30 | N30: =IF(COUNT(N31,N32)<2,"",IF((N32+N31)=0,"",N(N28)/((N32+N31)/2))) | O30: =JUL!K30 | P30: =AUG!K30 | Q30: =SEP!K30 | R30: =IF(COUNT(R31,R32)<2,"",IF((R32+R31)=0,"",N(R28)/((R32+R31)/2))) | S30: =IF(COUNT(S31,S32)<2,"",IF((S32+S31)=0,"",N(S28)/((S32+S31)/2)))
B31: Headcount last Month | C31: =OCT!K31 | D31: =NOV!K31 | E31: =DEC!K31 | F31: =IFERROR(AVERAGE(C31:E31),"") | G31: =JAN!K31 | H31: =FEB!K31 | I31: =MAR!K31 | J31: =IFERROR(AVERAGE(G31:I31),"") | K31: =APR!K31 | L31: =MAY!K31 | M31: =JUN!K31 | N31: =IFERROR(AVERAGE(K31:M31),"") | O31: =JUL!K31 | P31: =AUG!K31 | Q31: =SEP!K31 | R31: =IFERROR(AVERAGE(O31:Q31),"") | S31: =IFERROR(AVERAGE(C31:E31,G31:I31,K31:M31,O31:Q31),"")
B32: Headcount this Month | C32: =OCT!K32 | D32: =NOV!K32 | E32: =DEC!K32 | F32: =IFERROR(AVERAGE(C32:E32),"") | G32: =JAN!K32 | H32: =FEB!K32 | I32: =MAR!K32 | J32: =IFERROR(AVERAGE(G32:I32),"") | K32: =APR!K32 | L32: =MAY!K32 | M32: =JUN!K32 | N32: =IFERROR(AVERAGE(K32:M32),"") | O32: =JUL!K32 | P32: =AUG!K32 | Q32: =SEP!K32 | R32: =IFERROR(AVERAGE(O32:Q32),"") | S32: =IFERROR(AVERAGE(C32:E32,G32:I32,K32:M32,O32:Q32),"")
B33: Full Turnover (%) | C33: =OCT!K33 | D33: =NOV!K33 | E33: =DEC!K33 | F33: =IF(COUNT(F31,F32)<2,"",IF((F32+F31)=0,"",N(F24)/((F32+F31)/2))) | G33: =JAN!K33 | H33: =FEB!K33 | I33: =MAR!K33 | J33: =IF(COUNT(J31,J32)<2,"",IF((J32+J31)=0,"",N(J24)/((J32+J31)/2))) | K33: =APR!K33 | L33: =MAY!K33 | M33: =JUN!K33 | N33: =IF(COUNT(N31,N32)<2,"",IF((N32+N31)=0,"",N(N24)/((N32+N31)/2))) | O33: =JUL!K33 | P33: =AUG!K33 | Q33: =SEP!K33 | R33: =IF(COUNT(R31,R32)<2,"",IF((R32+R31)=0,"",N(R24)/((R32+R31)/2))) | S33: =IF(COUNT(S31,S32)<2,"",IF((S32+S31)=0,"",N(S24)/((S32+S31)/2)))
B34: Permanent Vacancies | C34: =OCT!K34 | D34: =NOV!K34 | E34: =DEC!K34 | F34: =IFERROR(AVERAGE(C34:E34),"") | G34: =JAN!K34 | H34: =FEB!K34 | I34: =MAR!K34 | J34: =IFERROR(AVERAGE(G34:I34),"") | K34: =APR!K34 | L34: =MAY!K34 | M34: =JUN!K34 | N34: =IFERROR(AVERAGE(K34:M34),"") | O34: =JUL!K34 | P34: =AUG!K34 | Q34: =SEP!K34 | R34: =IFERROR(AVERAGE(O34:Q34),"") | S34: =IFERROR(AVERAGE(C34:E34,G34:I34,K34:M34,O34:Q34),"")
B35: Temporary Vacancies | C35: =OCT!K35 | D35: =NOV!K35 | E35: =DEC!K35 | F35: =IFERROR(AVERAGE(C35:E35),"") | G35: =JAN!K35 | H35: =FEB!K35 | I35: =MAR!K35 | J35: =IFERROR(AVERAGE(G35:I35),"") | K35: =APR!K35 | L35: =MAY!K35 | M35: =JUN!K35 | N35: =IFERROR(AVERAGE(K35:M35),"") | O35: =JUL!K35 | P35: =AUG!K35 | Q35: =SEP!K35 | R35: =IFERROR(AVERAGE(O35:Q35),"") | S35: =IFERROR(AVERAGE(C35:E35,G35:I35,K35:M35,O35:Q35),"")
B36: Total Vacancies | C36: =OCT!K36 | D36: =NOV!K36 | E36: =DEC!K36 | F36: =IF(COUNT(F34:F35)=0,"",SUM(F34:F35)) | G36: =JAN!K36 | H36: =FEB!K36 | I36: =MAR!K36 | J36: =IF(COUNT(J34:J35)=0,"",SUM(J34:J35)) | K36: =APR!K36 | L36: =MAY!K36 | M36: =JUN!K36 | N36: =IF(COUNT(N34:N35)=0,"",SUM(N34:N35)) | O36: =JUL!K36 | P36: =AUG!K36 | Q36: =SEP!K36 | R36: =IF(COUNT(R34:R35)=0,"",SUM(R34:R35)) | S36: =IF(COUNT(S34:S35)=0,"",SUM(S34:S35))
B37: Authorized Positions | C37: =OCT!K37 | D37: =NOV!K37 | E37: =DEC!K37 | F37: =IF(COUNT(F5,F36)=0,"",N(F5)+N(F36)) | G37: =JAN!K37 | H37: =FEB!K37 | I37: =MAR!K37 | J37: =IF(COUNT(J5,J36)=0,"",N(J5)+N(J36)) | K37: =APR!K37 | L37: =MAY!K37 | M37: =JUN!K37 | N37: =IF(COUNT(N5,N36)=0,"",N(N5)+N(N36)) | O37: =JUL!K37 | P37: =AUG!K37 | Q37: =SEP!K37 | R37: =IF(COUNT(R5,R36)=0,"",N(R5)+N(R36)) | S37: =IF(COUNT(S5,S36)=0,"",N(S5)+N(S36))
B38: Vacancy Rate (%) | C38: =OCT!K38 | D38: =NOV!K38 | E38: =DEC!K38 | F38: =IFERROR(F36/F37,"") | G38: =JAN!K38 | H38: =FEB!K38 | I38: =MAR!K38 | J38: =IFERROR(J36/J37,"") | K38: =APR!K38 | L38: =MAY!K38 | M38: =JUN!K38 | N38: =IFERROR(N36/N37,"") | O38: =JUL!K38 | P38: =AUG!K38 | Q38: =SEP!K38 | R38: =IFERROR(R36/R37,"") | S38: =IFERROR(S36/S37,"")
B39: Permanent TimeToHire (Days) YTD | C39: =OCT!K39 | D39: =NOV!K39 | E39: =DEC!K39 | F39: =IFERROR(LOOKUP(2,1/ISNUMBER(C39:E39),C39:E39),"") | G39: =JAN!K39 | H39: =FEB!K39 | I39: =MAR!K39 | J39: =IFERROR(LOOKUP(2,1/ISNUMBER(G39:I39),G39:I39),"") | K39: =APR!K39 | L39: =MAY!K39 | M39: =JUN!K39 | N39: =IFERROR(LOOKUP(2,1/ISNUMBER(K39:M39),K39:M39),"") | O39: =JUL!K39 | P39: =AUG!K39 | Q39: =SEP!K39 | R39: =IFERROR(LOOKUP(2,1/ISNUMBER(O39:Q39),O39:Q39),"") | S39: =IFERROR(LOOKUP(2,1/ISNUMBER(C39:Q39),C39:Q39),"")
B40: Temporary TimeToHire (Days) YTD | C40: =OCT!K40 | D40: =NOV!K40 | E40: =DEC!K40 | F40: =IFERROR(LOOKUP(2,1/ISNUMBER(C40:E40),C40:E40),"") | G40: =JAN!K40 | H40: =FEB!K40 | I40: =MAR!K40 | J40: =IFERROR(LOOKUP(2,1/ISNUMBER(G40:I40),G40:I40),"") | K40: =APR!K40 | L40: =MAY!K40 | M40: =JUN!K40 | N40: =IFERROR(LOOKUP(2,1/ISNUMBER(K40:M40),K40:M40),"") | O40: =JUL!K40 | P40: =AUG!K40 | Q40: =SEP!K40 | R40: =IFERROR(LOOKUP(2,1/ISNUMBER(O40:Q40),O40:Q40),"") | S40: =IFERROR(LOOKUP(2,1/ISNUMBER(C40:Q40),C40:Q40),"")
...

Sheet OCT
B1: GCG CENTRAL AMERICA | C1: 1171 | D1: 1162 | E1: 1076 | F1: 1170 | G1: 1078 | H1: 1172 | I1: 1074 | J1: 1161
A2: 202610 | B2: OCT | C2: GCG Culinary Costa Rica | D2: GCG Food Guatemala | E2: GCG Guatemala | F2: GCG Aviation Ground Honduras | G2: GCG Honduras | H2: GCG Concessions Panama | I2: GCG El Salvador | J2: GCG Food El Salvador | K2: TOTAL | L2: Total by Division | M2: =N(M11)<>0
A3: =+A2 | B3: Permanent (Regular) Headcount | K3: =IF(COUNT(C3:J3)=0,"",SUM(C3:J3)) | L3: ∑
B4: Temporary (Fix Term) Headcount | K4: =IF(COUNT(C4:J4)=0,"",SUM(C4:J4)) | L4: ∑
B5: Employee Headcount (Productivity) | C5: =IF(COUNT(C3:C4)=0,"",SUM(C3:C4)) | D5: =IF(COUNT(D3:D4)=0,"",SUM(D3:D4)) | E5: =IF(COUNT(E3:E4)=0,"",SUM(E3:E4)) | F5: =IF(COUNT(F3:F4)=0,"",SUM(F3:F4)) | G5: =IF(COUNT(G3:G4)=0,"",SUM(G3:G4)) | H5: =IF(COUNT(H3:H4)=0,"",SUM(H3:H4)) | I5: =IF(COUNT(I3:I4)=0,"",SUM(I3:I4)) | J5: =IF(COUNT(J3:J4)=0,"",SUM(J3:J4)) | K5: =IF(COUNT(K3:K4)=0,"",SUM(K3:K4)) | L5: ϝ
B6: Headcount = 1.00 | K6: =IF(COUNT(C6:J6)=0,"",SUM(C6:J6)) | L6: ∑
B7: Headcount = 0.75 | K7: =IF(COUNT(C7:J7)=0,"",SUM(C7:J7)) | L7: ∑
B8: Headcount = 0.50 | K8: =IF(COUNT(C8:J8)=0,"",SUM(C8:J8)) | L8: ∑
B9: Headcount = 0.25 | K9: =IF(COUNT(C9:J9)=0,"",SUM(C9:J9)) | L9: ∑
B10: Standard Monthly Hours (FTE basis) | K10: =IFERROR(AVERAGE(C10:J10),"") | L10: Avg
B11: Employee FTE (Finance) | C11: =IF(COUNT(C6:C9)=0,"",N(C6)+N(C7)*0.75+N(C8)*0.5+N(C9)*0.25) | D11: =IF(COUNT(D6:D9)=0,"",N(D6)+N(D7)*0.75+N(D8)*0.5+N(D9)*0.25) | E11: =IF(COUNT(E6:E9)=0,"",N(E6)+N(E7)*0.75+N(E8)*0.5+N(E9)*0.25) | F11: =IF(COUNT(F6:F9)=0,"",N(F6)+N(F7)*0.75+N(F8)*0.5+N(F9)*0.25) | G11: =IF(COUNT(G6:G9)=0,"",N(G6)+N(G7)*0.75+N(G8)*0.5+N(G9)*0.25) | H11: =IF(COUNT(H6:H9)=0,"",N(H6)+N(H7)*0.75+N(H8)*0.5+N(H9)*0.25) | I11: =IF(COUNT(I6:I9)=0,"",N(I6)+N(I7)*0.75+N(I8)*0.5+N(I9)*0.25) | J11: =IF(COUNT(J6:J9)=0,"",N(J6)+N(J7)*0.75+N(J8)*0.5+N(J9)*0.25) | K11: =IF(COUNT(K6:K9)=0,"",N(K6)+N(K7)*0.75+N(K8)*0.5+N(K9)*0.25) | L11: FTE | M11: =IF(COUNT(K5:K9)=0,"",N(K6)+N(K7)+N(K8)+N(K9)-N(K5))
B12: Subcontracted Workforce HC | K12: =IF(COUNT(C12:J12)=0,"",SUM(C12:J12)) | L12: ∑
B13: Subcontracted Productive Hours | K13: =IF(COUNT(C13:J13)=0,"",SUM(C13:J13)) | L13: ∑
B14: Subcontracted FTE | C14: =IFERROR(C13/C10,"") | D14: =IFERROR(D13/D10,"") | E14: =IFERROR(E13/E10,"") | F14: =IFERROR(F13/F10,"") | G14: =IFERROR(G13/G10,"") | H14: =IFERROR(H13/H10,"") | I14: =IFERROR(I13/I10,"") | J14: =IFERROR(J13/J10,"") | K14: =IF(COUNT(C14:J14)=0,"",SUM(C14:J14)) | L14: FTE
B15: Total Operational Workforce | C15: =IF(COUNT(C5,C12)=0,"",SUM(C5,C12)) | D15: =IF(COUNT(D5,D12)=0,"",SUM(D5,D12)) | E15: =IF(COUNT(E5,E12)=0,"",SUM(E5,E12)) | F15: =IF(COUNT(F5,F12)=0,"",SUM(F5,F12)) | G15: =IF(COUNT(G5,G12)=0,"",SUM(G5,G12)) | H15: =IF(COUNT(H5,H12)=0,"",SUM(H5,H12)) | I15: =IF(COUNT(I5,I12)=0,"",SUM(I5,I12)) | J15: =IF(COUNT(J5,J12)=0,"",SUM(J5,J12)) | K15: =IF(COUNT(K5,K12)=0,"",SUM(K5,K12)) | L15: ϝ
B16: Total Operational FTE | C16: =IF(COUNT(C11,C14)=0,"",SUM(C11,C14)) | D16: =IF(COUNT(D11,D14)=0,"",SUM(D11,D14)) | E16: =IF(COUNT(E11,E14)=0,"",SUM(E11,E14)) | F16: =IF(COUNT(F11,F14)=0,"",SUM(F11,F14)) | G16: =IF(COUNT(G11,G14)=0,"",SUM(G11,G14)) | H16: =IF(COUNT(H11,H14)=0,"",SUM(H11,H14)) | I16: =IF(COUNT(I11,I14)=0,"",SUM(I11,I14)) | J16: =IF(COUNT(J11,J14)=0,"",SUM(J11,J14)) | K16: =IF(COUNT(K11,K14)=0,"",SUM(K11,K14)) | L16: FTE
B17: Subcontracted Share of Workforce (%) | C17: =IFERROR(C12/C15,"") | D17: =IFERROR(D12/D15,"") | E17: =IFERROR(E12/E15,"") | F17: =IFERROR(F12/F15,"") | G17: =IFERROR(G12/G15,"") | H17: =IFERROR(H12/H15,"") | I17: =IFERROR(I12/I15,"") | J17: =IFERROR(J12/J15,"") | K17: =IFERROR(K12/K15,"") | L17: ϝ
B18: FTE HR Team | K18: =IF(COUNT(C18:J18)=0,"",SUM(C18:J18)) | L18: ∑
B19: Permanent Hires | K19: =IF(COUNT(C19:J19)=0,"",SUM(C19:J19)) | L19: ∑
B20: Temporary Hires | K20: =IF(COUNT(C20:J20)=0,"",SUM(C20:J20)) | L20: ∑
B21: Total Hires | C21: =IF(COUNT(C19:C20)=0,"",SUM(C19:C20)) | D21: =IF(COUNT(D19:D20)=0,"",SUM(D19:D20)) | E21: =IF(COUNT(E19:E20)=0,"",SUM(E19:E20)) | F21: =IF(COUNT(F19:F20)=0,"",SUM(F19:F20)) | G21: =IF(COUNT(G19:G20)=0,"",SUM(G19:G20)) | H21: =IF(COUNT(H19:H20)=0,"",SUM(H19:H20)) | I21: =IF(COUNT(I19:I20)=0,"",SUM(I19:I20)) | J21: =IF(COUNT(J19:J20)=0,"",SUM(J19:J20)) | K21: =IF(COUNT(K19:K20)=0,"",SUM(K19:K20)) | L21: ϝ
B22: Permanent Exits | K22: =IF(COUNT(C22:J22)=0,"",SUM(C22:J22)) | L22: ∑
B23: Temporary Exits | K23: =IF(COUNT(C23:J23)=0,"",SUM(C23:J23)) | L23: ∑
B24: Total Exits | C24: =IF(COUNT(C22:C23)=0,"",SUM(C22:C23)) | D24: =IF(COUNT(D22:D23)=0,"",SUM(D22:D23)) | E24: =IF(COUNT(E22:E23)=0,"",SUM(E22:E23)) | F24: =IF(COUNT(F22:F23)=0,"",SUM(F22:F23)) | G24: =IF(COUNT(G22:G23)=0,"",SUM(G22:G23)) | H24: =IF(COUNT(H22:H23)=0,"",SUM(H22:H23)) | I24: =IF(COUNT(I22:I23)=0,"",SUM(I22:I23)) | J24: =IF(COUNT(J22:J23)=0,"",SUM(J22:J23)) | K24: =IF(COUNT(K22:K23)=0,"",SUM(K22:K23)) | L24: ϝ
B25: Permanent Turnover (%) | C25: =IF(COUNT(C31,C32)<2,"",IF((C32+C31)=0,"",N(C22)/((C32+C31)/2))) | D25: =IF(COUNT(D31,D32)<2,"",IF((D32+D31)=0,"",N(D22)/((D32+D31)/2))) | E25: =IF(COUNT(E31,E32)<2,"",IF((E32+E31)=0,"",N(E22)/((E32+E31)/2))) | F25: =IF(COUNT(F31,F32)<2,"",IF((F32+F31)=0,"",N(F22)/((F32+F31)/2))) | G25: =IF(COUNT(G31,G32)<2,"",IF((G32+G31)=0,"",N(G22)/((G32+G31)/2))) | H25: =IF(COUNT(H31,H32)<2,"",IF((H32+H31)=0,"",N(H22)/((H32+H31)/2))) | I25: =IF(COUNT(I31,I32)<2,"",IF((I32+I31)=0,"",N(I22)/((I32+I31)/2))) | J25: =IF(COUNT(J31,J32)<2,"",IF((J32+J31)=0,"",N(J22)/((J32+J31)/2))) | K25: =IF(COUNT(K31,K32)<2,"",IF((K32+K31)=0,"",N(K22)/((K32+K31)/2))) | L25: ϝ
B26: Temporary Turnover (%) | C26: =IF(COUNT(C31,C32)<2,"",IF((C32+C31)=0,"",N(C23)/((C32+C31)/2))) | D26: =IF(COUNT(D31,D32)<2,"",IF((D32+D31)=0,"",N(D23)/((D32+D31)/2))) | E26: =IF(COUNT(E31,E32)<2,"",IF((E32+E31)=0,"",N(E23)/((E32+E31)/2))) | F26: =IF(COUNT(F31,F32)<2,"",IF((F32+F31)=0,"",N(F23)/((F32+F31)/2))) | G26: =IF(COUNT(G31,G32)<2,"",IF((G32+G31)=0,"",N(G23)/((G32+G31)/2))) | H26: =IF(COUNT(H31,H32)<2,"",IF((H32+H31)=0,"",N(H23)/((H32+H31)/2))) | I26: =IF(COUNT(I31,I32)<2,"",IF((I32+I31)=0,"",N(I23)/((I32+I31)/2))) | J26: =IF(COUNT(J31,J32)<2,"",IF((J32+J31)=0,"",N(J23)/((J32+J31)/2))) | K26: =IF(COUNT(K31,K32)<2,"",IF((K32+K31)=0,"",N(K23)/((K32+K31)/2))) | L26: ϝ
B27: Voluntary Terminations | K27: =IF(COUNT(C27:J27)=0,"",SUM(C27:J27)) | L27: ∑
B28: Involuntary Terminations | K28: =IF(COUNT(C28:J28)=0,"",SUM(C28:J28)) | L28: ∑
B29: Voluntary Turnover (%) | C29: =IF(COUNT(C31,C32)<2,"",IF((C32+C31)=0,"",N(C27)/((C32+C31)/2))) | D29: =IF(COUNT(D31,D32)<2,"",IF((D32+D31)=0,"",N(D27)/((D32+D31)/2))) | E29: =IF(COUNT(E31,E32)<2,"",IF((E32+E31)=0,"",N(E27)/((E32+E31)/2))) | F29: =IF(COUNT(F31,F32)<2,"",IF((F32+F31)=0,"",N(F27)/((F32+F31)/2))) | G29: =IF(COUNT(G31,G32)<2,"",IF((G32+G31)=0,"",N(G27)/((G32+G31)/2))) | H29: =IF(COUNT(H31,H32)<2,"",IF((H32+H31)=0,"",N(H27)/((H32+H31)/2))) | I29: =IF(COUNT(I31,I32)<2,"",IF((I32+I31)=0,"",N(I27)/((I32+I31)/2))) | J29: =IF(COUNT(J31,J32)<2,"",IF((J32+J31)=0,"",N(J27)/((J32+J31)/2))) | K29: =IF(COUNT(K31,K32)<2,"",IF((K32+K31)=0,"",N(K27)/((K32+K31)/2))) | L29: ϝ
B30: Involuntary Turnover (%) | C30: =IF(COUNT(C31,C32)<2,"",IF((C32+C31)=0,"",N(C28)/((C32+C31)/2))) | D30: =IF(COUNT(D31,D32)<2,"",IF((D32+D31)=0,"",N(D28)/((D32+D31)/2))) | E30: =IF(COUNT(E31,E32)<2,"",IF((E32+E31)=0,"",N(E28)/((E32+E31)/2))) | F30: =IF(COUNT(F31,F32)<2,"",IF((F32+F31)=0,"",N(F28)/((F32+F31)/2))) | G30: =IF(COUNT(G31,G32)<2,"",IF((G32+G31)=0,"",N(G28)/((G32+G31)/2))) | H30: =IF(COUNT(H31,H32)<2,"",IF((H32+H31)=0,"",N(H28)/((H32+H31)/2))) | I30: =IF(COUNT(I31,I32)<2,"",IF((I32+I31)=0,"",N(I28)/((I32+I31)/2))) | J30: =IF(COUNT(J31,J32)<2,"",IF((J32+J31)=0,"",N(J28)/((J32+J31)/2))) | K30: =IF(COUNT(K31,K32)<2,"",IF((K32+K31)=0,"",N(K28)/((K32+K31)/2))) | L30: ϝ
B31: Headcount last Month | K31: =IF(COUNT(C31:J31)=0,"",SUM(C31:J31)) | L31: ∑
B32: Headcount this Month | C32: =IF(C5="","",C5) | D32: =IF(D5="","",D5) | E32: =IF(E5="","",E5) | F32: =IF(F5="","",F5) | G32: =IF(G5="","",G5) | H32: =IF(H5="","",H5) | I32: =IF(I5="","",I5) | J32: =IF(J5="","",J5) | K32: =IF(COUNT(C32:J32)=0,"",SUM(C32:J32)) | L32: ∑
B33: Full Turnover (%) | C33: =IF(COUNT(C31,C32)<2,"",IF((C32+C31)=0,"",N(C24)/((C32+C31)/2))) | D33: =IF(COUNT(D31,D32)<2,"",IF((D32+D31)=0,"",N(D24)/((D32+D31)/2))) | E33: =IF(COUNT(E31,E32)<2,"",IF((E32+E31)=0,"",N(E24)/((E32+E31)/2))) | F33: =IF(COUNT(F31,F32)<2,"",IF((F32+F31)=0,"",N(F24)/((F32+F31)/2))) | G33: =IF(COUNT(G31,G32)<2,"",IF((G32+G31)=0,"",N(G24)/((G32+G31)/2))) | H33: =IF(COUNT(H31,H32)<2,"",IF((H32+H31)=0,"",N(H24)/((H32+H31)/2))) | I33: =IF(COUNT(I31,I32)<2,"",IF((I32+I31)=0,"",N(I24)/((I32+I31)/2))) | J33: =IF(COUNT(J31,J32)<2,"",IF((J32+J31)=0,"",N(J24)/((J32+J31)/2))) | K33: =IF(COUNT(K31,K32)<2,"",IF((K32+K31)=0,"",N(K24)/((K32+K31)/2))) | L33: ϝ
B34: Permanent Vacancies | K34: =IF(COUNT(C34:J34)=0,"",SUM(C34:J34)) | L34: ∑
B35: Temporary Vacancies | K35: =IF(COUNT(C35:J35)=0,"",SUM(C35:J35)) | L35: ∑
B36: Total Vacancies | C36: =IF(COUNT(C34:C35)=0,"",SUM(C34:C35)) | D36: =IF(COUNT(D34:D35)=0,"",SUM(D34:D35)) | E36: =IF(COUNT(E34:E35)=0,"",SUM(E34:E35)) | F36: =IF(COUNT(F34:F35)=0,"",SUM(F34:F35)) | G36: =IF(COUNT(G34:G35)=0,"",SUM(G34:G35)) | H36: =IF(COUNT(H34:H35)=0,"",SUM(H34:H35)) | I36: =IF(COUNT(I34:I35)=0,"",SUM(I34:I35)) | J36: =IF(COUNT(J34:J35)=0,"",SUM(J34:J35)) | K36: =IF(COUNT(K34:K35)=0,"",SUM(K34:K35)) | L36: ϝ
B37: Authorized Positions | C37: =IF(COUNT(C5,C36)=0,"",N(C5)+N(C36)) | D37: =IF(COUNT(D5,D36)=0,"",N(D5)+N(D36)) | E37: =IF(COUNT(E5,E36)=0,"",N(E5)+N(E36)) | F37: =IF(COUNT(F5,F36)=0,"",N(F5)+N(F36)) | G37: =IF(COUNT(G5,G36)=0,"",N(G5)+N(G36)) | H37: =IF(COUNT(H5,H36)=0,"",N(H5)+N(H36)) | I37: =IF(COUNT(I5,I36)=0,"",N(I5)+N(I36)) | J37: =IF(COUNT(J5,J36)=0,"",N(J5)+N(J36)) | K37: =IF(COUNT(K5,K36)=0,"",N(K5)+N(K36)) | L37: ϝ
B38: Vacancy Rate (%) | C38: =IFERROR(C36/C37,"") | D38: =IFERROR(D36/D37,"") | E38: =IFERROR(E36/E37,"") | F38: =IFERROR(F36/F37,"") | G38: =IFERROR(G36/G37,"") | H38: =IFERROR(H36/H37,"") | I38: =IFERROR(I36/I37,"") | J38: =IFERROR(J36/J37,"") | K38: =IFERROR(K36/K37,"") | L38: ϝ
B39: Permanent TimeToHire (Days) YTD | C39: =IF('(Culinary_CRI)'!$AB$4="","",'(Culinary_CRI)'!$AB$4) | D39: =IF('(Food_GTM)'!$AB$4="","",'(Food_GTM)'!$AB$4) | E39: =IF('(GCG_GTM)'!$AB$4="","",'(GCG_GTM)'!$AB$4) | F39: =IF('(Ground_HND)'!$AB$4="","",'(Ground_HND)'!$AB$4) | G39: =IF('(GCG_HND)'!$AB$4="","",'(GCG_HND)'!$AB$4) | H39: =IF('(Concess_PAN)'!$AB$4="","",'(Concess_PAN)'!$AB$4) | I39: =IF('(GCG_SLV)'!$AB$4="","",'(GCG_SLV)'!$AB$4) | J39: =IF('(Food_SLV)'!$AB$4="","",'(Food_SLV)'!$AB$4) | K39: =IFERROR(AVERAGE(C39:J39),"") | L39: Avg
B40: Temporary TimeToHire (Days) YTD | C40: =IF('(Culinary_CRI)'!$AD$4="","",'(Culinary_CRI)'!$AD$4) | D40: =IF('(Food_GTM)'!$AD$4="","",'(Food_GTM)'!$AD$4) | E40: =IF('(GCG_GTM)'!$AD$4="","",'(GCG_GTM)'!$AD$4) | F40: =IF('(Ground_HND)'!$AD$4="","",'(Ground_HND)'!$AD$4) | G40: =IF('(GCG_HND)'!$AD$4="","",'(GCG_HND)'!$AD$4) | H40: =IF('(Concess_PAN)'!$AD$4="","",'(Concess_PAN)'!$AD$4) | I40: =IF('(GCG_SLV)'!$AD$4="","",'(GCG_SLV)'!$AD$4) | J40: =IF('(Food_SLV)'!$AD$4="","",'(Food_SLV)'!$AD$4) | K40: =IFERROR(AVERAGE(C40:J40),"") | L40: Avg
...

Sheet NOV
B1: GCG CENTRAL AMERICA | C1: 1171 | D1: 1162 | E1: 1076 | F1: 1170 | G1: 1078 | H1: 1172 | I1: 1074 | J1: 1161
A2: =VALUE(TEXT(EDATE(DATE(LEFT(OCT!A2,4),RIGHT(OCT!A2,2),1),1),"yyyymm")) | B2: NOV | C2: GCG Culinary Costa Rica | D2: GCG Food Guatemala | E2: GCG Guatemala | F2: GCG Aviation Ground Honduras | G2: GCG Honduras | H2: GCG Concessions Panama | I2: GCG El Salvador | J2: GCG Food El Salvador | K2: TOTAL | L2: Total by Division | M2: =N(M11)<>0
A3: =+A2 | B3: Permanent (Regular) Headcount | K3: =IF(COUNT(C3:J3)=0,"",SUM(C3:J3)) | L3: ∑
B4: Temporary (Fix Term) Headcount | K4: =IF(COUNT(C4:J4)=0,"",SUM(C4:J4)) | L4: ∑
B5: Employee Headcount (Productivity) | C5: =IF(COUNT(C3:C4)=0,"",SUM(C3:C4)) | D5: =IF(COUNT(D3:D4)=0,"",SUM(D3:D4)) | E5: =IF(COUNT(E3:E4)=0,"",SUM(E3:E4)) | F5: =IF(COUNT(F3:F4)=0,"",SUM(F3:F4)) | G5: =IF(COUNT(G3:G4)=0,"",SUM(G3:G4)) | H5: =IF(COUNT(H3:H4)=0,"",SUM(H3:H4)) | I5: =IF(COUNT(I3:I4)=0,"",SUM(I3:I4)) | J5: =IF(COUNT(J3:J4)=0,"",SUM(J3:J4)) | K5: =IF(COUNT(K3:K4)=0,"",SUM(K3:K4)) | L5: ϝ
B6: Headcount = 1.00 | K6: =IF(COUNT(C6:J6)=0,"",SUM(C6:J6)) | L6: ∑
B7: Headcount = 0.75 | K7: =IF(COUNT(C7:J7)=0,"",SUM(C7:J7)) | L7: ∑
B8: Headcount = 0.50 | K8: =IF(COUNT(C8:J8)=0,"",SUM(C8:J8)) | L8: ∑
B9: Headcount = 0.25 | K9: =IF(COUNT(C9:J9)=0,"",SUM(C9:J9)) | L9: ∑
B10: Standard Monthly Hours (FTE basis) | K10: =IFERROR(AVERAGE(C10:J10),"") | L10: Avg
B11: Employee FTE (Finance) | C11: =IF(COUNT(C6:C9)=0,"",N(C6)+N(C7)*0.75+N(C8)*0.5+N(C9)*0.25) | D11: =IF(COUNT(D6:D9)=0,"",N(D6)+N(D7)*0.75+N(D8)*0.5+N(D9)*0.25) | E11: =IF(COUNT(E6:E9)=0,"",N(E6)+N(E7)*0.75+N(E8)*0.5+N(E9)*0.25) | F11: =IF(COUNT(F6:F9)=0,"",N(F6)+N(F7)*0.75+N(F8)*0.5+N(F9)*0.25) | G11: =IF(COUNT(G6:G9)=0,"",N(G6)+N(G7)*0.75+N(G8)*0.5+N(G9)*0.25) | H11: =IF(COUNT(H6:H9)=0,"",N(H6)+N(H7)*0.75+N(H8)*0.5+N(H9)*0.25) | I11: =IF(COUNT(I6:I9)=0,"",N(I6)+N(I7)*0.75+N(I8)*0.5+N(I9)*0.25) | J11: =IF(COUNT(J6:J9)=0,"",N(J6)+N(J7)*0.75+N(J8)*0.5+N(J9)*0.25) | K11: =IF(COUNT(K6:K9)=0,"",N(K6)+N(K7)*0.75+N(K8)*0.5+N(K9)*0.25) | L11: FTE | M11: =IF(COUNT(K5:K9)=0,"",N(K6)+N(K7)+N(K8)+N(K9)-N(K5))
B12: Subcontracted Workforce HC | K12: =IF(COUNT(C12:J12)=0,"",SUM(C12:J12)) | L12: ∑
B13: Subcontracted Productive Hours | K13: =IF(COUNT(C13:J13)=0,"",SUM(C13:J13)) | L13: ∑
B14: Subcontracted FTE | C14: =IFERROR(C13/C10,"") | D14: =IFERROR(D13/D10,"") | E14: =IFERROR(E13/E10,"") | F14: =IFERROR(F13/F10,"") | G14: =IFERROR(G13/G10,"") | H14: =IFERROR(H13/H10,"") | I14: =IFERROR(I13/I10,"") | J14: =IFERROR(J13/J10,"") | K14: =IF(COUNT(C14:J14)=0,"",SUM(C14:J14)) | L14: FTE
B15: Total Operational Workforce | C15: =IF(COUNT(C5,C12)=0,"",SUM(C5,C12)) | D15: =IF(COUNT(D5,D12)=0,"",SUM(D5,D12)) | E15: =IF(COUNT(E5,E12)=0,"",SUM(E5,E12)) | F15: =IF(COUNT(F5,F12)=0,"",SUM(F5,F12)) | G15: =IF(COUNT(G5,G12)=0,"",SUM(G5,G12)) | H15: =IF(COUNT(H5,H12)=0,"",SUM(H5,H12)) | I15: =IF(COUNT(I5,I12)=0,"",SUM(I5,I12)) | J15: =IF(COUNT(J5,J12)=0,"",SUM(J5,J12)) | K15: =IF(COUNT(K5,K12)=0,"",SUM(K5,K12)) | L15: ϝ
B16: Total Operational FTE | C16: =IF(COUNT(C11,C14)=0,"",SUM(C11,C14)) | D16: =IF(COUNT(D11,D14)=0,"",SUM(D11,D14)) | E16: =IF(COUNT(E11,E14)=0,"",SUM(E11,E14)) | F16: =IF(COUNT(F11,F14)=0,"",SUM(F11,F14)) | G16: =IF(COUNT(G11,G14)=0,"",SUM(G11,G14)) | H16: =IF(COUNT(H11,H14)=0,"",SUM(H11,H14)) | I16: =IF(COUNT(I11,I14)=0,"",SUM(I11,I14)) | J16: =IF(COUNT(J11,J14)=0,"",SUM(J11,J14)) | K16: =IF(COUNT(K11,K14)=0,"",SUM(K11,K14)) | L16: FTE
B17: Subcontracted Share of Workforce (%) | C17: =IFERROR(C12/C15,"") | D17: =IFERROR(D12/D15,"") | E17: =IFERROR(E12/E15,"") | F17: =IFERROR(F12/F15,"") | G17: =IFERROR(G12/G15,"") | H17: =IFERROR(H12/H15,"") | I17: =IFERROR(I12/I15,"") | J17: =IFERROR(J12/J15,"") | K17: =IFERROR(K12/K15,"") | L17: ϝ
B18: FTE HR Team | K18: =IF(COUNT(C18:J18)=0,"",SUM(C18:J18)) | L18: ∑
B19: Permanent Hires | K19: =IF(COUNT(C19:J19)=0,"",SUM(C19:J19)) | L19: ∑
B20: Temporary Hires | K20: =IF(COUNT(C20:J20)=0,"",SUM(C20:J20)) | L20: ∑
B21: Total Hires | C21: =IF(COUNT(C19:C20)=0,"",SUM(C19:C20)) | D21: =IF(COUNT(D19:D20)=0,"",SUM(D19:D20)) | E21: =IF(COUNT(E19:E20)=0,"",SUM(E19:E20)) | F21: =IF(COUNT(F19:F20)=0,"",SUM(F19:F20)) | G21: =IF(COUNT(G19:G20)=0,"",SUM(G19:G20)) | H21: =IF(COUNT(H19:H20)=0,"",SUM(H19:H20)) | I21: =IF(COUNT(I19:I20)=0,"",SUM(I19:I20)) | J21: =IF(COUNT(J19:J20)=0,"",SUM(J19:J20)) | K21: =IF(COUNT(K19:K20)=0,"",SUM(K19:K20)) | L21: ϝ
B22: Permanent Exits | K22: =IF(COUNT(C22:J22)=0,"",SUM(C22:J22)) | L22: ∑
B23: Temporary Exits | K23: =IF(COUNT(C23:J23)=0,"",SUM(C23:J23)) | L23: ∑
B24: Total Exits | C24: =IF(COUNT(C22:C23)=0,"",SUM(C22:C23)) | D24: =IF(COUNT(D22:D23)=0,"",SUM(D22:D23)) | E24: =IF(COUNT(E22:E23)=0,"",SUM(E22:E23)) | F24: =IF(COUNT(F22:F23)=0,"",SUM(F22:F23)) | G24: =IF(COUNT(G22:G23)=0,"",SUM(G22:G23)) | H24: =IF(COUNT(H22:H23)=0,"",SUM(H22:H23)) | I24: =IF(COUNT(I22:I23)=0,"",SUM(I22:I23)) | J24: =IF(COUNT(J22:J23)=0,"",SUM(J22:J23)) | K24: =IF(COUNT(K22:K23)=0,"",SUM(K22:K23)) | L24: ϝ
B25: Permanent Turnover (%) | C25: =IF(COUNT(C31,C32)<2,"",IF((C32+C31)=0,"",N(C22)/((C32+C31)/2))) | D25: =IF(COUNT(D31,D32)<2,"",IF((D32+D31)=0,"",N(D22)/((D32+D31)/2))) | E25: =IF(COUNT(E31,E32)<2,"",IF((E32+E31)=0,"",N(E22)/((E32+E31)/2))) | F25: =IF(COUNT(F31,F32)<2,"",IF((F32+F31)=0,"",N(F22)/((F32+F31)/2))) | G25: =IF(COUNT(G31,G32)<2,"",IF((G32+G31)=0,"",N(G22)/((G32+G31)/2))) | H25: =IF(COUNT(H31,H32)<2,"",IF((H32+H31)=0,"",N(H22)/((H32+H31)/2))) | I25: =IF(COUNT(I31,I32)<2,"",IF((I32+I31)=0,"",N(I22)/((I32+I31)/2))) | J25: =IF(COUNT(J31,J32)<2,"",IF((J32+J31)=0,"",N(J22)/((J32+J31)/2))) | K25: =IF(COUNT(K31,K32)<2,"",IF((K32+K31)=0,"",N(K22)/((K32+K31)/2))) | L25: ϝ
B26: Temporary Turnover (%) | C26: =IF(COUNT(C31,C32)<2,"",IF((C32+C31)=0,"",N(C23)/((C32+C31)/2))) | D26: =IF(COUNT(D31,D32)<2,"",IF((D32+D31)=0,"",N(D23)/((D32+D31)/2))) | E26: =IF(COUNT(E31,E32)<2,"",IF((E32+E31)=0,"",N(E23)/((E32+E31)/2))) | F26: =IF(COUNT(F31,F32)<2,"",IF((F32+F31)=0,"",N(F23)/((F32+F31)/2))) | G26: =IF(COUNT(G31,G32)<2,"",IF((G32+G31)=0,"",N(G23)/((G32+G31)/2))) | H26: =IF(COUNT(H31,H32)<2,"",IF((H32+H31)=0,"",N(H23)/((H32+H31)/2))) | I26: =IF(COUNT(I31,I32)<2,"",IF((I32+I31)=0,"",N(I23)/((I32+I31)/2))) | J26: =IF(COUNT(J31,J32)<2,"",IF((J32+J31)=0,"",N(J23)/((J32+J31)/2))) | K26: =IF(COUNT(K31,K32)<2,"",IF((K32+K31)=0,"",N(K23)/((K32+K31)/2))) | L26: ϝ
B27: Voluntary Terminations | K27: =IF(COUNT(C27:J27)=0,"",SUM(C27:J27)) | L27: ∑
B28: Involuntary Terminations | K28: =IF(COUNT(C28:J28)=0,"",SUM(C28:J28)) | L28: ∑
B29: Voluntary Turnover (%) | C29: =IF(COUNT(C31,C32)<2,"",IF((C32+C31)=0,"",N(C27)/((C32+C31)/2))) | D29: =IF(COUNT(D31,D32)<2,"",IF((D32+D31)=0,"",N(D27)/((D32+D31)/2))) | E29: =IF(COUNT(E31,E32)<2,"",IF((E32+E31)=0,"",N(E27)/((E32+E31)/2))) | F29: =IF(COUNT(F31,F32)<2,"",IF((F32+F31)=0,"",N(F27)/((F32+F31)/2))) | G29: =IF(COUNT(G31,G32)<2,"",IF((G32+G31)=0,"",N(G27)/((G32+G31)/2))) | H29: =IF(COUNT(H31,H32)<2,"",IF((H32+H31)=0,"",N(H27)/((H32+H31)/2))) | I29: =IF(COUNT(I31,I32)<2,"",IF((I32+I31)=0,"",N(I27)/((I32+I31)/2))) | J29: =IF(COUNT(J31,J32)<2,"",IF((J32+J31)=0,"",N(J27)/((J32+J31)/2))) | K29: =IF(COUNT(K31,K32)<2,"",IF((K32+K31)=0,"",N(K27)/((K32+K31)/2))) | L29: ϝ
B30: Involuntary Turnover (%) | C30: =IF(COUNT(C31,C32)<2,"",IF((C32+C31)=0,"",N(C28)/((C32+C31)/2))) | D30: =IF(COUNT(D31,D32)<2,"",IF((D32+D31)=0,"",N(D28)/((D32+D31)/2))) | E30: =IF(COUNT(E31,E32)<2,"",IF((E32+E31)=0,"",N(E28)/((E32+E31)/2))) | F30: =IF(COUNT(F31,F32)<2,"",IF((F32+F31)=0,"",N(F28)/((F32+F31)/2))) | G30: =IF(COUNT(G31,G32)<2,"",IF((G32+G31)=0,"",N(G28)/((G32+G31)/2))) | H30: =IF(COUNT(H31,H32)<2,"",IF((H32+H31)=0,"",N(H28)/((H32+H31)/2))) | I30: =IF(COUNT(I31,I32)<2,"",IF((I32+I31)=0,"",N(I28)/((I32+I31)/2))) | J30: =IF(COUNT(J31,J32)<2,"",IF((J32+J31)=0,"",N(J28)/((J32+J31)/2))) | K30: =IF(COUNT(K31,K32)<2,"",IF((K32+K31)=0,"",N(K28)/((K32+K31)/2))) | L30: ϝ
B31: Headcount last Month | C31: =IF(OCT!C5="","",OCT!C5) | D31: =IF(OCT!D5="","",OCT!D5) | E31: =IF(OCT!E5="","",OCT!E5) | F31: =IF(OCT!F5="","",OCT!F5) | G31: =IF(OCT!G5="","",OCT!G5) | H31: =IF(OCT!H5="","",OCT!H5) | I31: =IF(OCT!I5="","",OCT!I5) | J31: =IF(OCT!J5="","",OCT!J5) | K31: =IF(COUNT(C31:J31)=0,"",SUM(C31:J31)) | L31: ∑
B32: Headcount this Month | C32: =IF(C5="","",C5) | D32: =IF(D5="","",D5) | E32: =IF(E5="","",E5) | F32: =IF(F5="","",F5) | G32: =IF(G5="","",G5) | H32: =IF(H5="","",H5) | I32: =IF(I5="","",I5) | J32: =IF(J5="","",J5) | K32: =IF(COUNT(C32:J32)=0,"",SUM(C32:J32)) | L32: ∑
B33: Full Turnover (%) | C33: =IF(COUNT(C31,C32)<2,"",IF((C32+C31)=0,"",N(C24)/((C32+C31)/2))) | D33: =IF(COUNT(D31,D32)<2,"",IF((D32+D31)=0,"",N(D24)/((D32+D31)/2))) | E33: =IF(COUNT(E31,E32)<2,"",IF((E32+E31)=0,"",N(E24)/((E32+E31)/2))) | F33: =IF(COUNT(F31,F32)<2,"",IF((F32+F31)=0,"",N(F24)/((F32+F31)/2))) | G33: =IF(COUNT(G31,G32)<2,"",IF((G32+G31)=0,"",N(G24)/((G32+G31)/2))) | H33: =IF(COUNT(H31,H32)<2,"",IF((H32+H31)=0,"",N(H24)/((H32+H31)/2))) | I33: =IF(COUNT(I31,I32)<2,"",IF((I32+I31)=0,"",N(I24)/((I32+I31)/2))) | J33: =IF(COUNT(J31,J32)<2,"",IF((J32+J31)=0,"",N(J24)/((J32+J31)/2))) | K33: =IF(COUNT(K31,K32)<2,"",IF((K32+K31)=0,"",N(K24)/((K32+K31)/2))) | L33: ϝ
B34: Permanent Vacancies | K34: =IF(COUNT(C34:J34)=0,"",SUM(C34:J34)) | L34: ∑
B35: Temporary Vacancies | K35: =IF(COUNT(C35:J35)=0,"",SUM(C35:J35)) | L35: ∑
B36: Total Vacancies | C36: =IF(COUNT(C34:C35)=0,"",SUM(C34:C35)) | D36: =IF(COUNT(D34:D35)=0,"",SUM(D34:D35)) | E36: =IF(COUNT(E34:E35)=0,"",SUM(E34:E35)) | F36: =IF(COUNT(F34:F35)=0,"",SUM(F34:F35)) | G36: =IF(COUNT(G34:G35)=0,"",SUM(G34:G35)) | H36: =IF(COUNT(H34:H35)=0,"",SUM(H34:H35)) | I36: =IF(COUNT(I34:I35)=0,"",SUM(I34:I35)) | J36: =IF(COUNT(J34:J35)=0,"",SUM(J34:J35)) | K36: =IF(COUNT(K34:K35)=0,"",SUM(K34:K35)) | L36: ϝ
B37: Authorized Positions | C37: =IF(COUNT(C5,C36)=0,"",N(C5)+N(C36)) | D37: =IF(COUNT(D5,D36)=0,"",N(D5)+N(D36)) | E37: =IF(COUNT(E5,E36)=0,"",N(E5)+N(E36)) | F37: =IF(COUNT(F5,F36)=0,"",N(F5)+N(F36)) | G37: =IF(COUNT(G5,G36)=0,"",N(G5)+N(G36)) | H37: =IF(COUNT(H5,H36)=0,"",N(H5)+N(H36)) | I37: =IF(COUNT(I5,I36)=0,"",N(I5)+N(I36)) | J37: =IF(COUNT(J5,J36)=0,"",N(J5)+N(J36)) | K37: =IF(COUNT(K5,K36)=0,"",N(K5)+N(K36)) | L37: ϝ
B38: Vacancy Rate (%) | C38: =IFERROR(C36/C37,"") | D38: =IFERROR(D36/D37,"") | E38: =IFERROR(E36/E37,"") | F38: =IFERROR(F36/F37,"") | G38: =IFERROR(G36/G37,"") | H38: =IFERROR(H36/H37,"") | I38: =IFERROR(I36/I37,"") | J38: =IFERROR(J36/J37,"") | K38: =IFERROR(K36/K37,"") | L38: ϝ
B39: Permanent TimeToHire (Days) YTD | C39: =IF('(Culinary_CRI)'!$AB$5="","",'(Culinary_CRI)'!$AB$5) | D39: =IF('(Food_GTM)'!$AB$5="","",'(Food_GTM)'!$AB$5) | E39: =IF('(GCG_GTM)'!$AB$5="","",'(GCG_GTM)'!$AB$5) | F39: =IF('(Ground_HND)'!$AB$5="","",'(Ground_HND)'!$AB$5) | G39: =IF('(GCG_HND)'!$AB$5="","",'(GCG_HND)'!$AB$5) | H39: =IF('(Concess_PAN)'!$AB$5="","",'(Concess_PAN)'!$AB$5) | I39: =IF('(GCG_SLV)'!$AB$5="","",'(GCG_SLV)'!$AB$5) | J39: =IF('(Food_SLV)'!$AB$5="","",'(Food_SLV)'!$AB$5) | K39: =IFERROR(AVERAGE(C39:J39),"") | L39: Avg
B40: Temporary TimeToHire (Days) YTD | C40: =IF('(Culinary_CRI)'!$AD$5="","",'(Culinary_CRI)'!$AD$5) | D40: =IF('(Food_GTM)'!$AD$5="","",'(Food_GTM)'!$AD$5) | E40: =IF('(GCG_GTM)'!$AD$5="","",'(GCG_GTM)'!$AD$5) | F40: =IF('(Ground_HND)'!$AD$5="","",'(Ground_HND)'!$AD$5) | G40: =IF('(GCG_HND)'!$AD$5="","",'(GCG_HND)'!$AD$5) | H40: =IF('(Concess_PAN)'!$AD$5="","",'(Concess_PAN)'!$AD$5) | I40: =IF('(GCG_SLV)'!$AD$5="","",'(GCG_SLV)'!$AD$5) | J40: =IF('(Food_SLV)'!$AD$5="","",'(Food_SLV)'!$AD$5) | K40: =IFERROR(AVERAGE(C40:J40),"") | L40: Avg
...

Sheet DEC
B1: GCG CENTRAL AMERICA | C1: 1171 | D1: 1162 | E1: 1076 | F1: 1170 | G1: 1078 | H1: 1172 | I1: 1074 | J1: 1161
A2: =VALUE(TEXT(EDATE(DATE(LEFT(NOV!A2,4),RIGHT(NOV!A2,2),1),1),"yyyymm")) | B2: DEC | C2: GCG Culinary Costa Rica | D2: GCG Food Guatemala | E2: GCG Guatemala | F2: GCG Aviation Ground Honduras | G2: GCG Honduras | H2: GCG Concessions Panama | I2: GCG El Salvador | J2: GCG Food El Salvador | K2: TOTAL | L2: Total by Division | M2: =N(M11)<>0
A3: =+A2 | B3: Permanent (Regular) Headcount | K3: =IF(COUNT(C3:J3)=0,"",SUM(C3:J3)) | L3: ∑
B4: Temporary (Fix Term) Headcount | K4: =IF(COUNT(C4:J4)=0,"",SUM(C4:J4)) | L4: ∑
B5: Employee Headcount (Productivity) | C5: =IF(COUNT(C3:C4)=0,"",SUM(C3:C4)) | D5: =IF(COUNT(D3:D4)=0,"",SUM(D3:D4)) | E5: =IF(COUNT(E3:E4)=0,"",SUM(E3:E4)) | F5: =IF(COUNT(F3:F4)=0,"",SUM(F3:F4)) | G5: =IF(COUNT(G3:G4)=0,"",SUM(G3:G4)) | H5: =IF(COUNT(H3:H4)=0,"",SUM(H3:H4)) | I5: =IF(COUNT(I3:I4)=0,"",SUM(I3:I4)) | J5: =IF(COUNT(J3:J4)=0,"",SUM(J3:J4)) | K5: =IF(COUNT(K3:K4)=0,"",SUM(K3:K4)) | L5: ϝ
B6: Headcount = 1.00 | K6: =IF(COUNT(C6:J6)=0,"",SUM(C6:J6)) | L6: ∑
B7: Headcount = 0.75 | K7: =IF(COUNT(C7:J7)=0,"",SUM(C7:J7)) | L7: ∑
B8: Headcount = 0.50 | K8: =IF(COUNT(C8:J8)=0,"",SUM(C8:J8)) | L8: ∑
B9: Headcount = 0.25 | K9: =IF(COUNT(C9:J9)=0,"",SUM(C9:J9)) | L9: ∑
B10: Standard Monthly Hours (FTE basis) | K10: =IFERROR(AVERAGE(C10:J10),"") | L10: Avg
B11: Employee FTE (Finance) | C11: =IF(COUNT(C6:C9)=0,"",N(C6)+N(C7)*0.75+N(C8)*0.5+N(C9)*0.25) | D11: =IF(COUNT(D6:D9)=0,"",N(D6)+N(D7)*0.75+N(D8)*0.5+N(D9)*0.25) | E11: =IF(COUNT(E6:E9)=0,"",N(E6)+N(E7)*0.75+N(E8)*0.5+N(E9)*0.25) | F11: =IF(COUNT(F6:F9)=0,"",N(F6)+N(F7)*0.75+N(F8)*0.5+N(F9)*0.25) | G11: =IF(COUNT(G6:G9)=0,"",N(G6)+N(G7)*0.75+N(G8)*0.5+N(G9)*0.25) | H11: =IF(COUNT(H6:H9)=0,"",N(H6)+N(H7)*0.75+N(H8)*0.5+N(H9)*0.25) | I11: =IF(COUNT(I6:I9)=0,"",N(I6)+N(I7)*0.75+N(I8)*0.5+N(I9)*0.25) | J11: =IF(COUNT(J6:J9)=0,"",N(J6)+N(J7)*0.75+N(J8)*0.5+N(J9)*0.25) | K11: =IF(COUNT(K6:K9)=0,"",N(K6)+N(K7)*0.75+N(K8)*0.5+N(K9)*0.25) | L11: FTE | M11: =IF(COUNT(K5:K9)=0,"",N(K6)+N(K7)+N(K8)+N(K9)-N(K5))
B12: Subcontracted Workforce HC | K12: =IF(COUNT(C12:J12)=0,"",SUM(C12:J12)) | L12: ∑
B13: Subcontracted Productive Hours | K13: =IF(COUNT(C13:J13)=0,"",SUM(C13:J13)) | L13: ∑
B14: Subcontracted FTE | C14: =IFERROR(C13/C10,"") | D14: =IFERROR(D13/D10,"") | E14: =IFERROR(E13/E10,"") | F14: =IFERROR(F13/F10,"") | G14: =IFERROR(G13/G10,"") | H14: =IFERROR(H13/H10,"") | I14: =IFERROR(I13/I10,"") | J14: =IFERROR(J13/J10,"") | K14: =IF(COUNT(C14:J14)=0,"",SUM(C14:J14)) | L14: FTE
B15: Total Operational Workforce | C15: =IF(COUNT(C5,C12)=0,"",SUM(C5,C12)) | D15: =IF(COUNT(D5,D12)=0,"",SUM(D5,D12)) | E15: =IF(COUNT(E5,E12)=0,"",SUM(E5,E12)) | F15: =IF(COUNT(F5,F12)=0,"",SUM(F5,F12)) | G15: =IF(COUNT(G5,G12)=0,"",SUM(G5,G12)) | H15: =IF(COUNT(H5,H12)=0,"",SUM(H5,H12)) | I15: =IF(COUNT(I5,I12)=0,"",SUM(I5,I12)) | J15: =IF(COUNT(J5,J12)=0,"",SUM(J5,J12)) | K15: =IF(COUNT(K5,K12)=0,"",SUM(K5,K12)) | L15: ϝ
B16: Total Operational FTE | C16: =IF(COUNT(C11,C14)=0,"",SUM(C11,C14)) | D16: =IF(COUNT(D11,D14)=0,"",SUM(D11,D14)) | E16: =IF(COUNT(E11,E14)=0,"",SUM(E11,E14)) | F16: =IF(COUNT(F11,F14)=0,"",SUM(F11,F14)) | G16: =IF(COUNT(G11,G14)=0,"",SUM(G11,G14)) | H16: =IF(COUNT(H11,H14)=0,"",SUM(H11,H14)) | I16: =IF(COUNT(I11,I14)=0,"",SUM(I11,I14)) | J16: =IF(COUNT(J11,J14)=0,"",SUM(J11,J14)) | K16: =IF(COUNT(K11,K14)=0,"",SUM(K11,K14)) | L16: FTE
B17: Subcontracted Share of Workforce (%) | C17: =IFERROR(C12/C15,"") | D17: =IFERROR(D12/D15,"") | E17: =IFERROR(E12/E15,"") | F17: =IFERROR(F12/F15,"") | G17: =IFERROR(G12/G15,"") | H17: =IFERROR(H12/H15,"") | I17: =IFERROR(I12/I15,"") | J17: =IFERROR(J12/J15,"") | K17: =IFERROR(K12/K15,"") | L17: ϝ
B18: FTE HR Team | K18: =IF(COUNT(C18:J18)=0,"",SUM(C18:J18)) | L18: ∑
B19: Permanent Hires | K19: =IF(COUNT(C19:J19)=0,"",SUM(C19:J19)) | L19: ∑
B20: Temporary Hires | K20: =IF(COUNT(C20:J20)=0,"",SUM(C20:J20)) | L20: ∑
B21: Total Hires | C21: =IF(COUNT(C19:C20)=0,"",SUM(C19:C20)) | D21: =IF(COUNT(D19:D20)=0,"",SUM(D19:D20)) | E21: =IF(COUNT(E19:E20)=0,"",SUM(E19:E20)) | F21: =IF(COUNT(F19:F20)=0,"",SUM(F19:F20)) | G21: =IF(COUNT(G19:G20)=0,"",SUM(G19:G20)) | H21: =IF(COUNT(H19:H20)=0,"",SUM(H19:H20)) | I21: =IF(COUNT(I19:I20)=0,"",SUM(I19:I20)) | J21: =IF(COUNT(J19:J20)=0,"",SUM(J19:J20)) | K21: =IF(COUNT(K19:K20)=0,"",SUM(K19:K20)) | L21: ϝ
B22: Permanent Exits | K22: =IF(COUNT(C22:J22)=0,"",SUM(C22:J22)) | L22: ∑
B23: Temporary Exits | K23: =IF(COUNT(C23:J23)=0,"",SUM(C23:J23)) | L23: ∑
B24: Total Exits | C24: =IF(COUNT(C22:C23)=0,"",SUM(C22:C23)) | D24: =IF(COUNT(D22:D23)=0,"",SUM(D22:D23)) | E24: =IF(COUNT(E22:E23)=0,"",SUM(E22:E23)) | F24: =IF(COUNT(F22:F23)=0,"",SUM(F22:F23)) | G24: =IF(COUNT(G22:G23)=0,"",SUM(G22:G23)) | H24: =IF(COUNT(H22:H23)=0,"",SUM(H22:H23)) | I24: =IF(COUNT(I22:I23)=0,"",SUM(I22:I23)) | J24: =IF(COUNT(J22:J23)=0,"",SUM(J22:J23)) | K24: =IF(COUNT(K22:K23)=0,"",SUM(K22:K23)) | L24: ϝ
B25: Permanent Turnover (%) | C25: =IF(COUNT(C31,C32)<2,"",IF((C32+C31)=0,"",N(C22)/((C32+C31)/2))) | D25: =IF(COUNT(D31,D32)<2,"",IF((D32+D31)=0,"",N(D22)/((D32+D31)/2))) | E25: =IF(COUNT(E31,E32)<2,"",IF((E32+E31)=0,"",N(E22)/((E32+E31)/2))) | F25: =IF(COUNT(F31,F32)<2,"",IF((F32+F31)=0,"",N(F22)/((F32+F31)/2))) | G25: =IF(COUNT(G31,G32)<2,"",IF((G32+G31)=0,"",N(G22)/((G32+G31)/2))) | H25: =IF(COUNT(H31,H32)<2,"",IF((H32+H31)=0,"",N(H22)/((H32+H31)/2))) | I25: =IF(COUNT(I31,I32)<2,"",IF((I32+I31)=0,"",N(I22)/((I32+I31)/2))) | J25: =IF(COUNT(J31,J32)<2,"",IF((J32+J31)=0,"",N(J22)/((J32+J31)/2))) | K25: =IF(COUNT(K31,K32)<2,"",IF((K32+K31)=0,"",N(K22)/((K32+K31)/2))) | L25: ϝ
B26: Temporary Turnover (%) | C26: =IF(COUNT(C31,C32)<2,"",IF((C32+C31)=0,"",N(C23)/((C32+C31)/2))) | D26: =IF(COUNT(D31,D32)<2,"",IF((D32+D31)=0,"",N(D23)/((D32+D31)/2))) | E26: =IF(COUNT(E31,E32)<2,"",IF((E32+E31)=0,"",N(E23)/((E32+E31)/2))) | F26: =IF(COUNT(F31,F32)<2,"",IF((F32+F31)=0,"",N(F23)/((F32+F31)/2))) | G26: =IF(COUNT(G31,G32)<2,"",IF((G32+G31)=0,"",N(G23)/((G32+G31)/2))) | H26: =IF(COUNT(H31,H32)<2,"",IF((H32+H31)=0,"",N(H23)/((H32+H31)/2))) | I26: =IF(COUNT(I31,I32)<2,"",IF((I32+I31)=0,"",N(I23)/((I32+I31)/2))) | J26: =IF(COUNT(J31,J32)<2,"",IF((J32+J31)=0,"",N(J23)/((J32+J31)/2))) | K26: =IF(COUNT(K31,K32)<2,"",IF((K32+K31)=0,"",N(K23)/((K32+K31)/2))) | L26: ϝ
B27: Voluntary Terminations | K27: =IF(COUNT(C27:J27)=0,"",SUM(C27:J27)) | L27: ∑
B28: Involuntary Terminations | K28: =IF(COUNT(C28:J28)=0,"",SUM(C28:J28)) | L28: ∑
B29: Voluntary Turnover (%) | C29: =IF(COUNT(C31,C32)<2,"",IF((C32+C31)=0,"",N(C27)/((C32+C31)/2))) | D29: =IF(COUNT(D31,D32)<2,"",IF((D32+D31)=0,"",N(D27)/((D32+D31)/2))) | E29: =IF(COUNT(E31,E32)<2,"",IF((E32+E31)=0,"",N(E27)/((E32+E31)/2))) | F29: =IF(COUNT(F31,F32)<2,"",IF((F32+F31)=0,"",N(F27)/((F32+F31)/2))) | G29: =IF(COUNT(G31,G32)<2,"",IF((G32+G31)=0,"",N(G27)/((G32+G31)/2))) | H29: =IF(COUNT(H31,H32)<2,"",IF((H32+H31)=0,"",N(H27)/((H32+H31)/2))) | I29: =IF(COUNT(I31,I32)<2,"",IF((I32+I31)=0,"",N(I27)/((I32+I31)/2))) | J29: =IF(COUNT(J31,J32)<2,"",IF((J32+J31)=0,"",N(J27)/((J32+J31)/2))) | K29: =IF(COUNT(K31,K32)<2,"",IF((K32+K31)=0,"",N(K27)/((K32+K31)/2))) | L29: ϝ
B30: Involuntary Turnover (%) | C30: =IF(COUNT(C31,C32)<2,"",IF((C32+C31)=0,"",N(C28)/((C32+C31)/2))) | D30: =IF(COUNT(D31,D32)<2,"",IF((D32+D31)=0,"",N(D28)/((D32+D31)/2))) | E30: =IF(COUNT(E31,E32)<2,"",IF((E32+E31)=0,"",N(E28)/((E32+E31)/2))) | F30: =IF(COUNT(F31,F32)<2,"",IF((F32+F31)=0,"",N(F28)/((F32+F31)/2))) | G30: =IF(COUNT(G31,G32)<2,"",IF((G32+G31)=0,"",N(G28)/((G32+G31)/2))) | H30: =IF(COUNT(H31,H32)<2,"",IF((H32+H31)=0,"",N(H28)/((H32+H31)/2))) | I30: =IF(COUNT(I31,I32)<2,"",IF((I32+I31)=0,"",N(I28)/((I32+I31)/2))) | J30: =IF(COUNT(J31,J32)<2,"",IF((J32+J31)=0,"",N(J28)/((J32+J31)/2))) | K30: =IF(COUNT(K31,K32)<2,"",IF((K32+K31)=0,"",N(K28)/((K32+K31)/2))) | L30: ϝ
B31: Headcount last Month | C31: =IF(NOV!C5="","",NOV!C5) | D31: =IF(NOV!D5="","",NOV!D5) | E31: =IF(NOV!E5="","",NOV!E5) | F31: =IF(NOV!F5="","",NOV!F5) | G31: =IF(NOV!G5="","",NOV!G5) | H31: =IF(NOV!H5="","",NOV!H5) | I31: =IF(NOV!I5="","",NOV!I5) | J31: =IF(NOV!J5="","",NOV!J5) | K31: =IF(COUNT(C31:J31)=0,"",SUM(C31:J31)) | L31: ∑
B32: Headcount this Month | C32: =IF(C5="","",C5) | D32: =IF(D5="","",D5) | E32: =IF(E5="","",E5) | F32: =IF(F5="","",F5) | G32: =IF(G5="","",G5) | H32: =IF(H5="","",H5) | I32: =IF(I5="","",I5) | J32: =IF(J5="","",J5) | K32: =IF(COUNT(C32:J32)=0,"",SUM(C32:J32)) | L32: ∑
B33: Full Turnover (%) | C33: =IF(COUNT(C31,C32)<2,"",IF((C32+C31)=0,"",N(C24)/((C32+C31)/2))) | D33: =IF(COUNT(D31,D32)<2,"",IF((D32+D31)=0,"",N(D24)/((D32+D31)/2))) | E33: =IF(COUNT(E31,E32)<2,"",IF((E32+E31)=0,"",N(E24)/((E32+E31)/2))) | F33: =IF(COUNT(F31,F32)<2,"",IF((F32+F31)=0,"",N(F24)/((F32+F31)/2))) | G33: =IF(COUNT(G31,G32)<2,"",IF((G32+G31)=0,"",N(G24)/((G32+G31)/2))) | H33: =IF(COUNT(H31,H32)<2,"",IF((H32+H31)=0,"",N(H24)/((H32+H31)/2))) | I33: =IF(COUNT(I31,I32)<2,"",IF((I32+I31)=0,"",N(I24)/((I32+I31)/2))) | J33: =IF(COUNT(J31,J32)<2,"",IF((J32+J31)=0,"",N(J24)/((J32+J31)/2))) | K33: =IF(COUNT(K31,K32)<2,"",IF((K32+K31)=0,"",N(K24)/((K32+K31)/2))) | L33: ϝ
B34: Permanent Vacancies | K34: =IF(COUNT(C34:J34)=0,"",SUM(C34:J34)) | L34: ∑
B35: Temporary Vacancies | K35: =IF(COUNT(C35:J35)=0,"",SUM(C35:J35)) | L35: ∑
B36: Total Vacancies | C36: =IF(COUNT(C34:C35)=0,"",SUM(C34:C35)) | D36: =IF(COUNT(D34:D35)=0,"",SUM(D34:D35)) | E36: =IF(COUNT(E34:E35)=0,"",SUM(E34:E35)) | F36: =IF(COUNT(F34:F35)=0,"",SUM(F34:F35)) | G36: =IF(COUNT(G34:G35)=0,"",SUM(G34:G35)) | H36: =IF(COUNT(H34:H35)=0,"",SUM(H34:H35)) | I36: =IF(COUNT(I34:I35)=0,"",SUM(I34:I35)) | J36: =IF(COUNT(J34:J35)=0,"",SUM(J34:J35)) | K36: =IF(COUNT(K34:K35)=0,"",SUM(K34:K35)) | L36: ϝ
B37: Authorized Positions | C37: =IF(COUNT(C5,C36)=0,"",N(C5)+N(C36)) | D37: =IF(COUNT(D5,D36)=0,"",N(D5)+N(D36)) | E37: =IF(COUNT(E5,E36)=0,"",N(E5)+N(E36)) | F37: =IF(COUNT(F5,F36)=0,"",N(F5)+N(F36)) | G37: =IF(COUNT(G5,G36)=0,"",N(G5)+N(G36)) | H37: =IF(COUNT(H5,H36)=0,"",N(H5)+N(H36)) | I37: =IF(COUNT(I5,I36)=0,"",N(I5)+N(I36)) | J37: =IF(COUNT(J5,J36)=0,"",N(J5)+N(J36)) | K37: =IF(COUNT(K5,K36)=0,"",N(K5)+N(K36)) | L37: ϝ
B38: Vacancy Rate (%) | C38: =IFERROR(C36/C37,"") | D38: =IFERROR(D36/D37,"") | E38: =IFERROR(E36/E37,"") | F38: =IFERROR(F36/F37,"") | G38: =IFERROR(G36/G37,"") | H38: =IFERROR(H36/H37,"") | I38: =IFERROR(I36/I37,"") | J38: =IFERROR(J36/J37,"") | K38: =IFERROR(K36/K37,"") | L38: ϝ
B39: Permanent TimeToHire (Days) YTD | C39: =IF('(Culinary_CRI)'!$AB$6="","",'(Culinary_CRI)'!$AB$6) | D39: =IF('(Food_GTM)'!$AB$6="","",'(Food_GTM)'!$AB$6) | E39: =IF('(GCG_GTM)'!$AB$6="","",'(GCG_GTM)'!$AB$6) | F39: =IF('(Ground_HND)'!$AB$6="","",'(Ground_HND)'!$AB$6) | G39: =IF('(GCG_HND)'!$AB$6="","",'(GCG_HND)'!$AB$6) | H39: =IF('(Concess_PAN)'!$AB$6="","",'(Concess_PAN)'!$AB$6) | I39: =IF('(GCG_SLV)'!$AB$6="","",'(GCG_SLV)'!$AB$6) | J39: =IF('(Food_SLV)'!$AB$6="","",'(Food_SLV)'!$AB$6) | K39: =IFERROR(AVERAGE(C39:J39),"") | L39: Avg
B40: Temporary TimeToHire (Days) YTD | C40: =IF('(Culinary_CRI)'!$AD$6="","",'(Culinary_CRI)'!$AD$6) | D40: =IF('(Food_GTM)'!$AD$6="","",'(Food_GTM)'!$AD$6) | E40: =IF('(GCG_GTM)'!$AD$6="","",'(GCG_GTM)'!$AD$6) | F40: =IF('(Ground_HND)'!$AD$6="","",'(Ground_HND)'!$AD$6) | G40: =IF('(GCG_HND)'!$AD$6="","",'(GCG_HND)'!$AD$6) | H40: =IF('(Concess_PAN)'!$AD$6="","",'(Concess_PAN)'!$AD$6) | I40: =IF('(GCG_SLV)'!$AD$6="","",'(GCG_SLV)'!$AD$6) | J40: =IF('(Food_SLV)'!$AD$6="","",'(Food_SLV)'!$AD$6) | K40: =IFERROR(AVERAGE(C40:J40),"") | L40: Avg
...

Sheet JAN
B1: GCG CENTRAL AMERICA | C1: 1171 | D1: 1162 | E1: 1076 | F1: 1170 | G1: 1078 | H1: 1172 | I1: 1074 | J1: 1161
A2: =VALUE(TEXT(EDATE(DATE(LEFT(DEC!A2,4),RIGHT(DEC!A2,2),1),1),"yyyymm")) | B2: JAN | C2: GCG Culinary Costa Rica | D2: GCG Food Guatemala | E2: GCG Guatemala | F2: GCG Aviation Ground Honduras | G2: GCG Honduras | H2: GCG Concessions Panama | I2: GCG El Salvador | J2: GCG Food El Salvador | K2: TOTAL | L2: Total by Division | M2: =N(M11)<>0
A3: =+A2 | B3: Permanent (Regular) Headcount | K3: =IF(COUNT(C3:J3)=0,"",SUM(C3:J3)) | L3: ∑
B4: Temporary (Fix Term) Headcount | K4: =IF(COUNT(C4:J4)=0,"",SUM(C4:J4)) | L4: ∑
B5: Employee Headcount (Productivity) | C5: =IF(COUNT(C3:C4)=0,"",SUM(C3:C4)) | D5: =IF(COUNT(D3:D4)=0,"",SUM(D3:D4)) | E5: =IF(COUNT(E3:E4)=0,"",SUM(E3:E4)) | F5: =IF(COUNT(F3:F4)=0,"",SUM(F3:F4)) | G5: =IF(COUNT(G3:G4)=0,"",SUM(G3:G4)) | H5: =IF(COUNT(H3:H4)=0,"",SUM(H3:H4)) | I5: =IF(COUNT(I3:I4)=0,"",SUM(I3:I4)) | J5: =IF(COUNT(J3:J4)=0,"",SUM(J3:J4)) | K5: =IF(COUNT(K3:K4)=0,"",SUM(K3:K4)) | L5: ϝ
B6: Headcount = 1.00 | K6: =IF(COUNT(C6:J6)=0,"",SUM(C6:J6)) | L6: ∑
B7: Headcount = 0.75 | K7: =IF(COUNT(C7:J7)=0,"",SUM(C7:J7)) | L7: ∑
B8: Headcount = 0.50 | K8: =IF(COUNT(C8:J8)=0,"",SUM(C8:J8)) | L8: ∑
B9: Headcount = 0.25 | K9: =IF(COUNT(C9:J9)=0,"",SUM(C9:J9)) | L9: ∑
B10: Standard Monthly Hours (FTE basis) | K10: =IFERROR(AVERAGE(C10:J10),"") | L10: Avg
B11: Employee FTE (Finance) | C11: =IF(COUNT(C6:C9)=0,"",N(C6)+N(C7)*0.75+N(C8)*0.5+N(C9)*0.25) | D11: =IF(COUNT(D6:D9)=0,"",N(D6)+N(D7)*0.75+N(D8)*0.5+N(D9)*0.25) | E11: =IF(COUNT(E6:E9)=0,"",N(E6)+N(E7)*0.75+N(E8)*0.5+N(E9)*0.25) | F11: =IF(COUNT(F6:F9)=0,"",N(F6)+N(F7)*0.75+N(F8)*0.5+N(F9)*0.25) | G11: =IF(COUNT(G6:G9)=0,"",N(G6)+N(G7)*0.75+N(G8)*0.5+N(G9)*0.25) | H11: =IF(COUNT(H6:H9)=0,"",N(H6)+N(H7)*0.75+N(H8)*0.5+N(H9)*0.25) | I11: =IF(COUNT(I6:I9)=0,"",N(I6)+N(I7)*0.75+N(I8)*0.5+N(I9)*0.25) | J11: =IF(COUNT(J6:J9)=0,"",N(J6)+N(J7)*0.75+N(J8)*0.5+N(J9)*0.25) | K11: =IF(COUNT(K6:K9)=0,"",N(K6)+N(K7)*0.75+N(K8)*0.5+N(K9)*0.25) | L11: FTE | M11: =IF(COUNT(K5:K9)=0,"",N(K6)+N(K7)+N(K8)+N(K9)-N(K5))
B12: Subcontracted Workforce HC | K12: =IF(COUNT(C12:J12)=0,"",SUM(C12:J12)) | L12: ∑
B13: Subcontracted Productive Hours | K13: =IF(COUNT(C13:J13)=0,"",SUM(C13:J13)) | L13: ∑
B14: Subcontracted FTE | C14: =IFERROR(C13/C10,"") | D14: =IFERROR(D13/D10,"") | E14: =IFERROR(E13/E10,"") | F14: =IFERROR(F13/F10,"") | G14: =IFERROR(G13/G10,"") | H14: =IFERROR(H13/H10,"") | I14: =IFERROR(I13/I10,"") | J14: =IFERROR(J13/J10,"") | K14: =IF(COUNT(C14:J14)=0,"",SUM(C14:J14)) | L14: FTE
B15: Total Operational Workforce | C15: =IF(COUNT(C5,C12)=0,"",SUM(C5,C12)) | D15: =IF(COUNT(D5,D12)=0,"",SUM(D5,D12)) | E15: =IF(COUNT(E5,E12)=0,"",SUM(E5,E12)) | F15: =IF(COUNT(F5,F12)=0,"",SUM(F5,F12)) | G15: =IF(COUNT(G5,G12)=0,"",SUM(G5,G12)) | H15: =IF(COUNT(H5,H12)=0,"",SUM(H5,H12)) | I15: =IF(COUNT(I5,I12)=0,"",SUM(I5,I12)) | J15: =IF(COUNT(J5,J12)=0,"",SUM(J5,J12)) | K15: =IF(COUNT(K5,K12)=0,"",SUM(K5,K12)) | L15: ϝ
B16: Total Operational FTE | C16: =IF(COUNT(C11,C14)=0,"",SUM(C11,C14)) | D16: =IF(COUNT(D11,D14)=0,"",SUM(D11,D14)) | E16: =IF(COUNT(E11,E14)=0,"",SUM(E11,E14)) | F16: =IF(COUNT(F11,F14)=0,"",SUM(F11,F14)) | G16: =IF(COUNT(G11,G14)=0,"",SUM(G11,G14)) | H16: =IF(COUNT(H11,H14)=0,"",SUM(H11,H14)) | I16: =IF(COUNT(I11,I14)=0,"",SUM(I11,I14)) | J16: =IF(COUNT(J11,J14)=0,"",SUM(J11,J14)) | K16: =IF(COUNT(K11,K14)=0,"",SUM(K11,K14)) | L16: FTE
B17: Subcontracted Share of Workforce (%) | C17: =IFERROR(C12/C15,"") | D17: =IFERROR(D12/D15,"") | E17: =IFERROR(E12/E15,"") | F17: =IFERROR(F12/F15,"") | G17: =IFERROR(G12/G15,"") | H17: =IFERROR(H12/H15,"") | I17: =IFERROR(I12/I15,"") | J17: =IFERROR(J12/J15,"") | K17: =IFERROR(K12/K15,"") | L17: ϝ
B18: FTE HR Team | K18: =IF(COUNT(C18:J18)=0,"",SUM(C18:J18)) | L18: ∑
B19: Permanent Hires | K19: =IF(COUNT(C19:J19)=0,"",SUM(C19:J19)) | L19: ∑
B20: Temporary Hires | K20: =IF(COUNT(C20:J20)=0,"",SUM(C20:J20)) | L20: ∑
B21: Total Hires | C21: =IF(COUNT(C19:C20)=0,"",SUM(C19:C20)) | D21: =IF(COUNT(D19:D20)=0,"",SUM(D19:D20)) | E21: =IF(COUNT(E19:E20)=0,"",SUM(E19:E20)) | F21: =IF(COUNT(F19:F20)=0,"",SUM(F19:F20)) | G21: =IF(COUNT(G19:G20)=0,"",SUM(G19:G20)) | H21: =IF(COUNT(H19:H20)=0,"",SUM(H19:H20)) | I21: =IF(COUNT(I19:I20)=0,"",SUM(I19:I20)) | J21: =IF(COUNT(J19:J20)=0,"",SUM(J19:J20)) | K21: =IF(COUNT(K19:K20)=0,"",SUM(K19:K20)) | L21: ϝ
B22: Permanent Exits | K22: =IF(COUNT(C22:J22)=0,"",SUM(C22:J22)) | L22: ∑
B23: Temporary Exits | K23: =IF(COUNT(C23:J23)=0,"",SUM(C23:J23)) | L23: ∑
B24: Total Exits | C24: =IF(COUNT(C22:C23)=0,"",SUM(C22:C23)) | D24: =IF(COUNT(D22:D23)=0,"",SUM(D22:D23)) | E24: =IF(COUNT(E22:E23)=0,"",SUM(E22:E23)) | F24: =IF(COUNT(F22:F23)=0,"",SUM(F22:F23)) | G24: =IF(COUNT(G22:G23)=0,"",SUM(G22:G23)) | H24: =IF(COUNT(H22:H23)=0,"",SUM(H22:H23)) | I24: =IF(COUNT(I22:I23)=0,"",SUM(I22:I23)) | J24: =IF(COUNT(J22:J23)=0,"",SUM(J22:J23)) | K24: =IF(COUNT(K22:K23)=0,"",SUM(K22:K23)) | L24: ϝ
B25: Permanent Turnover (%) | C25: =IF(COUNT(C31,C32)<2,"",IF((C32+C31)=0,"",N(C22)/((C32+C31)/2))) | D25: =IF(COUNT(D31,D32)<2,"",IF((D32+D31)=0,"",N(D22)/((D32+D31)/2))) | E25: =IF(COUNT(E31,E32)<2,"",IF((E32+E31)=0,"",N(E22)/((E32+E31)/2))) | F25: =IF(COUNT(F31,F32)<2,"",IF((F32+F31)=0,"",N(F22)/((F32+F31)/2))) | G25: =IF(COUNT(G31,G32)<2,"",IF((G32+G31)=0,"",N(G22)/((G32+G31)/2))) | H25: =IF(COUNT(H31,H32)<2,"",IF((H32+H31)=0,"",N(H22)/((H32+H31)/2))) | I25: =IF(COUNT(I31,I32)<2,"",IF((I32+I31)=0,"",N(I22)/((I32+I31)/2))) | J25: =IF(COUNT(J31,J32)<2,"",IF((J32+J31)=0,"",N(J22)/((J32+J31)/2))) | K25: =IF(COUNT(K31,K32)<2,"",IF((K32+K31)=0,"",N(K22)/((K32+K31)/2))) | L25: ϝ
B26: Temporary Turnover (%) | C26: =IF(COUNT(C31,C32)<2,"",IF((C32+C31)=0,"",N(C23)/((C32+C31)/2))) | D26: =IF(COUNT(D31,D32)<2,"",IF((D32+D31)=0,"",N(D23)/((D32+D31)/2))) | E26: =IF(COUNT(E31,E32)<2,"",IF((E32+E31)=0,"",N(E23)/((E32+E31)/2))) | F26: =IF(COUNT(F31,F32)<2,"",IF((F32+F31)=0,"",N(F23)/((F32+F31)/2))) | G26: =IF(COUNT(G31,G32)<2,"",IF((G32+G31)=0,"",N(G23)/((G32+G31)/2))) | H26: =IF(COUNT(H31,H32)<2,"",IF((H32+H31)=0,"",N(H23)/((H32+H31)/2))) | I26: =IF(COUNT(I31,I32)<2,"",IF((I32+I31)=0,"",N(I23)/((I32+I31)/2))) | J26: =IF(COUNT(J31,J32)<2,"",IF((J32+J31)=0,"",N(J23)/((J32+J31)/2))) | K26: =IF(COUNT(K31,K32)<2,"",IF((K32+K31)=0,"",N(K23)/((K32+K31)/2))) | L26: ϝ
B27: Voluntary Terminations | K27: =IF(COUNT(C27:J27)=0,"",SUM(C27:J27)) | L27: ∑
B28: Involuntary Terminations | K28: =IF(COUNT(C28:J28)=0,"",SUM(C28:J28)) | L28: ∑
B29: Voluntary Turnover (%) | C29: =IF(COUNT(C31,C32)<2,"",IF((C32+C31)=0,"",N(C27)/((C32+C31)/2))) | D29: =IF(COUNT(D31,D32)<2,"",IF((D32+D31)=0,"",N(D27)/((D32+D31)/2))) | E29: =IF(COUNT(E31,E32)<2,"",IF((E32+E31)=0,"",N(E27)/((E32+E31)/2))) | F29: =IF(COUNT(F31,F32)<2,"",IF((F32+F31)=0,"",N(F27)/((F32+F31)/2))) | G29: =IF(COUNT(G31,G32)<2,"",IF((G32+G31)=0,"",N(G27)/((G32+G31)/2))) | H29: =IF(COUNT(H31,H32)<2,"",IF((H32+H31)=0,"",N(H27)/((H32+H31)/2))) | I29: =IF(COUNT(I31,I32)<2,"",IF((I32+I31)=0,"",N(I27)/((I32+I31)/2))) | J29: =IF(COUNT(J31,J32)<2,"",IF((J32+J31)=0,"",N(J27)/((J32+J31)/2))) | K29: =IF(COUNT(K31,K32)<2,"",IF((K32+K31)=0,"",N(K27)/((K32+K31)/2))) | L29: ϝ
B30: Involuntary Turnover (%) | C30: =IF(COUNT(C31,C32)<2,"",IF((C32+C31)=0,"",N(C28)/((C32+C31)/2))) | D30: =IF(COUNT(D31,D32)<2,"",IF((D32+D31)=0,"",N(D28)/((D32+D31)/2))) | E30: =IF(COUNT(E31,E32)<2,"",IF((E32+E31)=0,"",N(E28)/((E32+E31)/2))) | F30: =IF(COUNT(F31,F32)<2,"",IF((F32+F31)=0,"",N(F28)/((F32+F31)/2))) | G30: =IF(COUNT(G31,G32)<2,"",IF((G32+G31)=0,"",N(G28)/((G32+G31)/2))) | H30: =IF(COUNT(H31,H32)<2,"",IF((H32+H31)=0,"",N(H28)/((H32+H31)/2))) | I30: =IF(COUNT(I31,I32)<2,"",IF((I32+I31)=0,"",N(I28)/((I32+I31)/2))) | J30: =IF(COUNT(J31,J32)<2,"",IF((J32+J31)=0,"",N(J28)/((J32+J31)/2))) | K30: =IF(COUNT(K31,K32)<2,"",IF((K32+K31)=0,"",N(K28)/((K32+K31)/2))) | L30: ϝ
