Workbook

Sheet Quarter
B1: MANUFACTURING
A2: FY2027 | B2: Quarter | C2: OCT | D2: NOV | E2: DEC | F2: ∑Q1 | G2: JAN | H2: FEB | I2: MAR | J2: ∑Q2 | K2: APR | L2: MAY | M2: JUN | N2: ∑Q3 | O2: JUL | P2: AUG | Q2: SEP | R2: ∑Q4 | S2: FY2027
B3: Permanent (Regular) Headcount | C3: =OCT!L3 | D3: =NOV!L3 | E3: =DEC!L3 | F3: =IFERROR(AVERAGE(C3:E3),"") | G3: =JAN!L3 | H3: =FEB!L3 | I3: =MAR!L3 | J3: =IFERROR(AVERAGE(G3:I3),"") | K3: =APR!L3 | L3: =MAY!L3 | M3: =JUN!L3 | N3: =IFERROR(AVERAGE(K3:M3),"") | O3: =JUL!L3 | P3: =AUG!L3 | Q3: =SEP!L3 | R3: =IFERROR(AVERAGE(O3:Q3),"") | S3: =IFERROR(AVERAGE(C3:E3,G3:I3,K3:M3,O3:Q3),"")
B4: Temporary (Fix Term) Headcount | C4: =OCT!L4 | D4: =NOV!L4 | E4: =DEC!L4 | F4: =IFERROR(AVERAGE(C4:E4),"") | G4: =JAN!L4 | H4: =FEB!L4 | I4: =MAR!L4 | J4: =IFERROR(AVERAGE(G4:I4),"") | K4: =APR!L4 | L4: =MAY!L4 | M4: =JUN!L4 | N4: =IFERROR(AVERAGE(K4:M4),"") | O4: =JUL!L4 | P4: =AUG!L4 | Q4: =SEP!L4 | R4: =IFERROR(AVERAGE(O4:Q4),"") | S4: =IFERROR(AVERAGE(C4:E4,G4:I4,K4:M4,O4:Q4),"")
B5: Employee Headcount (Productivity) | C5: =OCT!L5 | D5: =NOV!L5 | E5: =DEC!L5 | F5: =IF(COUNT(F3:F4)=0,"",SUM(F3:F4)) | G5: =JAN!L5 | H5: =FEB!L5 | I5: =MAR!L5 | J5: =IF(COUNT(J3:J4)=0,"",SUM(J3:J4)) | K5: =APR!L5 | L5: =MAY!L5 | M5: =JUN!L5 | N5: =IF(COUNT(N3:N4)=0,"",SUM(N3:N4)) | O5: =JUL!L5 | P5: =AUG!L5 | Q5: =SEP!L5 | R5: =IF(COUNT(R3:R4)=0,"",SUM(R3:R4)) | S5: =IF(COUNT(S3:S4)=0,"",SUM(S3:S4))
B6: Headcount = 1.00 | C6: =OCT!L6 | D6: =NOV!L6 | E6: =DEC!L6 | F6: =IFERROR(AVERAGE(C6:E6),"") | G6: =JAN!L6 | H6: =FEB!L6 | I6: =MAR!L6 | J6: =IFERROR(AVERAGE(G6:I6),"") | K6: =APR!L6 | L6: =MAY!L6 | M6: =JUN!L6 | N6: =IFERROR(AVERAGE(K6:M6),"") | O6: =JUL!L6 | P6: =AUG!L6 | Q6: =SEP!L6 | R6: =IFERROR(AVERAGE(O6:Q6),"") | S6: =IFERROR(AVERAGE(C6:E6,G6:I6,K6:M6,O6:Q6),"")
B7: Headcount = 0.75 | C7: =OCT!L7 | D7: =NOV!L7 | E7: =DEC!L7 | F7: =IFERROR(AVERAGE(C7:E7),"") | G7: =JAN!L7 | H7: =FEB!L7 | I7: =MAR!L7 | J7: =IFERROR(AVERAGE(G7:I7),"") | K7: =APR!L7 | L7: =MAY!L7 | M7: =JUN!L7 | N7: =IFERROR(AVERAGE(K7:M7),"") | O7: =JUL!L7 | P7: =AUG!L7 | Q7: =SEP!L7 | R7: =IFERROR(AVERAGE(O7:Q7),"") | S7: =IFERROR(AVERAGE(C7:E7,G7:I7,K7:M7,O7:Q7),"")
B8: Headcount = 0.50 | C8: =OCT!L8 | D8: =NOV!L8 | E8: =DEC!L8 | F8: =IFERROR(AVERAGE(C8:E8),"") | G8: =JAN!L8 | H8: =FEB!L8 | I8: =MAR!L8 | J8: =IFERROR(AVERAGE(G8:I8),"") | K8: =APR!L8 | L8: =MAY!L8 | M8: =JUN!L8 | N8: =IFERROR(AVERAGE(K8:M8),"") | O8: =JUL!L8 | P8: =AUG!L8 | Q8: =SEP!L8 | R8: =IFERROR(AVERAGE(O8:Q8),"") | S8: =IFERROR(AVERAGE(C8:E8,G8:I8,K8:M8,O8:Q8),"")
B9: Headcount = 0.25 | C9: =OCT!L9 | D9: =NOV!L9 | E9: =DEC!L9 | F9: =IFERROR(AVERAGE(C9:E9),"") | G9: =JAN!L9 | H9: =FEB!L9 | I9: =MAR!L9 | J9: =IFERROR(AVERAGE(G9:I9),"") | K9: =APR!L9 | L9: =MAY!L9 | M9: =JUN!L9 | N9: =IFERROR(AVERAGE(K9:M9),"") | O9: =JUL!L9 | P9: =AUG!L9 | Q9: =SEP!L9 | R9: =IFERROR(AVERAGE(O9:Q9),"") | S9: =IFERROR(AVERAGE(C9:E9,G9:I9,K9:M9,O9:Q9),"")
B10: Standard Monthly Hours (FTE basis) | C10: =OCT!L10 | D10: =NOV!L10 | E10: =DEC!L10 | F10: =IFERROR(AVERAGE(C10:E10),"") | G10: =JAN!L10 | H10: =FEB!L10 | I10: =MAR!L10 | J10: =IFERROR(AVERAGE(G10:I10),"") | K10: =APR!L10 | L10: =MAY!L10 | M10: =JUN!L10 | N10: =IFERROR(AVERAGE(K10:M10),"") | O10: =JUL!L10 | P10: =AUG!L10 | Q10: =SEP!L10 | R10: =IFERROR(AVERAGE(O10:Q10),"") | S10: =IFERROR(AVERAGE(C10:E10,G10:I10,K10:M10,O10:Q10),"")
B11: Employee FTE (Finance) | C11: =OCT!L11 | D11: =NOV!L11 | E11: =DEC!L11 | F11: =IF(COUNT(F6:F9)=0,"",N(F6)+N(F7)*0.75+N(F8)*0.5+N(F9)*0.25) | G11: =JAN!L11 | H11: =FEB!L11 | I11: =MAR!L11 | J11: =IF(COUNT(J6:J9)=0,"",N(J6)+N(J7)*0.75+N(J8)*0.5+N(J9)*0.25) | K11: =APR!L11 | L11: =MAY!L11 | M11: =JUN!L11 | N11: =IF(COUNT(N6:N9)=0,"",N(N6)+N(N7)*0.75+N(N8)*0.5+N(N9)*0.25) | O11: =JUL!L11 | P11: =AUG!L11 | Q11: =SEP!L11 | R11: =IF(COUNT(R6:R9)=0,"",N(R6)+N(R7)*0.75+N(R8)*0.5+N(R9)*0.25) | S11: =IF(COUNT(S6:S9)=0,"",N(S6)+N(S7)*0.75+N(S8)*0.5+N(S9)*0.25)
B12: Subcontracted Workforce HC | C12: =OCT!L12 | D12: =NOV!L12 | E12: =DEC!L12 | F12: =IFERROR(AVERAGE(C12:E12),"") | G12: =JAN!L12 | H12: =FEB!L12 | I12: =MAR!L12 | J12: =IFERROR(AVERAGE(G12:I12),"") | K12: =APR!L12 | L12: =MAY!L12 | M12: =JUN!L12 | N12: =IFERROR(AVERAGE(K12:M12),"") | O12: =JUL!L12 | P12: =AUG!L12 | Q12: =SEP!L12 | R12: =IFERROR(AVERAGE(O12:Q12),"") | S12: =IFERROR(AVERAGE(C12:E12,G12:I12,K12:M12,O12:Q12),"")
B13: Subcontracted Productive Hours | C13: =OCT!L13 | D13: =NOV!L13 | E13: =DEC!L13 | F13: =IFERROR(AVERAGE(C13:E13),"") | G13: =JAN!L13 | H13: =FEB!L13 | I13: =MAR!L13 | J13: =IFERROR(AVERAGE(G13:I13),"") | K13: =APR!L13 | L13: =MAY!L13 | M13: =JUN!L13 | N13: =IFERROR(AVERAGE(K13:M13),"") | O13: =JUL!L13 | P13: =AUG!L13 | Q13: =SEP!L13 | R13: =IFERROR(AVERAGE(O13:Q13),"") | S13: =IFERROR(AVERAGE(C13:E13,G13:I13,K13:M13,O13:Q13),"")
B14: Subcontracted FTE | C14: =OCT!L14 | D14: =NOV!L14 | E14: =DEC!L14 | F14: =IFERROR(F13/F10,"") | G14: =JAN!L14 | H14: =FEB!L14 | I14: =MAR!L14 | J14: =IFERROR(J13/J10,"") | K14: =APR!L14 | L14: =MAY!L14 | M14: =JUN!L14 | N14: =IFERROR(N13/N10,"") | O14: =JUL!L14 | P14: =AUG!L14 | Q14: =SEP!L14 | R14: =IFERROR(R13/R10,"") | S14: =IFERROR(S13/S10,"")
B15: Total Operational Workforce | C15: =OCT!L15 | D15: =NOV!L15 | E15: =DEC!L15 | F15: =IF(COUNT(F5,F12)=0,"",SUM(F5,F12)) | G15: =JAN!L15 | H15: =FEB!L15 | I15: =MAR!L15 | J15: =IF(COUNT(J5,J12)=0,"",SUM(J5,J12)) | K15: =APR!L15 | L15: =MAY!L15 | M15: =JUN!L15 | N15: =IF(COUNT(N5,N12)=0,"",SUM(N5,N12)) | O15: =JUL!L15 | P15: =AUG!L15 | Q15: =SEP!L15 | R15: =IF(COUNT(R5,R12)=0,"",SUM(R5,R12)) | S15: =IF(COUNT(S5,S12)=0,"",SUM(S5,S12))
B16: Total Operational FTE | C16: =OCT!L16 | D16: =NOV!L16 | E16: =DEC!L16 | F16: =IF(COUNT(F11,F14)=0,"",SUM(F11,F14)) | G16: =JAN!L16 | H16: =FEB!L16 | I16: =MAR!L16 | J16: =IF(COUNT(J11,J14)=0,"",SUM(J11,J14)) | K16: =APR!L16 | L16: =MAY!L16 | M16: =JUN!L16 | N16: =IF(COUNT(N11,N14)=0,"",SUM(N11,N14)) | O16: =JUL!L16 | P16: =AUG!L16 | Q16: =SEP!L16 | R16: =IF(COUNT(R11,R14)=0,"",SUM(R11,R14)) | S16: =IF(COUNT(S11,S14)=0,"",SUM(S11,S14))
B17: Subcontracted Share of Workforce (%) | C17: =OCT!L17 | D17: =NOV!L17 | E17: =DEC!L17 | F17: =IFERROR(F12/F15,"") | G17: =JAN!L17 | H17: =FEB!L17 | I17: =MAR!L17 | J17: =IFERROR(J12/J15,"") | K17: =APR!L17 | L17: =MAY!L17 | M17: =JUN!L17 | N17: =IFERROR(N12/N15,"") | O17: =JUL!L17 | P17: =AUG!L17 | Q17: =SEP!L17 | R17: =IFERROR(R12/R15,"") | S17: =IFERROR(S12/S15,"")
B18: FTE HR Team | C18: =OCT!L18 | D18: =NOV!L18 | E18: =DEC!L18 | F18: =IFERROR(AVERAGE(C18:E18),"") | G18: =JAN!L18 | H18: =FEB!L18 | I18: =MAR!L18 | J18: =IFERROR(AVERAGE(G18:I18),"") | K18: =APR!L18 | L18: =MAY!L18 | M18: =JUN!L18 | N18: =IFERROR(AVERAGE(K18:M18),"") | O18: =JUL!L18 | P18: =AUG!L18 | Q18: =SEP!L18 | R18: =IFERROR(AVERAGE(O18:Q18),"") | S18: =IFERROR(AVERAGE(C18:E18,G18:I18,K18:M18,O18:Q18),"")
B19: Permanent Hires | C19: =OCT!L19 | D19: =NOV!L19 | E19: =DEC!L19 | F19: =IF(COUNT(C19:E19)=0,"",SUM(C19:E19)) | G19: =JAN!L19 | H19: =FEB!L19 | I19: =MAR!L19 | J19: =IF(COUNT(G19:I19)=0,"",SUM(G19:I19)) | K19: =APR!L19 | L19: =MAY!L19 | M19: =JUN!L19 | N19: =IF(COUNT(K19:M19)=0,"",SUM(K19:M19)) | O19: =JUL!L19 | P19: =AUG!L19 | Q19: =SEP!L19 | R19: =IF(COUNT(O19:Q19)=0,"",SUM(O19:Q19)) | S19: =IF(COUNT(C19:E19,G19:I19,K19:M19,O19:Q19)=0,"",SUM(C19:E19,G19:I19,K19:M19,O19:Q19))
B20: Temporary Hires | C20: =OCT!L20 | D20: =NOV!L20 | E20: =DEC!L20 | F20: =IF(COUNT(C20:E20)=0,"",SUM(C20:E20)) | G20: =JAN!L20 | H20: =FEB!L20 | I20: =MAR!L20 | J20: =IF(COUNT(G20:I20)=0,"",SUM(G20:I20)) | K20: =APR!L20 | L20: =MAY!L20 | M20: =JUN!L20 | N20: =IF(COUNT(K20:M20)=0,"",SUM(K20:M20)) | O20: =JUL!L20 | P20: =AUG!L20 | Q20: =SEP!L20 | R20: =IF(COUNT(O20:Q20)=0,"",SUM(O20:Q20)) | S20: =IF(COUNT(C20:E20,G20:I20,K20:M20,O20:Q20)=0,"",SUM(C20:E20,G20:I20,K20:M20,O20:Q20))
B21: Total Hires | C21: =OCT!L21 | D21: =NOV!L21 | E21: =DEC!L21 | F21: =IF(COUNT(F19:F20)=0,"",SUM(F19:F20)) | G21: =JAN!L21 | H21: =FEB!L21 | I21: =MAR!L21 | J21: =IF(COUNT(J19:J20)=0,"",SUM(J19:J20)) | K21: =APR!L21 | L21: =MAY!L21 | M21: =JUN!L21 | N21: =IF(COUNT(N19:N20)=0,"",SUM(N19:N20)) | O21: =JUL!L21 | P21: =AUG!L21 | Q21: =SEP!L21 | R21: =IF(COUNT(R19:R20)=0,"",SUM(R19:R20)) | S21: =IF(COUNT(S19:S20)=0,"",SUM(S19:S20))
B22: Permanent Exits | C22: =OCT!L22 | D22: =NOV!L22 | E22: =DEC!L22 | F22: =IF(COUNT(C22:E22)=0,"",SUM(C22:E22)) | G22: =JAN!L22 | H22: =FEB!L22 | I22: =MAR!L22 | J22: =IF(COUNT(G22:I22)=0,"",SUM(G22:I22)) | K22: =APR!L22 | L22: =MAY!L22 | M22: =JUN!L22 | N22: =IF(COUNT(K22:M22)=0,"",SUM(K22:M22)) | O22: =JUL!L22 | P22: =AUG!L22 | Q22: =SEP!L22 | R22: =IF(COUNT(O22:Q22)=0,"",SUM(O22:Q22)) | S22: =IF(COUNT(C22:E22,G22:I22,K22:M22,O22:Q22)=0,"",SUM(C22:E22,G22:I22,K22:M22,O22:Q22))
B23: Temporary Exits | C23: =OCT!L23 | D23: =NOV!L23 | E23: =DEC!L23 | F23: =IF(COUNT(C23:E23)=0,"",SUM(C23:E23)) | G23: =JAN!L23 | H23: =FEB!L23 | I23: =MAR!L23 | J23: =IF(COUNT(G23:I23)=0,"",SUM(G23:I23)) | K23: =APR!L23 | L23: =MAY!L23 | M23: =JUN!L23 | N23: =IF(COUNT(K23:M23)=0,"",SUM(K23:M23)) | O23: =JUL!L23 | P23: =AUG!L23 | Q23: =SEP!L23 | R23: =IF(COUNT(O23:Q23)=0,"",SUM(O23:Q23)) | S23: =IF(COUNT(C23:E23,G23:I23,K23:M23,O23:Q23)=0,"",SUM(C23:E23,G23:I23,K23:M23,O23:Q23))
B24: Total Exits | C24: =OCT!L24 | D24: =NOV!L24 | E24: =DEC!L24 | F24: =IF(COUNT(F22:F23)=0,"",SUM(F22:F23)) | G24: =JAN!L24 | H24: =FEB!L24 | I24: =MAR!L24 | J24: =IF(COUNT(J22:J23)=0,"",SUM(J22:J23)) | K24: =APR!L24 | L24: =MAY!L24 | M24: =JUN!L24 | N24: =IF(COUNT(N22:N23)=0,"",SUM(N22:N23)) | O24: =JUL!L24 | P24: =AUG!L24 | Q24: =SEP!L24 | R24: =IF(COUNT(R22:R23)=0,"",SUM(R22:R23)) | S24: =IF(COUNT(S22:S23)=0,"",SUM(S22:S23))
B25: Permanent Turnover (%) | C25: =OCT!L25 | D25: =NOV!L25 | E25: =DEC!L25 | F25: =IF(COUNT(F31,F32)<2,"",IF((F32+F31)=0,"",N(F22)/((F32+F31)/2))) | G25: =JAN!L25 | H25: =FEB!L25 | I25: =MAR!L25 | J25: =IF(COUNT(J31,J32)<2,"",IF((J32+J31)=0,"",N(J22)/((J32+J31)/2))) | K25: =APR!L25 | L25: =MAY!L25 | M25: =JUN!L25 | N25: =IF(COUNT(N31,N32)<2,"",IF((N32+N31)=0,"",N(N22)/((N32+N31)/2))) | O25: =JUL!L25 | P25: =AUG!L25 | Q25: =SEP!L25 | R25: =IF(COUNT(R31,R32)<2,"",IF((R32+R31)=0,"",N(R22)/((R32+R31)/2))) | S25: =IF(COUNT(S31,S32)<2,"",IF((S32+S31)=0,"",N(S22)/((S32+S31)/2)))
B26: Temporary Turnover (%) | C26: =OCT!L26 | D26: =NOV!L26 | E26: =DEC!L26 | F26: =IF(COUNT(F31,F32)<2,"",IF((F32+F31)=0,"",N(F23)/((F32+F31)/2))) | G26: =JAN!L26 | H26: =FEB!L26 | I26: =MAR!L26 | J26: =IF(COUNT(J31,J32)<2,"",IF((J32+J31)=0,"",N(J23)/((J32+J31)/2))) | K26: =APR!L26 | L26: =MAY!L26 | M26: =JUN!L26 | N26: =IF(COUNT(N31,N32)<2,"",IF((N32+N31)=0,"",N(N23)/((N32+N31)/2))) | O26: =JUL!L26 | P26: =AUG!L26 | Q26: =SEP!L26 | R26: =IF(COUNT(R31,R32)<2,"",IF((R32+R31)=0,"",N(R23)/((R32+R31)/2))) | S26: =IF(COUNT(S31,S32)<2,"",IF((S32+S31)=0,"",N(S23)/((S32+S31)/2)))
B27: Voluntary Terminations | C27: =OCT!L27 | D27: =NOV!L27 | E27: =DEC!L27 | F27: =IF(COUNT(C27:E27)=0,"",SUM(C27:E27)) | G27: =JAN!L27 | H27: =FEB!L27 | I27: =MAR!L27 | J27: =IF(COUNT(G27:I27)=0,"",SUM(G27:I27)) | K27: =APR!L27 | L27: =MAY!L27 | M27: =JUN!L27 | N27: =IF(COUNT(K27:M27)=0,"",SUM(K27:M27)) | O27: =JUL!L27 | P27: =AUG!L27 | Q27: =SEP!L27 | R27: =IF(COUNT(O27:Q27)=0,"",SUM(O27:Q27)) | S27: =IF(COUNT(C27:E27,G27:I27,K27:M27,O27:Q27)=0,"",SUM(C27:E27,G27:I27,K27:M27,O27:Q27))
B28: Involuntary Terminations | C28: =OCT!L28 | D28: =NOV!L28 | E28: =DEC!L28 | F28: =IF(COUNT(C28:E28)=0,"",SUM(C28:E28)) | G28: =JAN!L28 | H28: =FEB!L28 | I28: =MAR!L28 | J28: =IF(COUNT(G28:I28)=0,"",SUM(G28:I28)) | K28: =APR!L28 | L28: =MAY!L28 | M28: =JUN!L28 | N28: =IF(COUNT(K28:M28)=0,"",SUM(K28:M28)) | O28: =JUL!L28 | P28: =AUG!L28 | Q28: =SEP!L28 | R28: =IF(COUNT(O28:Q28)=0,"",SUM(O28:Q28)) | S28: =IF(COUNT(C28:E28,G28:I28,K28:M28,O28:Q28)=0,"",SUM(C28:E28,G28:I28,K28:M28,O28:Q28))
B29: Voluntary Turnover (%) | C29: =OCT!L29 | D29: =NOV!L29 | E29: =DEC!L29 | F29: =IF(COUNT(F31,F32)<2,"",IF((F32+F31)=0,"",N(F27)/((F32+F31)/2))) | G29: =JAN!L29 | H29: =FEB!L29 | I29: =MAR!L29 | J29: =IF(COUNT(J31,J32)<2,"",IF((J32+J31)=0,"",N(J27)/((J32+J31)/2))) | K29: =APR!L29 | L29: =MAY!L29 | M29: =JUN!L29 | N29: =IF(COUNT(N31,N32)<2,"",IF((N32+N31)=0,"",N(N27)/((N32+N31)/2))) | O29: =JUL!L29 | P29: =AUG!L29 | Q29: =SEP!L29 | R29: =IF(COUNT(R31,R32)<2,"",IF((R32+R31)=0,"",N(R27)/((R32+R31)/2))) | S29: =IF(COUNT(S31,S32)<2,"",IF((S32+S31)=0,"",N(S27)/((S32+S31)/2)))
B30: Involuntary Turnover (%) | C30: =OCT!L30 | D30: =NOV!L30 | E30: =DEC!L30 | F30: =IF(COUNT(F31,F32)<2,"",IF((F32+F31)=0,"",N(F28)/((F32+F31)/2))) | G30: =JAN!L30 | H30: =FEB!L30 | I30: =MAR!L30 | J30: =IF(COUNT(J31,J32)<2,"",IF((J32+J31)=0,"",N(J28)/((J32+J31)/2))) | K30: =APR!L30 | L30: =MAY!L30 | M30: =JUN!L30 | N30: =IF(COUNT(N31,N32)<2,"",IF((N32+N31)=0,"",N(N28)/((N32+N31)/2))) | O30: =JUL!L30 | P30: =AUG!L30 | Q30: =SEP!L30 | R30: =IF(COUNT(R31,R32)<2,"",IF((R32+R31)=0,"",N(R28)/((R32+R31)/2))) | S30: =IF(COUNT(S31,S32)<2,"",IF((S32+S31)=0,"",N(S28)/((S32+S31)/2)))
B31: Headcount last Month | C31: =OCT!L31 | D31: =NOV!L31 | E31: =DEC!L31 | F31: =IFERROR(AVERAGE(C31:E31),"") | G31: =JAN!L31 | H31: =FEB!L31 | I31: =MAR!L31 | J31: =IFERROR(AVERAGE(G31:I31),"") | K31: =APR!L31 | L31: =MAY!L31 | M31: =JUN!L31 | N31: =IFERROR(AVERAGE(K31:M31),"") | O31: =JUL!L31 | P31: =AUG!L31 | Q31: =SEP!L31 | R31: =IFERROR(AVERAGE(O31:Q31),"") | S31: =IFERROR(AVERAGE(C31:E31,G31:I31,K31:M31,O31:Q31),"")
B32: Headcount this Month | C32: =OCT!L32 | D32: =NOV!L32 | E32: =DEC!L32 | F32: =IFERROR(AVERAGE(C32:E32),"") | G32: =JAN!L32 | H32: =FEB!L32 | I32: =MAR!L32 | J32: =IFERROR(AVERAGE(G32:I32),"") | K32: =APR!L32 | L32: =MAY!L32 | M32: =JUN!L32 | N32: =IFERROR(AVERAGE(K32:M32),"") | O32: =JUL!L32 | P32: =AUG!L32 | Q32: =SEP!L32 | R32: =IFERROR(AVERAGE(O32:Q32),"") | S32: =IFERROR(AVERAGE(C32:E32,G32:I32,K32:M32,O32:Q32),"")
B33: Full Turnover (%) | C33: =OCT!L33 | D33: =NOV!L33 | E33: =DEC!L33 | F33: =IF(COUNT(F31,F32)<2,"",IF((F32+F31)=0,"",N(F24)/((F32+F31)/2))) | G33: =JAN!L33 | H33: =FEB!L33 | I33: =MAR!L33 | J33: =IF(COUNT(J31,J32)<2,"",IF((J32+J31)=0,"",N(J24)/((J32+J31)/2))) | K33: =APR!L33 | L33: =MAY!L33 | M33: =JUN!L33 | N33: =IF(COUNT(N31,N32)<2,"",IF((N32+N31)=0,"",N(N24)/((N32+N31)/2))) | O33: =JUL!L33 | P33: =AUG!L33 | Q33: =SEP!L33 | R33: =IF(COUNT(R31,R32)<2,"",IF((R32+R31)=0,"",N(R24)/((R32+R31)/2))) | S33: =IF(COUNT(S31,S32)<2,"",IF((S32+S31)=0,"",N(S24)/((S32+S31)/2)))
B34: Permanent Vacancies | C34: =OCT!L34 | D34: =NOV!L34 | E34: =DEC!L34 | F34: =IFERROR(AVERAGE(C34:E34),"") | G34: =JAN!L34 | H34: =FEB!L34 | I34: =MAR!L34 | J34: =IFERROR(AVERAGE(G34:I34),"") | K34: =APR!L34 | L34: =MAY!L34 | M34: =JUN!L34 | N34: =IFERROR(AVERAGE(K34:M34),"") | O34: =JUL!L34 | P34: =AUG!L34 | Q34: =SEP!L34 | R34: =IFERROR(AVERAGE(O34:Q34),"") | S34: =IFERROR(AVERAGE(C34:E34,G34:I34,K34:M34,O34:Q34),"")
B35: Temporary Vacancies | C35: =OCT!L35 | D35: =NOV!L35 | E35: =DEC!L35 | F35: =IFERROR(AVERAGE(C35:E35),"") | G35: =JAN!L35 | H35: =FEB!L35 | I35: =MAR!L35 | J35: =IFERROR(AVERAGE(G35:I35),"") | K35: =APR!L35 | L35: =MAY!L35 | M35: =JUN!L35 | N35: =IFERROR(AVERAGE(K35:M35),"") | O35: =JUL!L35 | P35: =AUG!L35 | Q35: =SEP!L35 | R35: =IFERROR(AVERAGE(O35:Q35),"") | S35: =IFERROR(AVERAGE(C35:E35,G35:I35,K35:M35,O35:Q35),"")
B36: Total Vacancies | C36: =OCT!L36 | D36: =NOV!L36 | E36: =DEC!L36 | F36: =IF(COUNT(F34:F35)=0,"",SUM(F34:F35)) | G36: =JAN!L36 | H36: =FEB!L36 | I36: =MAR!L36 | J36: =IF(COUNT(J34:J35)=0,"",SUM(J34:J35)) | K36: =APR!L36 | L36: =MAY!L36 | M36: =JUN!L36 | N36: =IF(COUNT(N34:N35)=0,"",SUM(N34:N35)) | O36: =JUL!L36 | P36: =AUG!L36 | Q36: =SEP!L36 | R36: =IF(COUNT(R34:R35)=0,"",SUM(R34:R35)) | S36: =IF(COUNT(S34:S35)=0,"",SUM(S34:S35))
B37: Authorized Positions | C37: =OCT!L37 | D37: =NOV!L37 | E37: =DEC!L37 | F37: =IF(COUNT(F5,F36)=0,"",N(F5)+N(F36)) | G37: =JAN!L37 | H37: =FEB!L37 | I37: =MAR!L37 | J37: =IF(COUNT(J5,J36)=0,"",N(J5)+N(J36)) | K37: =APR!L37 | L37: =MAY!L37 | M37: =JUN!L37 | N37: =IF(COUNT(N5,N36)=0,"",N(N5)+N(N36)) | O37: =JUL!L37 | P37: =AUG!L37 | Q37: =SEP!L37 | R37: =IF(COUNT(R5,R36)=0,"",N(R5)+N(R36)) | S37: =IF(COUNT(S5,S36)=0,"",N(S5)+N(S36))
B38: Vacancy Rate (%) | C38: =OCT!L38 | D38: =NOV!L38 | E38: =DEC!L38 | F38: =IFERROR(F36/F37,"") | G38: =JAN!L38 | H38: =FEB!L38 | I38: =MAR!L38 | J38: =IFERROR(J36/J37,"") | K38: =APR!L38 | L38: =MAY!L38 | M38: =JUN!L38 | N38: =IFERROR(N36/N37,"") | O38: =JUL!L38 | P38: =AUG!L38 | Q38: =SEP!L38 | R38: =IFERROR(R36/R37,"") | S38: =IFERROR(S36/S37,"")
B39: Permanent TimeToHire (Days) YTD | C39: =OCT!L39 | D39: =NOV!L39 | E39: =DEC!L39 | F39: =IFERROR(LOOKUP(2,1/ISNUMBER(C39:E39),C39:E39),"") | G39: =JAN!L39 | H39: =FEB!L39 | I39: =MAR!L39 | J39: =IFERROR(LOOKUP(2,1/ISNUMBER(G39:I39),G39:I39),"") | K39: =APR!L39 | L39: =MAY!L39 | M39: =JUN!L39 | N39: =IFERROR(LOOKUP(2,1/ISNUMBER(K39:M39),K39:M39),"") | O39: =JUL!L39 | P39: =AUG!L39 | Q39: =SEP!L39 | R39: =IFERROR(LOOKUP(2,1/ISNUMBER(O39:Q39),O39:Q39),"") | S39: =IFERROR(LOOKUP(2,1/ISNUMBER(C39:Q39),C39:Q39),"")
B40: Temporary TimeToHire (Days) YTD | C40: =OCT!L40 | D40: =NOV!L40 | E40: =DEC!L40 | F40: =IFERROR(LOOKUP(2,1/ISNUMBER(C40:E40),C40:E40),"") | G40: =JAN!L40 | H40: =FEB!L40 | I40: =MAR!L40 | J40: =IFERROR(LOOKUP(2,1/ISNUMBER(G40:I40),G40:I40),"") | K40: =APR!L40 | L40: =MAY!L40 | M40: =JUN!L40 | N40: =IFERROR(LOOKUP(2,1/ISNUMBER(K40:M40),K40:M40),"") | O40: =JUL!L40 | P40: =AUG!L40 | Q40: =SEP!L40 | R40: =IFERROR(LOOKUP(2,1/ISNUMBER(O40:Q40),O40:Q40),"") | S40: =IFERROR(LOOKUP(2,1/ISNUMBER(C40:Q40),C40:Q40),"")
...

Sheet OCT
B1: MANUFACTURING
A2: 202610 | B2: OCT | C2: GEL Manufacturing Holding Co. Ltd. | D2: CLC Domicana (Dominican Republic) | E2: Caribbean Label Crafts Ltd. (Barbados) | F2: Ecuakao (Ecuador) | G2: Hipac Ltd. (Barbados) | H2: Label Craft Jamaica Ltd. (Jamaica) | I2: McBride (Caribbean) Ltd. | J2: Precision Packaging Inc. (Barbados) | K2: Purity Bakeries Ltd. (Barbados) | L2: TOTAL | M2: Total by Division | N2: =N(N11)<>0
A3: =+A2 | B3: Permanent (Regular) Headcount | L3: =IF(COUNT(C3:K3)=0,"",SUM(C3:K3)) | M3: ∑
B4: Temporary (Fix Term) Headcount | L4: =IF(COUNT(C4:K4)=0,"",SUM(C4:K4)) | M4: ∑
B5: Employee Headcount (Productivity) | C5: =IF(COUNT(C3:C4)=0,"",SUM(C3:C4)) | D5: =IF(COUNT(D3:D4)=0,"",SUM(D3:D4)) | E5: =IF(COUNT(E3:E4)=0,"",SUM(E3:E4)) | F5: =IF(COUNT(F3:F4)=0,"",SUM(F3:F4)) | G5: =IF(COUNT(G3:G4)=0,"",SUM(G3:G4)) | H5: =IF(COUNT(H3:H4)=0,"",SUM(H3:H4)) | I5: =IF(COUNT(I3:I4)=0,"",SUM(I3:I4)) | J5: =IF(COUNT(J3:J4)=0,"",SUM(J3:J4)) | ... L5: =IF(COUNT(L3:L4)=0,"",SUM(L3:L4)) | M5: ϝ
B6: Headcount = 1.00 | L6: =IF(COUNT(C6:K6)=0,"",SUM(C6:K6)) | M6: ∑
B7: Headcount = 0.75 | L7: =IF(COUNT(C7:K7)=0,"",SUM(C7:K7)) | M7: ∑
B8: Headcount = 0.50 | L8: =IF(COUNT(C8:K8)=0,"",SUM(C8:K8)) | M8: ∑
B9: Headcount = 0.25 | L9: =IF(COUNT(C9:K9)=0,"",SUM(C9:K9)) | M9: ∑
B10: Standard Monthly Hours (FTE basis) | L10: =IFERROR(AVERAGE(C10:K10),"") | M10: Avg
B11: Employee FTE (Finance) | C11: =IF(COUNT(C6:C9)=0,"",N(C6)+N(C7)*0.75+N(C8)*0.5+N(C9)*0.25) | D11: =IF(COUNT(D6:D9)=0,"",N(D6)+N(D7)*0.75+N(D8)*0.5+N(D9)*0.25) | E11: =IF(COUNT(E6:E9)=0,"",N(E6)+N(E7)*0.75+N(E8)*0.5+N(E9)*0.25) | F11: =IF(COUNT(F6:F9)=0,"",N(F6)+N(F7)*0.75+N(F8)*0.5+N(F9)*0.25) | G11: =IF(COUNT(G6:G9)=0,"",N(G6)+N(G7)*0.75+N(G8)*0.5+N(G9)*0.25) | H11: =IF(COUNT(H6:H9)=0,"",N(H6)+N(H7)*0.75+N(H8)*0.5+N(H9)*0.25) | I11: =IF(COUNT(I6:I9)=0,"",N(I6)+N(I7)*0.75+N(I8)*0.5+N(I9)*0.25) | J11: =IF(COUNT(J6:J9)=0,"",N(J6)+N(J7)*0.75+N(J8)*0.5+N(J9)*0.25) | ... L11: =IF(COUNT(L6:L9)=0,"",N(L6)+N(L7)*0.75+N(L8)*0.5+N(L9)*0.25) | M11: FTE | N11: =IF(COUNT(L5:L9)=0,"",N(L6)+N(L7)+N(L8)+N(L9)-N(L5))
B12: Subcontracted Workforce HC | L12: =IF(COUNT(C12:K12)=0,"",SUM(C12:K12)) | M12: ∑
B13: Subcontracted Productive Hours | L13: =IF(COUNT(C13:K13)=0,"",SUM(C13:K13)) | M13: ∑
B14: Subcontracted FTE | C14: =IFERROR(C13/C10,"") | D14: =IFERROR(D13/D10,"") | E14: =IFERROR(E13/E10,"") | F14: =IFERROR(F13/F10,"") | G14: =IFERROR(G13/G10,"") | H14: =IFERROR(H13/H10,"") | I14: =IFERROR(I13/I10,"") | J14: =IFERROR(J13/J10,"") | K14: =IFERROR(K13/K10,"") | L14: =IF(COUNT(C14:K14)=0,"",SUM(C14:K14)) | M14: FTE
B15: Total Operational Workforce | C15: =IF(COUNT(C5,C12)=0,"",SUM(C5,C12)) | D15: =IF(COUNT(D5,D12)=0,"",SUM(D5,D12)) | E15: =IF(COUNT(E5,E12)=0,"",SUM(E5,E12)) | F15: =IF(COUNT(F5,F12)=0,"",SUM(F5,F12)) | G15: =IF(COUNT(G5,G12)=0,"",SUM(G5,G12)) | H15: =IF(COUNT(H5,H12)=0,"",SUM(H5,H12)) | I15: =IF(COUNT(I5,I12)=0,"",SUM(I5,I12)) | J15: =IF(COUNT(J5,J12)=0,"",SUM(J5,J12)) | ... L15: =IF(COUNT(L5,L12)=0,"",SUM(L5,L12)) | M15: ϝ
B16: Total Operational FTE | C16: =IF(COUNT(C11,C14)=0,"",SUM(C11,C14)) | D16: =IF(COUNT(D11,D14)=0,"",SUM(D11,D14)) | E16: =IF(COUNT(E11,E14)=0,"",SUM(E11,E14)) | F16: =IF(COUNT(F11,F14)=0,"",SUM(F11,F14)) | G16: =IF(COUNT(G11,G14)=0,"",SUM(G11,G14)) | H16: =IF(COUNT(H11,H14)=0,"",SUM(H11,H14)) | I16: =IF(COUNT(I11,I14)=0,"",SUM(I11,I14)) | J16: =IF(COUNT(J11,J14)=0,"",SUM(J11,J14)) | ... L16: =IF(COUNT(L11,L14)=0,"",SUM(L11,L14)) | M16: FTE
B17: Subcontracted Share of Workforce (%) | C17: =IFERROR(C12/C15,"") | D17: =IFERROR(D12/D15,"") | E17: =IFERROR(E12/E15,"") | F17: =IFERROR(F12/F15,"") | G17: =IFERROR(G12/G15,"") | H17: =IFERROR(H12/H15,"") | I17: =IFERROR(I12/I15,"") | J17: =IFERROR(J12/J15,"") | ... L17: =IFERROR(L12/L15,"") | M17: ϝ
B18: FTE HR Team | L18: =IF(COUNT(C18:K18)=0,"",SUM(C18:K18)) | M18: ∑
B19: Permanent Hires | L19: =IF(COUNT(C19:K19)=0,"",SUM(C19:K19)) | M19: ∑
B20: Temporary Hires | L20: =IF(COUNT(C20:K20)=0,"",SUM(C20:K20)) | M20: ∑
B21: Total Hires | C21: =IF(COUNT(C19:C20)=0,"",SUM(C19:C20)) | D21: =IF(COUNT(D19:D20)=0,"",SUM(D19:D20)) | E21: =IF(COUNT(E19:E20)=0,"",SUM(E19:E20)) | F21: =IF(COUNT(F19:F20)=0,"",SUM(F19:F20)) | G21: =IF(COUNT(G19:G20)=0,"",SUM(G19:G20)) | H21: =IF(COUNT(H19:H20)=0,"",SUM(H19:H20)) | I21: =IF(COUNT(I19:I20)=0,"",SUM(I19:I20)) | J21: =IF(COUNT(J19:J20)=0,"",SUM(J19:J20)) | ... L21: =IF(COUNT(L19:L20)=0,"",SUM(L19:L20)) | M21: ϝ
B22: Permanent Exits | L22: =IF(COUNT(C22:K22)=0,"",SUM(C22:K22)) | M22: ∑
B23: Temporary Exits | L23: =IF(COUNT(C23:K23)=0,"",SUM(C23:K23)) | M23: ∑
B24: Total Exits | C24: =IF(COUNT(C22:C23)=0,"",SUM(C22:C23)) | D24: =IF(COUNT(D22:D23)=0,"",SUM(D22:D23)) | E24: =IF(COUNT(E22:E23)=0,"",SUM(E22:E23)) | F24: =IF(COUNT(F22:F23)=0,"",SUM(F22:F23)) | G24: =IF(COUNT(G22:G23)=0,"",SUM(G22:G23)) | H24: =IF(COUNT(H22:H23)=0,"",SUM(H22:H23)) | I24: =IF(COUNT(I22:I23)=0,"",SUM(I22:I23)) | J24: =IF(COUNT(J22:J23)=0,"",SUM(J22:J23)) | ... L24: =IF(COUNT(L22:L23)=0,"",SUM(L22:L23)) | M24: ϝ
B25: Permanent Turnover (%) | C25: =IF(COUNT(C31,C32)<2,"",IF((C32+C31)=0,"",N(C22)/((C32+C31)/2))) | D25: =IF(COUNT(D31,D32)<2,"",IF((D32+D31)=0,"",N(D22)/((D32+D31)/2))) | E25: =IF(COUNT(E31,E32)<2,"",IF((E32+E31)=0,"",N(E22)/((E32+E31)/2))) | F25: =IF(COUNT(F31,F32)<2,"",IF((F32+F31)=0,"",N(F22)/((F32+F31)/2))) | G25: =IF(COUNT(G31,G32)<2,"",IF((G32+G31)=0,"",N(G22)/((G32+G31)/2))) | H25: =IF(COUNT(H31,H32)<2,"",IF((H32+H31)=0,"",N(H22)/((H32+H31)/2))) | I25: =IF(COUNT(I31,I32)<2,"",IF((I32+I31)=0,"",N(I22)/((I32+I31)/2))) | J25: =IF(COUNT(J31,J32)<2,"",IF((J32+J31)=0,"",N(J22)/((J32+J31)/2))) | ... L25: =IF(COUNT(L31,L32)<2,"",IF((L32+L31)=0,"",N(L22)/((L32+L31)/2))) | M25: ϝ
B26: Temporary Turnover (%) | C26: =IF(COUNT(C31,C32)<2,"",IF((C32+C31)=0,"",N(C23)/((C32+C31)/2))) | D26: =IF(COUNT(D31,D32)<2,"",IF((D32+D31)=0,"",N(D23)/((D32+D31)/2))) | E26: =IF(COUNT(E31,E32)<2,"",IF((E32+E31)=0,"",N(E23)/((E32+E31)/2))) | F26: =IF(COUNT(F31,F32)<2,"",IF((F32+F31)=0,"",N(F23)/((F32+F31)/2))) | G26: =IF(COUNT(G31,G32)<2,"",IF((G32+G31)=0,"",N(G23)/((G32+G31)/2))) | H26: =IF(COUNT(H31,H32)<2,"",IF((H32+H31)=0,"",N(H23)/((H32+H31)/2))) | I26: =IF(COUNT(I31,I32)<2,"",IF((I32+I31)=0,"",N(I23)/((I32+I31)/2))) | J26: =IF(COUNT(J31,J32)<2,"",IF((J32+J31)=0,"",N(J23)/((J32+J31)/2))) | ... L26: =IF(COUNT(L31,L32)<2,"",IF((L32+L31)=0,"",N(L23)/((L32+L31)/2))) | M26: ϝ
B27: Voluntary Terminations | L27: =IF(COUNT(C27:K27)=0,"",SUM(C27:K27)) | M27: ∑
B28: Involuntary Terminations | L28: =IF(COUNT(C28:K28)=0,"",SUM(C28:K28)) | M28: ∑
B29: Voluntary Turnover (%) | C29: =IF(COUNT(C31,C32)<2,"",IF((C32+C31)=0,"",N(C27)/((C32+C31)/2))) | D29: =IF(COUNT(D31,D32)<2,"",IF((D32+D31)=0,"",N(D27)/((D32+D31)/2))) | E29: =IF(COUNT(E31,E32)<2,"",IF((E32+E31)=0,"",N(E27)/((E32+E31)/2))) | F29: =IF(COUNT(F31,F32)<2,"",IF((F32+F31)=0,"",N(F27)/((F32+F31)/2))) | G29: =IF(COUNT(G31,G32)<2,"",IF((G32+G31)=0,"",N(G27)/((G32+G31)/2))) | H29: =IF(COUNT(H31,H32)<2,"",IF((H32+H31)=0,"",N(H27)/((H32+H31)/2))) | I29: =IF(COUNT(I31,I32)<2,"",IF((I32+I31)=0,"",N(I27)/((I32+I31)/2))) | J29: =IF(COUNT(J31,J32)<2,"",IF((J32+J31)=0,"",N(J27)/((J32+J31)/2))) | ... L29: =IF(COUNT(L31,L32)<2,"",IF((L32+L31)=0,"",N(L27)/((L32+L31)/2))) | M29: ϝ
B30: Involuntary Turnover (%) | C30: =IF(COUNT(C31,C32)<2,"",IF((C32+C31)=0,"",N(C28)/((C32+C31)/2))) | D30: =IF(COUNT(D31,D32)<2,"",IF((D32+D31)=0,"",N(D28)/((D32+D31)/2))) | E30: =IF(COUNT(E31,E32)<2,"",IF((E32+E31)=0,"",N(E28)/((E32+E31)/2))) | F30: =IF(COUNT(F31,F32)<2,"",IF((F32+F31)=0,"",N(F28)/((F32+F31)/2))) | G30: =IF(COUNT(G31,G32)<2,"",IF((G32+G31)=0,"",N(G28)/((G32+G31)/2))) | H30: =IF(COUNT(H31,H32)<2,"",IF((H32+H31)=0,"",N(H28)/((H32+H31)/2))) | I30: =IF(COUNT(I31,I32)<2,"",IF((I32+I31)=0,"",N(I28)/((I32+I31)/2))) | J30: =IF(COUNT(J31,J32)<2,"",IF((J32+J31)=0,"",N(J28)/((J32+J31)/2))) | ... L30: =IF(COUNT(L31,L32)<2,"",IF((L32+L31)=0,"",N(L28)/((L32+L31)/2))) | M30: ϝ
B31: Headcount last Month | L31: =IF(COUNT(C31:K31)=0,"",SUM(C31:K31)) | M31: ∑
B32: Headcount this Month | C32: =IF(C5="","",C5) | D32: =IF(D5="","",D5) | E32: =IF(E5="","",E5) | F32: =IF(F5="","",F5) | G32: =IF(G5="","",G5) | H32: =IF(H5="","",H5) | I32: =IF(I5="","",I5) | J32: =IF(J5="","",J5) | K32: =IF(K5="","",K5) | L32: =IF(COUNT(C32:K32)=0,"",SUM(C32:K32)) | M32: ∑
B33: Full Turnover (%) | C33: =IF(COUNT(C31,C32)<2,"",IF((C32+C31)=0,"",N(C24)/((C32+C31)/2))) | D33: =IF(COUNT(D31,D32)<2,"",IF((D32+D31)=0,"",N(D24)/((D32+D31)/2))) | E33: =IF(COUNT(E31,E32)<2,"",IF((E32+E31)=0,"",N(E24)/((E32+E31)/2))) | F33: =IF(COUNT(F31,F32)<2,"",IF((F32+F31)=0,"",N(F24)/((F32+F31)/2))) | G33: =IF(COUNT(G31,G32)<2,"",IF((G32+G31)=0,"",N(G24)/((G32+G31)/2))) | H33: =IF(COUNT(H31,H32)<2,"",IF((H32+H31)=0,"",N(H24)/((H32+H31)/2))) | I33: =IF(COUNT(I31,I32)<2,"",IF((I32+I31)=0,"",N(I24)/((I32+I31)/2))) | J33: =IF(COUNT(J31,J32)<2,"",IF((J32+J31)=0,"",N(J24)/((J32+J31)/2))) | ... L33: =IF(COUNT(L31,L32)<2,"",IF((L32+L31)=0,"",N(L24)/((L32+L31)/2))) | M33: ϝ
B34: Permanent Vacancies | L34: =IF(COUNT(C34:K34)=0,"",SUM(C34:K34)) | M34: ∑
B35: Temporary Vacancies | L35: =IF(COUNT(C35:K35)=0,"",SUM(C35:K35)) | M35: ∑
B36: Total Vacancies | C36: =IF(COUNT(C34:C35)=0,"",SUM(C34:C35)) | D36: =IF(COUNT(D34:D35)=0,"",SUM(D34:D35)) | E36: =IF(COUNT(E34:E35)=0,"",SUM(E34:E35)) | F36: =IF(COUNT(F34:F35)=0,"",SUM(F34:F35)) | G36: =IF(COUNT(G34:G35)=0,"",SUM(G34:G35)) | H36: =IF(COUNT(H34:H35)=0,"",SUM(H34:H35)) | I36: =IF(COUNT(I34:I35)=0,"",SUM(I34:I35)) | J36: =IF(COUNT(J34:J35)=0,"",SUM(J34:J35)) | ... L36: =IF(COUNT(L34:L35)=0,"",SUM(L34:L35)) | M36: ϝ
B37: Authorized Positions | C37: =IF(COUNT(C5,C36)=0,"",N(C5)+N(C36)) | D37: =IF(COUNT(D5,D36)=0,"",N(D5)+N(D36)) | E37: =IF(COUNT(E5,E36)=0,"",N(E5)+N(E36)) | F37: =IF(COUNT(F5,F36)=0,"",N(F5)+N(F36)) | G37: =IF(COUNT(G5,G36)=0,"",N(G5)+N(G36)) | H37: =IF(COUNT(H5,H36)=0,"",N(H5)+N(H36)) | I37: =IF(COUNT(I5,I36)=0,"",N(I5)+N(I36)) | J37: =IF(COUNT(J5,J36)=0,"",N(J5)+N(J36)) | ... L37: =IF(COUNT(L5,L36)=0,"",N(L5)+N(L36)) | M37: ϝ
B38: Vacancy Rate (%) | C38: =IFERROR(C36/C37,"") | D38: =IFERROR(D36/D37,"") | E38: =IFERROR(E36/E37,"") | F38: =IFERROR(F36/F37,"") | G38: =IFERROR(G36/G37,"") | H38: =IFERROR(H36/H37,"") | I38: =IFERROR(I36/I37,"") | J38: =IFERROR(J36/J37,"") | ... L38: =IFERROR(L36/L37,"") | M38: ϝ
B39: Permanent TimeToHire (Days) YTD | C39: =IF('(GEL_Holding)'!$AB$4="","",'(GEL_Holding)'!$AB$4) | D39: =IF('(Dom_CLC)'!$AB$4="","",'(Dom_CLC)'!$AB$4) | E39: =IF('(Car_Label)'!$AB$4="","",'(Car_Label)'!$AB$4) | F39: =IF('(Ecuakao)'!$AB$4="","",'(Ecuakao)'!$AB$4) | G39: =IF('(Hipac)'!$AB$4="","",'(Hipac)'!$AB$4) | H39: =IF('(Jam_Label)'!$AB$4="","",'(Jam_Label)'!$AB$4) | I39: =IF('(Mc_Bride)'!$AB$4="","",'(Mc_Bride)'!$AB$4) | J39: =IF('(Precision)'!$AB$4="","",'(Precision)'!$AB$4) | K39: =IF('(Purity)'!$AB$4="","",'(Purity)'!$AB$4) | L39: =IFERROR(AVERAGE(C39:K39),"") | M39: Avg
B40: Temporary TimeToHire (Days) YTD | C40: =IF('(GEL_Holding)'!$AD$4="","",'(GEL_Holding)'!$AD$4) | D40: =IF('(Dom_CLC)'!$AD$4="","",'(Dom_CLC)'!$AD$4) | E40: =IF('(Car_Label)'!$AD$4="","",'(Car_Label)'!$AD$4) | F40: =IF('(Ecuakao)'!$AD$4="","",'(Ecuakao)'!$AD$4) | G40: =IF('(Hipac)'!$AD$4="","",'(Hipac)'!$AD$4) | H40: =IF('(Jam_Label)'!$AD$4="","",'(Jam_Label)'!$AD$4) | I40: =IF('(Mc_Bride)'!$AD$4="","",'(Mc_Bride)'!$AD$4) | J40: =IF('(Precision)'!$AD$4="","",'(Precision)'!$AD$4) | K40: =IF('(Purity)'!$AD$4="","",'(Purity)'!$AD$4) | L40: =IFERROR(AVERAGE(C40:K40),"") | M40: Avg
...

Sheet NOV
B1: MANUFACTURING
A2: =VALUE(TEXT(EDATE(DATE(LEFT(OCT!A2,4),RIGHT(OCT!A2,2),1),1),"yyyymm")) | B2: NOV | C2: GEL Manufacturing Holding Co. Ltd. | D2: CLC Domicana (Dominican Republic) | E2: Caribbean Label Crafts Ltd. (Barbados) | F2: Ecuakao (Ecuador) | G2: Hipac Ltd. (Barbados) | H2: Label Craft Jamaica Ltd. (Jamaica) | I2: McBride (Caribbean) Ltd. | J2: Precision Packaging Inc. (Barbados) | K2: Purity Bakeries Ltd. (Barbados) | L2: TOTAL | M2: Total by Division | N2: =N(N11)<>0
A3: =+A2 | B3: Permanent (Regular) Headcount | L3: =IF(COUNT(C3:K3)=0,"",SUM(C3:K3)) | M3: ∑
B4: Temporary (Fix Term) Headcount | L4: =IF(COUNT(C4:K4)=0,"",SUM(C4:K4)) | M4: ∑
B5: Employee Headcount (Productivity) | C5: =IF(COUNT(C3:C4)=0,"",SUM(C3:C4)) | D5: =IF(COUNT(D3:D4)=0,"",SUM(D3:D4)) | E5: =IF(COUNT(E3:E4)=0,"",SUM(E3:E4)) | F5: =IF(COUNT(F3:F4)=0,"",SUM(F3:F4)) | G5: =IF(COUNT(G3:G4)=0,"",SUM(G3:G4)) | H5: =IF(COUNT(H3:H4)=0,"",SUM(H3:H4)) | I5: =IF(COUNT(I3:I4)=0,"",SUM(I3:I4)) | J5: =IF(COUNT(J3:J4)=0,"",SUM(J3:J4)) | ... L5: =IF(COUNT(L3:L4)=0,"",SUM(L3:L4)) | M5: ϝ
B6: Headcount = 1.00 | L6: =IF(COUNT(C6:K6)=0,"",SUM(C6:K6)) | M6: ∑
B7: Headcount = 0.75 | L7: =IF(COUNT(C7:K7)=0,"",SUM(C7:K7)) | M7: ∑
B8: Headcount = 0.50 | L8: =IF(COUNT(C8:K8)=0,"",SUM(C8:K8)) | M8: ∑
B9: Headcount = 0.25 | L9: =IF(COUNT(C9:K9)=0,"",SUM(C9:K9)) | M9: ∑
B10: Standard Monthly Hours (FTE basis) | L10: =IFERROR(AVERAGE(C10:K10),"") | M10: Avg
B11: Employee FTE (Finance) | C11: =IF(COUNT(C6:C9)=0,"",N(C6)+N(C7)*0.75+N(C8)*0.5+N(C9)*0.25) | D11: =IF(COUNT(D6:D9)=0,"",N(D6)+N(D7)*0.75+N(D8)*0.5+N(D9)*0.25) | E11: =IF(COUNT(E6:E9)=0,"",N(E6)+N(E7)*0.75+N(E8)*0.5+N(E9)*0.25) | F11: =IF(COUNT(F6:F9)=0,"",N(F6)+N(F7)*0.75+N(F8)*0.5+N(F9)*0.25) | G11: =IF(COUNT(G6:G9)=0,"",N(G6)+N(G7)*0.75+N(G8)*0.5+N(G9)*0.25) | H11: =IF(COUNT(H6:H9)=0,"",N(H6)+N(H7)*0.75+N(H8)*0.5+N(H9)*0.25) | I11: =IF(COUNT(I6:I9)=0,"",N(I6)+N(I7)*0.75+N(I8)*0.5+N(I9)*0.25) | J11: =IF(COUNT(J6:J9)=0,"",N(J6)+N(J7)*0.75+N(J8)*0.5+N(J9)*0.25) | ... L11: =IF(COUNT(L6:L9)=0,"",N(L6)+N(L7)*0.75+N(L8)*0.5+N(L9)*0.25) | M11: FTE | N11: =IF(COUNT(L5:L9)=0,"",N(L6)+N(L7)+N(L8)+N(L9)-N(L5))
B12: Subcontracted Workforce HC | L12: =IF(COUNT(C12:K12)=0,"",SUM(C12:K12)) | M12: ∑
B13: Subcontracted Productive Hours | L13: =IF(COUNT(C13:K13)=0,"",SUM(C13:K13)) | M13: ∑
B14: Subcontracted FTE | C14: =IFERROR(C13/C10,"") | D14: =IFERROR(D13/D10,"") | E14: =IFERROR(E13/E10,"") | F14: =IFERROR(F13/F10,"") | G14: =IFERROR(G13/G10,"") | H14: =IFERROR(H13/H10,"") | I14: =IFERROR(I13/I10,"") | J14: =IFERROR(J13/J10,"") | K14: =IFERROR(K13/K10,"") | L14: =IF(COUNT(C14:K14)=0,"",SUM(C14:K14)) | M14: FTE
B15: Total Operational Workforce | C15: =IF(COUNT(C5,C12)=0,"",SUM(C5,C12)) | D15: =IF(COUNT(D5,D12)=0,"",SUM(D5,D12)) | E15: =IF(COUNT(E5,E12)=0,"",SUM(E5,E12)) | F15: =IF(COUNT(F5,F12)=0,"",SUM(F5,F12)) | G15: =IF(COUNT(G5,G12)=0,"",SUM(G5,G12)) | H15: =IF(COUNT(H5,H12)=0,"",SUM(H5,H12)) | I15: =IF(COUNT(I5,I12)=0,"",SUM(I5,I12)) | J15: =IF(COUNT(J5,J12)=0,"",SUM(J5,J12)) | ... L15: =IF(COUNT(L5,L12)=0,"",SUM(L5,L12)) | M15: ϝ
B16: Total Operational FTE | C16: =IF(COUNT(C11,C14)=0,"",SUM(C11,C14)) | D16: =IF(COUNT(D11,D14)=0,"",SUM(D11,D14)) | E16: =IF(COUNT(E11,E14)=0,"",SUM(E11,E14)) | F16: =IF(COUNT(F11,F14)=0,"",SUM(F11,F14)) | G16: =IF(COUNT(G11,G14)=0,"",SUM(G11,G14)) | H16: =IF(COUNT(H11,H14)=0,"",SUM(H11,H14)) | I16: =IF(COUNT(I11,I14)=0,"",SUM(I11,I14)) | J16: =IF(COUNT(J11,J14)=0,"",SUM(J11,J14)) | ... L16: =IF(COUNT(L11,L14)=0,"",SUM(L11,L14)) | M16: FTE
B17: Subcontracted Share of Workforce (%) | C17: =IFERROR(C12/C15,"") | D17: =IFERROR(D12/D15,"") | E17: =IFERROR(E12/E15,"") | F17: =IFERROR(F12/F15,"") | G17: =IFERROR(G12/G15,"") | H17: =IFERROR(H12/H15,"") | I17: =IFERROR(I12/I15,"") | J17: =IFERROR(J12/J15,"") | ... L17: =IFERROR(L12/L15,"") | M17: ϝ
B18: FTE HR Team | L18: =IF(COUNT(C18:K18)=0,"",SUM(C18:K18)) | M18: ∑
B19: Permanent Hires | L19: =IF(COUNT(C19:K19)=0,"",SUM(C19:K19)) | M19: ∑
B20: Temporary Hires | L20: =IF(COUNT(C20:K20)=0,"",SUM(C20:K20)) | M20: ∑
B21: Total Hires | C21: =IF(COUNT(C19:C20)=0,"",SUM(C19:C20)) | D21: =IF(COUNT(D19:D20)=0,"",SUM(D19:D20)) | E21: =IF(COUNT(E19:E20)=0,"",SUM(E19:E20)) | F21: =IF(COUNT(F19:F20)=0,"",SUM(F19:F20)) | G21: =IF(COUNT(G19:G20)=0,"",SUM(G19:G20)) | H21: =IF(COUNT(H19:H20)=0,"",SUM(H19:H20)) | I21: =IF(COUNT(I19:I20)=0,"",SUM(I19:I20)) | J21: =IF(COUNT(J19:J20)=0,"",SUM(J19:J20)) | ... L21: =IF(COUNT(L19:L20)=0,"",SUM(L19:L20)) | M21: ϝ
B22: Permanent Exits | L22: =IF(COUNT(C22:K22)=0,"",SUM(C22:K22)) | M22: ∑
B23: Temporary Exits | L23: =IF(COUNT(C23:K23)=0,"",SUM(C23:K23)) | M23: ∑
B24: Total Exits | C24: =IF(COUNT(C22:C23)=0,"",SUM(C22:C23)) | D24: =IF(COUNT(D22:D23)=0,"",SUM(D22:D23)) | E24: =IF(COUNT(E22:E23)=0,"",SUM(E22:E23)) | F24: =IF(COUNT(F22:F23)=0,"",SUM(F22:F23)) | G24: =IF(COUNT(G22:G23)=0,"",SUM(G22:G23)) | H24: =IF(COUNT(H22:H23)=0,"",SUM(H22:H23)) | I24: =IF(COUNT(I22:I23)=0,"",SUM(I22:I23)) | J24: =IF(COUNT(J22:J23)=0,"",SUM(J22:J23)) | ... L24: =IF(COUNT(L22:L23)=0,"",SUM(L22:L23)) | M24: ϝ
B25: Permanent Turnover (%) | C25: =IF(COUNT(C31,C32)<2,"",IF((C32+C31)=0,"",N(C22)/((C32+C31)/2))) | D25: =IF(COUNT(D31,D32)<2,"",IF((D32+D31)=0,"",N(D22)/((D32+D31)/2))) | E25: =IF(COUNT(E31,E32)<2,"",IF((E32+E31)=0,"",N(E22)/((E32+E31)/2))) | F25: =IF(COUNT(F31,F32)<2,"",IF((F32+F31)=0,"",N(F22)/((F32+F31)/2))) | G25: =IF(COUNT(G31,G32)<2,"",IF((G32+G31)=0,"",N(G22)/((G32+G31)/2))) | H25: =IF(COUNT(H31,H32)<2,"",IF((H32+H31)=0,"",N(H22)/((H32+H31)/2))) | I25: =IF(COUNT(I31,I32)<2,"",IF((I32+I31)=0,"",N(I22)/((I32+I31)/2))) | J25: =IF(COUNT(J31,J32)<2,"",IF((J32+J31)=0,"",N(J22)/((J32+J31)/2))) | ... L25: =IF(COUNT(L31,L32)<2,"",IF((L32+L31)=0,"",N(L22)/((L32+L31)/2))) | M25: ϝ
B26: Temporary Turnover (%) | C26: =IF(COUNT(C31,C32)<2,"",IF((C32+C31)=0,"",N(C23)/((C32+C31)/2))) | D26: =IF(COUNT(D31,D32)<2,"",IF((D32+D31)=0,"",N(D23)/((D32+D31)/2))) | E26: =IF(COUNT(E31,E32)<2,"",IF((E32+E31)=0,"",N(E23)/((E32+E31)/2))) | F26: =IF(COUNT(F31,F32)<2,"",IF((F32+F31)=0,"",N(F23)/((F32+F31)/2))) | G26: =IF(COUNT(G31,G32)<2,"",IF((G32+G31)=0,"",N(G23)/((G32+G31)/2))) | H26: =IF(COUNT(H31,H32)<2,"",IF((H32+H31)=0,"",N(H23)/((H32+H31)/2))) | I26: =IF(COUNT(I31,I32)<2,"",IF((I32+I31)=0,"",N(I23)/((I32+I31)/2))) | J26: =IF(COUNT(J31,J32)<2,"",IF((J32+J31)=0,"",N(J23)/((J32+J31)/2))) | ... L26: =IF(COUNT(L31,L32)<2,"",IF((L32+L31)=0,"",N(L23)/((L32+L31)/2))) | M26: ϝ
B27: Voluntary Terminations | L27: =IF(COUNT(C27:K27)=0,"",SUM(C27:K27)) | M27: ∑
B28: Involuntary Terminations | L28: =IF(COUNT(C28:K28)=0,"",SUM(C28:K28)) | M28: ∑
B29: Voluntary Turnover (%) | C29: =IF(COUNT(C31,C32)<2,"",IF((C32+C31)=0,"",N(C27)/((C32+C31)/2))) | D29: =IF(COUNT(D31,D32)<2,"",IF((D32+D31)=0,"",N(D27)/((D32+D31)/2))) | E29: =IF(COUNT(E31,E32)<2,"",IF((E32+E31)=0,"",N(E27)/((E32+E31)/2))) | F29: =IF(COUNT(F31,F32)<2,"",IF((F32+F31)=0,"",N(F27)/((F32+F31)/2))) | G29: =IF(COUNT(G31,G32)<2,"",IF((G32+G31)=0,"",N(G27)/((G32+G31)/2))) | H29: =IF(COUNT(H31,H32)<2,"",IF((H32+H31)=0,"",N(H27)/((H32+H31)/2))) | I29: =IF(COUNT(I31,I32)<2,"",IF((I32+I31)=0,"",N(I27)/((I32+I31)/2))) | J29: =IF(COUNT(J31,J32)<2,"",IF((J32+J31)=0,"",N(J27)/((J32+J31)/2))) | ... L29: =IF(COUNT(L31,L32)<2,"",IF((L32+L31)=0,"",N(L27)/((L32+L31)/2))) | M29: ϝ
B30: Involuntary Turnover (%) | C30: =IF(COUNT(C31,C32)<2,"",IF((C32+C31)=0,"",N(C28)/((C32+C31)/2))) | D30: =IF(COUNT(D31,D32)<2,"",IF((D32+D31)=0,"",N(D28)/((D32+D31)/2))) | E30: =IF(COUNT(E31,E32)<2,"",IF((E32+E31)=0,"",N(E28)/((E32+E31)/2))) | F30: =IF(COUNT(F31,F32)<2,"",IF((F32+F31)=0,"",N(F28)/((F32+F31)/2))) | G30: =IF(COUNT(G31,G32)<2,"",IF((G32+G31)=0,"",N(G28)/((G32+G31)/2))) | H30: =IF(COUNT(H31,H32)<2,"",IF((H32+H31)=0,"",N(H28)/((H32+H31)/2))) | I30: =IF(COUNT(I31,I32)<2,"",IF((I32+I31)=0,"",N(I28)/((I32+I31)/2))) | J30: =IF(COUNT(J31,J32)<2,"",IF((J32+J31)=0,"",N(J28)/((J32+J31)/2))) | ... L30: =IF(COUNT(L31,L32)<2,"",IF((L32+L31)=0,"",N(L28)/((L32+L31)/2))) | M30: ϝ
B31: Headcount last Month | C31: =IF(OCT!C5="","",OCT!C5) | D31: =IF(OCT!D5="","",OCT!D5) | E31: =IF(OCT!E5="","",OCT!E5) | F31: =IF(OCT!F5="","",OCT!F5) | G31: =IF(OCT!G5="","",OCT!G5) | H31: =IF(OCT!H5="","",OCT!H5) | I31: =IF(OCT!I5="","",OCT!I5) | J31: =IF(OCT!J5="","",OCT!J5) | K31: =IF(OCT!K5="","",OCT!K5) | L31: =IF(COUNT(C31:K31)=0,"",SUM(C31:K31)) | M31: ∑
B32: Headcount this Month | C32: =IF(C5="","",C5) | D32: =IF(D5="","",D5) | E32: =IF(E5="","",E5) | F32: =IF(F5="","",F5) | G32: =IF(G5="","",G5) | H32: =IF(H5="","",H5) | I32: =IF(I5="","",I5) | J32: =IF(J5="","",J5) | K32: =IF(K5="","",K5) | L32: =IF(COUNT(C32:K32)=0,"",SUM(C32:K32)) | M32: ∑
B33: Full Turnover (%) | C33: =IF(COUNT(C31,C32)<2,"",IF((C32+C31)=0,"",N(C24)/((C32+C31)/2))) | D33: =IF(COUNT(D31,D32)<2,"",IF((D32+D31)=0,"",N(D24)/((D32+D31)/2))) | E33: =IF(COUNT(E31,E32)<2,"",IF((E32+E31)=0,"",N(E24)/((E32+E31)/2))) | F33: =IF(COUNT(F31,F32)<2,"",IF((F32+F31)=0,"",N(F24)/((F32+F31)/2))) | G33: =IF(COUNT(G31,G32)<2,"",IF((G32+G31)=0,"",N(G24)/((G32+G31)/2))) | H33: =IF(COUNT(H31,H32)<2,"",IF((H32+H31)=0,"",N(H24)/((H32+H31)/2))) | I33: =IF(COUNT(I31,I32)<2,"",IF((I32+I31)=0,"",N(I24)/((I32+I31)/2))) | J33: =IF(COUNT(J31,J32)<2,"",IF((J32+J31)=0,"",N(J24)/((J32+J31)/2))) | ... L33: =IF(COUNT(L31,L32)<2,"",IF((L32+L31)=0,"",N(L24)/((L32+L31)/2))) | M33: ϝ
B34: Permanent Vacancies | L34: =IF(COUNT(C34:K34)=0,"",SUM(C34:K34)) | M34: ∑
B35: Temporary Vacancies | L35: =IF(COUNT(C35:K35)=0,"",SUM(C35:K35)) | M35: ∑
B36: Total Vacancies | C36: =IF(COUNT(C34:C35)=0,"",SUM(C34:C35)) | D36: =IF(COUNT(D34:D35)=0,"",SUM(D34:D35)) | E36: =IF(COUNT(E34:E35)=0,"",SUM(E34:E35)) | F36: =IF(COUNT(F34:F35)=0,"",SUM(F34:F35)) | G36: =IF(COUNT(G34:G35)=0,"",SUM(G34:G35)) | H36: =IF(COUNT(H34:H35)=0,"",SUM(H34:H35)) | I36: =IF(COUNT(I34:I35)=0,"",SUM(I34:I35)) | J36: =IF(COUNT(J34:J35)=0,"",SUM(J34:J35)) | ... L36: =IF(COUNT(L34:L35)=0,"",SUM(L34:L35)) | M36: ϝ
B37: Authorized Positions | C37: =IF(COUNT(C5,C36)=0,"",N(C5)+N(C36)) | D37: =IF(COUNT(D5,D36)=0,"",N(D5)+N(D36)) | E37: =IF(COUNT(E5,E36)=0,"",N(E5)+N(E36)) | F37: =IF(COUNT(F5,F36)=0,"",N(F5)+N(F36)) | G37: =IF(COUNT(G5,G36)=0,"",N(G5)+N(G36)) | H37: =IF(COUNT(H5,H36)=0,"",N(H5)+N(H36)) | I37: =IF(COUNT(I5,I36)=0,"",N(I5)+N(I36)) | J37: =IF(COUNT(J5,J36)=0,"",N(J5)+N(J36)) | ... L37: =IF(COUNT(L5,L36)=0,"",N(L5)+N(L36)) | M37: ϝ
B38: Vacancy Rate (%) | C38: =IFERROR(C36/C37,"") | D38: =IFERROR(D36/D37,"") | E38: =IFERROR(E36/E37,"") | F38: =IFERROR(F36/F37,"") | G38: =IFERROR(G36/G37,"") | H38: =IFERROR(H36/H37,"") | I38: =IFERROR(I36/I37,"") | J38: =IFERROR(J36/J37,"") | ... L38: =IFERROR(L36/L37,"") | M38: ϝ
B39: Permanent TimeToHire (Days) YTD | C39: =IF('(GEL_Holding)'!$AB$5="","",'(GEL_Holding)'!$AB$5) | D39: =IF('(Dom_CLC)'!$AB$5="","",'(Dom_CLC)'!$AB$5) | E39: =IF('(Car_Label)'!$AB$5="","",'(Car_Label)'!$AB$5) | F39: =IF('(Ecuakao)'!$AB$5="","",'(Ecuakao)'!$AB$5) | G39: =IF('(Hipac)'!$AB$5="","",'(Hipac)'!$AB$5) | H39: =IF('(Jam_Label)'!$AB$5="","",'(Jam_Label)'!$AB$5) | I39: =IF('(Mc_Bride)'!$AB$5="","",'(Mc_Bride)'!$AB$5) | J39: =IF('(Precision)'!$AB$5="","",'(Precision)'!$AB$5) | K39: =IF('(Purity)'!$AB$5="","",'(Purity)'!$AB$5) | L39: =IFERROR(AVERAGE(C39:K39),"") | M39: Avg
B40: Temporary TimeToHire (Days) YTD | C40: =IF('(GEL_Holding)'!$AD$5="","",'(GEL_Holding)'!$AD$5) | D40: =IF('(Dom_CLC)'!$AD$5="","",'(Dom_CLC)'!$AD$5) | E40: =IF('(Car_Label)'!$AD$5="","",'(Car_Label)'!$AD$5) | F40: =IF('(Ecuakao)'!$AD$5="","",'(Ecuakao)'!$AD$5) | G40: =IF('(Hipac)'!$AD$5="","",'(Hipac)'!$AD$5) | H40: =IF('(Jam_Label)'!$AD$5="","",'(Jam_Label)'!$AD$5) | I40: =IF('(Mc_Bride)'!$AD$5="","",'(Mc_Bride)'!$AD$5) | J40: =IF('(Precision)'!$AD$5="","",'(Precision)'!$AD$5) | K40: =IF('(Purity)'!$AD$5="","",'(Purity)'!$AD$5) | L40: =IFERROR(AVERAGE(C40:K40),"") | M40: Avg
...

Sheet DEC
B1: MANUFACTURING
A2: =VALUE(TEXT(EDATE(DATE(LEFT(NOV!A2,4),RIGHT(NOV!A2,2),1),1),"yyyymm")) | B2: DEC | C2: GEL Manufacturing Holding Co. Ltd. | D2: CLC Domicana (Dominican Republic) | E2: Caribbean Label Crafts Ltd. (Barbados) | F2: Ecuakao (Ecuador) | G2: Hipac Ltd. (Barbados) | H2: Label Craft Jamaica Ltd. (Jamaica) | I2: McBride (Caribbean) Ltd. | J2: Precision Packaging Inc. (Barbados) | K2: Purity Bakeries Ltd. (Barbados) | L2: TOTAL | M2: Total by Division | N2: =N(N11)<>0
A3: =+A2 | B3: Permanent (Regular) Headcount | L3: =IF(COUNT(C3:K3)=0,"",SUM(C3:K3)) | M3: ∑
B4: Temporary (Fix Term) Headcount | L4: =IF(COUNT(C4:K4)=0,"",SUM(C4:K4)) | M4: ∑
B5: Employee Headcount (Productivity) | C5: =IF(COUNT(C3:C4)=0,"",SUM(C3:C4)) | D5: =IF(COUNT(D3:D4)=0,"",SUM(D3:D4)) | E5: =IF(COUNT(E3:E4)=0,"",SUM(E3:E4)) | F5: =IF(COUNT(F3:F4)=0,"",SUM(F3:F4)) | G5: =IF(COUNT(G3:G4)=0,"",SUM(G3:G4)) | H5: =IF(COUNT(H3:H4)=0,"",SUM(H3:H4)) | I5: =IF(COUNT(I3:I4)=0,"",SUM(I3:I4)) | J5: =IF(COUNT(J3:J4)=0,"",SUM(J3:J4)) | ... L5: =IF(COUNT(L3:L4)=0,"",SUM(L3:L4)) | M5: ϝ
B6: Headcount = 1.00 | L6: =IF(COUNT(C6:K6)=0,"",SUM(C6:K6)) | M6: ∑
B7: Headcount = 0.75 | L7: =IF(COUNT(C7:K7)=0,"",SUM(C7:K7)) | M7: ∑
B8: Headcount = 0.50 | L8: =IF(COUNT(C8:K8)=0,"",SUM(C8:K8)) | M8: ∑
B9: Headcount = 0.25 | L9: =IF(COUNT(C9:K9)=0,"",SUM(C9:K9)) | M9: ∑
B10: Standard Monthly Hours (FTE basis) | L10: =IFERROR(AVERAGE(C10:K10),"") | M10: Avg
B11: Employee FTE (Finance) | C11: =IF(COUNT(C6:C9)=0,"",N(C6)+N(C7)*0.75+N(C8)*0.5+N(C9)*0.25) | D11: =IF(COUNT(D6:D9)=0,"",N(D6)+N(D7)*0.75+N(D8)*0.5+N(D9)*0.25) | E11: =IF(COUNT(E6:E9)=0,"",N(E6)+N(E7)*0.75+N(E8)*0.5+N(E9)*0.25) | F11: =IF(COUNT(F6:F9)=0,"",N(F6)+N(F7)*0.75+N(F8)*0.5+N(F9)*0.25) | G11: =IF(COUNT(G6:G9)=0,"",N(G6)+N(G7)*0.75+N(G8)*0.5+N(G9)*0.25) | H11: =IF(COUNT(H6:H9)=0,"",N(H6)+N(H7)*0.75+N(H8)*0.5+N(H9)*0.25) | I11: =IF(COUNT(I6:I9)=0,"",N(I6)+N(I7)*0.75+N(I8)*0.5+N(I9)*0.25) | J11: =IF(COUNT(J6:J9)=0,"",N(J6)+N(J7)*0.75+N(J8)*0.5+N(J9)*0.25) | ... L11: =IF(COUNT(L6:L9)=0,"",N(L6)+N(L7)*0.75+N(L8)*0.5+N(L9)*0.25) | M11: FTE | N11: =IF(COUNT(L5:L9)=0,"",N(L6)+N(L7)+N(L8)+N(L9)-N(L5))
B12: Subcontracted Workforce HC | L12: =IF(COUNT(C12:K12)=0,"",SUM(C12:K12)) | M12: ∑
B13: Subcontracted Productive Hours | L13: =IF(COUNT(C13:K13)=0,"",SUM(C13:K13)) | M13: ∑
B14: Subcontracted FTE | C14: =IFERROR(C13/C10,"") | D14: =IFERROR(D13/D10,"") | E14: =IFERROR(E13/E10,"") | F14: =IFERROR(F13/F10,"") | G14: =IFERROR(G13/G10,"") | H14: =IFERROR(H13/H10,"") | I14: =IFERROR(I13/I10,"") | J14: =IFERROR(J13/J10,"") | K14: =IFERROR(K13/K10,"") | L14: =IF(COUNT(C14:K14)=0,"",SUM(C14:K14)) | M14: FTE
B15: Total Operational Workforce | C15: =IF(COUNT(C5,C12)=0,"",SUM(C5,C12)) | D15: =IF(COUNT(D5,D12)=0,"",SUM(D5,D12)) | E15: =IF(COUNT(E5,E12)=0,"",SUM(E5,E12)) | F15: =IF(COUNT(F5,F12)=0,"",SUM(F5,F12)) | G15: =IF(COUNT(G5,G12)=0,"",SUM(G5,G12)) | H15: =IF(COUNT(H5,H12)=0,"",SUM(H5,H12)) | I15: =IF(COUNT(I5,I12)=0,"",SUM(I5,I12)) | J15: =IF(COUNT(J5,J12)=0,"",SUM(J5,J12)) | ... L15: =IF(COUNT(L5,L12)=0,"",SUM(L5,L12)) | M15: ϝ
B16: Total Operational FTE | C16: =IF(COUNT(C11,C14)=0,"",SUM(C11,C14)) | D16: =IF(COUNT(D11,D14)=0,"",SUM(D11,D14)) | E16: =IF(COUNT(E11,E14)=0,"",SUM(E11,E14)) | F16: =IF(COUNT(F11,F14)=0,"",SUM(F11,F14)) | G16: =IF(COUNT(G11,G14)=0,"",SUM(G11,G14)) | H16: =IF(COUNT(H11,H14)=0,"",SUM(H11,H14)) | I16: =IF(COUNT(I11,I14)=0,"",SUM(I11,I14)) | J16: =IF(COUNT(J11,J14)=0,"",SUM(J11,J14)) | ... L16: =IF(COUNT(L11,L14)=0,"",SUM(L11,L14)) | M16: FTE
B17: Subcontracted Share of Workforce (%) | C17: =IFERROR(C12/C15,"") | D17: =IFERROR(D12/D15,"") | E17: =IFERROR(E12/E15,"") | F17: =IFERROR(F12/F15,"") | G17: =IFERROR(G12/G15,"") | H17: =IFERROR(H12/H15,"") | I17: =IFERROR(I12/I15,"") | J17: =IFERROR(J12/J15,"") | ... L17: =IFERROR(L12/L15,"") | M17: ϝ
B18: FTE HR Team | L18: =IF(COUNT(C18:K18)=0,"",SUM(C18:K18)) | M18: ∑
B19: Permanent Hires | L19: =IF(COUNT(C19:K19)=0,"",SUM(C19:K19)) | M19: ∑
B20: Temporary Hires | L20: =IF(COUNT(C20:K20)=0,"",SUM(C20:K20)) | M20: ∑
B21: Total Hires | C21: =IF(COUNT(C19:C20)=0,"",SUM(C19:C20)) | D21: =IF(COUNT(D19:D20)=0,"",SUM(D19:D20)) | E21: =IF(COUNT(E19:E20)=0,"",SUM(E19:E20)) | F21: =IF(COUNT(F19:F20)=0,"",SUM(F19:F20)) | G21: =IF(COUNT(G19:G20)=0,"",SUM(G19:G20)) | H21: =IF(COUNT(H19:H20)=0,"",SUM(H19:H20)) | I21: =IF(COUNT(I19:I20)=0,"",SUM(I19:I20)) | J21: =IF(COUNT(J19:J20)=0,"",SUM(J19:J20)) | ... L21: =IF(COUNT(L19:L20)=0,"",SUM(L19:L20)) | M21: ϝ
B22: Permanent Exits | L22: =IF(COUNT(C22:K22)=0,"",SUM(C22:K22)) | M22: ∑
B23: Temporary Exits | L23: =IF(COUNT(C23:K23)=0,"",SUM(C23:K23)) | M23: ∑
B24: Total Exits | C24: =IF(COUNT(C22:C23)=0,"",SUM(C22:C23)) | D24: =IF(COUNT(D22:D23)=0,"",SUM(D22:D23)) | E24: =IF(COUNT(E22:E23)=0,"",SUM(E22:E23)) | F24: =IF(COUNT(F22:F23)=0,"",SUM(F22:F23)) | G24: =IF(COUNT(G22:G23)=0,"",SUM(G22:G23)) | H24: =IF(COUNT(H22:H23)=0,"",SUM(H22:H23)) | I24: =IF(COUNT(I22:I23)=0,"",SUM(I22:I23)) | J24: =IF(COUNT(J22:J23)=0,"",SUM(J22:J23)) | ... L24: =IF(COUNT(L22:L23)=0,"",SUM(L22:L23)) | M24: ϝ
B25: Permanent Turnover (%) | C25: =IF(COUNT(C31,C32)<2,"",IF((C32+C31)=0,"",N(C22)/((C32+C31)/2))) | D25: =IF(COUNT(D31,D32)<2,"",IF((D32+D31)=0,"",N(D22)/((D32+D31)/2))) | E25: =IF(COUNT(E31,E32)<2,"",IF((E32+E31)=0,"",N(E22)/((E32+E31)/2))) | F25: =IF(COUNT(F31,F32)<2,"",IF((F32+F31)=0,"",N(F22)/((F32+F31)/2))) | G25: =IF(COUNT(G31,G32)<2,"",IF((G32+G31)=0,"",N(G22)/((G32+G31)/2))) | H25: =IF(COUNT(H31,H32)<2,"",IF((H32+H31)=0,"",N(H22)/((H32+H31)/2))) | I25: =IF(COUNT(I31,I32)<2,"",IF((I32+I31)=0,"",N(I22)/((I32+I31)/2))) | J25: =IF(COUNT(J31,J32)<2,"",IF((J32+J31)=0,"",N(J22)/((J32+J31)/2))) | ... L25: =IF(COUNT(L31,L32)<2,"",IF((L32+L31)=0,"",N(L22)/((L32+L31)/2))) | M25: ϝ
B26: Temporary Turnover (%) | C26: =IF(COUNT(C31,C32)<2,"",IF((C32+C31)=0,"",N(C23)/((C32+C31)/2))) | D26: =IF(COUNT(D31,D32)<2,"",IF((D32+D31)=0,"",N(D23)/((D32+D31)/2))) | E26: =IF(COUNT(E31,E32)<2,"",IF((E32+E31)=0,"",N(E23)/((E32+E31)/2))) | F26: =IF(COUNT(F31,F32)<2,"",IF((F32+F31)=0,"",N(F23)/((F32+F31)/2))) | G26: =IF(COUNT(G31,G32)<2,"",IF((G32+G31)=0,"",N(G23)/((G32+G31)/2))) | H26: =IF(COUNT(H31,H32)<2,"",IF((H32+H31)=0,"",N(H23)/((H32+H31)/2))) | I26: =IF(COUNT(I31,I32)<2,"",IF((I32+I31)=0,"",N(I23)/((I32+I31)/2))) | J26: =IF(COUNT(J31,J32)<2,"",IF((J32+J31)=0,"",N(J23)/((J32+J31)/2))) | ... L26: =IF(COUNT(L31,L32)<2,"",IF((L32+L31)=0,"",N(L23)/((L32+L31)/2))) | M26: ϝ
B27: Voluntary Terminations | L27: =IF(COUNT(C27:K27)=0,"",SUM(C27:K27)) | M27: ∑
B28: Involuntary Terminations | L28: =IF(COUNT(C28:K28)=0,"",SUM(C28:K28)) | M28: ∑
B29: Voluntary Turnover (%) | C29: =IF(COUNT(C31,C32)<2,"",IF((C32+C31)=0,"",N(C27)/((C32+C31)/2))) | D29: =IF(COUNT(D31,D32)<2,"",IF((D32+D31)=0,"",N(D27)/((D32+D31)/2))) | E29: =IF(COUNT(E31,E32)<2,"",IF((E32+E31)=0,"",N(E27)/((E32+E31)/2))) | F29: =IF(COUNT(F31,F32)<2,"",IF((F32+F31)=0,"",N(F27)/((F32+F31)/2))) | G29: =IF(COUNT(G31,G32)<2,"",IF((G32+G31)=0,"",N(G27)/((G32+G31)/2))) | H29: =IF(COUNT(H31,H32)<2,"",IF((H32+H31)=0,"",N(H27)/((H32+H31)/2))) | I29: =IF(COUNT(I31,I32)<2,"",IF((I32+I31)=0,"",N(I27)/((I32+I31)/2))) | J29: =IF(COUNT(J31,J32)<2,"",IF((J32+J31)=0,"",N(J27)/((J32+J31)/2))) | ... L29: =IF(COUNT(L31,L32)<2,"",IF((L32+L31)=0,"",N(L27)/((L32+L31)/2))) | M29: ϝ
B30: Involuntary Turnover (%) | C30: =IF(COUNT(C31,C32)<2,"",IF((C32+C31)=0,"",N(C28)/((C32+C31)/2))) | D30: =IF(COUNT(D31,D32)<2,"",IF((D32+D31)=0,"",N(D28)/((D32+D31)/2))) | E30: =IF(COUNT(E31,E32)<2,"",IF((E32+E31)=0,"",N(E28)/((E32+E31)/2))) | F30: =IF(COUNT(F31,F32)<2,"",IF((F32+F31)=0,"",N(F28)/((F32+F31)/2))) | G30: =IF(COUNT(G31,G32)<2,"",IF((G32+G31)=0,"",N(G28)/((G32+G31)/2))) | H30: =IF(COUNT(H31,H32)<2,"",IF((H32+H31)=0,"",N(H28)/((H32+H31)/2))) | I30: =IF(COUNT(I31,I32)<2,"",IF((I32+I31)=0,"",N(I28)/((I32+I31)/2))) | J30: =IF(COUNT(J31,J32)<2,"",IF((J32+J31)=0,"",N(J28)/((J32+J31)/2))) | ... L30: =IF(COUNT(L31,L32)<2,"",IF((L32+L31)=0,"",N(L28)/((L32+L31)/2))) | M30: ϝ
B31: Headcount last Month | C31: =IF(NOV!C5="","",NOV!C5) | D31: =IF(NOV!D5="","",NOV!D5) | E31: =IF(NOV!E5="","",NOV!E5) | F31: =IF(NOV!F5="","",NOV!F5) | G31: =IF(NOV!G5="","",NOV!G5) | H31: =IF(NOV!H5="","",NOV!H5) | I31: =IF(NOV!I5="","",NOV!I5) | J31: =IF(NOV!J5="","",NOV!J5) | K31: =IF(NOV!K5="","",NOV!K5) | L31: =IF(COUNT(C31:K31)=0,"",SUM(C31:K31)) | M31: ∑
B32: Headcount this Month | C32: =IF(C5="","",C5) | D32: =IF(D5="","",D5) | E32: =IF(E5="","",E5) | F32: =IF(F5="","",F5) | G32: =IF(G5="","",G5) | H32: =IF(H5="","",H5) | I32: =IF(I5="","",I5) | J32: =IF(J5="","",J5) | K32: =IF(K5="","",K5) | L32: =IF(COUNT(C32:K32)=0,"",SUM(C32:K32)) | M32: ∑
B33: Full Turnover (%) | C33: =IF(COUNT(C31,C32)<2,"",IF((C32+C31)=0,"",N(C24)/((C32+C31)/2))) | D33: =IF(COUNT(D31,D32)<2,"",IF((D32+D31)=0,"",N(D24)/((D32+D31)/2))) | E33: =IF(COUNT(E31,E32)<2,"",IF((E32+E31)=0,"",N(E24)/((E32+E31)/2))) | F33: =IF(COUNT(F31,F32)<2,"",IF((F32+F31)=0,"",N(F24)/((F32+F31)/2))) | G33: =IF(COUNT(G31,G32)<2,"",IF((G32+G31)=0,"",N(G24)/((G32+G31)/2))) | H33: =IF(COUNT(H31,H32)<2,"",IF((H32+H31)=0,"",N(H24)/((H32+H31)/2))) | I33: =IF(COUNT(I31,I32)<2,"",IF((I32+I31)=0,"",N(I24)/((I32+I31)/2))) | J33: =IF(COUNT(J31,J32)<2,"",IF((J32+J31)=0,"",N(J24)/((J32+J31)/2))) | ... L33: =IF(COUNT(L31,L32)<2,"",IF((L32+L31)=0,"",N(L24)/((L32+L31)/2))) | M33: ϝ
B34: Permanent Vacancies | L34: =IF(COUNT(C34:K34)=0,"",SUM(C34:K34)) | M34: ∑
B35: Temporary Vacancies | L35: =IF(COUNT(C35:K35)=0,"",SUM(C35:K35)) | M35: ∑
B36: Total Vacancies | C36: =IF(COUNT(C34:C35)=0,"",SUM(C34:C35)) | D36: =IF(COUNT(D34:D35)=0,"",SUM(D34:D35)) | E36: =IF(COUNT(E34:E35)=0,"",SUM(E34:E35)) | F36: =IF(COUNT(F34:F35)=0,"",SUM(F34:F35)) | G36: =IF(COUNT(G34:G35)=0,"",SUM(G34:G35)) | H36: =IF(COUNT(H34:H35)=0,"",SUM(H34:H35)) | I36: =IF(COUNT(I34:I35)=0,"",SUM(I34:I35)) | J36: =IF(COUNT(J34:J35)=0,"",SUM(J34:J35)) | ... L36: =IF(COUNT(L34:L35)=0,"",SUM(L34:L35)) | M36: ϝ
B37: Authorized Positions | C37: =IF(COUNT(C5,C36)=0,"",N(C5)+N(C36)) | D37: =IF(COUNT(D5,D36)=0,"",N(D5)+N(D36)) | E37: =IF(COUNT(E5,E36)=0,"",N(E5)+N(E36)) | F37: =IF(COUNT(F5,F36)=0,"",N(F5)+N(F36)) | G37: =IF(COUNT(G5,G36)=0,"",N(G5)+N(G36)) | H37: =IF(COUNT(H5,H36)=0,"",N(H5)+N(H36)) | I37: =IF(COUNT(I5,I36)=0,"",N(I5)+N(I36)) | J37: =IF(COUNT(J5,J36)=0,"",N(J5)+N(J36)) | ... L37: =IF(COUNT(L5,L36)=0,"",N(L5)+N(L36)) | M37: ϝ
B38: Vacancy Rate (%) | C38: =IFERROR(C36/C37,"") | D38: =IFERROR(D36/D37,"") | E38: =IFERROR(E36/E37,"") | F38: =IFERROR(F36/F37,"") | G38: =IFERROR(G36/G37,"") | H38: =IFERROR(H36/H37,"") | I38: =IFERROR(I36/I37,"") | J38: =IFERROR(J36/J37,"") | ... L38: =IFERROR(L36/L37,"") | M38: ϝ
B39: Permanent TimeToHire (Days) YTD | C39: =IF('(GEL_Holding)'!$AB$6="","",'(GEL_Holding)'!$AB$6) | D39: =IF('(Dom_CLC)'!$AB$6="","",'(Dom_CLC)'!$AB$6) | E39: =IF('(Car_Label)'!$AB$6="","",'(Car_Label)'!$AB$6) | F39: =IF('(Ecuakao)'!$AB$6="","",'(Ecuakao)'!$AB$6) | G39: =IF('(Hipac)'!$AB$6="","",'(Hipac)'!$AB$6) | H39: =IF('(Jam_Label)'!$AB$6="","",'(Jam_Label)'!$AB$6) | I39: =IF('(Mc_Bride)'!$AB$6="","",'(Mc_Bride)'!$AB$6) | J39: =IF('(Precision)'!$AB$6="","",'(Precision)'!$AB$6) | K39: =IF('(Purity)'!$AB$6="","",'(Purity)'!$AB$6) | L39: =IFERROR(AVERAGE(C39:K39),"") | M39: Avg
B40: Temporary TimeToHire (Days) YTD | C40: =IF('(GEL_Holding)'!$AD$6="","",'(GEL_Holding)'!$AD$6) | D40: =IF('(Dom_CLC)'!$AD$6="","",'(Dom_CLC)'!$AD$6) | E40: =IF('(Car_Label)'!$AD$6="","",'(Car_Label)'!$AD$6) | F40: =IF('(Ecuakao)'!$AD$6="","",'(Ecuakao)'!$AD$6) | G40: =IF('(Hipac)'!$AD$6="","",'(Hipac)'!$AD$6) | H40: =IF('(Jam_Label)'!$AD$6="","",'(Jam_Label)'!$AD$6) | I40: =IF('(Mc_Bride)'!$AD$6="","",'(Mc_Bride)'!$AD$6) | J40: =IF('(Precision)'!$AD$6="","",'(Precision)'!$AD$6) | K40: =IF('(Purity)'!$AD$6="","",'(Purity)'!$AD$6) | L40: =IFERROR(AVERAGE(C40:K40),"") | M40: Avg
...

Sheet JAN
B1: MANUFACTURING
A2: =VALUE(TEXT(EDATE(DATE(LEFT(DEC!A2,4),RIGHT(DEC!A2,2),1),1),"yyyymm")) | B2: JAN | C2: GEL Manufacturing Holding Co. Ltd. | D2: CLC Domicana (Dominican Republic) | E2: Caribbean Label Crafts Ltd. (Barbados) | F2: Ecuakao (Ecuador) | G2: Hipac Ltd. (Barbados) | H2: Label Craft Jamaica Ltd. (Jamaica) | I2: McBride (Caribbean) Ltd. | J2: Precision Packaging Inc. (Barbados) | K2: Purity Bakeries Ltd. (Barbados) | L2: TOTAL | M2: Total by Division | N2: =N(N11)<>0
A3: =+A2 | B3: Permanent (Regular) Headcount | L3: =IF(COUNT(C3:K3)=0,"",SUM(C3:K3)) | M3: ∑
B4: Temporary (Fix Term) Headcount | L4: =IF(COUNT(C4:K4)=0,"",SUM(C4:K4)) | M4: ∑
B5: Employee Headcount (Productivity) | C5: =IF(COUNT(C3:C4)=0,"",SUM(C3:C4)) | D5: =IF(COUNT(D3:D4)=0,"",SUM(D3:D4)) | E5: =IF(COUNT(E3:E4)=0,"",SUM(E3:E4)) | F5: =IF(COUNT(F3:F4)=0,"",SUM(F3:F4)) | G5: =IF(COUNT(G3:G4)=0,"",SUM(G3:G4)) | H5: =IF(COUNT(H3:H4)=0,"",SUM(H3:H4)) | I5: =IF(COUNT(I3:I4)=0,"",SUM(I3:I4)) | J5: =IF(COUNT(J3:J4)=0,"",SUM(J3:J4)) | ... L5: =IF(COUNT(L3:L4)=0,"",SUM(L3:L4)) | M5: ϝ
B6: Headcount = 1.00 | L6: =IF(COUNT(C6:K6)=0,"",SUM(C6:K6)) | M6: ∑
B7: Headcount = 0.75 | L7: =IF(COUNT(C7:K7)=0,"",SUM(C7:K7)) | M7: ∑
B8: Headcount = 0.50 | L8: =IF(COUNT(C8:K8)=0,"",SUM(C8:K8)) | M8: ∑
B9: Headcount = 0.25 | L9: =IF(COUNT(C9:K9)=0,"",SUM(C9:K9)) | M9: ∑
B10: Standard Monthly Hours (FTE basis) | L10: =IFERROR(AVERAGE(C10:K10),"") | M10: Avg
B11: Employee FTE (Finance) | C11: =IF(COUNT(C6:C9)=0,"",N(C6)+N(C7)*0.75+N(C8)*0.5+N(C9)*0.25) | D11: =IF(COUNT(D6:D9)=0,"",N(D6)+N(D7)*0.75+N(D8)*0.5+N(D9)*0.25) | E11: =IF(COUNT(E6:E9)=0,"",N(E6)+N(E7)*0.75+N(E8)*0.5+N(E9)*0.25) | F11: =IF(COUNT(F6:F9)=0,"",N(F6)+N(F7)*0.75+N(F8)*0.5+N(F9)*0.25) | G11: =IF(COUNT(G6:G9)=0,"",N(G6)+N(G7)*0.75+N(G8)*0.5+N(G9)*0.25) | H11: =IF(COUNT(H6:H9)=0,"",N(H6)+N(H7)*0.75+N(H8)*0.5+N(H9)*0.25) | I11: =IF(COUNT(I6:I9)=0,"",N(I6)+N(I7)*0.75+N(I8)*0.5+N(I9)*0.25) | J11: =IF(COUNT(J6:J9)=0,"",N(J6)+N(J7)*0.75+N(J8)*0.5+N(J9)*0.25) | ... L11: =IF(COUNT(L6:L9)=0,"",N(L6)+N(L7)*0.75+N(L8)*0.5+N(L9)*0.25) | M11: FTE | N11: =IF(COUNT(L5:L9)=0,"",N(L6)+N(L7)+N(L8)+N(L9)-N(L5))
B12: Subcontracted Workforce HC | L12: =IF(COUNT(C12:K12)=0,"",SUM(C12:K12)) | M12: ∑
B13: Subcontracted Productive Hours | L13: =IF(COUNT(C13:K13)=0,"",SUM(C13:K13)) | M13: ∑
B14: Subcontracted FTE | C14: =IFERROR(C13/C10,"") | D14: =IFERROR(D13/D10,"") | E14: =IFERROR(E13/E10,"") | F14: =IFERROR(F13/F10,"") | G14: =IFERROR(G13/G10,"") | H14: =IFERROR(H13/H10,"") | I14: =IFERROR(I13/I10,"") | J14: =IFERROR(J13/J10,"") | K14: =IFERROR(K13/K10,"") | L14: =IF(COUNT(C14:K14)=0,"",SUM(C14:K14)) | M14: FTE
B15: Total Operational Workforce | C15: =IF(COUNT(C5,C12)=0,"",SUM(C5,C12)) | D15: =IF(COUNT(D5,D12)=0,"",SUM(D5,D12)) | E15: =IF(COUNT(E5,E12)=0,"",SUM(E5,E12)) | F15: =IF(COUNT(F5,F12)=0,"",SUM(F5,F12)) | G15: =IF(COUNT(G5,G12)=0,"",SUM(G5,G12)) | H15: =IF(COUNT(H5,H12)=0,"",SUM(H5,H12)) | I15: =IF(COUNT(I5,I12)=0,"",SUM(I5,I12)) | J15: =IF(COUNT(J5,J12)=0,"",SUM(J5,J12)) | ... L15: =IF(COUNT(L5,L12)=0,"",SUM(L5,L12)) | M15: ϝ
B16: Total Operational FTE | C16: =IF(COUNT(C11,C14)=0,"",SUM(C11,C14)) | D16: =IF(COUNT(D11,D14)=0,"",SUM(D11,D14)) | E16: =IF(COUNT(E11,E14)=0,"",SUM(E11,E14)) | F16: =IF(COUNT(F11,F14)=0,"",SUM(F11,F14)) | G16: =IF(COUNT(G11,G14)=0,"",SUM(G11,G14)) | H16: =IF(COUNT(H11,H14)=0,"",SUM(H11,H14)) | I16: =IF(COUNT(I11,I14)=0,"",SUM(I11,I14)) | J16: =IF(COUNT(J11,J14)=0,"",SUM(J11,J14)) | ... L16: =IF(COUNT(L11,L14)=0,"",SUM(L11,L14)) | M16: FTE
B17: Subcontracted Share of Workforce (%) | C17: =IFERROR(C12/C15,"") | D17: =IFERROR(D12/D15,"") | E17: =IFERROR(E12/E15,"") | F17: =IFERROR(F12/F15,"") | G17: =IFERROR(G12/G15,"") | H17: =IFERROR(H12/H15,"") | I17: =IFERROR(I12/I15,"") | J17: =IFERROR(J12/J15,"") | ... L17: =IFERROR(L12/L15,"") | M17: ϝ
B18: FTE HR Team | L18: =IF(COUNT(C18:K18)=0,"",SUM(C18:K18)) | M18: ∑
B19: Permanent Hires | L19: =IF(COUNT(C19:K19)=0,"",SUM(C19:K19)) | M19: ∑
B20: Temporary Hires | L20: =IF(COUNT(C20:K20)=0,"",SUM(C20:K20)) | M20: ∑
B21: Total Hires | C21: =IF(COUNT(C19:C20)=0,"",SUM(C19:C20)) | D21: =IF(COUNT(D19:D20)=0,"",SUM(D19:D20)) | E21: =IF(COUNT(E19:E20)=0,"",SUM(E19:E20)) | F21: =IF(COUNT(F19:F20)=0,"",SUM(F19:F20)) | G21: =IF(COUNT(G19:G20)=0,"",SUM(G19:G20)) | H21: =IF(COUNT(H19:H20)=0,"",SUM(H19:H20)) | I21: =IF(COUNT(I19:I20)=0,"",SUM(I19:I20)) | J21: =IF(COUNT(J19:J20)=0,"",SUM(J19:J20)) | ... L21: =IF(COUNT(L19:L20)=0,"",SUM(L19:L20)) | M21: ϝ
B22: Permanent Exits | L22: =IF(COUNT(C22:K22)=0,"",SUM(C22:K22)) | M22: ∑
B23: Temporary Exits | L23: =IF(COUNT(C23:K23)=0,"",SUM(C23:K23)) | M23: ∑
B24: Total Exits | C24: =IF(COUNT(C22:C23)=0,"",SUM(C22:C23)) | D24: =IF(COUNT(D22:D23)=0,"",SUM(D22:D23)) | E24: =IF(COUNT(E22:E23)=0,"",SUM(E22:E23)) | F24: =IF(COUNT(F22:F23)=0,"",SUM(F22:F23)) | G24: =IF(COUNT(G22:G23)=0,"",SUM(G22:G23)) | H24: =IF(COUNT(H22:H23)=0,"",SUM(H22:H23)) | I24: =IF(COUNT(I22:I23)=0,"",SUM(I22:I23)) | J24: =IF(COUNT(J22:J23)=0,"",SUM(J22:J23)) | ... L24: =IF(COUNT(L22:L23)=0,"",SUM(L22:L23)) | M24: ϝ
B25: Permanent Turnover (%) | C25: =IF(COUNT(C31,C32)<2,"",IF((C32+C31)=0,"",N(C22)/((C32+C31)/2))) | D25: =IF(COUNT(D31,D32)<2,"",IF((D32+D31)=0,"",N(D22)/((D32+D31)/2))) | E25: =IF(COUNT(E31,E32)<2,"",IF((E32+E31)=0,"",N(E22)/((E32+E31)/2))) | F25: =IF(COUNT(F31,F32)<2,"",IF((F32+F31)=0,"",N(F22)/((F32+F31)/2))) | G25: =IF(COUNT(G31,G32)<2,"",IF((G32+G31)=0,"",N(G22)/((G32+G31)/2))) | H25: =IF(COUNT(H31,H32)<2,"",IF((H32+H31)=0,"",N(H22)/((H32+H31)/2))) | I25: =IF(COUNT(I31,I32)<2,"",IF((I32+I31)=0,"",N(I22)/((I32+I31)/2))) | J25: =IF(COUNT(J31,J32)<2,"",IF((J32+J31)=0,"",N(J22)/((J32+J31)/2))) | ... L25: =IF(COUNT(L31,L32)<2,"",IF((L32+L31)=0,"",N(L22)/((L32+L31)/2))) | M25: ϝ
B26: Temporary Turnover (%) | C26: =IF(COUNT(C31,C32)<2,"",IF((C32+C31)=0,"",N(C23)/((C32+C31)/2))) | D26: =IF(COUNT(D31,D32)<2,"",IF((D32+D31)=0,"",N(D23)/((D32+D31)/2))) | E26: =IF(COUNT(E31,E32)<2,"",IF((E32+E31)=0,"",N(E23)/((E32+E31)/2))) | F26: =IF(COUNT(F31,F32)<2,"",IF((F32+F31)=0,"",N(F23)/((F32+F31)/2))) | G26: =IF(COUNT(G31,G32)<2,"",IF((G32+G31)=0,"",N(G23)/((G32+G31)/2))) | H26: =IF(COUNT(H31,H32)<2,"",IF((H32+H31)=0,"",N(H23)/((H32+H31)/2))) | I26: =IF(COUNT(I31,I32)<2,"",IF((I32+I31)=0,"",N(I23)/((I32+I31)/2))) | J26: =IF(COUNT(J31,J32)<2,"",IF((J32+J31)=0,"",N(J23)/((J32+J31)/2))) | ... L26: =IF(COUNT(L31,L32)<2,"",IF((L32+L31)=0,"",N(L23)/((L32+L31)/2))) | M26: ϝ
B27: Voluntary Terminations | L27: =IF(COUNT(C27:K27)=0,"",SUM(C27:K27)) | M27: ∑
B28: Involuntary Terminations | L28: =IF(COUNT(C28:K28)=0,"",SUM(C28:K28)) | M28: ∑
